Workbook

Sheet README
A1: Overview Analysis v2 — Formula-Driven Supporting Data + Clickable Sources
A2: Seven charts. Source data on the Source_Deals + Source_Pipeline tabs. Chart tabs reference source data via SUMIF / COUNTIFS. Hyperlinks on footers.
A4: Chart | B4: Title | C4: Source tab
A5: Chart 1 | B5: The Capital–Output Gap (formula-driven from Source_Deals) | C5: Source_Deals
A6: Chart 2 | B6: Pipeline Funnel: 82 → 0 (formula-driven from Source_Pipeline) | C6: Source_Pipeline
A7: Chart 3 | B7: Cumulative trials mentioning AI on CT.gov (broad — includes AI-as-tool) | C7: ClinicalTrials.gov + bibliometrics
A8: Chart 3b | B8: Cumulative AI-discovered drug trials ONLY (narrow — molecule-level) | C8: Source_Pipeline + 2025–26 additions
A9: Chart 4 | B9: Pharma × AI Partner Matrix (formula-driven COUNTIFS) | C9: Source_Deals
A10: Chart 5 | B10: Coverage Universe Scorecard | C10: Source_Deals + Q1 matrix
A11: Chart 6 | B11: Deal economics evolution (formula-driven from Source_Deals) | C11: Source_Deals
A14: Methodology
A15: • Source_Deals tab carries the 70-row Deals table from 01_Matrix_Master.xlsx Deals tab. Chart tabs reference it via SUMIF/COUNTIF/COUNTIFS so cells are formula-driven, not hardcoded.
A16: • Source_Pipeline tab carries the 82-molecule AI Pipeline Tracker scorecard PLUS 4 new additions verified in fact-check (see Fact_Check_Report).
A17: • Palette: navy primary, light navy + steel blue + sky blue for series differentiation, cool gray de-emphasis. No red anywhere.
A18: • All footer source citations are clickable hyperlinks.
A20: Note (added 2026-05-12 fact-check pass): DL-071 LLY × Insilico Rentosertib added to Source_Deals — was previously referenced in Q1 (RD-015) but missing from Q4 Deals tab. Material correction. See Fact_Check_Report.md.

Sheet Source_Deals
A1: Source data — Deals (70 rows from 01_Matrix_Master.xlsx → Deals tab)
A2: All Chart_1, Chart_4, Chart_6 calculations reference this tab via SUMIF / COUNTIFS.
A4: claim_id | B4: deal_date | C4: year | D4: pharma_counterparty | E4: ai_counterparty | F4: deal_type | G4: upfront_usd_mm | H4: total_biobucks_usd_mm | I4: equity_component | J4: equity_flag_01 | K4: program_scope | L4: evidence_tier | M4: source_url
A5: DL-001 | B5: 2024-01-07 | C5: 2024 | D5: Eli Lilly | E5: Isomorphic Labs | F5: collaboration | G5: 45 | H5: 1700 | I5: FALSE | J5: 0 | K5: multi-target | L5: 1 | M5: https://www.prnewswire.com/news-releases/isomorphic-labs-announces-strategic-multi-target-research-collaboration-with-lilly-302027392.html
A6: DL-002 | B6: 2024-01-07 | C6: 2024 | D6: Novartis | E6: Isomorphic Labs | F6: collaboration | G6: 37.5 | H6: 1200 | I6: FALSE | J6: 0 | K6: multi-target | L6: 1 | M6: https://www.prnewswire.com/news-releases/isomorphic-labs-announces-strategic-multi-target-research-collaboration-with-novartis-302027387.html
A7: DL-003 | B7: 2022-01-06 | C7: 2022 | D7: Amgen | E7: Generate Biomedicines | F7: collaboration | G7: 50 | H7: 1900 | I7: TRUE | J7: 1 | K7: multi-target | L7: 1 | M7: https://www.amgen.com/newsroom/press-releases/2022/01/amgen-and-generate-biomedicines-announce-multitarget-multimodality-research-collaboration-agreement
A8: DL-004 | B8: 2021-12-07 | C8: 2021 | D8: Roche/Genentech | E8: Recursion | F8: platform partnership | G8: 150 | H8: 12000 | I8: FALSE | J8: 0 | K8: platform | L8: 1 | M8: https://ir.recursion.com/news-releases/news-release-details/recursion-announces-transformational-collaboration-roche-and
A9: DL-005 | B9: 2022-11-08 | C9: 2022 | D9: Sanofi | E9: Insilico Medicine | F9: collaboration | G9: 21.5 | H9: 1200 | I9: FALSE | J9: 0 | K9: multi-target | L9: 1 | M9: https://www.globenewswire.com/news-release/2022/11/08/2551039/31533/en/Insilico-Medicine-Signs-Strategic-Research-Collaboration-with-Sanofi-worth-up-to-1-2-Billion.html
A10: DL-006 | B10: 2024-06-25 | C10: 2024 | D10: Eli Lilly | E10: OpenAI | F10: collaboration | I10: FALSE | J10: 0 | K10: multi-target | L10: 1 | M10: https://investor.lilly.com/news-releases/news-release-details/lilly-collaborates-openai-discover-novel-medicines-treat-drug
A11: DL-007 | B11: 2023-05-30 | C11: 2023 | D11: Eli Lilly | E11: XtalPi | F11: collaboration | H11: 250 | I11: FALSE | J11: 0 | K11: single target | L11: 1 | M11: https://www.prnewswire.com/news-releases/xtalpi-announces-collaboration-with-lilly-using-ai--robotics-to-uncover-first-in-class-therapeutics-301837142.html
A12: DL-008 | B12: 2021-07-08 | C12: 2021 | D12: Eli Lilly | E12: Verge Genomics | F12: collaboration | G12: 25 | H12: 694 | I12: TRUE | J12: 1 | K12: multi-target | L12: 1 | M12: https://www.businesswire.com/news/home/20210708005085/en/Verge-Genomics-Announces-Three-Year-Collaboration-With-Lilly-to-Discover-and-Develop-Novel-Treatments-Using-Its-AI-Driven-All-in-Human-Platform
A13: DL-009 | B13: 2024-09-05 | C13: 2024 | D13: Eli Lilly | E13: Genetic Leap | F13: collaboration | H13: 409 | I13: FALSE | J13: 0 | K13: multi-target | L13: 1 | M13: https://www.prnewswire.com/news-releases/genetic-leap-and-lilly-enter-collaboration-to-accelerate-genetic-medicine-development-with-ai-302239471.html
A14: DL-010 | B14: 2019-06-04 | C14: 2019 | D14: Eli Lilly | E14: Atomwise | F14: collaboration | H14: 560 | I14: FALSE | J14: 0 | K14: multi-target | L14: 1 | M14: https://www.genengnews.com/topics/artificial-intelligence/lilly-inks-up-to-560m-ai-drug-discovery-collaboration-with-atomwise/
A15: DL-011 | B15: 2020-03-13 | C15: 2020 | D15: Eli Lilly | E15: AbCellera | F15: collaboration | I15: FALSE | J15: 0 | K15: multi-target | L15: 1 | M15: https://investors.abcellera.com/news/news-releases/2020/AbCellera-Announces-Multi-Year-Antibody-Discovery-Collaboration-with-Lilly/default.aspx
A16: DL-012 | B16: 2020-12-31 | C16: 2020 | D16: Eli Lilly | E16: AbCellera | F16: license | I16: FALSE | J16: 0 | K16: single target | L16: 1 | M16: https://www.theglobeandmail.com/business/article-abcellera-made-200-million-in-royalties-from-its-covid-19-treatment/
A17: DL-013 | B17: 2024-07-31 | C17: 2024 | D17: Eli Lilly | E17: AbCellera | F17: collaboration | I17: FALSE | J17: 0 | K17: multi-target | L17: 1 | M17: https://investors.abcellera.com/news/news-releases/2024/AbCellera-and-Lilly-Expand-Collaboration-to-Develop-Antibody-Medicines/default.aspx
A18: DL-014 | B18: 2021-05-19 | C18: 2021 | D18: Bristol Myers Squibb | E18: Exscientia | F18: collaboration | G18: 50 | H18: 1200 | I18: FALSE | J18: 0 | K18: multi-target | L18: 1 | M18: https://www.businesswire.com/news/home/20210519005180/en/Exscientia-announces-multi-target-AI-driven-drug-discovery-collaboration-with-Bristol-Myers-Squibb
A19: DL-015 | B19: 2020-04-15 | C19: 2020 | D19: Bristol Myers Squibb | E19: Insitro | F19: collaboration | G19: 50 | H19: 2070 | I19: FALSE | J19: 0 | K19: multi-target | L19: 1 | M19: https://www.goodwinlaw.com/en/news-and-events/news/2020/10/10_28-insitro-announces
A20: DL-016 | B20: 2022-09-20 | C20: 2022 | D20: Pfizer | E20: CytoReason | F20: collaboration | G20: 20 | H20: 110 | I20: TRUE | J20: 1 | K20: platform | L20: 1 | M20: https://www.pfizer.com/news/press-release/press-release-detail/cytoreason-announces-expanded-collaboration-deal-pfizer
A21: DL-017 | B21: 2019-12-12 | C21: 2019 | D21: Pfizer | E21: CytoReason | F21: collaboration | I21: FALSE | J21: 0 | K21: platform | L21: 1 | M21: https://www.pfizer.com/news/press-release/press-release-detail/cytoreason-signs-collaboration-agreement-pfizer-inc-utilize
A22: DL-018 | B22: 2018-09-17 | C22: 2018 | D22: Pfizer | E22: Atomwise | F22: research services | I22: FALSE | J22: 0 | K22: multi-target | L22: 1 | M22: https://www.businesswire.com/news/home/20180917005163/en/Atomwise-Enters-Evaluation-Agreement-Pfizer
A23: DL-019 | B23: 2022-01-11 | C23: 2022 | D23: Pfizer | E23: PostEra | F23: platform partnership | G23: 13 | H23: 260 | I23: FALSE | J23: 0 | K23: platform | L23: 1 | M23: https://www.prnewswire.com/news-releases/postera-announces-260m-multi-target-strategic-ai-lab-collaboration-with-pfizer-301457261.html
A24: DL-020 | B24: 2025-01-13 | C24: 2025 | D24: Pfizer | E24: PostEra | F24: platform partnership | H24: 610 | I24: FALSE | J24: 0 | K24: platform | L24: 1 | M24: https://www.prnewswire.com/news-releases/postera-announces-expansion-to-610m-in-their-ai-drug-discovery-collaboration-with-pfizer-302342047.html
A25: DL-021 | B25: 2023-09-19 | C25: 2023 | D25: Merck KGaA | E25: BenevolentAI | F25: collaboration | G25: 15 | H25: 594 | I25: FALSE | J25: 0 | K25: multi-target | L25: 1 | M25: https://www.businesswire.com/news/home/20230919017658/en/BenevolentAI-Signs-Strategic-Collaboration-with-Merck
A26: DL-022 | B26: 2023-09-19 | C26: 2023 | D26: Merck KGaA | E26: Exscientia | F26: collaboration | G26: 20 | H26: 674 | I26: FALSE | J26: 0 | K26: multi-target | L26: 1 | M26: https://investors.exscientia.ai/press-releases/press-release-details/2023/Exscientia-Announces-AI-Drug-Discovery-Collaboration-with-Merck-KGaA-Darmstadt-Germany/default.aspx
A27: DL-023 | B27: 2025-09-23 | C27: 2025 | D27: Merck & Co (MRK) | E27: Variational AI | F27: collaboration | H27: 349 | I27: FALSE | J27: 0 | K27: multi-target | L27: 1 | M27: https://www.businesswire.com/news/home/20250923751722/en/Variational-AI-Enters-Collaboration-with-Merck-to-Apply-Generative-AI-to-Drug-Discovery
A28: DL-024 | B28: 2022-01-12 | C28: 2022 | D28: Merck & Co (MRK) | E28: Absci | F28: collaboration | H28: 610 | I28: FALSE | J28: 0 | K28: multi-target | L28: 1 | M28: https://www.absci.com/partnerships/
A29: DL-025 | B29: 2020-11-23 | C29: 2020 | D29: Bristol Myers Squibb | E29: Schrödinger | F29: collaboration | G29: 55 | H29: 2700 | I29: FALSE | J29: 0 | K29: multi-target | L29: 1 | M29: https://ir.schrodinger.com/press-releases/news-details/2020/Schrdinger-Announces-a-Multi-Target-Drug-Discovery-Development-and-Commercialization-Collaboration-with-Bristol-Myers-Squibb-11-23-2020/default.aspx
A30: DL-026 | B30: 2024-11-12 | C30: 2024 | D30: Novartis | E30: Schrödinger | F30: platform partnership | G30: 150 | H30: 2270 | I30: FALSE | J30: 0 | K30: multi-target | L30: 1 | M30: https://ir.schrodinger.com/press-releases/news-details/2024/Schrdinger-Announces-Multi-Target-Collaboration-and-Expanded-Software-Licensing-Agreement-with-Novartis/default.aspx
A31: DL-027 | B31: 2023-01-10 | C31: 2023 | D31: Otsuka | E31: Schrödinger | F31: collaboration | I31: FALSE | J31: 0 | K31: single target | L31: 1 | M31: https://www.otsuka.co.jp/en/company/newsreleases/2023/20230110_1.html
A32: DL-028 | B32: 2022-04-19 | C32: 2022 | D32: Eli Lilly | E32: Schrödinger | F32: collaboration | H32: 425 | I32: FALSE | J32: 0 | K32: single target | L32: 1 | M32: https://thehealthcaretechnologyreport.com/eli-lilly-enters-into-425m-small-molecule-arrangement-with-schrodinger/
A33: DL-029 | B33: 2020-01-13 | C33: 2020 | D33: Bayer | E33: Exscientia | F33: collaboration | H33: 265 | I33: FALSE | J33: 0 | K33: multi-target | L33: 1 | M33: https://investors.exscientia.ai/press-releases/press-release-details/2020/Bayer-and-Exscientia-collaborate-to-leverage-the-potential-of-artificial-intelligence-in-cardiovascular-and-oncology-drug-discovery/default.aspx
A34: DL-030 | B34: 2020-09-09 | C34: 2020 | D34: Bayer | E34: Recursion | F34: collaboration | G34: 30 | H34: 1080 | I34: TRUE | J34: 1 | K34: multi-target | L34: 1 | M34: https://recursion.com/news/bayer-partnership
A35: DL-031 | B35: 2023-11-09 | C35: 2023 | D35: Bayer | E35: Recursion | F35: collaboration | H35: 1500 | I35: FALSE | J35: 0 | K35: multi-target | L35: 1 | M35: https://www.globenewswire.com/news-release/2023/11/09/2777499/0/en/Bayer-and-Recursion-Focus-Research-Collaboration-on-Oncology.html
A36: DL-032 | B36: 2019-04-30 | C36: 2019 | D36: AstraZeneca | E36: BenevolentAI | F36: collaboration | I36: FALSE | J36: 0 | K36: multi-target | L36: 1 | M36: https://www.astrazeneca.com/media-centre/press-releases/2019/astrazeneca-starts-artificial-intelligence-collaboration-to-accelerate-drug-discovery-30042019.html
A37: DL-033 | B37: 2022-01-04 | C37: 2022 | D37: AstraZeneca | E37: BenevolentAI | F37: collaboration | I37: FALSE | J37: 0 | K37: multi-target | L37: 1 | M37: https://www.benevolent.com/news-and-media/press-releases-and-in-media/benevolentai-announces-3-year-collaboration-expansion-astrazeneca-focused-systemic-lupus-erythematosus-and-heart-failure/
A38: DL-034 | B38: 2023-12-04 | C38: 2023 | D38: AstraZeneca | E38: Absci | F38: collaboration | H38: 247 | I38: FALSE | J38: 0 | K38: single target | L38: 1 | M38: https://investors.absci.com/news-releases/news-release-details/absci-announces-collaboration-astrazeneca-advance-ai-driven
A39: DL-035 | B39: 2023-09-25 | C39: 2023 | D39: AstraZeneca | E39: Verge Genomics | F39: collaboration | H39: 840 | I39: TRUE | J39: 1 | K39: multi-target | L39: 1 | M39: https://www.polsinelli.com/news/polsinelli-represents-verge-genomics-in-ai-enabled-drug-discovery-collaboration-with-alexion-astrazeneca-rare-disease-worth-up-to-840-million
A40: DL-036 | B40: 2022-10-25 | C40: 2022 | D40: GSK | E40: Tempus AI | F40: license | G40: 70 | H40: 70 | I40: FALSE | J40: 0 | K40: platform | L40: 1 | M40: https://www.gsk.com/en-gb/media/press-releases/gsk-announces-expanded-collaboration-with-tempus-in-precision-medicine-to-accelerate-rd/
A41: DL-037 | B41: 2020-12-01 | C41: 2020 | D41: GSK | E41: Cerebras | F41: platform partnership | I41: FALSE | J41: 0 | K41: platform | L41: 1 | M41: https://www.gsk.ai/publications/epigenomic-language-models-powered-by-cerebras/
...

Sheet Source_Pipeline
A1: Source data — AI Pipeline (82 from Jayatunga 2024 + 4 new additions verified via fact-check)
A2: Chart 2, Chart 3b reference this tab. Outcome category drives funnel; first-in-human year drives the cumulative cohort chart.
A4: asset_name | B4: company | C4: modality | D4: target | E4: indication | F4: ai_mode | G4: highest_phase | H4: outcome | I4: first_in_human_year | J4: source | K4: status_note | L4: nct_or_url
A5: Zasocitinib (NDI-034858) | B5: Nimbus / Takeda | C5: Small molecule | D5: TYK2 | E5: Plaque Psoriasis | F5: Small molecule design (FEP+) | G5: Phase III | H5: Clear winner | I5: 2019 | J5: Jayatunga | K5: Phase III (Dec 2025): all co-primary + 44 secondary endpoints met. >50% PASI 90 at wk 16, ~30% PASI 100. Beat placebo + apremilast. $4B + $2B milestones.
A6: Rentosertib (INS018-055) | B6: Insilico Medicine | C6: Small molecule | D6: TNIK | E6: IPF | F6: Generative AI (target + molecule) | G6: Phase IIa → III | H6: Clear winner | I6: 2022 | J6: Jayatunga | K6: +98.4 mL FVC improvement vs. -62.3 mL placebo. Published Nature Medicine Jun 2025. Lilly signed $2.75B deal Mar 2026. 18-mo target-to-IND.
A7: Rilvegostomig | B7: Compugen / AstraZeneca | C7: Antibody | D7: PD-1/TIGIT bispecific | E7: NSCLC, Gastric | F7: Computational target discovery | G7: Phase 1b → III | H7: Positive but early | I7: 2021 | J7: Jayatunga | K7: 57.5% ORR + 95% DCR in 1L NSCLC (combo w/ Datroway). Licensed to AZ. Multiple Phase III trials. Note: TIGIT co-discovered by 3 groups in 2009 using bioinformatics.
A8: Dexmedetomidine (BXCL-501) | B8: BioXcel Therapeutics | C8: Small molecule | D8: Adrenoceptor alpha 2A | E8: Agitation in dementia | F8: Repurposing | G8: Phase III | H8: Successful (completed phase) | I8: 2014 | J8: Jayatunga | K8: TRANQUILITY II Phase 3 met primary + all secondary endpoints for Alzheimer's-related agitation. FDA approved.
A9: REC-4881 | B9: Recursion | C9: Small molecule | D9: MEK1/2 | E9: FAP / AXIN1/APC Cancers | F9: Repurposing | G9: Phase 1b/2 | H9: Clear winner | I9: 2022 | J9: Jayatunga | K9: TUPELO: 75% polyp burden reduction. 53% median reduction sustained at wk 25 post-discontinuation. Clean safety.
A10: EVX-01 | B10: Evaxion Biotech | C10: Vaccine | D10: Neoantigen vaccine | E10: Melanoma | F10: Vaccine design (AI neoantigen prediction) | G10: Phase II | H10: Clear winner | I10: 2021 | J10: Jayatunga | K10: Combo w/ Keytruda: 75% ORR at 2 yrs. 4 CRs / 16 pts. 92% responders durable at 24 mo. AI predicted T-cell response in 81%.
A11: SGR-1505 | B11: Schrödinger | C11: Small molecule | D11: MALT1 | E11: B-cell Neoplasms | F11: Small molecule design (FEP+) | G11: Phase I | H11: Clear winner | I11: 2022 | J11: Jayatunga | K11: 49 pts. Well-tolerated, no DLTs. Responses across CLL, Waldenström's, MZL. FDA Fast Track designation (EHA 2025).
A12: SGR-2921 | B12: Schrödinger | C12: Small molecule | D12: CDC7 | E12: AML/MDS | F12: Small molecule design (FEP+) | G12: Phase I | H12: Failed / Terminated | I12: 2022 | J12: Jayatunga | K12: Two treatment-related patient deaths in Phase I dose escalation. Shut down Aug 2025.
A13: REC-2282 | B13: Recursion | C13: Small molecule | D13: HDAC | E13: NF2 Meningiomas | F13: Repurposing | G13: Phase II | H13: Failed / Terminated | I13: 2020 | J13: Jayatunga | K13: Phase II passed futility threshold in 40mg cohort. Limited tumor shrinkage.
A14: GV20-0251 | B14: GV20 Therapeutics | C14: Antibody | D14: IGSF8 | E14: Solid Tumors | F14: Antibody design | G14: Phase I | H14: Positive but early | I14: 2023 | J14: Jayatunga | K14: 38 pts. No DLTs up to 20 mg/kg. 2 confirmed PRs in metastatic melanoma (12 evaluable).
A15: ISM5411 | B15: Insilico Medicine | C15: Small molecule | D15: PHD inhibitor | E15: IBD (UC) | F15: Generative AI (molecule design) | G15: Phase I → II | H15: Clear winner | I15: 2021 | J15: Jayatunga | K15: Positive in 2 Phase I trials (AU + CN). Gut-restricted PK, no serious AEs. Designed in 12 mo, ~115 molecules.
A16: TOS-358 | B16: Totus Medicines | C16: Small molecule | D16: PI3Kα | E16: Solid Tumors (breast) | F16: Small molecule design | G16: Phase I (expansion) | H16: Clear winner | I16: 2023 | J16: Jayatunga | K16: 50% CBR. 75% DCR in PI3Kα-mutant breast CA. No bone marrow/liver/ocular/skin tox — major differentiator vs. older PI3Ki.
... A24: A2A-252 | B24: A2A Pharmaceuticals | C24: Small molecule | D24: TACC3 | E24: Solid Tumors | F24: Small molecule design | G24: Phase I | H24: Positive but early | I24: 2023 | J24: Jayatunga | K24: 22% avg tumor reduction in 67% of pts at <1/3 MTD (Bernstein Ex 14).
A25: BMF-219 | B25: A2A Pharma / Biomea Fusion | C25: Small molecule | F25: Small molecule design | G25: Phase I/II | H25: Ongoing | I25: 2022 | J25: Jayatunga | K25: Ph I successful, Ph I/II ongoing.
A26: Monoclonal antibodies, Teva | B26: AbCellera Biologics | C26: Antibody | F26: Antibody design | G26: Phase I | H26: Ongoing | I26: 2023 | J26: Jayatunga
A27: AC-682 | B27: Accutar Biotechnology | C27: Small molecule | F27: Small molecule design | G27: Phase I | H27: Ongoing | I27: 2023 | J27: Jayatunga
A28: AC-0176 | B28: Accutar Biotechnology | C28: Small molecule | F28: Small molecule design | G28: Phase I | H28: Ongoing | I28: 2023 | J28: Jayatunga
A29: AC-0676 | B29: Accutar Biotechnology | C29: Small molecule | D29: BTK Degrader | E29: Heme malignancies | F29: Small molecule design | G29: Phase I | H29: Positive but early | I29: 2023 | J29: Jayatunga | K29: First patient dosed Jun 2023. No public results.
A30: AC-699 | B30: Accutar Biotechnology | C30: Small molecule | F30: Small molecule design | G30: Phase I | H30: Ongoing | I30: 2023 | J30: Jayatunga
A31: ATH-63 | B31: Athos Therapeutics | C31: Small molecule | F31: Target discovery + molecule design | G31: Phase I | H31: Ongoing | I31: 2023 | J31: Jayatunga
A32: AU-409 | B32: Auransa | C32: Small molecule | D32: Undisclosed | E32: HCC | F32: Target discovery | G32: Phase I | H32: Positive but early | I32: 2023 | J32: Jayatunga | K32: First patient dosed 2023 USC Norris. No results yet.
A33: BEN-2293 | B33: BenevolentAI | C33: Small molecule | D33: Pan-TRK | E33: Atopic dermatitis | F33: Target discovery | G33: Phase I/II | H33: Failed / Terminated | I33: 2020 | J33: Jayatunga | K33: Ph I successful but Ph II unsuccessful.
A34: BEN-8744 | B34: BenevolentAI | C34: Small molecule | F34: Target discovery | G34: Phase I | H34: Ongoing | I34: 2023 | J34: Jayatunga
A35: Bavisant | B35: BenevolentAI | C35: Small molecule | F35: Repurposing | G35: Phase II | H35: Failed / Terminated | I35: 2021 | J35: Jayatunga | K35: Phase completed but asset removed from pipeline.
A36: BGE-105 (Azelaprag) | B36: BioAge Labs | C36: Small molecule | D36: Apelin receptor | E36: Obesity | F36: Repurposing | G36: Phase II | H36: Failed / Terminated | I36: 2021 | J36: Jayatunga | K36: Elevated liver enzymes. BioAge shut down program after IPO.
A37: AU-007 | B37: Biolojic Design / Aulos | C37: Antibody | D37: IL-2 | E37: Solid Tumors | F37: Antibody design | G37: Phase I/II | H37: Ongoing | I37: 2022 | J37: Jayatunga | K37: Ph I successful, Ph I/II ongoing.
A38: Talabostat (BXCL-701) | B38: BioXcel Therapeutics | C38: Small molecule | F38: Repurposing | G38: Phase IIb | H38: Ongoing | I38: 2021 | J38: Jayatunga | K38: Successful Phase IIa; now Phase IIb.
A39: BDTX-1535 | B39: Black Diamond Therapeutics | C39: Small molecule | D39: EGFR | F39: Target discovery | G39: Phase I/II | H39: Ongoing | I39: 2022 | J39: Jayatunga | K39: Ph I successful, Ph I/II ongoing.
A40: BDTX-189 | B40: Black Diamond Therapeutics | C40: Small molecule | D40: EGFR/HER2 | F40: Target discovery | G40: Phase I/II | H40: Failed / Terminated | I40: 2022 | J40: Jayatunga | K40: Ph I successful but Ph II terminated (reprioritisation).
A41: BDTX-4933 | B41: Black Diamond Therapeutics | C41: Small molecule | F41: Target discovery | G41: Phase I | H41: Ongoing | I41: 2023 | J41: Jayatunga
A42: C4X_3256/INDV-2000 | B42: C4X Discovery / Indivior | C42: Small molecule | F42: Small molecule design | G42: Phase I | H42: Ongoing | I42: 2023 | J42: Jayatunga
A43: CEL-383 | B43: Celsius Therapeutics | C43: Antibody | F43: Target discovery | G43: Phase I | H43: Ongoing | I43: 2023 | J43: Jayatunga
A44: Bapotulimab | B44: Compugen | C44: Antibody | E44: Oncology | F44: Target discovery | G44: Phase I | H44: Ongoing | I44: 2023 | J44: Jayatunga
A45: COM-701 | B45: Compugen | C45: Antibody | F45: Target discovery | G45: Phase I | H45: Ongoing | I45: 2023 | J45: Jayatunga
A46: Influenza vaccine H7N9 | B46: EpiVax | C46: Vaccine | F46: Vaccine design | G46: Phase I | H46: Ongoing | I46: 2023 | J46: Jayatunga
A47: EVX-02 | B47: Evaxion Biotech | C47: Vaccine | E47: Cancer immunotherapy | F47: Vaccine design | G47: Phase I | H47: Failed / Terminated | I47: 2023 | J47: Jayatunga | K47: Ph I successful but terminated before Ph II to accelerate 2nd-gen platform.
A48: EVOEXS-21546 | B48: Exscientia | C48: Small molecule | D48: A2a receptor | F48: Small molecule design | G48: Phase I | H48: Failed / Terminated | I48: 2021 | J48: Jayatunga | K48: Phase Ia successful but Ib/II terminated — couldn't reach therapeutic index.
...

Sheet Chart_1_Capital_vs_Output
A1: Chart 1 — The Capital–Output Gap
A2: Cumulative AI-pharma deal upfront ($M) vs. cumulative AI-discovered FDA approvals. All cells formula-driven from Source_Deals tab.
A4: Year | B4: Annual upfront $M (SUMIF) | C4: Cumulative upfront $M (running) | D4: Cumulative FDA approvals (AI-discovered)
A5: 2018 | B5: =SUMIFS(Source_Deals!G:G, Source_Deals!C:C, 2018) -> 0 | C5: =B5 -> 0 | D5: 0
A6: 2019 | B6: =SUMIFS(Source_Deals!G:G, Source_Deals!C:C, 2019) -> 0 | C6: =C5+B6 -> 0 | D6: 0
A7: 2020 | B7: =SUMIFS(Source_Deals!G:G, Source_Deals!C:C, 2020) -> 135 | C7: =C6+B7 -> 135 | D7: 0
A8: 2021 | B8: =SUMIFS(Source_Deals!G:G, Source_Deals!C:C, 2021) -> 805 | C8: =C7+B8 -> 940 | D8: 0
A9: 2022 | B9: =SUMIFS(Source_Deals!G:G, Source_Deals!C:C, 2022) -> 4194.5 | C9: =C8+B9 -> 5134.5 | D9: 0
A10: 2023 | B10: =SUMIFS(Source_Deals!G:G, Source_Deals!C:C, 2023) -> 297 | C10: =C9+B10 -> 5431.5 | D10: 0
A11: 2024 | B11: =SUMIFS(Source_Deals!G:G, Source_Deals!C:C, 2024) -> 955.5 | C11: =C10+B11 -> 6387 | D11: 0
A12: 2025 | B12: =SUMIFS(Source_Deals!G:G, Source_Deals!C:C, 2025) -> 600 | C12: =C11+B12 -> 6987 | D12: 0
A13: 2026 YTD | B13: =SUMIFS(Source_Deals!G:G, Source_Deals!C:C, 2026) -> 1000 | C13: =C12+B13 -> 7987 | D13: 0
A30: As of 2026-05-11. All cells formula-driven via SUMIFS pointing to Source_Deals tab.
A31: Cumulative upfront = running total of disclosed upfronts per Source_Deals!G column, filtered by year in Source_Deals!C column.
A32: Cumulative FDA approvals = zero through 2026-05-11. Zasocitinib NDA targeted FY2026 (would be the first to break the floor).
A33: Source: 01_Matrix_Master.xlsx Deals tab — 70 deal rows verified
A34: Cross-check: AI Pipeline Tracker (Jayatunga 2024)

Sheet Chart_2_Pipeline_Funnel
A1: Chart 2 — The AI Discovery Funnel
A2: 82 (Jayatunga cohort) → 0 FDA approvals. Cells formula-driven via COUNTIF on Source_Pipeline. Updates as new molecules added.
A4: Funnel stage | B4: Count (formula) | C4: % of cohort
A5: 1. AI-discovered cohort (Jayatunga + extensions + new additions) | B5: =COUNTA(Source_Pipeline!A5:A90) -> 86 | C5: =B5/$B$5 -> 1
A6: 2. Reached Phase I or beyond | B6: =COUNTA(Source_Pipeline!A5:A90)-COUNTIF(Source_Pipeline!G5:G90,"Pre-Phase I") -> 85 | C6: =B6/$B$5 -> 0.98837209
A7: 3. Have completed-phase readouts | B7: =COUNTIF(Source_Pipeline!H5:H90,"Clear winner")+COUNTIF(Source_Pipeline!H5:H90,"Successful (completed phase)")+COUNTIF(Source_Pipeline!H5:H90,"Failed / Terminated") -> 26 | C7: =B7/$B$5 -> 0.30232558
A8: 4. Successful through completed phase | B8: =COUNTIF(Source_Pipeline!H5:H90,"Clear winner")+COUNTIF(Source_Pipeline!H5:H90,"Successful (completed phase)")+COUNTIF(Source_Pipeline!H5:H90,"Positive but early") -> 28 | C8: =B8/$B$5 -> 0.3255814
A9: 5. Cleared Phase 3 primary endpoint | B9: 1 | C9: =B9/$B$5 -> 0.011627907
A10: 6. FDA-approved | B10: 0 | C10: =B10/$B$5 -> 0
A30: As of 2026-05-11. Cohort size and stage counts formula-driven from Source_Pipeline tab via COUNTIF.
A31: Cohort definition: 82 from Jayatunga et al. 2024 (peer-reviewed, BCG-authored) + 4 Bernstein-added molecules verified May 2026.
A32: Stage 4 = 'Clear winner' + 'Successful' + 'Positive but early' counts. Stage 5 = Zasocitinib only (manually anchored).
A33: Source: Jayatunga 2024 cohort
A34: Zasocitinib NCT06108544 (Phase 3 completed Dec 2024)

Sheet Chart_3_CTgov_AI_Trials
A1: Chart 3 — Cumulative trials mentioning AI on ClinicalTrials.gov (BROAD)
A2: Includes trials USING AI as analytical tool (imaging, monitoring, diagnostics) — NOT just AI-discovered molecules. Stylized from public bibliometrics.
A4: Year | B4: Cumulative trials (CT.gov text-search 'AI / ML / deep learning')
A5: 2015 | B5: 145
A6: 2016 | B6: 220
A7: 2017 | B7: 340
A8: 2018 | B8: 510
A9: 2019 | B9: 750
A10: 2020 | B10: 1100
A11: 2021 | B11: 1620
A12: 2022 | B12: 2310
A13: 2023 | B13: 3200
A14: 2024 | B14: 4280
A15: 2025 | B15: 5560
A16: 2026 YTD | B16: 6100
A30: As of 2026-05-11. STYLIZED — anchored on documented bibliometric trends.
A31: Methodology: cumulative count of CT.gov records mentioning 'AI', 'machine learning', or 'deep learning' in any field. Includes trials that USE AI tools (image analysis, monitoring, RWE) — NOT a count of AI-discovered molecules.
A32: See Chart 3b for the narrower 'AI-discovered drugs only' view.
A33: Source: ClinicalTrials.gov public registry
A34: Liu et al. 2023 Frontiers in Med bibliometric analysis

Sheet Chart_3b_AI_Discovered_Only
A1: Chart 3b — Cumulative AI-discovered drug trials, narrow definition (NEW)
A2: Molecule-level only: counts molecules in our verified AI-discovered cohort that have entered Phase I by year. Formula-driven from Source_Pipeline.
A4: Year | B4: New molecules entering clinic (annual) | C4: Cumulative AI-discovered molecules in clinic
A5: 2014 | B5: =COUNTIF(Source_Pipeline!I5:I90, 2014) -> 1 | C5: =B5 -> 1
A6: 2015 | B6: =COUNTIF(Source_Pipeline!I5:I90, 2015) -> 0 | C6: =C5+B6 -> 1
A7: 2016 | B7: =COUNTIF(Source_Pipeline!I5:I90, 2016) -> 0 | C7: =C6+B7 -> 1
A8: 2017 | B8: =COUNTIF(Source_Pipeline!I5:I90, 2017) -> 0 | C8: =C7+B8 -> 1
A9: 2018 | B9: =COUNTIF(Source_Pipeline!I5:I90, 2018) -> 0 | C9: =C8+B9 -> 1
A10: 2019 | B10: =COUNTIF(Source_Pipeline!I5:I90, 2019) -> 3 | C10: =C9+B10 -> 4
A11: 2020 | B11: =COUNTIF(Source_Pipeline!I5:I90, 2020) -> 5 | C11: =C10+B11 -> 9
A12: 2021 | B12: =COUNTIF(Source_Pipeline!I5:I90, 2021) -> 17 | C12: =C11+B12 -> 26
A13: 2022 | B13: =COUNTIF(Source_Pipeline!I5:I90, 2022) -> 15 | C13: =C12+B13 -> 41
A14: 2023 | B14: =COUNTIF(Source_Pipeline!I5:I90, 2023) -> 40 | C14: =C13+B14 -> 81
A15: 2024 | B15: =COUNTIF(Source_Pipeline!I5:I90, 2024) -> 1 | C15: =C14+B15 -> 82
A16: 2025 | B16: =COUNTIF(Source_Pipeline!I5:I90, 2025) -> 4 | C16: =C15+B16 -> 86
A17: 2026 | B17: =COUNTIF(Source_Pipeline!I5:I90, 2026) -> 0 | C17: =C16+B17 -> 86
A30: As of 2026-05-11. NARROW DEFINITION — AI-discovered molecules only (not trials using AI as a tool).
A31: Methodology: first-in-human (FIH) year derived from Source_Pipeline tab column I. FIH years for landmark molecules manually anchored (Zasocitinib 2019, Rentosertib 2022, DSP-1181 2020); others estimated from highest-phase backdated by typical clinical timelines.
A32: Compare with Chart 3: trial-level AI mentions are ~6,100 cumulative; AI-DISCOVERED molecule-level is ~86. The 70× ratio is itself the punchline — most CT.gov 'AI' activity is tool-use, not drug-discovery.
A33: Important methodology caveat: the Jayatunga 82-cohort is a peer-reviewed conservative sample. A broader landscape estimate (biomednexus 2026) cites ~173 AI-discovered programs in clinic across all stages — flag this as an Industry Estimate (Tier 3 sourcing).
A34: Source: Jayatunga 2024 cohort
A35: Iambic IAM1363 NCT06253871 (Bernstein addition)
A36: Insilico 2025 Annual Results (ISM3412, ISM6331 additions)

Sheet Chart_4_Partner_Matrix
A1: Chart 4 — Pharma × AI Partner Matrix
A2: Deal count per pair, 2018–2026. Cells formula-driven via COUNTIFS on Source_Deals.
B4: Recursion | C4: Exscientia | D4: AbCellera | E4: Schrödinger | F4: Insilico Medicine | G4: OpenAI | H4: Atomwise | I4: BenevolentAI | J4: Isomorphic Labs | K4: XtalPi | L4: Verge Genomics | M4: Insitro | N4: Generate Biomedicines | O4: Tempus AI | P4: Total
A5: Eli Lilly | B5: =COUNTIFS(Source_Deals!D:D,"Eli Lilly",Source_Deals!E:E,"Recursion") -> 0 | C5: =COUNTIFS(Source_Deals!D:D,"Eli Lilly",Source_Deals!E:E,"Exscientia") -> 0 | D5: =COUNTIFS(Source_Deals!D:D,"Eli Lilly",Source_Deals!E:E,"AbCellera") -> 3 | E5: =COUNTIFS(Source_Deals!D:D,"Eli Lilly",Source_Deals!E:E,"Schrödinger") -> 2 | F5: =COUNTIFS(Source_Deals!D:D,"Eli Lilly",Source_Deals!E:E,"Insilico Medicine") -> 1 | G5: =COUNTIFS(Source_Deals!D:D,"Eli Lilly",Source_Deals!E:E,"OpenAI") -> 1 | H5: =COUNTIFS(Source_Deals!D:D,"Eli Lilly",Source_Deals!E:E,"Atomwise") -> 1 | I5: =COUNTIFS(Source_Deals!D:D,"Eli Lilly",Source_Deals!E:E,"BenevolentAI") -> 0 | J5: =COUNTIFS(Source_Deals!D:D,"Eli Lilly",Source_Deals!E:E,"Isomorphic Labs") -> 1 | K5: =COUNTIFS(Source_Deals!D:D,"Eli Lilly",Source_Deals!E:E,"XtalPi") -> 1 | L5: =COUNTIFS(Source_Deals!D:D,"Eli Lilly",Source_Deals!E:E,"Verge Genomics") -> 1 | M5: =COUNTIFS(Source_Deals!D:D,"Eli Lilly",Source_Deals!E:E,"Insitro") -> 0 | N5: =COUNTIFS(Source_Deals!D:D,"Eli Lilly",Source_Deals!E:E,"Generate Biomedicines") -> 0 | O5: =COUNTIFS(Source_Deals!D:D,"Eli Lilly",Source_Deals!E:E,"Tempus AI") -> 0 | P5: =COUNTIF(Source_Deals!D:D,"Eli Lilly") -> 12
A6: Sanofi | B6: =COUNTIFS(Source_Deals!D:D,"Sanofi",Source_Deals!E:E,"Recursion") -> 1 | C6: =COUNTIFS(Source_Deals!D:D,"Sanofi",Source_Deals!E:E,"Exscientia") -> 0 | D6: =COUNTIFS(Source_Deals!D:D,"Sanofi",Source_Deals!E:E,"AbCellera") -> 0 | E6: =COUNTIFS(Source_Deals!D:D,"Sanofi",Source_Deals!E:E,"Schrödinger") -> 0 | F6: =COUNTIFS(Source_Deals!D:D,"Sanofi",Source_Deals!E:E,"Insilico Medicine") -> 2 | G6: =COUNTIFS(Source_Deals!D:D,"Sanofi",Source_Deals!E:E,"OpenAI") -> 1 | H6: =COUNTIFS(Source_Deals!D:D,"Sanofi",Source_Deals!E:E,"Atomwise") -> 1 | I6: =COUNTIFS(Source_Deals!D:D,"Sanofi",Source_Deals!E:E,"BenevolentAI") -> 0 | J6: =COUNTIFS(Source_Deals!D:D,"Sanofi",Source_Deals!E:E,"Isomorphic Labs") -> 0 | K6: =COUNTIFS(Source_Deals!D:D,"Sanofi",Source_Deals!E:E,"XtalPi") -> 0 | L6: =COUNTIFS(Source_Deals!D:D,"Sanofi",Source_Deals!E:E,"Verge Genomics") -> 0 | M6: =COUNTIFS(Source_Deals!D:D,"Sanofi",Source_Deals!E:E,"Insitro") -> 0 | N6: =COUNTIFS(Source_Deals!D:D,"Sanofi",Source_Deals!E:E,"Generate Biomedicines") -> 0 | O6: =COUNTIFS(Source_Deals!D:D,"Sanofi",Source_Deals!E:E,"Tempus AI") -> 0 | P6: =COUNTIF(Source_Deals!D:D,"Sanofi") -> 7
A7: Pfizer | B7: =COUNTIFS(Source_Deals!D:D,"Pfizer",Source_Deals!E:E,"Recursion") -> 0 | C7: =COUNTIFS(Source_Deals!D:D,"Pfizer",Source_Deals!E:E,"Exscientia") -> 0 | D7: =COUNTIFS(Source_Deals!D:D,"Pfizer",Source_Deals!E:E,"AbCellera") -> 0 | E7: =COUNTIFS(Source_Deals!D:D,"Pfizer",Source_Deals!E:E,"Schrödinger") -> 0 | F7: =COUNTIFS(Source_Deals!D:D,"Pfizer",Source_Deals!E:E,"Insilico Medicine") -> 0 | G7: =COUNTIFS(Source_Deals!D:D,"Pfizer",Source_Deals!E:E,"OpenAI") -> 0 | H7: =COUNTIFS(Source_Deals!D:D,"Pfizer",Source_Deals!E:E,"Atomwise") -> 1 | I7: =COUNTIFS(Source_Deals!D:D,"Pfizer",Source_Deals!E:E,"BenevolentAI") -> 0 | J7: =COUNTIFS(Source_Deals!D:D,"Pfizer",Source_Deals!E:E,"Isomorphic Labs") -> 0 | K7: =COUNTIFS(Source_Deals!D:D,"Pfizer",Source_Deals!E:E,"XtalPi") -> 1 | L7: =COUNTIFS(Source_Deals!D:D,"Pfizer",Source_Deals!E:E,"Verge Genomics") -> 0 | M7: =COUNTIFS(Source_Deals!D:D,"Pfizer",Source_Deals!E:E,"Insitro") -> 0 | N7: =COUNTIFS(Source_Deals!D:D,"Pfizer",Source_Deals!E:E,"Generate Biomedicines") -> 0 | O7: =COUNTIFS(Source_Deals!D:D,"Pfizer",Source_Deals!E:E,"Tempus AI") -> 0 | P7: =COUNTIF(Source_Deals!D:D,"Pfizer") -> 6
A8: Bristol Myers Squibb | B8: =COUNTIFS(Source_Deals!D:D,"Bristol Myers Squibb",Source_Deals!E:E,"Recursion") -> 0 | C8: =COUNTIFS(Source_Deals!D:D,"Bristol Myers Squibb",Source_Deals!E:E,"Exscientia") -> 2 | D8: =COUNTIFS(Source_Deals!D:D,"Bristol Myers Squibb",Source_Deals!E:E,"AbCellera") -> 0 | E8: =COUNTIFS(Source_Deals!D:D,"Bristol Myers Squibb",Source_Deals!E:E,"Schrödinger") -> 1 | F8: =COUNTIFS(Source_Deals!D:D,"Bristol Myers Squibb",Source_Deals!E:E,"Insilico Medicine") -> 0 | G8: =COUNTIFS(Source_Deals!D:D,"Bristol Myers Squibb",Source_Deals!E:E,"OpenAI") -> 0 | H8: =COUNTIFS(Source_Deals!D:D,"Bristol Myers Squibb",Source_Deals!E:E,"Atomwise") -> 0 | I8: =COUNTIFS(Source_Deals!D:D,"Bristol Myers Squibb",Source_Deals!E:E,"BenevolentAI") -> 0 | J8: =COUNTIFS(Source_Deals!D:D,"Bristol Myers Squibb",Source_Deals!E:E,"Isomorphic Labs") -> 0 | K8: =COUNTIFS(Source_Deals!D:D,"Bristol Myers Squibb",Source_Deals!E:E,"XtalPi") -> 0 | L8: =COUNTIFS(Source_Deals!D:D,"Bristol Myers Squibb",Source_Deals!E:E,"Verge Genomics") -> 0 | M8: =COUNTIFS(Source_Deals!D:D,"Bristol Myers Squibb",Source_Deals!E:E,"Insitro") -> 1 | N8: =COUNTIFS(Source_Deals!D:D,"Bristol Myers Squibb",Source_Deals!E:E,"Generate Biomedicines") -> 0 | O8: =COUNTIFS(Source_Deals!D:D,"Bristol Myers Squibb",Source_Deals!E:E,"Tempus AI") -> 0 | P8: =COUNTIF(Source_Deals!D:D,"Bristol Myers Squibb") -> 4
A9: Merck & Co (MRK) | B9: =COUNTIFS(Source_Deals!D:D,"Merck & Co (MRK)",Source_Deals!E:E,"Recursion") -> 0 | C9: =COUNTIFS(Source_Deals!D:D,"Merck & Co (MRK)",Source_Deals!E:E,"Exscientia") -> 0 | D9: =COUNTIFS(Source_Deals!D:D,"Merck & Co (MRK)",Source_Deals!E:E,"AbCellera") -> 0 | E9: =COUNTIFS(Source_Deals!D:D,"Merck & Co (MRK)",Source_Deals!E:E,"Schrödinger") -> 0 | F9: =COUNTIFS(Source_Deals!D:D,"Merck & Co (MRK)",Source_Deals!E:E,"Insilico Medicine") -> 0 | G9: =COUNTIFS(Source_Deals!D:D,"Merck & Co (MRK)",Source_Deals!E:E,"OpenAI") -> 0 | H9: =COUNTIFS(Source_Deals!D:D,"Merck & Co (MRK)",Source_Deals!E:E,"Atomwise") -> 0 | I9: =COUNTIFS(Source_Deals!D:D,"Merck & Co (MRK)",Source_Deals!E:E,"BenevolentAI") -> 0 | J9: =COUNTIFS(Source_Deals!D:D,"Merck & Co (MRK)",Source_Deals!E:E,"Isomorphic Labs") -> 0 | K9: =COUNTIFS(Source_Deals!D:D,"Merck & Co (MRK)",Source_Deals!E:E,"XtalPi") -> 0 | L9: =COUNTIFS(Source_Deals!D:D,"Merck & Co (MRK)",Source_Deals!E:E,"Verge Genomics") -> 0 | M9: =COUNTIFS(Source_Deals!D:D,"Merck & Co (MRK)",Source_Deals!E:E,"Insitro") -> 0 | N9: =COUNTIFS(Source_Deals!D:D,"Merck & Co (MRK)",Source_Deals!E:E,"Generate Biomedicines") -> 0 | O9: =COUNTIFS(Source_Deals!D:D,"Merck & Co (MRK)",Source_Deals!E:E,"Tempus AI") -> 0 | P9: =COUNTIF(Source_Deals!D:D,"Merck & Co (MRK)") -> 4
A10: Bayer | B10: =COUNTIFS(Source_Deals!D:D,"Bayer",Source_Deals!E:E,"Recursion") -> 3 | C10: =COUNTIFS(Source_Deals!D:D,"Bayer",Source_Deals!E:E,"Exscientia") -> 1 | D10: =COUNTIFS(Source_Deals!D:D,"Bayer",Source_Deals!E:E,"AbCellera") -> 0 | E10: =COUNTIFS(Source_Deals!D:D,"Bayer",Source_Deals!E:E,"Schrödinger") -> 0 | F10: =COUNTIFS(Source_Deals!D:D,"Bayer",Source_Deals!E:E,"Insilico Medicine") -> 0 | G10: =COUNTIFS(Source_Deals!D:D,"Bayer",Source_Deals!E:E,"OpenAI") -> 0 | H10: =COUNTIFS(Source_Deals!D:D,"Bayer",Source_Deals!E:E,"Atomwise") -> 0 | I10: =COUNTIFS(Source_Deals!D:D,"Bayer",Source_Deals!E:E,"BenevolentAI") -> 0 | J10: =COUNTIFS(Source_Deals!D:D,"Bayer",Source_Deals!E:E,"Isomorphic Labs") -> 0 | K10: =COUNTIFS(Source_Deals!D:D,"Bayer",Source_Deals!E:E,"XtalPi") -> 0 | L10: =COUNTIFS(Source_Deals!D:D,"Bayer",Source_Deals!E:E,"Verge Genomics") -> 0 | M10: =COUNTIFS(Source_Deals!D:D,"Bayer",Source_Deals!E:E,"Insitro") -> 0 | N10: =COUNTIFS(Source_Deals!D:D,"Bayer",Source_Deals!E:E,"Generate Biomedicines") -> 0 | O10: =COUNTIFS(Source_Deals!D:D,"Bayer",Source_Deals!E:E,"Tempus AI") -> 0 | P10: =COUNTIF(Source_Deals!D:D,"Bayer") -> 4
A11: AstraZeneca | B11: =COUNTIFS(Source_Deals!D:D,"AstraZeneca",Source_Deals!E:E,"Recursion") -> 0 | C11: =COUNTIFS(Source_Deals!D:D,"AstraZeneca",Source_Deals!E:E,"Exscientia") -> 0 | D11: =COUNTIFS(Source_Deals!D:D,"AstraZeneca",Source_Deals!E:E,"AbCellera") -> 0 | E11: =COUNTIFS(Source_Deals!D:D,"AstraZeneca",Source_Deals!E:E,"Schrödinger") -> 0 | F11: =COUNTIFS(Source_Deals!D:D,"AstraZeneca",Source_Deals!E:E,"Insilico Medicine") -> 0 | G11: =COUNTIFS(Source_Deals!D:D,"AstraZeneca",Source_Deals!E:E,"OpenAI") -> 0 | H11: =COUNTIFS(Source_Deals!D:D,"AstraZeneca",Source_Deals!E:E,"Atomwise") -> 0 | I11: =COUNTIFS(Source_Deals!D:D,"AstraZeneca",Source_Deals!E:E,"BenevolentAI") -> 2 | J11: =COUNTIFS(Source_Deals!D:D,"AstraZeneca",Source_Deals!E:E,"Isomorphic Labs") -> 0 | K11: =COUNTIFS(Source_Deals!D:D,"AstraZeneca",Source_Deals!E:E,"XtalPi") -> 0 | L11: =COUNTIFS(Source_Deals!D:D,"AstraZeneca",Source_Deals!E:E,"Verge Genomics") -> 1 | M11: =COUNTIFS(Source_Deals!D:D,"AstraZeneca",Source_Deals!E:E,"Insitro") -> 0 | N11: =COUNTIFS(Source_Deals!D:D,"AstraZeneca",Source_Deals!E:E,"Generate Biomedicines") -> 0 | O11: =COUNTIFS(Source_Deals!D:D,"AstraZeneca",Source_Deals!E:E,"Tempus AI") -> 0 | P11: =COUNTIF(Source_Deals!D:D,"AstraZeneca") -> 4
A12: AbbVie | B12: =COUNTIFS(Source_Deals!D:D,"AbbVie",Source_Deals!E:E,"Recursion") -> 0 | C12: =COUNTIFS(Source_Deals!D:D,"AbbVie",Source_Deals!E:E,"Exscientia") -> 0 | D12: =COUNTIFS(Source_Deals!D:D,"AbbVie",Source_Deals!E:E,"AbCellera") -> 2 | E12: =COUNTIFS(Source_Deals!D:D,"AbbVie",Source_Deals!E:E,"Schrödinger") -> 0 | F12: =COUNTIFS(Source_Deals!D:D,"AbbVie",Source_Deals!E:E,"Insilico Medicine") -> 0 | G12: =COUNTIFS(Source_Deals!D:D,"AbbVie",Source_Deals!E:E,"OpenAI") -> 0 | H12: =COUNTIFS(Source_Deals!D:D,"AbbVie",Source_Deals!E:E,"Atomwise") -> 0 | I12: =COUNTIFS(Source_Deals!D:D,"AbbVie",Source_Deals!E:E,"BenevolentAI") -> 0 | J12: =COUNTIFS(Source_Deals!D:D,"AbbVie",Source_Deals!E:E,"Isomorphic Labs") -> 0 | K12: =COUNTIFS(Source_Deals!D:D,"AbbVie",Source_Deals!E:E,"XtalPi") -> 0 | L12: =COUNTIFS(Source_Deals!D:D,"AbbVie",Source_Deals!E:E,"Verge Genomics") -> 0 | M12: =COUNTIFS(Source_Deals!D:D,"AbbVie",Source_Deals!E:E,"Insitro") -> 0 | N12: =COUNTIFS(Source_Deals!D:D,"AbbVie",Source_Deals!E:E,"Generate Biomedicines") -> 0 | O12: =COUNTIFS(Source_Deals!D:D,"AbbVie",Source_Deals!E:E,"Tempus AI") -> 0 | P12: =COUNTIF(Source_Deals!D:D,"AbbVie") -> 4
A13: Novartis | B13: =COUNTIFS(Source_Deals!D:D,"Novartis",Source_Deals!E:E,"Recursion") -> 0 | C13: =COUNTIFS(Source_Deals!D:D,"Novartis",Source_Deals!E:E,"Exscientia") -> 0 | D13: =COUNTIFS(Source_Deals!D:D,"Novartis",Source_Deals!E:E,"AbCellera") -> 0 | E13: =COUNTIFS(Source_Deals!D:D,"Novartis",Source_Deals!E:E,"Schrödinger") -> 1 | F13: =COUNTIFS(Source_Deals!D:D,"Novartis",Source_Deals!E:E,"Insilico Medicine") -> 0 | G13: =COUNTIFS(Source_Deals!D:D,"Novartis",Source_Deals!E:E,"OpenAI") -> 0 | H13: =COUNTIFS(Source_Deals!D:D,"Novartis",Source_Deals!E:E,"Atomwise") -> 0 | I13: =COUNTIFS(Source_Deals!D:D,"Novartis",Source_Deals!E:E,"BenevolentAI") -> 0 | J13: =COUNTIFS(Source_Deals!D:D,"Novartis",Source_Deals!E:E,"Isomorphic Labs") -> 1 | K13: =COUNTIFS(Source_Deals!D:D,"Novartis",Source_Deals!E:E,"XtalPi") -> 0 | L13: =COUNTIFS(Source_Deals!D:D,"Novartis",Source_Deals!E:E,"Verge Genomics") -> 0 | M13: =COUNTIFS(Source_Deals!D:D,"Novartis",Source_Deals!E:E,"Insitro") -> 0 | N13: =COUNTIFS(Source_Deals!D:D,"Novartis",Source_Deals!E:E,"Generate Biomedicines") -> 0 | O13: =COUNTIFS(Source_Deals!D:D,"Novartis",Source_Deals!E:E,"Tempus AI") -> 0 | P13: =COUNTIF(Source_Deals!D:D,"Novartis") -> 3
A14: Roche/Genentech | B14: =COUNTIFS(Source_Deals!D:D,"Roche/Genentech",Source_Deals!E:E,"Recursion") -> 2 | C14: =COUNTIFS(Source_Deals!D:D,"Roche/Genentech",Source_Deals!E:E,"Exscientia") -> 0 | D14: =COUNTIFS(Source_Deals!D:D,"Roche/Genentech",Source_Deals!E:E,"AbCellera") -> 0 | E14: =COUNTIFS(Source_Deals!D:D,"Roche/Genentech",Source_Deals!E:E,"Schrödinger") -> 0 | F14: =COUNTIFS(Source_Deals!D:D,"Roche/Genentech",Source_Deals!E:E,"Insilico Medicine") -> 0 | G14: =COUNTIFS(Source_Deals!D:D,"Roche/Genentech",Source_Deals!E:E,"OpenAI") -> 0 | H14: =COUNTIFS(Source_Deals!D:D,"Roche/Genentech",Source_Deals!E:E,"Atomwise") -> 0 | I14: =COUNTIFS(Source_Deals!D:D,"Roche/Genentech",Source_Deals!E:E,"BenevolentAI") -> 0 | J14: =COUNTIFS(Source_Deals!D:D,"Roche/Genentech",Source_Deals!E:E,"Isomorphic Labs") -> 0 | K14: =COUNTIFS(Source_Deals!D:D,"Roche/Genentech",Source_Deals!E:E,"XtalPi") -> 0 | L14: =COUNTIFS(Source_Deals!D:D,"Roche/Genentech",Source_Deals!E:E,"Verge Genomics") -> 0 | M14: =COUNTIFS(Source_Deals!D:D,"Roche/Genentech",Source_Deals!E:E,"Insitro") -> 0 | N14: =COUNTIFS(Source_Deals!D:D,"Roche/Genentech",Source_Deals!E:E,"Generate Biomedicines") -> 0 | O14: =COUNTIFS(Source_Deals!D:D,"Roche/Genentech",Source_Deals!E:E,"Tempus AI") -> 0 | P14: =COUNTIF(Source_Deals!D:D,"Roche/Genentech") -> 2
A15: GSK | B15: =COUNTIFS(Source_Deals!D:D,"GSK",Source_Deals!E:E,"Recursion") -> 0 | C15: =COUNTIFS(Source_Deals!D:D,"GSK",Source_Deals!E:E,"Exscientia") -> 0 | D15: =COUNTIFS(Source_Deals!D:D,"GSK",Source_Deals!E:E,"AbCellera") -> 0 | E15: =COUNTIFS(Source_Deals!D:D,"GSK",Source_Deals!E:E,"Schrödinger") -> 0 | F15: =COUNTIFS(Source_Deals!D:D,"GSK",Source_Deals!E:E,"Insilico Medicine") -> 0 | G15: =COUNTIFS(Source_Deals!D:D,"GSK",Source_Deals!E:E,"OpenAI") -> 0 | H15: =COUNTIFS(Source_Deals!D:D,"GSK",Source_Deals!E:E,"Atomwise") -> 0 | I15: =COUNTIFS(Source_Deals!D:D,"GSK",Source_Deals!E:E,"BenevolentAI") -> 0 | J15: =COUNTIFS(Source_Deals!D:D,"GSK",Source_Deals!E:E,"Isomorphic Labs") -> 0 | K15: =COUNTIFS(Source_Deals!D:D,"GSK",Source_Deals!E:E,"XtalPi") -> 0 | L15: =COUNTIFS(Source_Deals!D:D,"GSK",Source_Deals!E:E,"Verge Genomics") -> 0 | M15: =COUNTIFS(Source_Deals!D:D,"GSK",Source_Deals!E:E,"Insitro") -> 0 | N15: =COUNTIFS(Source_Deals!D:D,"GSK",Source_Deals!E:E,"Generate Biomedicines") -> 0 | O15: =COUNTIFS(Source_Deals!D:D,"GSK",Source_Deals!E:E,"Tempus AI") -> 1 | P15: =COUNTIF(Source_Deals!D:D,"GSK") -> 2
A16: Moderna | B16: =COUNTIFS(Source_Deals!D:D,"Moderna",Source_Deals!E:E,"Recursion") -> 0 | C16: =COUNTIFS(Source_Deals!D:D,"Moderna",Source_Deals!E:E,"Exscientia") -> 0 | D16: =COUNTIFS(Source_Deals!D:D,"Moderna",Source_Deals!E:E,"AbCellera") -> 0 | E16: =COUNTIFS(Source_Deals!D:D,"Moderna",Source_Deals!E:E,"Schrödinger") -> 0 | F16: =COUNTIFS(Source_Deals!D:D,"Moderna",Source_Deals!E:E,"Insilico Medicine") -> 0 | G16: =COUNTIFS(Source_Deals!D:D,"Moderna",Source_Deals!E:E,"OpenAI") -> 1 | H16: =COUNTIFS(Source_Deals!D:D,"Moderna",Source_Deals!E:E,"Atomwise") -> 0 | I16: =COUNTIFS(Source_Deals!D:D,"Moderna",Source_Deals!E:E,"BenevolentAI") -> 0 | J16: =COUNTIFS(Source_Deals!D:D,"Moderna",Source_Deals!E:E,"Isomorphic Labs") -> 0 | K16: =COUNTIFS(Source_Deals!D:D,"Moderna",Source_Deals!E:E,"XtalPi") -> 0 | L16: =COUNTIFS(Source_Deals!D:D,"Moderna",Source_Deals!E:E,"Verge Genomics") -> 0 | M16: =COUNTIFS(Source_Deals!D:D,"Moderna",Source_Deals!E:E,"Insitro") -> 0 | N16: =COUNTIFS(Source_Deals!D:D,"Moderna",Source_Deals!E:E,"Generate Biomedicines") -> 0 | O16: =COUNTIFS(Source_Deals!D:D,"Moderna",Source_Deals!E:E,"Tempus AI") -> 0 | P16: =COUNTIF(Source_Deals!D:D,"Moderna") -> 2
A17: Gilead | B17: =COUNTIFS(Source_Deals!D:D,"Gilead",Source_Deals!E:E,"Recursion") -> 0 | C17: =COUNTIFS(Source_Deals!D:D,"Gilead",Source_Deals!E:E,"Exscientia") -> 0 | D17: =COUNTIFS(Source_Deals!D:D,"Gilead",Source_Deals!E:E,"AbCellera") -> 0 | E17: =COUNTIFS(Source_Deals!D:D,"Gilead",Source_Deals!E:E,"Schrödinger") -> 0 | F17: =COUNTIFS(Source_Deals!D:D,"Gilead",Source_Deals!E:E,"Insilico Medicine") -> 0 | G17: =COUNTIFS(Source_Deals!D:D,"Gilead",Source_Deals!E:E,"OpenAI") -> 0 | H17: =COUNTIFS(Source_Deals!D:D,"Gilead",Source_Deals!E:E,"Atomwise") -> 0 | I17: =COUNTIFS(Source_Deals!D:D,"Gilead",Source_Deals!E:E,"BenevolentAI") -> 0 | J17: =COUNTIFS(Source_Deals!D:D,"Gilead",Source_Deals!E:E,"Isomorphic Labs") -> 0 | K17: =COUNTIFS(Source_Deals!D:D,"Gilead",Source_Deals!E:E,"XtalPi") -> 0 | L17: =COUNTIFS(Source_Deals!D:D,"Gilead",Source_Deals!E:E,"Verge Genomics") -> 0 | M17: =COUNTIFS(Source_Deals!D:D,"Gilead",Source_Deals!E:E,"Insitro") -> 0 | N17: =COUNTIFS(Source_Deals!D:D,"Gilead",Source_Deals!E:E,"Generate Biomedicines") -> 0 | O17: =COUNTIFS(Source_Deals!D:D,"Gilead",Source_Deals!E:E,"Tempus AI") -> 0 | P17: =COUNTIF(Source_Deals!D:D,"Gilead") -> 2
A18: Amgen | B18: =COUNTIFS(Source_Deals!D:D,"Amgen",Source_Deals!E:E,"Recursion") -> 0 | C18: =COUNTIFS(Source_Deals!D:D,"Amgen",Source_Deals!E:E,"Exscientia") -> 0 | D18: =COUNTIFS(Source_Deals!D:D,"Amgen",Source_Deals!E:E,"AbCellera") -> 0 | E18: =COUNTIFS(Source_Deals!D:D,"Amgen",Source_Deals!E:E,"Schrödinger") -> 0 | F18: =COUNTIFS(Source_Deals!D:D,"Amgen",Source_Deals!E:E,"Insilico Medicine") -> 0 | G18: =COUNTIFS(Source_Deals!D:D,"Amgen",Source_Deals!E:E,"OpenAI") -> 0 | H18: =COUNTIFS(Source_Deals!D:D,"Amgen",Source_Deals!E:E,"Atomwise") -> 0 | I18: =COUNTIFS(Source_Deals!D:D,"Amgen",Source_Deals!E:E,"BenevolentAI") -> 0 | J18: =COUNTIFS(Source_Deals!D:D,"Amgen",Source_Deals!E:E,"Isomorphic Labs") -> 0 | K18: =COUNTIFS(Source_Deals!D:D,"Amgen",Source_Deals!E:E,"XtalPi") -> 0 | L18: =COUNTIFS(Source_Deals!D:D,"Amgen",Source_Deals!E:E,"Verge Genomics") -> 0 | M18: =COUNTIFS(Source_Deals!D:D,"Amgen",Source_Deals!E:E,"Insitro") -> 0 | N18: =COUNTIFS(Source_Deals!D:D,"Amgen",Source_Deals!E:E,"Generate Biomedicines") -> 1 | O18: =COUNTIFS(Source_Deals!D:D,"Amgen",Source_Deals!E:E,"Tempus AI") -> 0 | P18: =COUNTIF(Source_Deals!D:D,"Amgen") -> 1
A20: Total deals (AI counterparty) | B20: =COUNTIF(Source_Deals!E:E,"Recursion") -> 7 | C20: =COUNTIF(Source_Deals!E:E,"Exscientia") -> 6 | D20: =COUNTIF(Source_Deals!E:E,"AbCellera") -> 5 | E20: =COUNTIF(Source_Deals!E:E,"Schrödinger") -> 5 | F20: =COUNTIF(Source_Deals!E:E,"Insilico Medicine") -> 4 | G20: =COUNTIF(Source_Deals!E:E,"OpenAI") -> 3 | H20: =COUNTIF(Source_Deals!E:E,"Atomwise") -> 3 | I20: =COUNTIF(Source_Deals!E:E,"BenevolentAI") -> 3 | J20: =COUNTIF(Source_Deals!E:E,"Isomorphic Labs") -> 2 | K20: =COUNTIF(Source_Deals!E:E,"XtalPi") -> 2 | L20: =COUNTIF(Source_Deals!E:E,"Verge Genomics") -> 2 | M20: =COUNTIF(Source_Deals!E:E,"Insitro") -> 2 | N20: =COUNTIF(Source_Deals!E:E,"Generate Biomedicines") -> 1 | O20: =COUNTIF(Source_Deals!E:E,"Tempus AI") -> 1
A22: Heat-map legend: 0 deals = blank | 1 = pale blue | 2 = medium blue | 3+ = dark navy
A23: Conditional-formatting intensities will resolve after Excel recalcs the formulas; the underlying values are formula-driven from Source_Deals.
A25: As of 2026-05-11. Each cell = COUNTIFS(Source_Deals!D, pharma, Source_Deals!E, AI partner).
A26: Pharma list: 8 Bernstein-covered + 6 most-active non-covered. AI counterparty list: top 14 by deal count.
A27: Source: 01_Matrix_Master.xlsx Deals tab

Sheet Chart_5_Coverage_Scorecard
A1: Chart 5 — Coverage Universe Scorecard
A2: Eight covered pharma × five signal dimensions. Deal $ totals and deal counts are formula-driven; filing-grade counts and savings disclosed are manually anchored to specific rows.
A4: Coverage name | B4: Deal upfront committed ($M, SUMIFS) | C4: Total deals (COUNTIF) | D4: Filing-grade AI disclosures (count, manual) | E4: AI programs in clinic (count, manual) | F4: Disclosed AI savings ($M, manual) | G4: Verdict
A5: LLY | B5: =SUMIFS(Source_Deals!G:G,Source_Deals!D:D,"Eli Lilly") -> 1070 | C5: =COUNTIF(Source_Deals!D:D,"Eli Lilly") -> 12 | D5: 1 | E5: 4 | F5: 0 | G5: CAPITAL DEPLOYED, NO PROOF YET
A6: PFE | B6: =SUMIFS(Source_Deals!G:G,Source_Deals!D:D,"Pfizer") -> 33 | C6: =COUNTIF(Source_Deals!D:D,"Pfizer") -> 6 | D6: 1 | E6: 1 | F6: 1200 | G6: PROOF ON RECORD (narrow)
A7: MRK | B7: =SUMIFS(Source_Deals!G:G,Source_Deals!D:D,"Merck & Co (MRK)") -> 0 | C7: =COUNTIF(Source_Deals!D:D,"Merck & Co (MRK)") -> 4 | D7: 1 | E7: 2 | F7: 0 | G7: NARROW PROOF
A8: BMY | B8: =SUMIFS(Source_Deals!G:G,Source_Deals!D:D,"Bristol Myers Squibb") -> 155 | C8: =COUNTIF(Source_Deals!D:D,"Bristol Myers Squibb") -> 4 | D8: 0 | E8: 2 | F8: 0 | G8: TALKING, NO PROOF
A9: AMGN | B9: =SUMIFS(Source_Deals!G:G,Source_Deals!D:D,"Amgen") -> 50 | C9: =COUNTIF(Source_Deals!D:D,"Amgen") -> 1 | D9: 0 | E9: 1 | F9: 0 | G9: CAPITAL DEPLOYED, NO PROOF YET
A10: ABBV | B10: =SUMIFS(Source_Deals!G:G,Source_Deals!D:D,"AbbVie") -> 152 | C10: =COUNTIF(Source_Deals!D:D,"AbbVie") -> 4 | D10: 0 | E10: 0 | F10: 0 | G10: TALKING, NO PROOF
A11: MRNA | B11: =SUMIFS(Source_Deals!G:G,Source_Deals!D:D,"Moderna") -> 0 | C11: =COUNTIF(Source_Deals!D:D,"Moderna") -> 2 | D11: 0 | E11: 0 | F11: 0 | G11: STRUCTURAL FIT, THIN PROOF
A12: GILD | B12: =SUMIFS(Source_Deals!G:G,Source_Deals!D:D,"Gilead") -> 35 | C12: =COUNTIF(Source_Deals!D:D,"Gilead") -> 2 | D12: 0 | E12: 0 | F12: 0 | G12: SILENT / CONTRARIAN
A18: As of 2026-05-11. Cols B–C formula-driven (SUMIFS / COUNTIF on Source_Deals). Cols D–F manually anchored to specific matrix rows below.
A19: Filing-grade AI disclosure anchors: PFE = SG-001 ($1.2B Q4 2024 call); MRK = SG-005 (CSR drafting -55%); LLY = SG-008 (operating leverage proxy).
A20: AI programs in clinic counts: LLY (Rentosertib post-licensing + Isomorphic-derived = 4); PFE (Atomwise programs in clinic); MRK (Schrödinger MALT1+CDC7); BMY (Insitro CV+onc); AMGN (Generate molecules); ABBV/MRNA/GILD = 0.
A21: Source: 01_Matrix_Master.xlsx Matrix + Deals tabs
A22: PFE Q4 2024 earnings call transcript (SG-001 anchor)
A23: Insilico Rentosertib Nature Medicine 2025 (Lilly deal context)

Sheet Chart_6_Deal_Economics
A1: Chart 6 — Deal economics evolution, 2018–2026
A2: Annual upfront $ + equity prevalence %. Cells formula-driven from Source_Deals via SUMIFS / COUNTIFS.
A4: Year | B4: Annual upfront $M (SUMIFS) | C4: Deals count (COUNTIF) | D4: Equity-flagged count (SUMIFS) | E4: Equity prevalence (formula)
A5: 2018 | B5: =SUMIFS(Source_Deals!G:G,Source_Deals!C:C,2018) -> 0 | C5: =COUNTIF(Source_Deals!C:C,2018) -> 1 | D5: =SUMIFS(Source_Deals!J:J,Source_Deals!C:C,2018) -> 0 | E5: =IFERROR(D5/C5,0) -> 0
A6: 2019 | B6: =SUMIFS(Source_Deals!G:G,Source_Deals!C:C,2019) -> 0 | C6: =COUNTIF(Source_Deals!C:C,2019) -> 4 | D6: =SUMIFS(Source_Deals!J:J,Source_Deals!C:C,2019) -> 0 | E6: =IFERROR(D6/C6,0) -> 0
A7: 2020 | B7: =SUMIFS(Source_Deals!G:G,Source_Deals!C:C,2020) -> 135 | C7: =COUNTIF(Source_Deals!C:C,2020) -> 8 | D7: =SUMIFS(Source_Deals!J:J,Source_Deals!C:C,2020) -> 1 | E7: =IFERROR(D7/C7,0) -> 0.125
A8: 2021 | B8: =SUMIFS(Source_Deals!G:G,Source_Deals!C:C,2021) -> 805 | C8: =COUNTIF(Source_Deals!C:C,2021) -> 6 | D8: =SUMIFS(Source_Deals!J:J,Source_Deals!C:C,2021) -> 3 | E8: =IFERROR(D8/C8,0) -> 0.5
A9: 2022 | B9: =SUMIFS(Source_Deals!G:G,Source_Deals!C:C,2022) -> 4194.5 | C9: =COUNTIF(Source_Deals!C:C,2022) -> 13 | D9: =SUMIFS(Source_Deals!J:J,Source_Deals!C:C,2022) -> 2 | E9: =IFERROR(D9/C9,0) -> 0.15384615
A10: 2023 | B10: =SUMIFS(Source_Deals!G:G,Source_Deals!C:C,2023) -> 297 | C10: =COUNTIF(Source_Deals!C:C,2023) -> 17 | D10: =SUMIFS(Source_Deals!J:J,Source_Deals!C:C,2023) -> 1 | E10: =IFERROR(D10/C10,0) -> 0.058823529
A11: 2024 | B11: =SUMIFS(Source_Deals!G:G,Source_Deals!C:C,2024) -> 955.5 | C11: =COUNTIF(Source_Deals!C:C,2024) -> 11 | D11: =SUMIFS(Source_Deals!J:J,Source_Deals!C:C,2024) -> 0 | E11: =IFERROR(D11/C11,0) -> 0
A12: 2025 | B12: =SUMIFS(Source_Deals!G:G,Source_Deals!C:C,2025) -> 600 | C12: =COUNTIF(Source_Deals!C:C,2025) -> 9 | D12: =SUMIFS(Source_Deals!J:J,Source_Deals!C:C,2025) -> 1 | E12: =IFERROR(D12/C12,0) -> 0.11111111
A13: 2026 YTD | B13: =SUMIFS(Source_Deals!G:G,Source_Deals!C:C,2026) -> 1000 | C13: =COUNTIF(Source_Deals!C:C,2026) -> 2 | D13: =SUMIFS(Source_Deals!J:J,Source_Deals!C:C,2026) -> 0 | E13: =IFERROR(D13/C13,0) -> 0
A30: As of 2026-05-11. All numeric cells formula-driven via SUMIFS / COUNTIFS on Source_Deals.
A31: Equity prevalence = equity-flagged deals / total deals in year. Source_Deals!J is the binary equity flag (1 if deal has equity component, 0 otherwise).
A32: Source: 01_Matrix_Master.xlsx Deals tab — 70 verified deal rows
