Workbook

Sheet COVER
B2: Agilent Technologies (A) — Quarterly Model by End Market
B4: Purpose
B5: Quarterly revenue build by end market (Pharma, Chemical & Applied, Diagnostics & Clinical, Food, Academia & Gov, Environmental & Forensics) with organic / FX / M&A bridge. Secondary segment view (LDG, ACG, AMG). FY23-FY28. Agilent fiscal year ends Oct 31.
B7: Tab guide
B8: COVER — this page.
B9: Summary — consolidated headline, per-end-market table, per-segment table, LRP overlay.
B10: Model — end-market revenue build with organic / FX / M&A bridge, segment-level revenue build, segment income.
B11: Upside — FY26-FY28 model vs guidance.
B13: Color convention
B14: Black formulas | Blue hardcoded actuals | Red forward assumptions | Green cross-sheet links
B16: Notable M&A
B17: BIOVECTRA acquisition — closed May 2024. Canadian CDMO. ~$130M FY24 revenue, $149.5M FY25. Flows into LDG / Pharma end market. FY25 total Agilent M&A bridge was +1.8% — Biovectra is the main contributor; bolt-ons make up the rest.
... B23: Bernstein A Model (Revenue tab end-market history); Agilent 10-K / 10-Q disclosures for bridge percentages; company press releases for Biovectra.

Sheet Summary
B2: Agilent — Consolidated Summary
C4: Period | D4: 1Q | E4: 2Q | F4: 3Q | G4: 4Q | H4: FY | I4: 1Q | J4: 2Q | K4: 3Q | L4: 4Q | M4: FY | N4: 1Q | O4: 2Q | P4: 3Q | Q4: 4Q | R4: FY | S4: 1Q | T4: 2Q | U4: 3Q | V4: 4Q | W4: FY | X4: 1Q | Y4: 2Q | Z4: 3Q | AA4: 4Q | AB4: FY | AC4: 1Q | AD4: 2Q | AE4: 3Q | AF4: 4Q | AG4: FY
C5: Fiscal Year (Oct YE) | D5: 23 | E5: =D5 -> 23 | F5: =E5 -> 23 | G5: =F5 -> 23 | H5: =G5 -> 23 | I5: =H5+1 -> 24 | J5: =I5 -> 24 | K5: =J5 -> 24 | L5: =K5 -> 24 | M5: =L5 -> 24 | N5: =M5+1 -> 25 | O5: =N5 -> 25 | P5: =O5 -> 25 | Q5: =P5 -> 25 | R5: =Q5 -> 25 | S5: =R5+1 -> 26 | T5: =S5 -> 26 | U5: =T5 -> 26 | V5: =U5 -> 26 | W5: =V5 -> 26 | X5: =W5+1 -> 27 | Y5: =X5 -> 27 | Z5: =Y5 -> 27 | AA5: =Z5 -> 27 | AB5: =AA5 -> 27 | AC5: =AB5+1 -> 28 | AD5: =AC5 -> 28 | AE5: =AD5 -> 28 | AF5: =AE5 -> 28 | AG5: =AF5 -> 28
C7: Status | D7: REPORTED | I7: REPORTED | N7: REPORTED
C8: Reported (blank) or Estimate ("E") | U8: E | V8: E | W8: E | X8: E | Y8: E | Z8: E | AA8: E | AB8: E | AC8: E | AD8: E | AE8: E | AF8: E | AG8: E
C9: Fiscal Period | D9: =D$4&D5&D8 -> 1Q23 | E9: =E$4&E5&E8 -> 2Q23 | F9: =F$4&F5&F8 -> 3Q23 | G9: =G$4&G5&G8 -> 4Q23 | H9: =H$4&H5&H8 -> FY23 | I9: =I$4&I5&I8 -> 1Q24 | J9: =J$4&J5&J8 -> 2Q24 | K9: =K$4&K5&K8 -> 3Q24 | ... AG9: =AG$4&AG5&AG8 -> FY28E
C10: Period end date | D10: 44957 | E10: 45046 | F10: 45138 | G10: 45230 | H10: 45230 | I10: 45322 | J10: 45412 | K10: 45504 | L10: 45596 | M10: 45596 | N10: 45688 | O10: 45777 | P10: 45869 | Q10: 45961 | R10: 45961 | S10: 46053 | T10: 46142 | U10: 46234 | V10: 46326 | W10: 46326 | X10: 46418 | Y10: 46507 | Z10: 46599 | AA10: 46691 | AB10: 46691 | AC10: 46783 | AD10: 46873 | AE10: 46965 | AF10: 47057 | AG10: 47057
B11: REVENUE
C12: Total Agilent revenue ($M) | D12: =Model!D54 -> 1756 | E12: =Model!E54 -> 1717 | F12: =Model!F54 -> 1672 | G12: =Model!G54 -> 1688 | H12: =Model!H54 -> 6833 | I12: =Model!I54 -> 1658 | J12: =Model!J54 -> 1573 | K12: =Model!K54 -> 1578 | ... AG12: =Model!AG54 -> 7977.8383
C13: Reported Y/Y | D13: =Model!D55 -> 0 | E13: =Model!E55 -> 0 | F13: =Model!F55 -> 0 | G13: =Model!G55 -> 0 | H13: =Model!H55 -> 0 | I13: =Model!I55 -> -0.055808656 | J13: =Model!J55 -> -0.08386721 | K13: =Model!K55 -> -0.056220096 | ... AG13: =Model!AG55 -> 0.04
C14: Organic | D14: =Model!D56 -> 0 | E14: =Model!E56 -> 0 | F14: =Model!F56 -> 0 | G14: =Model!G56 -> 0 | H14: =Model!H56 -> 0 | I14: =Model!I56 -> -0.063808656 | J14: =Model!J56 -> -0.06986721 | K14: =Model!K56 -> -0.040220096 | ... AG14: =Model!AG56 -> 0.04
C15: M&A | D15: =Model!D57 -> 0 | E15: =Model!E57 -> 0 | F15: =Model!F57 -> 0 | G15: =Model!G57 -> 0 | H15: =Model!H57 -> 0 | I15: =Model!I57 -> -0.001 | J15: =Model!J57 -> 0 | K15: =Model!K57 -> 0 | ... AG15: =Model!AG57 -> 0
C16: FX | D16: =Model!D58 -> 0 | E16: =Model!E58 -> 0 | F16: =Model!F58 -> 0 | G16: =Model!G58 -> 0 | H16: =Model!H58 -> 0 | I16: =Model!I58 -> 0.009 | J16: =Model!J58 -> -0.014 | K16: =Model!K58 -> -0.016 | ... AG16: =Model!AG58 -> 0
B18: ADJ OPERATING INCOME
C19: Total adj op income ($M) | D19: =Model!D93 -> 483.645 | E19: =Model!E93 -> 473.81 | F19: =Model!F93 -> 461.435 | G19: =Model!G93 -> 465.79 | H19: =Model!H93 -> 1884.68 | I19: =Model!I93 -> 457.53 | J19: =Model!J93 -> 434.64 | K19: =Model!K93 -> 436.33 | ... AG19: =Model!AG93 -> 2204.348
C20: Adj op margin % | D20: =Model!D94 -> 0.27542426 | E20: =Model!E94 -> 0.27595224 | F20: =Model!F94 -> 0.27597787 | G20: =Model!G94 -> 0.27594194 | H20: =Model!H94 -> 0.27582028 | I20: =Model!I94 -> 0.27595296 | J20: =Model!J94 -> 0.27631278 | K20: =Model!K94 -> 0.27650824 | ... AG20: =Model!AG94 -> 0.27630893
C21: Margin Y/Y (bps) | D21: =Model!D95 -> 0 | E21: =Model!E95 -> 0 | F21: =Model!F95 -> 0 | G21: =Model!G95 -> 0 | H21: =Model!H95 -> 0 | I21: =Model!I95 -> 5.2869569 | J21: =Model!J95 -> 3.6053585 | K21: =Model!K95 -> 5.3036746 | ... AG21: =Model!AG95 -> 0
B23: BY END MARKET
C24: Pharma
C25: Revenue ($M) | D25: =Model!D24 -> 639 | E25: =Model!E24 -> 612 | F25: =Model!F24 -> 592 | G25: =Model!G24 -> 590 | H25: =Model!H24 -> 2433 | I25: =Model!I24 -> 565 | J25: =Model!J24 -> 542 | K25: =Model!K24 -> 540 | ... AG25: =Model!AG24 -> 2893.0204
C26: Reported Y/Y | D26: =Model!D25 -> 0 | E26: =Model!E25 -> 0 | F26: =Model!F25 -> 0 | G26: =Model!G25 -> 0 | H26: =Model!H25 -> 0 | I26: =Model!I25 -> -0.11580595 | J26: =Model!J25 -> -0.11437908 | K26: =Model!K25 -> -0.087837838 | ... AG26: =Model!AG25 -> 0.04
C28: Chemical & Applied
C29: Revenue ($M) | D29: =Model!D29 -> 406 | E29: =Model!E29 -> 378 | F29: =Model!F29 -> 378 | G29: =Model!G29 -> 381 | H29: =Model!H29 -> 1543 | I29: =Model!I29 -> 392 | J29: =Model!J29 -> 362 | K29: =Model!K29 -> 356 | ... AG29: =Model!AG29 -> 1816.5688
C30: Reported Y/Y | D30: =Model!D30 -> 0 | E30: =Model!E30 -> 0 | F30: =Model!F30 -> 0 | G30: =Model!G30 -> 0 | H30: =Model!H30 -> 0 | I30: =Model!I30 -> -0.034482759 | J30: =Model!J30 -> -0.042328042 | K30: =Model!K30 -> -0.058201058 | ... AG30: =Model!AG30 -> 0.04
C32: Diagnostics & Clinical
C33: Revenue ($M) | D33: =Model!D34 -> 239 | E33: =Model!E34 -> 250 | F33: =Model!F34 -> 241 | G33: =Model!G34 -> 236 | H33: =Model!H34 -> 966 | I33: =Model!I34 -> 228 | J33: =Model!J34 -> 239 | K33: =Model!K34 -> 242 | ... AG33: =Model!AG34 -> 1204.2102
C34: Reported Y/Y | D34: =Model!D35 -> 0 | E34: =Model!E35 -> 0 | F34: =Model!F35 -> 0 | G34: =Model!G35 -> 0 | H34: =Model!H35 -> 0 | I34: =Model!I35 -> -0.046025105 | J34: =Model!J35 -> -0.044 | K34: =Model!K35 -> 0.0041493776 | ... AG34: =Model!AG35 -> 0.04
C36: Food
C37: Revenue ($M) | D37: =Model!D39 -> 160 | E37: =Model!E39 -> 161 | F37: =Model!F39 -> 151 | G37: =Model!G39 -> 156 | H37: =Model!H39 -> 628 | I37: =Model!I39 -> 157 | J37: =Model!J39 -> 139 | K37: =Model!K39 -> 144 | ... AG37: =Model!AG39 -> 700.74701
C38: Reported Y/Y | D38: =Model!D40 -> 0 | E38: =Model!E40 -> 0 | F38: =Model!F40 -> 0 | G38: =Model!G40 -> 0 | H38: =Model!H40 -> 0 | I38: =Model!I40 -> -0.01875 | J38: =Model!J40 -> -0.13664596 | K38: =Model!K40 -> -0.046357616 | ... AG38: =Model!AG40 -> 0.04
C40: Academia & Government
C41: Revenue ($M) | D41: =Model!D44 -> 146 | E41: =Model!E44 -> 159 | F41: =Model!F44 -> 146 | G41: =Model!G44 -> 150 | H41: =Model!H44 -> 601 | I41: =Model!I44 -> 150 | J41: =Model!J44 -> 139 | K41: =Model!K44 -> 128 | ... AG41: =Model!AG44 -> 584.84275
C42: Reported Y/Y | D42: =Model!D45 -> 0 | E42: =Model!E45 -> 0 | F42: =Model!F45 -> 0 | G42: =Model!G45 -> 0 | H42: =Model!H45 -> 0 | I42: =Model!I45 -> 0.02739726 | J42: =Model!J45 -> -0.12578616 | K42: =Model!K45 -> -0.12328767 | ... AG42: =Model!AG45 -> 0.04
C44: Environmental & Forensics
C45: Revenue ($M) | D45: =Model!D49 -> 166 | E45: =Model!E49 -> 157 | F45: =Model!F49 -> 164 | G45: =Model!G49 -> 175 | H45: =Model!H49 -> 662 | I45: =Model!I49 -> 166 | J45: =Model!J49 -> 152 | K45: =Model!K49 -> 168 | ... AG45: =Model!AG49 -> 778.44915
C46: Reported Y/Y | D46: =Model!D50 -> 0 | E46: =Model!E50 -> 0 | F46: =Model!F50 -> 0 | G46: =Model!G50 -> 0 | H46: =Model!H50 -> 0 | I46: =Model!I50 -> 0 | J46: =Model!J50 -> -0.031847134 | K46: =Model!K50 -> 0.024390244 | ... AG46: =Model!AG50 -> 0.04
B49: BY SEGMENT
C50: Life Sciences & Diagnostics Group (LDG)
C51: Revenue ($M) | D51: =Model!D62 -> 719 | E51: =Model!E62 -> 726 | F51: =Model!F62 -> 661 | G51: =Model!G62 -> 674 | H51: =Model!H62 -> 2780 | I51: =Model!I62 -> 620 | J51: =Model!J62 -> 604 | K51: =Model!K62 -> 585 | ... AG51: =Model!AG62 -> 3129.0688
C52: Adj op income ($M) | D52: =Model!D78 -> 197.725 | E52: =Model!E78 -> 199.65 | F52: =Model!F78 -> 181.775 | G52: =Model!G78 -> 185.35 | H52: =Model!H78 -> 764.5 | I52: =Model!I78 -> 170.5 | J52: =Model!J78 -> 166.1 | K52: =Model!K78 -> 160.875 | ... AG52: =Model!AG78 -> 860.49392
...

Sheet Model
B2: Agilent Quarterly Model — Revenue by End Market & Segment Income ($M)
C4: Period | D4: 1Q | E4: 2Q | F4: 3Q | G4: 4Q | H4: FY | I4: 1Q | J4: 2Q | K4: 3Q | L4: 4Q | M4: FY | N4: 1Q | O4: 2Q | P4: 3Q | Q4: 4Q | R4: FY | S4: 1Q | T4: 2Q | U4: 3Q | V4: 4Q | W4: FY | X4: 1Q | Y4: 2Q | Z4: 3Q | AA4: 4Q | AB4: FY | AC4: 1Q | AD4: 2Q | AE4: 3Q | AF4: 4Q | AG4: FY
C5: Fiscal Year (Oct YE) | D5: 23 | E5: =D5 -> 23 | F5: =E5 -> 23 | G5: =F5 -> 23 | H5: =G5 -> 23 | I5: =H5+1 -> 24 | J5: =I5 -> 24 | K5: =J5 -> 24 | L5: =K5 -> 24 | M5: =L5 -> 24 | N5: =M5+1 -> 25 | O5: =N5 -> 25 | P5: =O5 -> 25 | Q5: =P5 -> 25 | R5: =Q5 -> 25 | S5: =R5+1 -> 26 | T5: =S5 -> 26 | U5: =T5 -> 26 | V5: =U5 -> 26 | W5: =V5 -> 26 | X5: =W5+1 -> 27 | Y5: =X5 -> 27 | Z5: =Y5 -> 27 | AA5: =Z5 -> 27 | AB5: =AA5 -> 27 | AC5: =AB5+1 -> 28 | AD5: =AC5 -> 28 | AE5: =AD5 -> 28 | AF5: =AE5 -> 28 | AG5: =AF5 -> 28
C7: Status | D7: REPORTED | I7: REPORTED | N7: REPORTED
C8: Reported (blank) or Estimate ("E") | U8: E | V8: E | W8: E | X8: E | Y8: E | Z8: E | AA8: E | AB8: E | AC8: E | AD8: E | AE8: E | AF8: E | AG8: E
C9: Fiscal Period | D9: =D$4&D5&D8 -> 1Q23 | E9: =E$4&E5&E8 -> 2Q23 | F9: =F$4&F5&F8 -> 3Q23 | G9: =G$4&G5&G8 -> 4Q23 | H9: =H$4&H5&H8 -> FY23 | I9: =I$4&I5&I8 -> 1Q24 | J9: =J$4&J5&J8 -> 2Q24 | K9: =K$4&K5&K8 -> 3Q24 | ... AG9: =AG$4&AG5&AG8 -> FY28E
C10: Period end date | D10: 44957 | E10: 45046 | F10: 45138 | G10: 45230 | H10: 45230 | I10: 45322 | J10: 45412 | K10: 45504 | L10: 45596 | M10: 45596 | N10: 45688 | O10: 45777 | P10: 45869 | Q10: 45961 | R10: 45961 | S10: 46053 | T10: 46142 | U10: 46234 | V10: 46326 | W10: 46326 | X10: 46418 | Y10: 46507 | Z10: 46599 | AA10: 46691 | AB10: 46691 | AC10: 46783 | AD10: 46873 | AE10: 46965 | AF10: 47057 | AG10: 47057
B11: TOP-LINE SUMMARY (from bottom of tab)
C12: Total Agilent revenue ($M) | D12: =D54 -> 1756 | E12: =E54 -> 1717 | F12: =F54 -> 1672 | G12: =G54 -> 1688 | H12: =H54 -> 6833 | I12: =I54 -> 1658 | J12: =J54 -> 1573 | K12: =K54 -> 1578 | ... AG12: =AG54 -> 7977.8383
C13: Reported Y/Y | D13: =D55 -> 0 | E13: =E55 -> 0 | F13: =F55 -> 0 | G13: =G55 -> 0 | H13: =H55 -> 0 | I13: =I55 -> -0.055808656 | J13: =J55 -> -0.08386721 | K13: =K55 -> -0.056220096 | ... AG13: =AG55 -> 0.04
C14: Organic | D14: =D56 -> 0 | E14: =E56 -> 0 | F14: =F56 -> 0 | G14: =G56 -> 0 | H14: =H56 -> 0 | I14: =I56 -> -0.063808656 | J14: =J56 -> -0.06986721 | K14: =K56 -> -0.040220096 | ... AG14: =AG56 -> 0.04
C15: M&A | D15: =D57 -> 0 | E15: =E57 -> 0 | F15: =F57 -> 0 | G15: =G57 -> 0 | H15: =H57 -> 0 | I15: =I57 -> -0.001 | J15: =J57 -> 0 | K15: =K57 -> 0 | ... AG15: =AG57 -> 0
C16: FX | D16: =D58 -> 0 | E16: =E58 -> 0 | F16: =F58 -> 0 | G16: =G58 -> 0 | H16: =H58 -> 0 | I16: =I58 -> 0.009 | J16: =J58 -> -0.014 | K16: =K58 -> -0.016 | ... AG16: =AG58 -> 0
C18: Total adj operating income ($M) | D18: =D93 -> 483.645 | E18: =E93 -> 473.81 | F18: =F93 -> 461.435 | G18: =G93 -> 465.79 | H18: =H93 -> 1884.68 | I18: =I93 -> 457.53 | J18: =J93 -> 434.64 | K18: =K93 -> 436.33 | ... AG18: =AG93 -> 2204.348
C19: Total adj op margin % | D19: =D94 -> 0.27542426 | E19: =E94 -> 0.27595224 | F19: =F94 -> 0.27597787 | G19: =G94 -> 0.27594194 | H19: =H94 -> 0.27582028 | I19: =I94 -> 0.27595296 | J19: =J94 -> 0.27631278 | K19: =K94 -> 0.27650824 | ... AG19: =AG94 -> 0.27630893
C20: Margin Y/Y (bps) | D20: =D95 -> 0 | E20: =E95 -> 0 | F20: =F95 -> 0 | G20: =G95 -> 0 | H20: =H95 -> 0 | I20: =I95 -> 5.2869569 | J20: =J95 -> 3.6053585 | K20: =K95 -> 5.3036746 | ... AG20: =AG95 -> 0
B22: END MARKET REVENUE BUILD
A24: Bernstein / 10-Q | C24: Pharma | D24: 639 | E24: 612 | F24: 592 | G24: 590 | H24: =D24+E24+F24+G24 -> 2433 | I24: 565 | J24: 542 | K24: 540 | L24: 595 | M24: =I24+J24+K24+L24 -> 2242 | N24: 585 | O24: 603 | P24: 629 | Q24: 690 | R24: =N24+O24+P24+Q24 -> 2507 | S24: 640 | T24: 663 | U24: =P24*(1+U26+U27+U28) -> 654.16 | V24: =Q24*(1+V26+V27+V28) -> 717.6 | W24: =S24+T24+U24+V24 -> 2674.76 | X24: =S24*(1+X26+X27+X28) -> 665.6 | Y24: =T24*(1+Y26+Y27+Y28) -> 689.52 | Z24: =U24*(1+Z26+Z27+Z28) -> 680.3264 | AA24: =V24*(1+AA26+AA27+AA28) -> 746.304 | AB24: =X24+Y24+Z24+AA24 -> 2781.7504 | AC24: =X24*(1+AC26+AC27+AC28) -> 692.224 | AD24: =Y24*(1+AD26+AD27+AD28) -> 717.1008 | AE24: =Z24*(1+AE26+AE27+AE28) -> 707.53946 | AF24: =AA24*(1+AF26+AF27+AF28) -> 776.15616 | AG24: =AC24+AD24+AE24+AF24 -> 2893.0204
C25: Reported Y/Y | I25: =IFERROR(I24/D24-1,0) -> -0.11580595 | J25: =IFERROR(J24/E24-1,0) -> -0.11437908 | K25: =IFERROR(K24/F24-1,0) -> -0.087837838 | L25: =IFERROR(L24/G24-1,0) -> 0.0084745763 | M25: =IFERROR(M24/H24-1,0) -> -0.078503905 | N25: =IFERROR(N24/I24-1,0) -> 0.03539823 | O25: =IFERROR(O24/J24-1,0) -> 0.11254613 | P25: =IFERROR(P24/K24-1,0) -> 0.16481481 | ... T25: =IFERROR(T24/O24-1,0) -> 0.099502488 | U25: =U26+U27+U28 -> 0.04 | V25: =V26+V27+V28 -> 0.04 | W25: =IFERROR(W24/R24-1,0) -> 0.066916633 | X25: =X26+X27+X28 -> 0.04 | Y25: =Y26+Y27+Y28 -> 0.04 | Z25: =Z26+Z27+Z28 -> 0.04 | AA25: =AA26+AA27+AA28 -> 0.04 | AB25: =IFERROR(AB24/W24-1,0) -> 0.04 | AC25: =AC26+AC27+AC28 -> 0.04 | AD25: =AD26+AD27+AD28 -> 0.04 | AE25: =AE26+AE27+AE28 -> 0.04 | AF25: =AF26+AF27+AF28 -> 0.04 | AG25: =IFERROR(AG24/AB24-1,0) -> 0.04
C26: Organic | D26: =IFERROR(D25-D27-D28,0) -> 0 | E26: =IFERROR(E25-E27-E28,0) -> 0 | F26: =IFERROR(F25-F27-F28,0) -> 0 | G26: =IFERROR(G25-G27-G28,0) -> 0 | I26: =IFERROR(I25-I27-I28,0) -> -0.1220579 | J26: =IFERROR(J25-J27-J28,0) -> -0.10037908 | K26: =IFERROR(K25-K27-K28,0) -> -0.071837838 | L26: =IFERROR(L25-L27-L28,0) -> -0.010691525 | M26: =IFERROR(((I26*D24)+(J26*E24)+(K26*F24)+(L26*G24))/(D24+E24+F24+G24),0) -> -0.077378956 | N26: =IFERROR(N25-N27-N28,0) -> 0.03339823 | O26: =IFERROR(O25-O27-O28,0) -> 0.058892989 | P26: =IFERROR(P25-P27-P28,0) -> 0.089214815 | Q26: =IFERROR(Q25-Q27-Q28,0) -> 0.11149916 | R26: =IFERROR(((N26*I24)+(O26*J24)+(P26*K24)+(Q26*L24))/(I24+J24+K24+L24),0) -> 0.073732382 | S26: =IFERROR(S25-S27-S28,0) -> 0.096866667 | T26: =IFERROR(T25-T27-T28,0) -> 0.059502488 | U26: 0.04 | V26: 0.04 | W26: =IFERROR(((S26*N24)+(T26*O24)+(U26*P24)+(V26*Q24))/(N24+O24+P24+Q24),0) -> 0.057960511 | X26: 0.04 | Y26: 0.04 | Z26: 0.04 | AA26: 0.04 | AB26: =IFERROR(((X26*S24)+(Y26*T24)+(Z26*U24)+(AA26*V24))/(S24+T24+U24+V24),0) -> 0.04 | AC26: 0.04 | AD26: 0.04 | AE26: 0.04 | AF26: 0.04 | AG26: =IFERROR(((AC26*X24)+(AD26*Y24)+(AE26*Z24)+(AF26*AA24))/(X24+Y24+Z24+AA24),0) -> 0.04
C27: M&A | D27: 0 | E27: 0 | F27: 0 | G27: 0 | I27: -0.0027480438 | J27: 0 | K27: 0 | L27: 0.017166102 | M27: =IFERROR(((I27*D24)+(J27*E24)+(K27*F24)+(L27*G24))/(D24+E24+F24+G24),0) -> 0.0034410193 | N27: 0 | O27: 0.069653137 | P27: 0.0526 | Q27: 0.037164706 | R27: =IFERROR(((N27*I24)+(O27*J24)+(P27*K24)+(Q27*L24))/(I24+J24+K24+L24),0) -> 0.039370651 | S27: -0.048849573 | T27: 0 | U27: 0 | V27: 0 | W27: =IFERROR(((S27*N24)+(T27*O24)+(U27*P24)+(V27*Q24))/(N24+O24+P24+Q24),0) -> -0.011398883 | X27: 0 | Y27: 0 | Z27: 0 | AA27: 0 | AB27: =IFERROR(((X27*S24)+(Y27*T24)+(Z27*U24)+(AA27*V24))/(S24+T24+U24+V24),0) -> 0 | AC27: 0 | AD27: 0 | AE27: 0 | AF27: 0 | AG27: =IFERROR(((AC27*X24)+(AD27*Y24)+(AE27*Z24)+(AF27*AA24))/(X24+Y24+Z24+AA24),0) -> 0
C28: FX | I28: 0.009 | J28: -0.014 | K28: -0.016 | L28: 0.002 | M28: =IFERROR(((I28*D24)+(J28*E24)+(K28*F24)+(L28*G24))/(D24+E24+F24+G24),0) -> -0.0045659679 | N28: 0.002 | O28: -0.016 | P28: 0.023 | Q28: 0.011 | R28: =IFERROR(((N28*I24)+(O28*J24)+(P28*K24)+(Q28*L24))/(I24+J24+K24+L24),0) -> 0.0050950045 | S28: 0.046 | T28: 0.04 | U28: 0 | V28: 0 | W28: =IFERROR(((S28*N24)+(T28*O24)+(U28*P24)+(V28*Q24))/(N24+O24+P24+Q24),0) -> 0.020355006 | X28: 0 | Y28: 0 | Z28: 0 | AA28: 0 | AB28: =IFERROR(((X28*S24)+(Y28*T24)+(Z28*U24)+(AA28*V24))/(S24+T24+U24+V24),0) -> 0 | AC28: 0 | AD28: 0 | AE28: 0 | AF28: 0 | AG28: =IFERROR(((AC28*X24)+(AD28*Y24)+(AE28*Z24)+(AF28*AA24))/(X24+Y24+Z24+AA24),0) -> 0
A29: Bernstein / 10-Q | C29: Chemical & Applied | D29: 406 | E29: 378 | F29: 378 | G29: 381 | H29: =D29+E29+F29+G29 -> 1543 | I29: 392 | J29: 362 | K29: 356 | L29: 385 | M29: =I29+J29+K29+L29 -> 1495 | N29: 379 | O29: 369 | P29: 399 | Q29: 414 | R29: =N29+O29+P29+Q29 -> 1561 | S29: 422 | T29: 412 | U29: =P29*(1+U31+U32+U33) -> 414.96 | V29: =Q29*(1+V31+V32+V33) -> 430.56 | W29: =S29+T29+U29+V29 -> 1679.52 | X29: =S29*(1+X31+X32+X33) -> 438.88 | Y29: =T29*(1+Y31+Y32+Y33) -> 428.48 | Z29: =U29*(1+Z31+Z32+Z33) -> 431.5584 | AA29: =V29*(1+AA31+AA32+AA33) -> 447.7824 | AB29: =X29+Y29+Z29+AA29 -> 1746.7008 | AC29: =X29*(1+AC31+AC32+AC33) -> 456.4352 | AD29: =Y29*(1+AD31+AD32+AD33) -> 445.6192 | AE29: =Z29*(1+AE31+AE32+AE33) -> 448.82074 | AF29: =AA29*(1+AF31+AF32+AF33) -> 465.6937 | AG29: =AC29+AD29+AE29+AF29 -> 1816.5688
C30: Reported Y/Y | I30: =IFERROR(I29/D29-1,0) -> -0.034482759 | J30: =IFERROR(J29/E29-1,0) -> -0.042328042 | K30: =IFERROR(K29/F29-1,0) -> -0.058201058 | L30: =IFERROR(L29/G29-1,0) -> 0.010498688 | M30: =IFERROR(M29/H29-1,0) -> -0.031108231 | N30: =IFERROR(N29/I29-1,0) -> -0.033163265 | O30: =IFERROR(O29/J29-1,0) -> 0.019337017 | P30: =IFERROR(P29/K29-1,0) -> 0.12078652 | ... T30: =IFERROR(T29/O29-1,0) -> 0.11653117 | U30: =U31+U32+U33 -> 0.04 | V30: =V31+V32+V33 -> 0.04 | W30: =IFERROR(W29/R29-1,0) -> 0.075925689 | X30: =X31+X32+X33 -> 0.04 | Y30: =Y31+Y32+Y33 -> 0.04 | Z30: =Z31+Z32+Z33 -> 0.04 | AA30: =AA31+AA32+AA33 -> 0.04 | AB30: =IFERROR(AB29/W29-1,0) -> 0.04 | AC30: =AC31+AC32+AC33 -> 0.04 | AD30: =AD31+AD32+AD33 -> 0.04 | AE30: =AE31+AE32+AE33 -> 0.04 | AF30: =AF31+AF32+AF33 -> 0.04 | AG30: =IFERROR(AG29/AB29-1,0) -> 0.04
C31: Organic | D31: =IFERROR(D30-D32-D33,0) -> 0 | E31: =IFERROR(E30-E32-E33,0) -> 0 | F31: =IFERROR(F30-F32-F33,0) -> 0 | G31: =IFERROR(G30-G32-G33,0) -> 0 | I31: =IFERROR(I30-I32-I33,0) -> -0.043482759 | J31: =IFERROR(J30-J32-J33,0) -> -0.028328042 | K31: =IFERROR(K30-K32-K33,0) -> -0.042201058 | L31: =IFERROR(L30-L32-L33,0) -> 0.0084986877 | M31: =IFERROR(((I31*D29)+(J31*E29)+(K31*F29)+(L31*G29))/(D29+E29+F29+G29),0) -> -0.026620868 | N31: =IFERROR(N30-N32-N33,0) -> -0.035163265 | O31: =IFERROR(O30-O32-O33,0) -> 0.035337017 | P31: =IFERROR(P30-P32-P33,0) -> 0.097786517 | Q31: =IFERROR(Q30-Q32-Q33,0) -> 0.064324675 | R31: =IFERROR(((N31*I29)+(O31*J29)+(P31*K29)+(Q31*L29))/(I29+J29+K29+L29),0) -> 0.039187291 | S31: =IFERROR(S30-S32-S33,0) -> 0.067456464 | T31: =IFERROR(T30-T32-T33,0) -> 0.076531165 | U31: 0.04 | V31: 0.04 | W31: =IFERROR(((S31*N29)+(T31*O29)+(U31*P29)+(V31*Q29))/(N29+O29+P29+Q29),0) -> 0.05530173 | X31: 0.04 | Y31: 0.04 | Z31: 0.04 | AA31: 0.04 | AB31: =IFERROR(((X31*S29)+(Y31*T29)+(Z31*U29)+(AA31*V29))/(S29+T29+U29+V29),0) -> 0.04 | AC31: 0.04 | AD31: 0.04 | AE31: 0.04 | AF31: 0.04 | AG31: =IFERROR(((AC31*X29)+(AD31*Y29)+(AE31*Z29)+(AF31*AA29))/(X29+Y29+Z29+AA29),0) -> 0.04
C32: M&A | D32: 0 | E32: 0 | F32: 0 | G32: 0 | I32: 0 | J32: 0 | K32: 0 | L32: 0 | M32: =IFERROR(((I32*D29)+(J32*E29)+(K32*F29)+(L32*G29))/(D29+E29+F29+G29),0) -> 0 | N32: 0 | O32: 0 | P32: 0 | Q32: 0 | R32: =IFERROR(((N32*I29)+(O32*J29)+(P32*K29)+(Q32*L29))/(I29+J29+K29+L29),0) -> 0 | S32: 0 | T32: 0 | U32: 0 | V32: 0 | W32: =IFERROR(((S32*N29)+(T32*O29)+(U32*P29)+(V32*Q29))/(N29+O29+P29+Q29),0) -> 0 | X32: 0 | Y32: 0 | Z32: 0 | AA32: 0 | AB32: =IFERROR(((X32*S29)+(Y32*T29)+(Z32*U29)+(AA32*V29))/(S29+T29+U29+V29),0) -> 0 | AC32: 0 | AD32: 0 | AE32: 0 | AF32: 0 | AG32: =IFERROR(((AC32*X29)+(AD32*Y29)+(AE32*Z29)+(AF32*AA29))/(X29+Y29+Z29+AA29),0) -> 0
C33: FX | I33: 0.009 | J33: -0.014 | K33: -0.016 | L33: 0.002 | M33: =IFERROR(((I33*D29)+(J33*E29)+(K33*F29)+(L33*G29))/(D29+E29+F29+G29),0) -> -0.0044873623 | N33: 0.002 | O33: -0.016 | P33: 0.023 | Q33: 0.011 | R33: =IFERROR(((N33*I29)+(O33*J29)+(P33*K29)+(Q33*L29))/(I29+J29+K29+L29),0) -> 0.0049598662 | S33: 0.046 | T33: 0.04 | U33: 0 | V33: 0 | W33: =IFERROR(((S33*N29)+(T33*O29)+(U33*P29)+(V33*Q29))/(N29+O29+P29+Q29),0) -> 0.020623959 | X33: 0 | Y33: 0 | Z33: 0 | AA33: 0 | AB33: =IFERROR(((X33*S29)+(Y33*T29)+(Z33*U29)+(AA33*V29))/(S29+T29+U29+V29),0) -> 0 | AC33: 0 | AD33: 0 | AE33: 0 | AF33: 0 | AG33: =IFERROR(((AC33*X29)+(AD33*Y29)+(AE33*Z29)+(AF33*AA29))/(X29+Y29+Z29+AA29),0) -> 0
A34: Bernstein / 10-Q | C34: Diagnostics & Clinical | D34: 239 | E34: 250 | F34: 241 | G34: 236 | H34: =D34+E34+F34+G34 -> 966 | I34: 228 | J34: 239 | K34: 242 | L34: 255 | M34: =I34+J34+K34+L34 -> 964 | N34: 240 | O34: 255 | P34: 258 | Q34: 276 | R34: =N34+O34+P34+Q34 -> 1029 | S34: 263 | T34: 295 | U34: =P34*(1+U36+U37+U38) -> 268.32 | V34: =Q34*(1+V36+V37+V38) -> 287.04 | W34: =S34+T34+U34+V34 -> 1113.36 | X34: =S34*(1+X36+X37+X38) -> 273.52 | Y34: =T34*(1+Y36+Y37+Y38) -> 306.8 | Z34: =U34*(1+Z36+Z37+Z38) -> 279.0528 | AA34: =V34*(1+AA36+AA37+AA38) -> 298.5216 | AB34: =X34+Y34+Z34+AA34 -> 1157.8944 | AC34: =X34*(1+AC36+AC37+AC38) -> 284.4608 | AD34: =Y34*(1+AD36+AD37+AD38) -> 319.072 | AE34: =Z34*(1+AE36+AE37+AE38) -> 290.21491 | AF34: =AA34*(1+AF36+AF37+AF38) -> 310.46246 | AG34: =AC34+AD34+AE34+AF34 -> 1204.2102
C35: Reported Y/Y | I35: =IFERROR(I34/D34-1,0) -> -0.046025105 | J35: =IFERROR(J34/E34-1,0) -> -0.044 | K35: =IFERROR(K34/F34-1,0) -> 0.0041493776 | L35: =IFERROR(L34/G34-1,0) -> 0.080508475 | M35: =IFERROR(M34/H34-1,0) -> -0.0020703934 | N35: =IFERROR(N34/I34-1,0) -> 0.052631579 | O35: =IFERROR(O34/J34-1,0) -> 0.066945607 | P35: =IFERROR(P34/K34-1,0) -> 0.066115702 | ... T35: =IFERROR(T34/O34-1,0) -> 0.15686275 | U35: =U36+U37+U38 -> 0.04 | V35: =V36+V37+V38 -> 0.04 | W35: =IFERROR(W34/R34-1,0) -> 0.081982507 | X35: =X36+X37+X38 -> 0.04 | Y35: =Y36+Y37+Y38 -> 0.04 | Z35: =Z36+Z37+Z38 -> 0.04 | AA35: =AA36+AA37+AA38 -> 0.04 | AB35: =IFERROR(AB34/W34-1,0) -> 0.04 | AC35: =AC36+AC37+AC38 -> 0.04 | AD35: =AD36+AD37+AD38 -> 0.04 | AE35: =AE36+AE37+AE38 -> 0.04 | AF35: =AF36+AF37+AF38 -> 0.04 | AG35: =IFERROR(AG34/AB34-1,0) -> 0.04
C36: Organic | D36: =IFERROR(D35-D37-D38,0) -> 0 | E36: =IFERROR(E35-E37-E38,0) -> 0 | F36: =IFERROR(F35-F37-F38,0) -> 0 | G36: =IFERROR(G35-G37-G38,0) -> 0 | I36: =IFERROR(I35-I37-I38,0) -> -0.055025105 | J36: =IFERROR(J35-J37-J38,0) -> -0.03 | K36: =IFERROR(K35-K37-K38,0) -> 0.020149378 | L36: =IFERROR(L35-L37-L38,0) -> 0.078508475 | M36: =IFERROR(((I36*D34)+(J36*E34)+(K36*F34)+(L36*G34))/(D34+E34+F34+G34),0) -> 0.0028291925 | N36: =IFERROR(N35-N37-N38,0) -> 0.050631579 | O36: =IFERROR(O35-O37-O38,0) -> 0.082945607 | P36: =IFERROR(P35-P37-P38,0) -> 0.043115702 | Q36: =IFERROR(Q35-Q37-Q38,0) -> 0.071352941 | R36: =IFERROR(((N36*I34)+(O36*J34)+(P36*K34)+(Q36*L34))/(I34+J34+K34+L34),0) -> 0.062237552 | S36: =IFERROR(S35-S37-S38,0) -> 0.049833333 | T36: =IFERROR(T35-T37-T38,0) -> 0.11686275 | U36: 0.04 | V36: 0.04 | W36: =IFERROR(((S36*N34)+(T36*O34)+(U36*P34)+(V36*Q34))/(N34+O34+P34+Q34),0) -> 0.061341108 | X36: 0.04 | Y36: 0.04 | Z36: 0.04 | AA36: 0.04 | AB36: =IFERROR(((X36*S34)+(Y36*T34)+(Z36*U34)+(AA36*V34))/(S34+T34+U34+V34),0) -> 0.04 | AC36: 0.04 | AD36: 0.04 | AE36: 0.04 | AF36: 0.04 | AG36: =IFERROR(((AC36*X34)+(AD36*Y34)+(AE36*Z34)+(AF36*AA34))/(X34+Y34+Z34+AA34),0) -> 0.04
C37: M&A | D37: 0 | E37: 0 | F37: 0 | G37: 0 | I37: 0 | J37: 0 | K37: 0 | L37: 0 | M37: =IFERROR(((I37*D34)+(J37*E34)+(K37*F34)+(L37*G34))/(D34+E34+F34+G34),0) -> 0 | N37: 0 | O37: 0 | P37: 0 | Q37: 0 | R37: =IFERROR(((N37*I34)+(O37*J34)+(P37*K34)+(Q37*L34))/(I34+J34+K34+L34),0) -> 0 | S37: 0 | T37: 0 | U37: 0 | V37: 0 | W37: =IFERROR(((S37*N34)+(T37*O34)+(U37*P34)+(V37*Q34))/(N34+O34+P34+Q34),0) -> 0 | X37: 0 | Y37: 0 | Z37: 0 | AA37: 0 | AB37: =IFERROR(((X37*S34)+(Y37*T34)+(Z37*U34)+(AA37*V34))/(S34+T34+U34+V34),0) -> 0 | AC37: 0 | AD37: 0 | AE37: 0 | AF37: 0 | AG37: =IFERROR(((AC37*X34)+(AD37*Y34)+(AE37*Z34)+(AF37*AA34))/(X34+Y34+Z34+AA34),0) -> 0
C38: FX | I38: 0.009 | J38: -0.014 | K38: -0.016 | L38: 0.002 | M38: =IFERROR(((I38*D34)+(J38*E34)+(K38*F34)+(L38*G34))/(D34+E34+F34+G34),0) -> -0.0048995859 | N38: 0.002 | O38: -0.016 | P38: 0.023 | Q38: 0.011 | R38: =IFERROR(((N38*I34)+(O38*J34)+(P38*K34)+(Q38*L34))/(I34+J34+K34+L34),0) -> 0.005189834 | S38: 0.046 | T38: 0.04 | U38: 0 | V38: 0 | W38: =IFERROR(((S38*N34)+(T38*O34)+(U38*P34)+(V38*Q34))/(N34+O34+P34+Q34),0) -> 0.020641399 | X38: 0 | Y38: 0 | Z38: 0 | AA38: 0 | AB38: =IFERROR(((X38*S34)+(Y38*T34)+(Z38*U34)+(AA38*V34))/(S34+T34+U34+V34),0) -> 0 | AC38: 0 | AD38: 0 | AE38: 0 | AF38: 0 | AG38: =IFERROR(((AC38*X34)+(AD38*Y34)+(AE38*Z34)+(AF38*AA34))/(X34+Y34+Z34+AA34),0) -> 0
A39: Bernstein / 10-Q | C39: Food | D39: 160 | E39: 161 | F39: 151 | G39: 156 | H39: =D39+E39+F39+G39 -> 628 | I39: 157 | J39: 139 | K39: 144 | L39: 152 | M39: =I39+J39+K39+L39 -> 592 | N39: 168 | O39: 147 | P39: 157 | Q39: 165 | R39: =N39+O39+P39+Q39 -> 637 | S39: 166 | T39: 147 | U39: =P39*(1+U41+U42+U43) -> 163.28 | V39: =Q39*(1+V41+V42+V43) -> 171.6 | W39: =S39+T39+U39+V39 -> 647.88 | X39: =S39*(1+X41+X42+X43) -> 172.64 | Y39: =T39*(1+Y41+Y42+Y43) -> 152.88 | Z39: =U39*(1+Z41+Z42+Z43) -> 169.8112 | AA39: =V39*(1+AA41+AA42+AA43) -> 178.464 | AB39: =X39+Y39+Z39+AA39 -> 673.7952 | AC39: =X39*(1+AC41+AC42+AC43) -> 179.5456 | AD39: =Y39*(1+AD41+AD42+AD43) -> 158.9952 | AE39: =Z39*(1+AE41+AE42+AE43) -> 176.60365 | AF39: =AA39*(1+AF41+AF42+AF43) -> 185.60256 | AG39: =AC39+AD39+AE39+AF39 -> 700.74701
C40: Reported Y/Y | I40: =IFERROR(I39/D39-1,0) -> -0.01875 | J40: =IFERROR(J39/E39-1,0) -> -0.13664596 | K40: =IFERROR(K39/F39-1,0) -> -0.046357616 | L40: =IFERROR(L39/G39-1,0) -> -0.025641026 | M40: =IFERROR(M39/H39-1,0) -> -0.057324841 | N40: =IFERROR(N39/I39-1,0) -> 0.070063694 | O40: =IFERROR(O39/J39-1,0) -> 0.057553957 | P40: =IFERROR(P39/K39-1,0) -> 0.090277778 | ... T40: =IFERROR(T39/O39-1,0) -> 0 | U40: =U41+U42+U43 -> 0.04 | V40: =V41+V42+V43 -> 0.04 | W40: =IFERROR(W39/R39-1,0) -> 0.017080063 | X40: =X41+X42+X43 -> 0.04 | Y40: =Y41+Y42+Y43 -> 0.04 | Z40: =Z41+Z42+Z43 -> 0.04 | AA40: =AA41+AA42+AA43 -> 0.04 | AB40: =IFERROR(AB39/W39-1,0) -> 0.04 | AC40: =AC41+AC42+AC43 -> 0.04 | AD40: =AD41+AD42+AD43 -> 0.04 | AE40: =AE41+AE42+AE43 -> 0.04 | AF40: =AF41+AF42+AF43 -> 0.04 | AG40: =IFERROR(AG39/AB39-1,0) -> 0.04
C41: Organic | D41: =IFERROR(D40-D42-D43,0) -> 0 | E41: =IFERROR(E40-E42-E43,0) -> 0 | F41: =IFERROR(F40-F42-F43,0) -> 0 | G41: =IFERROR(G40-G42-G43,0) -> 0 | I41: =IFERROR(I40-I42-I43,0) -> -0.02775 | J41: =IFERROR(J40-J42-J43,0) -> -0.12264596 | K41: =IFERROR(K40-K42-K43,0) -> -0.030357616 | L41: =IFERROR(L40-L42-L43,0) -> -0.027641026 | M41: =IFERROR(((I41*D39)+(J41*E39)+(K41*F39)+(L41*G39))/(D39+E39+F39+G39),0) -> -0.052678344 | N41: =IFERROR(N40-N42-N43,0) -> 0.068063694 | O41: =IFERROR(O40-O42-O43,0) -> 0.073553957 | P41: =IFERROR(P40-P42-P43,0) -> 0.067277778 | Q41: =IFERROR(Q40-Q42-Q43,0) -> 0.074526316 | R41: =IFERROR(((N41*I39)+(O41*J39)+(P41*K39)+(Q41*L39))/(I39+J39+K39+L39),0) -> 0.070820946 | S41: =IFERROR(S40-S42-S43,0) -> -0.057904762 | T41: =IFERROR(T40-T42-T43,0) -> -0.04 | U41: 0.04 | V41: 0.04 | W41: =IFERROR(((S41*N39)+(T41*O39)+(U41*P39)+(V41*Q39))/(N39+O39+P39+Q39),0) -> -0.0042825746 | X41: 0.04 | Y41: 0.04 | Z41: 0.04 | AA41: 0.04 | AB41: =IFERROR(((X41*S39)+(Y41*T39)+(Z41*U39)+(AA41*V39))/(S39+T39+U39+V39),0) -> 0.04 | AC41: 0.04 | AD41: 0.04 | AE41: 0.04 | AF41: 0.04 | AG41: =IFERROR(((AC41*X39)+(AD41*Y39)+(AE41*Z39)+(AF41*AA39))/(X39+Y39+Z39+AA39),0) -> 0.04
C42: M&A | D42: 0 | E42: 0 | F42: 0 | G42: 0 | I42: 0 | J42: 0 | K42: 0 | L42: 0 | M42: =IFERROR(((I42*D39)+(J42*E39)+(K42*F39)+(L42*G39))/(D39+E39+F39+G39),0) -> 0 | N42: 0 | O42: 0 | P42: 0 | Q42: 0 | R42: =IFERROR(((N42*I39)+(O42*J39)+(P42*K39)+(Q42*L39))/(I39+J39+K39+L39),0) -> 0 | S42: 0 | T42: 0 | U42: 0 | V42: 0 | W42: =IFERROR(((S42*N39)+(T42*O39)+(U42*P39)+(V42*Q39))/(N39+O39+P39+Q39),0) -> 0 | X42: 0 | Y42: 0 | Z42: 0 | AA42: 0 | AB42: =IFERROR(((X42*S39)+(Y42*T39)+(Z42*U39)+(AA42*V39))/(S39+T39+U39+V39),0) -> 0 | AC42: 0 | AD42: 0 | AE42: 0 | AF42: 0 | AG42: =IFERROR(((AC42*X39)+(AD42*Y39)+(AE42*Z39)+(AF42*AA39))/(X39+Y39+Z39+AA39),0) -> 0
C43: FX | I43: 0.009 | J43: -0.014 | K43: -0.016 | L43: 0.002 | M43: =IFERROR(((I43*D39)+(J43*E39)+(K43*F39)+(L43*G39))/(D39+E39+F39+G39),0) -> -0.0046464968 | N43: 0.002 | O43: -0.016 | P43: 0.023 | Q43: 0.011 | R43: =IFERROR(((N43*I39)+(O43*J39)+(P43*K39)+(Q43*L39))/(I39+J39+K39+L39),0) -> 0.0051925676 | S43: 0.046 | T43: 0.04 | U43: 0 | V43: 0 | W43: =IFERROR(((S43*N39)+(T43*O39)+(U43*P39)+(V43*Q39))/(N39+O39+P39+Q39),0) -> 0.021362637 | X43: 0 | Y43: 0 | Z43: 0 | AA43: 0 | AB43: =IFERROR(((X43*S39)+(Y43*T39)+(Z43*U39)+(AA43*V39))/(S39+T39+U39+V39),0) -> 0 | AC43: 0 | AD43: 0 | AE43: 0 | AF43: 0 | AG43: =IFERROR(((AC43*X39)+(AD43*Y39)+(AE43*Z39)+(AF43*AA39))/(X39+Y39+Z39+AA39),0) -> 0
A44: Bernstein / 10-Q | C44: Academia & Government | D44: 146 | E44: 159 | F44: 146 | G44: 150 | H44: =D44+E44+F44+G44 -> 601 | I44: 150 | J44: 139 | K44: 128 | L44: 150 | M44: =I44+J44+K44+L44 -> 567 | N44: 137 | O44: 135 | P44: 132 | Q44: 136 | R44: =N44+O44+P44+Q44 -> 540 | S44: 130 | T44: 132 | U44: =P44*(1+U46+U47+U48) -> 137.28 | V44: =Q44*(1+V46+V47+V48) -> 141.44 | W44: =S44+T44+U44+V44 -> 540.72 | X44: =S44*(1+X46+X47+X48) -> 135.2 | Y44: =T44*(1+Y46+Y47+Y48) -> 137.28 | Z44: =U44*(1+Z46+Z47+Z48) -> 142.7712 | AA44: =V44*(1+AA46+AA47+AA48) -> 147.0976 | AB44: =X44+Y44+Z44+AA44 -> 562.3488 | AC44: =X44*(1+AC46+AC47+AC48) -> 140.608 | AD44: =Y44*(1+AD46+AD47+AD48) -> 142.7712 | AE44: =Z44*(1+AE46+AE47+AE48) -> 148.48205 | AF44: =AA44*(1+AF46+AF47+AF48) -> 152.9815 | AG44: =AC44+AD44+AE44+AF44 -> 584.84275
C45: Reported Y/Y | I45: =IFERROR(I44/D44-1,0) -> 0.02739726 | J45: =IFERROR(J44/E44-1,0) -> -0.12578616 | K45: =IFERROR(K44/F44-1,0) -> -0.12328767 | L45: =IFERROR(L44/G44-1,0) -> 0 | M45: =IFERROR(M44/H44-1,0) -> -0.056572379 | N45: =IFERROR(N44/I44-1,0) -> -0.086666667 | O45: =IFERROR(O44/J44-1,0) -> -0.028776978 | P45: =IFERROR(P44/K44-1,0) -> 0.03125 | ... T45: =IFERROR(T44/O44-1,0) -> -0.022222222 | U45: =U46+U47+U48 -> 0.04 | V45: =V46+V47+V48 -> 0.04 | W45: =IFERROR(W44/R44-1,0) -> 0.0013333333 | X45: =X46+X47+X48 -> 0.04 | Y45: =Y46+Y47+Y48 -> 0.04 | Z45: =Z46+Z47+Z48 -> 0.04 | AA45: =AA46+AA47+AA48 -> 0.04 | AB45: =IFERROR(AB44/W44-1,0) -> 0.04 | AC45: =AC46+AC47+AC48 -> 0.04 | AD45: =AD46+AD47+AD48 -> 0.04 | AE45: =AE46+AE47+AE48 -> 0.04 | AF45: =AF46+AF47+AF48 -> 0.04 | AG45: =IFERROR(AG44/AB44-1,0) -> 0.04
C46: Organic | D46: =IFERROR(D45-D47-D48,0) -> 0 | E46: =IFERROR(E45-E47-E48,0) -> 0 | F46: =IFERROR(F45-F47-F48,0) -> 0 | G46: =IFERROR(G45-G47-G48,0) -> 0 | I46: =IFERROR(I45-I47-I48,0) -> 0.01839726 | J46: =IFERROR(J45-J47-J48,0) -> -0.11178616 | K46: =IFERROR(K45-K47-K48,0) -> -0.10728767 | L46: =IFERROR(L45-L47-L48,0) -> -0.002 | M46: =IFERROR(((I46*D44)+(J46*E44)+(K46*F44)+(L46*G44))/(D44+E44+F44+G44),0) -> -0.051667221 | N46: =IFERROR(N45-N47-N48,0) -> -0.088666667 | O46: =IFERROR(O45-O47-O48,0) -> -0.012776978 | P46: =IFERROR(P45-P47-P48,0) -> 0.00825 | Q46: =IFERROR(Q45-Q47-Q48,0) -> -0.10433333 | R46: =IFERROR(((N46*I44)+(O46*J44)+(P46*K44)+(Q46*L44))/(I44+J44+K44+L44),0) -> -0.052328042 | S46: =IFERROR(S45-S47-S48,0) -> -0.097094891 | T46: =IFERROR(T45-T47-T48,0) -> -0.062222222 | U46: 0.04 | V46: 0.04 | W46: =IFERROR(((S46*N44)+(T46*O44)+(U46*P44)+(V46*Q44))/(N44+O44+P44+Q44),0) -> -0.020337037 | X46: 0.04 | Y46: 0.04 | Z46: 0.04 | AA46: 0.04 | AB46: =IFERROR(((X46*S44)+(Y46*T44)+(Z46*U44)+(AA46*V44))/(S44+T44+U44+V44),0) -> 0.04 | AC46: 0.04 | AD46: 0.04 | AE46: 0.04 | AF46: 0.04 | AG46: =IFERROR(((AC46*X44)+(AD46*Y44)+(AE46*Z44)+(AF46*AA44))/(X44+Y44+Z44+AA44),0) -> 0.04
...

Sheet Upside
B2: Agilent Model vs Guidance
B4: Metric | C4: FY26 Guide | D4: FY26 Model | E4: FY26 Δ | F4: FY27 Model | G4: FY28 Model
B5: Revenue ($M) | C5: 7360 | D5: =Model!W54 -> 7375.96 | E5: =IFERROR((D5-C5)/C5,0) -> 0.0021684783 | F5: =Model!AB54 -> 7670.9984 | G5: =Model!AG54 -> 7977.8383
B6: Organic growth % | C6: 0.04 | D6: =Model!W56 -> 0.044975676 | E6: =D6-C6 -> 0.0049756765 | F6: =Model!AB56 -> 0.04 | G6: =Model!AG56 -> 0.04
B7: Adj op income ($M) | C7: 1950 | D7: =Model!W93 -> 2038.0436 | E7: =IFERROR((D7-C7)/C7,0) -> 0.045150564 | F7: =Model!AB93 -> 2119.5653 | G7: =Model!AG93 -> 2204.348
B8: Adj op margin % | C8: =C7/C5 -> 0.26494565 | D8: =D7/D5 -> 0.27630893 | E8: =D8-C8 -> 0.011363276 | F8: =F7/F5 -> 0.27630893 | G8: =G7/G5 -> 0.27630893
B10: How to use
B11: 1. Update column C (BLUE) with the latest guidance.
B12: 2. Adjust forward end-market organic / FX / M&A on the Model tab (RED cells).
B13: 3. Adjust segment margin assumptions on the Model tab to test op-leverage scenarios.
B14: 4. Watch columns D and E to size upside / downside vs. guidance.
