Workbook

Sheet Cover
A1: Life Science Tools Monthly Tracker
A4: Date Range: Jan 01, 2020 to Jul 31, 2026 | Generated: August 11, 2026
B7: Module Status
B8: Module | C8: Details | D8: Status
B9: Clinical Trials | C9: 28,726 trials fetched | D9: OK
B10: FDA Novel Approvals | C10: 422 novel approvals | D10: OK
B11: FDA Biosimilars | C11: 63 biosimilar entries | D11: OK
B12: NIH Outlays | C12: 90 NIH monthly records | D12: OK
B15: Report Contents
B16: Charts
C17: CT Charts
C18: FDA Charts
C19: MTS Charts
B20: Summary
C21: Summary Statistics
C22: Summary Statistics - Enrollment
C23: FDA Approval Summary
C24: MTS Summary Statistics
B25: Database
C26: Trial Database
C27: Novel Approval Database
C28: Biosimilar Approval Database
C29: MTS Database

Sheet ── Charts ──
A1: Charts

Sheet CT Charts

Sheet FDA Charts

Sheet _MTS_ChartData
A1: 2019 | B1: 35.882103 | D1: Aug 24 | E1: 4.5237147
A2: 2020 | B2: 36.692828 | D2: Sep 24 | E2: 4.2577705
A3: 2021 | B3: 39.350215 | D3: Oct 24 | E3: 4.2827096
A4: 2022 | B4: 41.942182 | D4: Nov 24 | E4: 3.9062613
A5: 2023 | B5: 46.479341 | D5: Dec 24 | E5: 3.9532513
A6: 2024 | B6: 48.980222 | D6: Jan 25 | E6: 3.5543499
A7: 2025 | B7: 46.748458 | D7: Feb 25 | E7: 3.7391572
A8: 2026 | B8: 22.391811 | D8: Mar 25 | E8: 3.5495495
A9: 2026 Ann. | B9: 38.4 | D9: Apr 25 | E9: 3.8495311
D10: May 25 | E10: 2.7680988
D11: Jun 25 | E11: 4.2518099
D12: Jul 25 | E12: 4.5197167
D13: Aug 25 | E13: 4.3715123
D14: Sep 25 | E14: 4.5950414
D15: Oct 25 | E15: 3.3139684
D16: Nov 25 | E16: 3.5981446
D17: Dec 25 | E17: 4.6375781
D18: Jan 26 | E18: 3.559405
D19: Feb 26 | E19: 3.4114674
D20: Mar 26 | E20: 4.0391356
D21: Apr 26 | E21: 3.6817412
... D24: Jul 26 | E24: 0

Sheet MTS Charts

Sheet ── Summary ──
A1: Summary

Sheet Summary Statistics
A1: Year | B1: Early Phase 1 | C1: Phase 1 | D1: Phase 1/2 | E1: Phase 2 | F1: Phase 2/3 | G1: Phase 3 | H1: Phase 4 | I1: Total
A2: 2020 | B2: =COUNTIFS('Trial Database'!$J$2:$J$28727,">="&DATE(2020,1,1),'Trial Database'!$J$2:$J$28727,"<"&DATE(2021,1,1),'Trial Database'!$E$2:$E$28727,"Early Phase 1") -> 0 | C2: =COUNTIFS('Trial Database'!$J$2:$J$28727,">="&DATE(2020,1,1),'Trial Database'!$J$2:$J$28727,"<"&DATE(2021,1,1),'Trial Database'!$E$2:$E$28727,"Phase 1") -> 0 | D2: =COUNTIFS('Trial Database'!$J$2:$J$28727,">="&DATE(2020,1,1),'Trial Database'!$J$2:$J$28727,"<"&DATE(2021,1,1),'Trial Database'!$E$2:$E$28727,"Phase 1/2") -> 0 | E2: =COUNTIFS('Trial Database'!$J$2:$J$28727,">="&DATE(2020,1,1),'Trial Database'!$J$2:$J$28727,"<"&DATE(2021,1,1),'Trial Database'!$E$2:$E$28727,"Phase 2") -> 0 | F2: =COUNTIFS('Trial Database'!$J$2:$J$28727,">="&DATE(2020,1,1),'Trial Database'!$J$2:$J$28727,"<"&DATE(2021,1,1),'Trial Database'!$E$2:$E$28727,"Phase 2/3") -> 0 | G2: =COUNTIFS('Trial Database'!$J$2:$J$28727,">="&DATE(2020,1,1),'Trial Database'!$J$2:$J$28727,"<"&DATE(2021,1,1),'Trial Database'!$E$2:$E$28727,"Phase 3") -> 0 | H2: =COUNTIFS('Trial Database'!$J$2:$J$28727,">="&DATE(2020,1,1),'Trial Database'!$J$2:$J$28727,"<"&DATE(2021,1,1),'Trial Database'!$E$2:$E$28727,"Phase 4") -> 0 | I2: =SUM(B2:H2) -> 0
A3: 2021 | B3: =COUNTIFS('Trial Database'!$J$2:$J$28727,">="&DATE(2021,1,1),'Trial Database'!$J$2:$J$28727,"<"&DATE(2022,1,1),'Trial Database'!$E$2:$E$28727,"Early Phase 1") -> 0 | C3: =COUNTIFS('Trial Database'!$J$2:$J$28727,">="&DATE(2021,1,1),'Trial Database'!$J$2:$J$28727,"<"&DATE(2022,1,1),'Trial Database'!$E$2:$E$28727,"Phase 1") -> 0 | D3: =COUNTIFS('Trial Database'!$J$2:$J$28727,">="&DATE(2021,1,1),'Trial Database'!$J$2:$J$28727,"<"&DATE(2022,1,1),'Trial Database'!$E$2:$E$28727,"Phase 1/2") -> 0 | E3: =COUNTIFS('Trial Database'!$J$2:$J$28727,">="&DATE(2021,1,1),'Trial Database'!$J$2:$J$28727,"<"&DATE(2022,1,1),'Trial Database'!$E$2:$E$28727,"Phase 2") -> 0 | F3: =COUNTIFS('Trial Database'!$J$2:$J$28727,">="&DATE(2021,1,1),'Trial Database'!$J$2:$J$28727,"<"&DATE(2022,1,1),'Trial Database'!$E$2:$E$28727,"Phase 2/3") -> 0 | G3: =COUNTIFS('Trial Database'!$J$2:$J$28727,">="&DATE(2021,1,1),'Trial Database'!$J$2:$J$28727,"<"&DATE(2022,1,1),'Trial Database'!$E$2:$E$28727,"Phase 3") -> 0 | H3: =COUNTIFS('Trial Database'!$J$2:$J$28727,">="&DATE(2021,1,1),'Trial Database'!$J$2:$J$28727,"<"&DATE(2022,1,1),'Trial Database'!$E$2:$E$28727,"Phase 4") -> 0 | I3: =SUM(B3:H3) -> 0
A4: 2022 | B4: =COUNTIFS('Trial Database'!$J$2:$J$28727,">="&DATE(2022,1,1),'Trial Database'!$J$2:$J$28727,"<"&DATE(2023,1,1),'Trial Database'!$E$2:$E$28727,"Early Phase 1") -> 0 | C4: =COUNTIFS('Trial Database'!$J$2:$J$28727,">="&DATE(2022,1,1),'Trial Database'!$J$2:$J$28727,"<"&DATE(2023,1,1),'Trial Database'!$E$2:$E$28727,"Phase 1") -> 0 | D4: =COUNTIFS('Trial Database'!$J$2:$J$28727,">="&DATE(2022,1,1),'Trial Database'!$J$2:$J$28727,"<"&DATE(2023,1,1),'Trial Database'!$E$2:$E$28727,"Phase 1/2") -> 0 | E4: =COUNTIFS('Trial Database'!$J$2:$J$28727,">="&DATE(2022,1,1),'Trial Database'!$J$2:$J$28727,"<"&DATE(2023,1,1),'Trial Database'!$E$2:$E$28727,"Phase 2") -> 0 | F4: =COUNTIFS('Trial Database'!$J$2:$J$28727,">="&DATE(2022,1,1),'Trial Database'!$J$2:$J$28727,"<"&DATE(2023,1,1),'Trial Database'!$E$2:$E$28727,"Phase 2/3") -> 0 | G4: =COUNTIFS('Trial Database'!$J$2:$J$28727,">="&DATE(2022,1,1),'Trial Database'!$J$2:$J$28727,"<"&DATE(2023,1,1),'Trial Database'!$E$2:$E$28727,"Phase 3") -> 0 | H4: =COUNTIFS('Trial Database'!$J$2:$J$28727,">="&DATE(2022,1,1),'Trial Database'!$J$2:$J$28727,"<"&DATE(2023,1,1),'Trial Database'!$E$2:$E$28727,"Phase 4") -> 0 | I4: =SUM(B4:H4) -> 0
A5: 2023 | B5: =COUNTIFS('Trial Database'!$J$2:$J$28727,">="&DATE(2023,1,1),'Trial Database'!$J$2:$J$28727,"<"&DATE(2024,1,1),'Trial Database'!$E$2:$E$28727,"Early Phase 1") -> 0 | C5: =COUNTIFS('Trial Database'!$J$2:$J$28727,">="&DATE(2023,1,1),'Trial Database'!$J$2:$J$28727,"<"&DATE(2024,1,1),'Trial Database'!$E$2:$E$28727,"Phase 1") -> 0 | D5: =COUNTIFS('Trial Database'!$J$2:$J$28727,">="&DATE(2023,1,1),'Trial Database'!$J$2:$J$28727,"<"&DATE(2024,1,1),'Trial Database'!$E$2:$E$28727,"Phase 1/2") -> 0 | E5: =COUNTIFS('Trial Database'!$J$2:$J$28727,">="&DATE(2023,1,1),'Trial Database'!$J$2:$J$28727,"<"&DATE(2024,1,1),'Trial Database'!$E$2:$E$28727,"Phase 2") -> 0 | F5: =COUNTIFS('Trial Database'!$J$2:$J$28727,">="&DATE(2023,1,1),'Trial Database'!$J$2:$J$28727,"<"&DATE(2024,1,1),'Trial Database'!$E$2:$E$28727,"Phase 2/3") -> 0 | G5: =COUNTIFS('Trial Database'!$J$2:$J$28727,">="&DATE(2023,1,1),'Trial Database'!$J$2:$J$28727,"<"&DATE(2024,1,1),'Trial Database'!$E$2:$E$28727,"Phase 3") -> 0 | H5: =COUNTIFS('Trial Database'!$J$2:$J$28727,">="&DATE(2023,1,1),'Trial Database'!$J$2:$J$28727,"<"&DATE(2024,1,1),'Trial Database'!$E$2:$E$28727,"Phase 4") -> 0 | I5: =SUM(B5:H5) -> 0
A6: 2024 | B6: =COUNTIFS('Trial Database'!$J$2:$J$28727,">="&DATE(2024,1,1),'Trial Database'!$J$2:$J$28727,"<"&DATE(2025,1,1),'Trial Database'!$E$2:$E$28727,"Early Phase 1") -> 0 | C6: =COUNTIFS('Trial Database'!$J$2:$J$28727,">="&DATE(2024,1,1),'Trial Database'!$J$2:$J$28727,"<"&DATE(2025,1,1),'Trial Database'!$E$2:$E$28727,"Phase 1") -> 0 | D6: =COUNTIFS('Trial Database'!$J$2:$J$28727,">="&DATE(2024,1,1),'Trial Database'!$J$2:$J$28727,"<"&DATE(2025,1,1),'Trial Database'!$E$2:$E$28727,"Phase 1/2") -> 0 | E6: =COUNTIFS('Trial Database'!$J$2:$J$28727,">="&DATE(2024,1,1),'Trial Database'!$J$2:$J$28727,"<"&DATE(2025,1,1),'Trial Database'!$E$2:$E$28727,"Phase 2") -> 0 | F6: =COUNTIFS('Trial Database'!$J$2:$J$28727,">="&DATE(2024,1,1),'Trial Database'!$J$2:$J$28727,"<"&DATE(2025,1,1),'Trial Database'!$E$2:$E$28727,"Phase 2/3") -> 0 | G6: =COUNTIFS('Trial Database'!$J$2:$J$28727,">="&DATE(2024,1,1),'Trial Database'!$J$2:$J$28727,"<"&DATE(2025,1,1),'Trial Database'!$E$2:$E$28727,"Phase 3") -> 0 | H6: =COUNTIFS('Trial Database'!$J$2:$J$28727,">="&DATE(2024,1,1),'Trial Database'!$J$2:$J$28727,"<"&DATE(2025,1,1),'Trial Database'!$E$2:$E$28727,"Phase 4") -> 0 | I6: =SUM(B6:H6) -> 0
A7: 2025 | B7: =COUNTIFS('Trial Database'!$J$2:$J$28727,">="&DATE(2025,1,1),'Trial Database'!$J$2:$J$28727,"<"&DATE(2026,1,1),'Trial Database'!$E$2:$E$28727,"Early Phase 1") -> 0 | C7: =COUNTIFS('Trial Database'!$J$2:$J$28727,">="&DATE(2025,1,1),'Trial Database'!$J$2:$J$28727,"<"&DATE(2026,1,1),'Trial Database'!$E$2:$E$28727,"Phase 1") -> 0 | D7: =COUNTIFS('Trial Database'!$J$2:$J$28727,">="&DATE(2025,1,1),'Trial Database'!$J$2:$J$28727,"<"&DATE(2026,1,1),'Trial Database'!$E$2:$E$28727,"Phase 1/2") -> 0 | E7: =COUNTIFS('Trial Database'!$J$2:$J$28727,">="&DATE(2025,1,1),'Trial Database'!$J$2:$J$28727,"<"&DATE(2026,1,1),'Trial Database'!$E$2:$E$28727,"Phase 2") -> 0 | F7: =COUNTIFS('Trial Database'!$J$2:$J$28727,">="&DATE(2025,1,1),'Trial Database'!$J$2:$J$28727,"<"&DATE(2026,1,1),'Trial Database'!$E$2:$E$28727,"Phase 2/3") -> 0 | G7: =COUNTIFS('Trial Database'!$J$2:$J$28727,">="&DATE(2025,1,1),'Trial Database'!$J$2:$J$28727,"<"&DATE(2026,1,1),'Trial Database'!$E$2:$E$28727,"Phase 3") -> 0 | H7: =COUNTIFS('Trial Database'!$J$2:$J$28727,">="&DATE(2025,1,1),'Trial Database'!$J$2:$J$28727,"<"&DATE(2026,1,1),'Trial Database'!$E$2:$E$28727,"Phase 4") -> 0 | I7: =SUM(B7:H7) -> 0
A8: 2026 through July | B8: =COUNTIFS('Trial Database'!$J$2:$J$28727,">="&DATE(2026,1,1),'Trial Database'!$J$2:$J$28727,"<"&DATE(2027,1,1),'Trial Database'!$E$2:$E$28727,"Early Phase 1") -> 0 | C8: =COUNTIFS('Trial Database'!$J$2:$J$28727,">="&DATE(2026,1,1),'Trial Database'!$J$2:$J$28727,"<"&DATE(2027,1,1),'Trial Database'!$E$2:$E$28727,"Phase 1") -> 0 | D8: =COUNTIFS('Trial Database'!$J$2:$J$28727,">="&DATE(2026,1,1),'Trial Database'!$J$2:$J$28727,"<"&DATE(2027,1,1),'Trial Database'!$E$2:$E$28727,"Phase 1/2") -> 0 | E8: =COUNTIFS('Trial Database'!$J$2:$J$28727,">="&DATE(2026,1,1),'Trial Database'!$J$2:$J$28727,"<"&DATE(2027,1,1),'Trial Database'!$E$2:$E$28727,"Phase 2") -> 0 | F8: =COUNTIFS('Trial Database'!$J$2:$J$28727,">="&DATE(2026,1,1),'Trial Database'!$J$2:$J$28727,"<"&DATE(2027,1,1),'Trial Database'!$E$2:$E$28727,"Phase 2/3") -> 0 | G8: =COUNTIFS('Trial Database'!$J$2:$J$28727,">="&DATE(2026,1,1),'Trial Database'!$J$2:$J$28727,"<"&DATE(2027,1,1),'Trial Database'!$E$2:$E$28727,"Phase 3") -> 0 | H8: =COUNTIFS('Trial Database'!$J$2:$J$28727,">="&DATE(2026,1,1),'Trial Database'!$J$2:$J$28727,"<"&DATE(2027,1,1),'Trial Database'!$E$2:$E$28727,"Phase 4") -> 0 | I8: =SUM(B8:H8) -> 0
A9: 2026 Annualized | B9: =ROUND(B8*12/MONTH(EOMONTH(TODAY(),-1)),0) -> 0 | C9: =ROUND(C8*12/MONTH(EOMONTH(TODAY(),-1)),0) -> 0 | D9: =ROUND(D8*12/MONTH(EOMONTH(TODAY(),-1)),0) -> 0 | E9: =ROUND(E8*12/MONTH(EOMONTH(TODAY(),-1)),0) -> 0 | F9: =ROUND(F8*12/MONTH(EOMONTH(TODAY(),-1)),0) -> 0 | G9: =ROUND(G8*12/MONTH(EOMONTH(TODAY(),-1)),0) -> 0 | H9: =ROUND(H8*12/MONTH(EOMONTH(TODAY(),-1)),0) -> 0 | I9: =SUM(B9:H9) -> 0
A12: Rolling Metrics | B12: Value
A13: T12M (Aug 2025 – Jul 2026) | B13: =COUNTIFS('Trial Database'!$J$2:$J$28727,">="&DATE(2025,8,1),'Trial Database'!$J$2:$J$28727,"<="&DATE(2026,7,31)) -> 0
A14: T12M Prior (Aug 2024 – Jul 2025) | B14: =COUNTIFS('Trial Database'!$J$2:$J$28727,">="&DATE(2024,8,1),'Trial Database'!$J$2:$J$28727,"<="&DATE(2025,7,31)) -> 0
A15: T12M vs T12M Prior % | B15: =IFERROR((B13-B14)/B14,"N/A") -> 0
A16: YoY % trials/day (Jul 2026 vs Jul 2025) | B16: =IFERROR(((COUNTIFS('Trial Database'!$J$2:$J$28727,">="&DATE(2026,7,1),'Trial Database'!$J$2:$J$28727,"<="&DATE(2026,7,31))/DAY(EOMONTH(DATE(2026,7,1),0)))-(COUNTIFS('Trial Database'!$J$2:$J$28727,">="&DATE(2025,7,1),'Trial Database'!$J$2:$J$28727,"<="&DATE(2025,7,31))/DAY(EOMONTH(DATE(2025,7,1),0))))/(COUNTIFS('Trial Database'!$J$2:$J$28727,">="&DATE(2025,7,1),'Trial Database'!$J$2:$J$28727,"<="&DATE(2025,7,31))/DAY(EOMONTH(DATE(2025,7,1),0))),"N/A") -> 0
A17: MoM % trials/day (Jul 2026 vs Jun 2026) | B17: =IFERROR(((COUNTIFS('Trial Database'!$J$2:$J$28727,">="&DATE(2026,7,1),'Trial Database'!$J$2:$J$28727,"<="&DATE(2026,7,31))/DAY(EOMONTH(DATE(2026,7,1),0)))-(COUNTIFS('Trial Database'!$J$2:$J$28727,">="&DATE(2026,6,1),'Trial Database'!$J$2:$J$28727,"<="&DATE(2026,6,30))/DAY(EOMONTH(DATE(2026,6,1),0))))/(COUNTIFS('Trial Database'!$J$2:$J$28727,">="&DATE(2026,6,1),'Trial Database'!$J$2:$J$28727,"<="&DATE(2026,6,30))/DAY(EOMONTH(DATE(2026,6,1),0))),"N/A") -> 0
A18: MoM Prior % trials/day (Jun 2026 vs May 2026) | B18: =IFERROR(((COUNTIFS('Trial Database'!$J$2:$J$28727,">="&DATE(2026,6,1),'Trial Database'!$J$2:$J$28727,"<="&DATE(2026,6,30))/DAY(EOMONTH(DATE(2026,6,1),0)))-(COUNTIFS('Trial Database'!$J$2:$J$28727,">="&DATE(2026,5,1),'Trial Database'!$J$2:$J$28727,"<="&DATE(2026,5,31))/DAY(EOMONTH(DATE(2026,5,1),0))))/(COUNTIFS('Trial Database'!$J$2:$J$28727,">="&DATE(2026,5,1),'Trial Database'!$J$2:$J$28727,"<="&DATE(2026,5,31))/DAY(EOMONTH(DATE(2026,5,1),0))),"N/A") -> 0
A21: Month | B21: Early Phase 1 | C21: Phase 1 | D21: Phase 1/2 | E21: Phase 2 | F21: Phase 2/3 | G21: Phase 3 | H21: Phase 4 | I21: Total | J21: Days | K21: Trials/Day
A22: 43831 | B22: =COUNTIFS('Trial Database'!$J$2:$J$28727,">="&DATE(2020,1,1),'Trial Database'!$J$2:$J$28727,"<"&DATE(2020,2,1),'Trial Database'!$E$2:$E$28727,"Early Phase 1") -> 0 | C22: =COUNTIFS('Trial Database'!$J$2:$J$28727,">="&DATE(2020,1,1),'Trial Database'!$J$2:$J$28727,"<"&DATE(2020,2,1),'Trial Database'!$E$2:$E$28727,"Phase 1") -> 0 | D22: =COUNTIFS('Trial Database'!$J$2:$J$28727,">="&DATE(2020,1,1),'Trial Database'!$J$2:$J$28727,"<"&DATE(2020,2,1),'Trial Database'!$E$2:$E$28727,"Phase 1/2") -> 0 | E22: =COUNTIFS('Trial Database'!$J$2:$J$28727,">="&DATE(2020,1,1),'Trial Database'!$J$2:$J$28727,"<"&DATE(2020,2,1),'Trial Database'!$E$2:$E$28727,"Phase 2") -> 0 | F22: =COUNTIFS('Trial Database'!$J$2:$J$28727,">="&DATE(2020,1,1),'Trial Database'!$J$2:$J$28727,"<"&DATE(2020,2,1),'Trial Database'!$E$2:$E$28727,"Phase 2/3") -> 0 | G22: =COUNTIFS('Trial Database'!$J$2:$J$28727,">="&DATE(2020,1,1),'Trial Database'!$J$2:$J$28727,"<"&DATE(2020,2,1),'Trial Database'!$E$2:$E$28727,"Phase 3") -> 0 | H22: =COUNTIFS('Trial Database'!$J$2:$J$28727,">="&DATE(2020,1,1),'Trial Database'!$J$2:$J$28727,"<"&DATE(2020,2,1),'Trial Database'!$E$2:$E$28727,"Phase 4") -> 0 | I22: =SUM(B22:H22) -> 0 | J22: =DAY(EOMONTH(A22,0)) -> 0 | K22: =IF(J22=0,0,I22/J22) -> 0
A23: 43862 | B23: =COUNTIFS('Trial Database'!$J$2:$J$28727,">="&DATE(2020,2,1),'Trial Database'!$J$2:$J$28727,"<"&DATE(2020,3,1),'Trial Database'!$E$2:$E$28727,"Early Phase 1") -> 0 | C23: =COUNTIFS('Trial Database'!$J$2:$J$28727,">="&DATE(2020,2,1),'Trial Database'!$J$2:$J$28727,"<"&DATE(2020,3,1),'Trial Database'!$E$2:$E$28727,"Phase 1") -> 0 | D23: =COUNTIFS('Trial Database'!$J$2:$J$28727,">="&DATE(2020,2,1),'Trial Database'!$J$2:$J$28727,"<"&DATE(2020,3,1),'Trial Database'!$E$2:$E$28727,"Phase 1/2") -> 0 | E23: =COUNTIFS('Trial Database'!$J$2:$J$28727,">="&DATE(2020,2,1),'Trial Database'!$J$2:$J$28727,"<"&DATE(2020,3,1),'Trial Database'!$E$2:$E$28727,"Phase 2") -> 0 | F23: =COUNTIFS('Trial Database'!$J$2:$J$28727,">="&DATE(2020,2,1),'Trial Database'!$J$2:$J$28727,"<"&DATE(2020,3,1),'Trial Database'!$E$2:$E$28727,"Phase 2/3") -> 0 | G23: =COUNTIFS('Trial Database'!$J$2:$J$28727,">="&DATE(2020,2,1),'Trial Database'!$J$2:$J$28727,"<"&DATE(2020,3,1),'Trial Database'!$E$2:$E$28727,"Phase 3") -> 0 | H23: =COUNTIFS('Trial Database'!$J$2:$J$28727,">="&DATE(2020,2,1),'Trial Database'!$J$2:$J$28727,"<"&DATE(2020,3,1),'Trial Database'!$E$2:$E$28727,"Phase 4") -> 0 | I23: =SUM(B23:H23) -> 0 | J23: =DAY(EOMONTH(A23,0)) -> 0 | K23: =IF(J23=0,0,I23/J23) -> 0
A24: 43891 | B24: =COUNTIFS('Trial Database'!$J$2:$J$28727,">="&DATE(2020,3,1),'Trial Database'!$J$2:$J$28727,"<"&DATE(2020,4,1),'Trial Database'!$E$2:$E$28727,"Early Phase 1") -> 0 | C24: =COUNTIFS('Trial Database'!$J$2:$J$28727,">="&DATE(2020,3,1),'Trial Database'!$J$2:$J$28727,"<"&DATE(2020,4,1),'Trial Database'!$E$2:$E$28727,"Phase 1") -> 0 | D24: =COUNTIFS('Trial Database'!$J$2:$J$28727,">="&DATE(2020,3,1),'Trial Database'!$J$2:$J$28727,"<"&DATE(2020,4,1),'Trial Database'!$E$2:$E$28727,"Phase 1/2") -> 0 | E24: =COUNTIFS('Trial Database'!$J$2:$J$28727,">="&DATE(2020,3,1),'Trial Database'!$J$2:$J$28727,"<"&DATE(2020,4,1),'Trial Database'!$E$2:$E$28727,"Phase 2") -> 0 | F24: =COUNTIFS('Trial Database'!$J$2:$J$28727,">="&DATE(2020,3,1),'Trial Database'!$J$2:$J$28727,"<"&DATE(2020,4,1),'Trial Database'!$E$2:$E$28727,"Phase 2/3") -> 0 | G24: =COUNTIFS('Trial Database'!$J$2:$J$28727,">="&DATE(2020,3,1),'Trial Database'!$J$2:$J$28727,"<"&DATE(2020,4,1),'Trial Database'!$E$2:$E$28727,"Phase 3") -> 0 | H24: =COUNTIFS('Trial Database'!$J$2:$J$28727,">="&DATE(2020,3,1),'Trial Database'!$J$2:$J$28727,"<"&DATE(2020,4,1),'Trial Database'!$E$2:$E$28727,"Phase 4") -> 0 | I24: =SUM(B24:H24) -> 0 | J24: =DAY(EOMONTH(A24,0)) -> 0 | K24: =IF(J24=0,0,I24/J24) -> 0
A25: 43922 | B25: =COUNTIFS('Trial Database'!$J$2:$J$28727,">="&DATE(2020,4,1),'Trial Database'!$J$2:$J$28727,"<"&DATE(2020,5,1),'Trial Database'!$E$2:$E$28727,"Early Phase 1") -> 0 | C25: =COUNTIFS('Trial Database'!$J$2:$J$28727,">="&DATE(2020,4,1),'Trial Database'!$J$2:$J$28727,"<"&DATE(2020,5,1),'Trial Database'!$E$2:$E$28727,"Phase 1") -> 0 | D25: =COUNTIFS('Trial Database'!$J$2:$J$28727,">="&DATE(2020,4,1),'Trial Database'!$J$2:$J$28727,"<"&DATE(2020,5,1),'Trial Database'!$E$2:$E$28727,"Phase 1/2") -> 0 | E25: =COUNTIFS('Trial Database'!$J$2:$J$28727,">="&DATE(2020,4,1),'Trial Database'!$J$2:$J$28727,"<"&DATE(2020,5,1),'Trial Database'!$E$2:$E$28727,"Phase 2") -> 0 | F25: =COUNTIFS('Trial Database'!$J$2:$J$28727,">="&DATE(2020,4,1),'Trial Database'!$J$2:$J$28727,"<"&DATE(2020,5,1),'Trial Database'!$E$2:$E$28727,"Phase 2/3") -> 0 | G25: =COUNTIFS('Trial Database'!$J$2:$J$28727,">="&DATE(2020,4,1),'Trial Database'!$J$2:$J$28727,"<"&DATE(2020,5,1),'Trial Database'!$E$2:$E$28727,"Phase 3") -> 0 | H25: =COUNTIFS('Trial Database'!$J$2:$J$28727,">="&DATE(2020,4,1),'Trial Database'!$J$2:$J$28727,"<"&DATE(2020,5,1),'Trial Database'!$E$2:$E$28727,"Phase 4") -> 0 | I25: =SUM(B25:H25) -> 0 | J25: =DAY(EOMONTH(A25,0)) -> 0 | K25: =IF(J25=0,0,I25/J25) -> 0
A26: 43952 | B26: =COUNTIFS('Trial Database'!$J$2:$J$28727,">="&DATE(2020,5,1),'Trial Database'!$J$2:$J$28727,"<"&DATE(2020,6,1),'Trial Database'!$E$2:$E$28727,"Early Phase 1") -> 0 | C26: =COUNTIFS('Trial Database'!$J$2:$J$28727,">="&DATE(2020,5,1),'Trial Database'!$J$2:$J$28727,"<"&DATE(2020,6,1),'Trial Database'!$E$2:$E$28727,"Phase 1") -> 0 | D26: =COUNTIFS('Trial Database'!$J$2:$J$28727,">="&DATE(2020,5,1),'Trial Database'!$J$2:$J$28727,"<"&DATE(2020,6,1),'Trial Database'!$E$2:$E$28727,"Phase 1/2") -> 0 | E26: =COUNTIFS('Trial Database'!$J$2:$J$28727,">="&DATE(2020,5,1),'Trial Database'!$J$2:$J$28727,"<"&DATE(2020,6,1),'Trial Database'!$E$2:$E$28727,"Phase 2") -> 0 | F26: =COUNTIFS('Trial Database'!$J$2:$J$28727,">="&DATE(2020,5,1),'Trial Database'!$J$2:$J$28727,"<"&DATE(2020,6,1),'Trial Database'!$E$2:$E$28727,"Phase 2/3") -> 0 | G26: =COUNTIFS('Trial Database'!$J$2:$J$28727,">="&DATE(2020,5,1),'Trial Database'!$J$2:$J$28727,"<"&DATE(2020,6,1),'Trial Database'!$E$2:$E$28727,"Phase 3") -> 0 | H26: =COUNTIFS('Trial Database'!$J$2:$J$28727,">="&DATE(2020,5,1),'Trial Database'!$J$2:$J$28727,"<"&DATE(2020,6,1),'Trial Database'!$E$2:$E$28727,"Phase 4") -> 0 | I26: =SUM(B26:H26) -> 0 | J26: =DAY(EOMONTH(A26,0)) -> 0 | K26: =IF(J26=0,0,I26/J26) -> 0
A27: 43983 | B27: =COUNTIFS('Trial Database'!$J$2:$J$28727,">="&DATE(2020,6,1),'Trial Database'!$J$2:$J$28727,"<"&DATE(2020,7,1),'Trial Database'!$E$2:$E$28727,"Early Phase 1") -> 0 | C27: =COUNTIFS('Trial Database'!$J$2:$J$28727,">="&DATE(2020,6,1),'Trial Database'!$J$2:$J$28727,"<"&DATE(2020,7,1),'Trial Database'!$E$2:$E$28727,"Phase 1") -> 0 | D27: =COUNTIFS('Trial Database'!$J$2:$J$28727,">="&DATE(2020,6,1),'Trial Database'!$J$2:$J$28727,"<"&DATE(2020,7,1),'Trial Database'!$E$2:$E$28727,"Phase 1/2") -> 0 | E27: =COUNTIFS('Trial Database'!$J$2:$J$28727,">="&DATE(2020,6,1),'Trial Database'!$J$2:$J$28727,"<"&DATE(2020,7,1),'Trial Database'!$E$2:$E$28727,"Phase 2") -> 0 | F27: =COUNTIFS('Trial Database'!$J$2:$J$28727,">="&DATE(2020,6,1),'Trial Database'!$J$2:$J$28727,"<"&DATE(2020,7,1),'Trial Database'!$E$2:$E$28727,"Phase 2/3") -> 0 | G27: =COUNTIFS('Trial Database'!$J$2:$J$28727,">="&DATE(2020,6,1),'Trial Database'!$J$2:$J$28727,"<"&DATE(2020,7,1),'Trial Database'!$E$2:$E$28727,"Phase 3") -> 0 | H27: =COUNTIFS('Trial Database'!$J$2:$J$28727,">="&DATE(2020,6,1),'Trial Database'!$J$2:$J$28727,"<"&DATE(2020,7,1),'Trial Database'!$E$2:$E$28727,"Phase 4") -> 0 | I27: =SUM(B27:H27) -> 0 | J27: =DAY(EOMONTH(A27,0)) -> 0 | K27: =IF(J27=0,0,I27/J27) -> 0
A28: 44013 | B28: =COUNTIFS('Trial Database'!$J$2:$J$28727,">="&DATE(2020,7,1),'Trial Database'!$J$2:$J$28727,"<"&DATE(2020,8,1),'Trial Database'!$E$2:$E$28727,"Early Phase 1") -> 0 | C28: =COUNTIFS('Trial Database'!$J$2:$J$28727,">="&DATE(2020,7,1),'Trial Database'!$J$2:$J$28727,"<"&DATE(2020,8,1),'Trial Database'!$E$2:$E$28727,"Phase 1") -> 0 | D28: =COUNTIFS('Trial Database'!$J$2:$J$28727,">="&DATE(2020,7,1),'Trial Database'!$J$2:$J$28727,"<"&DATE(2020,8,1),'Trial Database'!$E$2:$E$28727,"Phase 1/2") -> 0 | E28: =COUNTIFS('Trial Database'!$J$2:$J$28727,">="&DATE(2020,7,1),'Trial Database'!$J$2:$J$28727,"<"&DATE(2020,8,1),'Trial Database'!$E$2:$E$28727,"Phase 2") -> 0 | F28: =COUNTIFS('Trial Database'!$J$2:$J$28727,">="&DATE(2020,7,1),'Trial Database'!$J$2:$J$28727,"<"&DATE(2020,8,1),'Trial Database'!$E$2:$E$28727,"Phase 2/3") -> 0 | G28: =COUNTIFS('Trial Database'!$J$2:$J$28727,">="&DATE(2020,7,1),'Trial Database'!$J$2:$J$28727,"<"&DATE(2020,8,1),'Trial Database'!$E$2:$E$28727,"Phase 3") -> 0 | H28: =COUNTIFS('Trial Database'!$J$2:$J$28727,">="&DATE(2020,7,1),'Trial Database'!$J$2:$J$28727,"<"&DATE(2020,8,1),'Trial Database'!$E$2:$E$28727,"Phase 4") -> 0 | I28: =SUM(B28:H28) -> 0 | J28: =DAY(EOMONTH(A28,0)) -> 0 | K28: =IF(J28=0,0,I28/J28) -> 0
A29: 44044 | B29: =COUNTIFS('Trial Database'!$J$2:$J$28727,">="&DATE(2020,8,1),'Trial Database'!$J$2:$J$28727,"<"&DATE(2020,9,1),'Trial Database'!$E$2:$E$28727,"Early Phase 1") -> 0 | C29: =COUNTIFS('Trial Database'!$J$2:$J$28727,">="&DATE(2020,8,1),'Trial Database'!$J$2:$J$28727,"<"&DATE(2020,9,1),'Trial Database'!$E$2:$E$28727,"Phase 1") -> 0 | D29: =COUNTIFS('Trial Database'!$J$2:$J$28727,">="&DATE(2020,8,1),'Trial Database'!$J$2:$J$28727,"<"&DATE(2020,9,1),'Trial Database'!$E$2:$E$28727,"Phase 1/2") -> 0 | E29: =COUNTIFS('Trial Database'!$J$2:$J$28727,">="&DATE(2020,8,1),'Trial Database'!$J$2:$J$28727,"<"&DATE(2020,9,1),'Trial Database'!$E$2:$E$28727,"Phase 2") -> 0 | F29: =COUNTIFS('Trial Database'!$J$2:$J$28727,">="&DATE(2020,8,1),'Trial Database'!$J$2:$J$28727,"<"&DATE(2020,9,1),'Trial Database'!$E$2:$E$28727,"Phase 2/3") -> 0 | G29: =COUNTIFS('Trial Database'!$J$2:$J$28727,">="&DATE(2020,8,1),'Trial Database'!$J$2:$J$28727,"<"&DATE(2020,9,1),'Trial Database'!$E$2:$E$28727,"Phase 3") -> 0 | H29: =COUNTIFS('Trial Database'!$J$2:$J$28727,">="&DATE(2020,8,1),'Trial Database'!$J$2:$J$28727,"<"&DATE(2020,9,1),'Trial Database'!$E$2:$E$28727,"Phase 4") -> 0 | I29: =SUM(B29:H29) -> 0 | J29: =DAY(EOMONTH(A29,0)) -> 0 | K29: =IF(J29=0,0,I29/J29) -> 0
A30: 44075 | B30: =COUNTIFS('Trial Database'!$J$2:$J$28727,">="&DATE(2020,9,1),'Trial Database'!$J$2:$J$28727,"<"&DATE(2020,10,1),'Trial Database'!$E$2:$E$28727,"Early Phase 1") -> 0 | C30: =COUNTIFS('Trial Database'!$J$2:$J$28727,">="&DATE(2020,9,1),'Trial Database'!$J$2:$J$28727,"<"&DATE(2020,10,1),'Trial Database'!$E$2:$E$28727,"Phase 1") -> 0 | D30: =COUNTIFS('Trial Database'!$J$2:$J$28727,">="&DATE(2020,9,1),'Trial Database'!$J$2:$J$28727,"<"&DATE(2020,10,1),'Trial Database'!$E$2:$E$28727,"Phase 1/2") -> 0 | E30: =COUNTIFS('Trial Database'!$J$2:$J$28727,">="&DATE(2020,9,1),'Trial Database'!$J$2:$J$28727,"<"&DATE(2020,10,1),'Trial Database'!$E$2:$E$28727,"Phase 2") -> 0 | F30: =COUNTIFS('Trial Database'!$J$2:$J$28727,">="&DATE(2020,9,1),'Trial Database'!$J$2:$J$28727,"<"&DATE(2020,10,1),'Trial Database'!$E$2:$E$28727,"Phase 2/3") -> 0 | G30: =COUNTIFS('Trial Database'!$J$2:$J$28727,">="&DATE(2020,9,1),'Trial Database'!$J$2:$J$28727,"<"&DATE(2020,10,1),'Trial Database'!$E$2:$E$28727,"Phase 3") -> 0 | H30: =COUNTIFS('Trial Database'!$J$2:$J$28727,">="&DATE(2020,9,1),'Trial Database'!$J$2:$J$28727,"<"&DATE(2020,10,1),'Trial Database'!$E$2:$E$28727,"Phase 4") -> 0 | I30: =SUM(B30:H30) -> 0 | J30: =DAY(EOMONTH(A30,0)) -> 0 | K30: =IF(J30=0,0,I30/J30) -> 0
A31: 44105 | B31: =COUNTIFS('Trial Database'!$J$2:$J$28727,">="&DATE(2020,10,1),'Trial Database'!$J$2:$J$28727,"<"&DATE(2020,11,1),'Trial Database'!$E$2:$E$28727,"Early Phase 1") -> 0 | C31: =COUNTIFS('Trial Database'!$J$2:$J$28727,">="&DATE(2020,10,1),'Trial Database'!$J$2:$J$28727,"<"&DATE(2020,11,1),'Trial Database'!$E$2:$E$28727,"Phase 1") -> 0 | D31: =COUNTIFS('Trial Database'!$J$2:$J$28727,">="&DATE(2020,10,1),'Trial Database'!$J$2:$J$28727,"<"&DATE(2020,11,1),'Trial Database'!$E$2:$E$28727,"Phase 1/2") -> 0 | E31: =COUNTIFS('Trial Database'!$J$2:$J$28727,">="&DATE(2020,10,1),'Trial Database'!$J$2:$J$28727,"<"&DATE(2020,11,1),'Trial Database'!$E$2:$E$28727,"Phase 2") -> 0 | F31: =COUNTIFS('Trial Database'!$J$2:$J$28727,">="&DATE(2020,10,1),'Trial Database'!$J$2:$J$28727,"<"&DATE(2020,11,1),'Trial Database'!$E$2:$E$28727,"Phase 2/3") -> 0 | G31: =COUNTIFS('Trial Database'!$J$2:$J$28727,">="&DATE(2020,10,1),'Trial Database'!$J$2:$J$28727,"<"&DATE(2020,11,1),'Trial Database'!$E$2:$E$28727,"Phase 3") -> 0 | H31: =COUNTIFS('Trial Database'!$J$2:$J$28727,">="&DATE(2020,10,1),'Trial Database'!$J$2:$J$28727,"<"&DATE(2020,11,1),'Trial Database'!$E$2:$E$28727,"Phase 4") -> 0 | I31: =SUM(B31:H31) -> 0 | J31: =DAY(EOMONTH(A31,0)) -> 0 | K31: =IF(J31=0,0,I31/J31) -> 0
A32: 44136 | B32: =COUNTIFS('Trial Database'!$J$2:$J$28727,">="&DATE(2020,11,1),'Trial Database'!$J$2:$J$28727,"<"&DATE(2020,12,1),'Trial Database'!$E$2:$E$28727,"Early Phase 1") -> 0 | C32: =COUNTIFS('Trial Database'!$J$2:$J$28727,">="&DATE(2020,11,1),'Trial Database'!$J$2:$J$28727,"<"&DATE(2020,12,1),'Trial Database'!$E$2:$E$28727,"Phase 1") -> 0 | D32: =COUNTIFS('Trial Database'!$J$2:$J$28727,">="&DATE(2020,11,1),'Trial Database'!$J$2:$J$28727,"<"&DATE(2020,12,1),'Trial Database'!$E$2:$E$28727,"Phase 1/2") -> 0 | E32: =COUNTIFS('Trial Database'!$J$2:$J$28727,">="&DATE(2020,11,1),'Trial Database'!$J$2:$J$28727,"<"&DATE(2020,12,1),'Trial Database'!$E$2:$E$28727,"Phase 2") -> 0 | F32: =COUNTIFS('Trial Database'!$J$2:$J$28727,">="&DATE(2020,11,1),'Trial Database'!$J$2:$J$28727,"<"&DATE(2020,12,1),'Trial Database'!$E$2:$E$28727,"Phase 2/3") -> 0 | G32: =COUNTIFS('Trial Database'!$J$2:$J$28727,">="&DATE(2020,11,1),'Trial Database'!$J$2:$J$28727,"<"&DATE(2020,12,1),'Trial Database'!$E$2:$E$28727,"Phase 3") -> 0 | H32: =COUNTIFS('Trial Database'!$J$2:$J$28727,">="&DATE(2020,11,1),'Trial Database'!$J$2:$J$28727,"<"&DATE(2020,12,1),'Trial Database'!$E$2:$E$28727,"Phase 4") -> 0 | I32: =SUM(B32:H32) -> 0 | J32: =DAY(EOMONTH(A32,0)) -> 0 | K32: =IF(J32=0,0,I32/J32) -> 0
A33: 44166 | B33: =COUNTIFS('Trial Database'!$J$2:$J$28727,">="&DATE(2020,12,1),'Trial Database'!$J$2:$J$28727,"<"&DATE(2020,13,1),'Trial Database'!$E$2:$E$28727,"Early Phase 1") -> 0 | C33: =COUNTIFS('Trial Database'!$J$2:$J$28727,">="&DATE(2020,12,1),'Trial Database'!$J$2:$J$28727,"<"&DATE(2020,13,1),'Trial Database'!$E$2:$E$28727,"Phase 1") -> 0 | D33: =COUNTIFS('Trial Database'!$J$2:$J$28727,">="&DATE(2020,12,1),'Trial Database'!$J$2:$J$28727,"<"&DATE(2020,13,1),'Trial Database'!$E$2:$E$28727,"Phase 1/2") -> 0 | E33: =COUNTIFS('Trial Database'!$J$2:$J$28727,">="&DATE(2020,12,1),'Trial Database'!$J$2:$J$28727,"<"&DATE(2020,13,1),'Trial Database'!$E$2:$E$28727,"Phase 2") -> 0 | F33: =COUNTIFS('Trial Database'!$J$2:$J$28727,">="&DATE(2020,12,1),'Trial Database'!$J$2:$J$28727,"<"&DATE(2020,13,1),'Trial Database'!$E$2:$E$28727,"Phase 2/3") -> 0 | G33: =COUNTIFS('Trial Database'!$J$2:$J$28727,">="&DATE(2020,12,1),'Trial Database'!$J$2:$J$28727,"<"&DATE(2020,13,1),'Trial Database'!$E$2:$E$28727,"Phase 3") -> 0 | H33: =COUNTIFS('Trial Database'!$J$2:$J$28727,">="&DATE(2020,12,1),'Trial Database'!$J$2:$J$28727,"<"&DATE(2020,13,1),'Trial Database'!$E$2:$E$28727,"Phase 4") -> 0 | I33: =SUM(B33:H33) -> 0 | J33: =DAY(EOMONTH(A33,0)) -> 0 | K33: =IF(J33=0,0,I33/J33) -> 0
A34: 44197 | B34: =COUNTIFS('Trial Database'!$J$2:$J$28727,">="&DATE(2021,1,1),'Trial Database'!$J$2:$J$28727,"<"&DATE(2021,2,1),'Trial Database'!$E$2:$E$28727,"Early Phase 1") -> 0 | C34: =COUNTIFS('Trial Database'!$J$2:$J$28727,">="&DATE(2021,1,1),'Trial Database'!$J$2:$J$28727,"<"&DATE(2021,2,1),'Trial Database'!$E$2:$E$28727,"Phase 1") -> 0 | D34: =COUNTIFS('Trial Database'!$J$2:$J$28727,">="&DATE(2021,1,1),'Trial Database'!$J$2:$J$28727,"<"&DATE(2021,2,1),'Trial Database'!$E$2:$E$28727,"Phase 1/2") -> 0 | E34: =COUNTIFS('Trial Database'!$J$2:$J$28727,">="&DATE(2021,1,1),'Trial Database'!$J$2:$J$28727,"<"&DATE(2021,2,1),'Trial Database'!$E$2:$E$28727,"Phase 2") -> 0 | F34: =COUNTIFS('Trial Database'!$J$2:$J$28727,">="&DATE(2021,1,1),'Trial Database'!$J$2:$J$28727,"<"&DATE(2021,2,1),'Trial Database'!$E$2:$E$28727,"Phase 2/3") -> 0 | G34: =COUNTIFS('Trial Database'!$J$2:$J$28727,">="&DATE(2021,1,1),'Trial Database'!$J$2:$J$28727,"<"&DATE(2021,2,1),'Trial Database'!$E$2:$E$28727,"Phase 3") -> 0 | H34: =COUNTIFS('Trial Database'!$J$2:$J$28727,">="&DATE(2021,1,1),'Trial Database'!$J$2:$J$28727,"<"&DATE(2021,2,1),'Trial Database'!$E$2:$E$28727,"Phase 4") -> 0 | I34: =SUM(B34:H34) -> 0 | J34: =DAY(EOMONTH(A34,0)) -> 0 | K34: =IF(J34=0,0,I34/J34) -> 0
A35: 44228 | B35: =COUNTIFS('Trial Database'!$J$2:$J$28727,">="&DATE(2021,2,1),'Trial Database'!$J$2:$J$28727,"<"&DATE(2021,3,1),'Trial Database'!$E$2:$E$28727,"Early Phase 1") -> 0 | C35: =COUNTIFS('Trial Database'!$J$2:$J$28727,">="&DATE(2021,2,1),'Trial Database'!$J$2:$J$28727,"<"&DATE(2021,3,1),'Trial Database'!$E$2:$E$28727,"Phase 1") -> 0 | D35: =COUNTIFS('Trial Database'!$J$2:$J$28727,">="&DATE(2021,2,1),'Trial Database'!$J$2:$J$28727,"<"&DATE(2021,3,1),'Trial Database'!$E$2:$E$28727,"Phase 1/2") -> 0 | E35: =COUNTIFS('Trial Database'!$J$2:$J$28727,">="&DATE(2021,2,1),'Trial Database'!$J$2:$J$28727,"<"&DATE(2021,3,1),'Trial Database'!$E$2:$E$28727,"Phase 2") -> 0 | F35: =COUNTIFS('Trial Database'!$J$2:$J$28727,">="&DATE(2021,2,1),'Trial Database'!$J$2:$J$28727,"<"&DATE(2021,3,1),'Trial Database'!$E$2:$E$28727,"Phase 2/3") -> 0 | G35: =COUNTIFS('Trial Database'!$J$2:$J$28727,">="&DATE(2021,2,1),'Trial Database'!$J$2:$J$28727,"<"&DATE(2021,3,1),'Trial Database'!$E$2:$E$28727,"Phase 3") -> 0 | H35: =COUNTIFS('Trial Database'!$J$2:$J$28727,">="&DATE(2021,2,1),'Trial Database'!$J$2:$J$28727,"<"&DATE(2021,3,1),'Trial Database'!$E$2:$E$28727,"Phase 4") -> 0 | I35: =SUM(B35:H35) -> 0 | J35: =DAY(EOMONTH(A35,0)) -> 0 | K35: =IF(J35=0,0,I35/J35) -> 0
A36: 44256 | B36: =COUNTIFS('Trial Database'!$J$2:$J$28727,">="&DATE(2021,3,1),'Trial Database'!$J$2:$J$28727,"<"&DATE(2021,4,1),'Trial Database'!$E$2:$E$28727,"Early Phase 1") -> 0 | C36: =COUNTIFS('Trial Database'!$J$2:$J$28727,">="&DATE(2021,3,1),'Trial Database'!$J$2:$J$28727,"<"&DATE(2021,4,1),'Trial Database'!$E$2:$E$28727,"Phase 1") -> 0 | D36: =COUNTIFS('Trial Database'!$J$2:$J$28727,">="&DATE(2021,3,1),'Trial Database'!$J$2:$J$28727,"<"&DATE(2021,4,1),'Trial Database'!$E$2:$E$28727,"Phase 1/2") -> 0 | E36: =COUNTIFS('Trial Database'!$J$2:$J$28727,">="&DATE(2021,3,1),'Trial Database'!$J$2:$J$28727,"<"&DATE(2021,4,1),'Trial Database'!$E$2:$E$28727,"Phase 2") -> 0 | F36: =COUNTIFS('Trial Database'!$J$2:$J$28727,">="&DATE(2021,3,1),'Trial Database'!$J$2:$J$28727,"<"&DATE(2021,4,1),'Trial Database'!$E$2:$E$28727,"Phase 2/3") -> 0 | G36: =COUNTIFS('Trial Database'!$J$2:$J$28727,">="&DATE(2021,3,1),'Trial Database'!$J$2:$J$28727,"<"&DATE(2021,4,1),'Trial Database'!$E$2:$E$28727,"Phase 3") -> 0 | H36: =COUNTIFS('Trial Database'!$J$2:$J$28727,">="&DATE(2021,3,1),'Trial Database'!$J$2:$J$28727,"<"&DATE(2021,4,1),'Trial Database'!$E$2:$E$28727,"Phase 4") -> 0 | I36: =SUM(B36:H36) -> 0 | J36: =DAY(EOMONTH(A36,0)) -> 0 | K36: =IF(J36=0,0,I36/J36) -> 0
A37: 44287 | B37: =COUNTIFS('Trial Database'!$J$2:$J$28727,">="&DATE(2021,4,1),'Trial Database'!$J$2:$J$28727,"<"&DATE(2021,5,1),'Trial Database'!$E$2:$E$28727,"Early Phase 1") -> 0 | C37: =COUNTIFS('Trial Database'!$J$2:$J$28727,">="&DATE(2021,4,1),'Trial Database'!$J$2:$J$28727,"<"&DATE(2021,5,1),'Trial Database'!$E$2:$E$28727,"Phase 1") -> 0 | D37: =COUNTIFS('Trial Database'!$J$2:$J$28727,">="&DATE(2021,4,1),'Trial Database'!$J$2:$J$28727,"<"&DATE(2021,5,1),'Trial Database'!$E$2:$E$28727,"Phase 1/2") -> 0 | E37: =COUNTIFS('Trial Database'!$J$2:$J$28727,">="&DATE(2021,4,1),'Trial Database'!$J$2:$J$28727,"<"&DATE(2021,5,1),'Trial Database'!$E$2:$E$28727,"Phase 2") -> 0 | F37: =COUNTIFS('Trial Database'!$J$2:$J$28727,">="&DATE(2021,4,1),'Trial Database'!$J$2:$J$28727,"<"&DATE(2021,5,1),'Trial Database'!$E$2:$E$28727,"Phase 2/3") -> 0 | G37: =COUNTIFS('Trial Database'!$J$2:$J$28727,">="&DATE(2021,4,1),'Trial Database'!$J$2:$J$28727,"<"&DATE(2021,5,1),'Trial Database'!$E$2:$E$28727,"Phase 3") -> 0 | H37: =COUNTIFS('Trial Database'!$J$2:$J$28727,">="&DATE(2021,4,1),'Trial Database'!$J$2:$J$28727,"<"&DATE(2021,5,1),'Trial Database'!$E$2:$E$28727,"Phase 4") -> 0 | I37: =SUM(B37:H37) -> 0 | J37: =DAY(EOMONTH(A37,0)) -> 0 | K37: =IF(J37=0,0,I37/J37) -> 0
A38: 44317 | B38: =COUNTIFS('Trial Database'!$J$2:$J$28727,">="&DATE(2021,5,1),'Trial Database'!$J$2:$J$28727,"<"&DATE(2021,6,1),'Trial Database'!$E$2:$E$28727,"Early Phase 1") -> 0 | C38: =COUNTIFS('Trial Database'!$J$2:$J$28727,">="&DATE(2021,5,1),'Trial Database'!$J$2:$J$28727,"<"&DATE(2021,6,1),'Trial Database'!$E$2:$E$28727,"Phase 1") -> 0 | D38: =COUNTIFS('Trial Database'!$J$2:$J$28727,">="&DATE(2021,5,1),'Trial Database'!$J$2:$J$28727,"<"&DATE(2021,6,1),'Trial Database'!$E$2:$E$28727,"Phase 1/2") -> 0 | E38: =COUNTIFS('Trial Database'!$J$2:$J$28727,">="&DATE(2021,5,1),'Trial Database'!$J$2:$J$28727,"<"&DATE(2021,6,1),'Trial Database'!$E$2:$E$28727,"Phase 2") -> 0 | F38: =COUNTIFS('Trial Database'!$J$2:$J$28727,">="&DATE(2021,5,1),'Trial Database'!$J$2:$J$28727,"<"&DATE(2021,6,1),'Trial Database'!$E$2:$E$28727,"Phase 2/3") -> 0 | G38: =COUNTIFS('Trial Database'!$J$2:$J$28727,">="&DATE(2021,5,1),'Trial Database'!$J$2:$J$28727,"<"&DATE(2021,6,1),'Trial Database'!$E$2:$E$28727,"Phase 3") -> 0 | H38: =COUNTIFS('Trial Database'!$J$2:$J$28727,">="&DATE(2021,5,1),'Trial Database'!$J$2:$J$28727,"<"&DATE(2021,6,1),'Trial Database'!$E$2:$E$28727,"Phase 4") -> 0 | I38: =SUM(B38:H38) -> 0 | J38: =DAY(EOMONTH(A38,0)) -> 0 | K38: =IF(J38=0,0,I38/J38) -> 0
A39: 44348 | B39: =COUNTIFS('Trial Database'!$J$2:$J$28727,">="&DATE(2021,6,1),'Trial Database'!$J$2:$J$28727,"<"&DATE(2021,7,1),'Trial Database'!$E$2:$E$28727,"Early Phase 1") -> 0 | C39: =COUNTIFS('Trial Database'!$J$2:$J$28727,">="&DATE(2021,6,1),'Trial Database'!$J$2:$J$28727,"<"&DATE(2021,7,1),'Trial Database'!$E$2:$E$28727,"Phase 1") -> 0 | D39: =COUNTIFS('Trial Database'!$J$2:$J$28727,">="&DATE(2021,6,1),'Trial Database'!$J$2:$J$28727,"<"&DATE(2021,7,1),'Trial Database'!$E$2:$E$28727,"Phase 1/2") -> 0 | E39: =COUNTIFS('Trial Database'!$J$2:$J$28727,">="&DATE(2021,6,1),'Trial Database'!$J$2:$J$28727,"<"&DATE(2021,7,1),'Trial Database'!$E$2:$E$28727,"Phase 2") -> 0 | F39: =COUNTIFS('Trial Database'!$J$2:$J$28727,">="&DATE(2021,6,1),'Trial Database'!$J$2:$J$28727,"<"&DATE(2021,7,1),'Trial Database'!$E$2:$E$28727,"Phase 2/3") -> 0 | G39: =COUNTIFS('Trial Database'!$J$2:$J$28727,">="&DATE(2021,6,1),'Trial Database'!$J$2:$J$28727,"<"&DATE(2021,7,1),'Trial Database'!$E$2:$E$28727,"Phase 3") -> 0 | H39: =COUNTIFS('Trial Database'!$J$2:$J$28727,">="&DATE(2021,6,1),'Trial Database'!$J$2:$J$28727,"<"&DATE(2021,7,1),'Trial Database'!$E$2:$E$28727,"Phase 4") -> 0 | I39: =SUM(B39:H39) -> 0 | J39: =DAY(EOMONTH(A39,0)) -> 0 | K39: =IF(J39=0,0,I39/J39) -> 0
A40: 44378 | B40: =COUNTIFS('Trial Database'!$J$2:$J$28727,">="&DATE(2021,7,1),'Trial Database'!$J$2:$J$28727,"<"&DATE(2021,8,1),'Trial Database'!$E$2:$E$28727,"Early Phase 1") -> 0 | C40: =COUNTIFS('Trial Database'!$J$2:$J$28727,">="&DATE(2021,7,1),'Trial Database'!$J$2:$J$28727,"<"&DATE(2021,8,1),'Trial Database'!$E$2:$E$28727,"Phase 1") -> 0 | D40: =COUNTIFS('Trial Database'!$J$2:$J$28727,">="&DATE(2021,7,1),'Trial Database'!$J$2:$J$28727,"<"&DATE(2021,8,1),'Trial Database'!$E$2:$E$28727,"Phase 1/2") -> 0 | E40: =COUNTIFS('Trial Database'!$J$2:$J$28727,">="&DATE(2021,7,1),'Trial Database'!$J$2:$J$28727,"<"&DATE(2021,8,1),'Trial Database'!$E$2:$E$28727,"Phase 2") -> 0 | F40: =COUNTIFS('Trial Database'!$J$2:$J$28727,">="&DATE(2021,7,1),'Trial Database'!$J$2:$J$28727,"<"&DATE(2021,8,1),'Trial Database'!$E$2:$E$28727,"Phase 2/3") -> 0 | G40: =COUNTIFS('Trial Database'!$J$2:$J$28727,">="&DATE(2021,7,1),'Trial Database'!$J$2:$J$28727,"<"&DATE(2021,8,1),'Trial Database'!$E$2:$E$28727,"Phase 3") -> 0 | H40: =COUNTIFS('Trial Database'!$J$2:$J$28727,">="&DATE(2021,7,1),'Trial Database'!$J$2:$J$28727,"<"&DATE(2021,8,1),'Trial Database'!$E$2:$E$28727,"Phase 4") -> 0 | I40: =SUM(B40:H40) -> 0 | J40: =DAY(EOMONTH(A40,0)) -> 0 | K40: =IF(J40=0,0,I40/J40) -> 0
A41: 44409 | B41: =COUNTIFS('Trial Database'!$J$2:$J$28727,">="&DATE(2021,8,1),'Trial Database'!$J$2:$J$28727,"<"&DATE(2021,9,1),'Trial Database'!$E$2:$E$28727,"Early Phase 1") -> 0 | C41: =COUNTIFS('Trial Database'!$J$2:$J$28727,">="&DATE(2021,8,1),'Trial Database'!$J$2:$J$28727,"<"&DATE(2021,9,1),'Trial Database'!$E$2:$E$28727,"Phase 1") -> 0 | D41: =COUNTIFS('Trial Database'!$J$2:$J$28727,">="&DATE(2021,8,1),'Trial Database'!$J$2:$J$28727,"<"&DATE(2021,9,1),'Trial Database'!$E$2:$E$28727,"Phase 1/2") -> 0 | E41: =COUNTIFS('Trial Database'!$J$2:$J$28727,">="&DATE(2021,8,1),'Trial Database'!$J$2:$J$28727,"<"&DATE(2021,9,1),'Trial Database'!$E$2:$E$28727,"Phase 2") -> 0 | F41: =COUNTIFS('Trial Database'!$J$2:$J$28727,">="&DATE(2021,8,1),'Trial Database'!$J$2:$J$28727,"<"&DATE(2021,9,1),'Trial Database'!$E$2:$E$28727,"Phase 2/3") -> 0 | G41: =COUNTIFS('Trial Database'!$J$2:$J$28727,">="&DATE(2021,8,1),'Trial Database'!$J$2:$J$28727,"<"&DATE(2021,9,1),'Trial Database'!$E$2:$E$28727,"Phase 3") -> 0 | H41: =COUNTIFS('Trial Database'!$J$2:$J$28727,">="&DATE(2021,8,1),'Trial Database'!$J$2:$J$28727,"<"&DATE(2021,9,1),'Trial Database'!$E$2:$E$28727,"Phase 4") -> 0 | I41: =SUM(B41:H41) -> 0 | J41: =DAY(EOMONTH(A41,0)) -> 0 | K41: =IF(J41=0,0,I41/J41) -> 0
A42: 44440 | B42: =COUNTIFS('Trial Database'!$J$2:$J$28727,">="&DATE(2021,9,1),'Trial Database'!$J$2:$J$28727,"<"&DATE(2021,10,1),'Trial Database'!$E$2:$E$28727,"Early Phase 1") -> 0 | C42: =COUNTIFS('Trial Database'!$J$2:$J$28727,">="&DATE(2021,9,1),'Trial Database'!$J$2:$J$28727,"<"&DATE(2021,10,1),'Trial Database'!$E$2:$E$28727,"Phase 1") -> 0 | D42: =COUNTIFS('Trial Database'!$J$2:$J$28727,">="&DATE(2021,9,1),'Trial Database'!$J$2:$J$28727,"<"&DATE(2021,10,1),'Trial Database'!$E$2:$E$28727,"Phase 1/2") -> 0 | E42: =COUNTIFS('Trial Database'!$J$2:$J$28727,">="&DATE(2021,9,1),'Trial Database'!$J$2:$J$28727,"<"&DATE(2021,10,1),'Trial Database'!$E$2:$E$28727,"Phase 2") -> 0 | F42: =COUNTIFS('Trial Database'!$J$2:$J$28727,">="&DATE(2021,9,1),'Trial Database'!$J$2:$J$28727,"<"&DATE(2021,10,1),'Trial Database'!$E$2:$E$28727,"Phase 2/3") -> 0 | G42: =COUNTIFS('Trial Database'!$J$2:$J$28727,">="&DATE(2021,9,1),'Trial Database'!$J$2:$J$28727,"<"&DATE(2021,10,1),'Trial Database'!$E$2:$E$28727,"Phase 3") -> 0 | H42: =COUNTIFS('Trial Database'!$J$2:$J$28727,">="&DATE(2021,9,1),'Trial Database'!$J$2:$J$28727,"<"&DATE(2021,10,1),'Trial Database'!$E$2:$E$28727,"Phase 4") -> 0 | I42: =SUM(B42:H42) -> 0 | J42: =DAY(EOMONTH(A42,0)) -> 0 | K42: =IF(J42=0,0,I42/J42) -> 0
A43: 44470 | B43: =COUNTIFS('Trial Database'!$J$2:$J$28727,">="&DATE(2021,10,1),'Trial Database'!$J$2:$J$28727,"<"&DATE(2021,11,1),'Trial Database'!$E$2:$E$28727,"Early Phase 1") -> 0 | C43: =COUNTIFS('Trial Database'!$J$2:$J$28727,">="&DATE(2021,10,1),'Trial Database'!$J$2:$J$28727,"<"&DATE(2021,11,1),'Trial Database'!$E$2:$E$28727,"Phase 1") -> 0 | D43: =COUNTIFS('Trial Database'!$J$2:$J$28727,">="&DATE(2021,10,1),'Trial Database'!$J$2:$J$28727,"<"&DATE(2021,11,1),'Trial Database'!$E$2:$E$28727,"Phase 1/2") -> 0 | E43: =COUNTIFS('Trial Database'!$J$2:$J$28727,">="&DATE(2021,10,1),'Trial Database'!$J$2:$J$28727,"<"&DATE(2021,11,1),'Trial Database'!$E$2:$E$28727,"Phase 2") -> 0 | F43: =COUNTIFS('Trial Database'!$J$2:$J$28727,">="&DATE(2021,10,1),'Trial Database'!$J$2:$J$28727,"<"&DATE(2021,11,1),'Trial Database'!$E$2:$E$28727,"Phase 2/3") -> 0 | G43: =COUNTIFS('Trial Database'!$J$2:$J$28727,">="&DATE(2021,10,1),'Trial Database'!$J$2:$J$28727,"<"&DATE(2021,11,1),'Trial Database'!$E$2:$E$28727,"Phase 3") -> 0 | H43: =COUNTIFS('Trial Database'!$J$2:$J$28727,">="&DATE(2021,10,1),'Trial Database'!$J$2:$J$28727,"<"&DATE(2021,11,1),'Trial Database'!$E$2:$E$28727,"Phase 4") -> 0 | I43: =SUM(B43:H43) -> 0 | J43: =DAY(EOMONTH(A43,0)) -> 0 | K43: =IF(J43=0,0,I43/J43) -> 0
A44: 44501 | B44: =COUNTIFS('Trial Database'!$J$2:$J$28727,">="&DATE(2021,11,1),'Trial Database'!$J$2:$J$28727,"<"&DATE(2021,12,1),'Trial Database'!$E$2:$E$28727,"Early Phase 1") -> 0 | C44: =COUNTIFS('Trial Database'!$J$2:$J$28727,">="&DATE(2021,11,1),'Trial Database'!$J$2:$J$28727,"<"&DATE(2021,12,1),'Trial Database'!$E$2:$E$28727,"Phase 1") -> 0 | D44: =COUNTIFS('Trial Database'!$J$2:$J$28727,">="&DATE(2021,11,1),'Trial Database'!$J$2:$J$28727,"<"&DATE(2021,12,1),'Trial Database'!$E$2:$E$28727,"Phase 1/2") -> 0 | E44: =COUNTIFS('Trial Database'!$J$2:$J$28727,">="&DATE(2021,11,1),'Trial Database'!$J$2:$J$28727,"<"&DATE(2021,12,1),'Trial Database'!$E$2:$E$28727,"Phase 2") -> 0 | F44: =COUNTIFS('Trial Database'!$J$2:$J$28727,">="&DATE(2021,11,1),'Trial Database'!$J$2:$J$28727,"<"&DATE(2021,12,1),'Trial Database'!$E$2:$E$28727,"Phase 2/3") -> 0 | G44: =COUNTIFS('Trial Database'!$J$2:$J$28727,">="&DATE(2021,11,1),'Trial Database'!$J$2:$J$28727,"<"&DATE(2021,12,1),'Trial Database'!$E$2:$E$28727,"Phase 3") -> 0 | H44: =COUNTIFS('Trial Database'!$J$2:$J$28727,">="&DATE(2021,11,1),'Trial Database'!$J$2:$J$28727,"<"&DATE(2021,12,1),'Trial Database'!$E$2:$E$28727,"Phase 4") -> 0 | I44: =SUM(B44:H44) -> 0 | J44: =DAY(EOMONTH(A44,0)) -> 0 | K44: =IF(J44=0,0,I44/J44) -> 0
...

Sheet Summary Statistics - Enrollment
A1: Year | B1: Early Phase 1 | C1: Phase 1 | D1: Phase 1/2 | E1: Phase 2 | F1: Phase 2/3 | G1: Phase 3 | H1: Phase 4 | I1: Total
A2: 2020 | B2: =SUMIFS('Trial Database'!$H$2:$H$28727,'Trial Database'!$J$2:$J$28727,">="&DATE(2020,1,1),'Trial Database'!$J$2:$J$28727,"<"&DATE(2021,1,1),'Trial Database'!$E$2:$E$28727,"Early Phase 1") -> 0 | C2: =SUMIFS('Trial Database'!$H$2:$H$28727,'Trial Database'!$J$2:$J$28727,">="&DATE(2020,1,1),'Trial Database'!$J$2:$J$28727,"<"&DATE(2021,1,1),'Trial Database'!$E$2:$E$28727,"Phase 1") -> 0 | D2: =SUMIFS('Trial Database'!$H$2:$H$28727,'Trial Database'!$J$2:$J$28727,">="&DATE(2020,1,1),'Trial Database'!$J$2:$J$28727,"<"&DATE(2021,1,1),'Trial Database'!$E$2:$E$28727,"Phase 1/2") -> 0 | E2: =SUMIFS('Trial Database'!$H$2:$H$28727,'Trial Database'!$J$2:$J$28727,">="&DATE(2020,1,1),'Trial Database'!$J$2:$J$28727,"<"&DATE(2021,1,1),'Trial Database'!$E$2:$E$28727,"Phase 2") -> 0 | F2: =SUMIFS('Trial Database'!$H$2:$H$28727,'Trial Database'!$J$2:$J$28727,">="&DATE(2020,1,1),'Trial Database'!$J$2:$J$28727,"<"&DATE(2021,1,1),'Trial Database'!$E$2:$E$28727,"Phase 2/3") -> 0 | G2: =SUMIFS('Trial Database'!$H$2:$H$28727,'Trial Database'!$J$2:$J$28727,">="&DATE(2020,1,1),'Trial Database'!$J$2:$J$28727,"<"&DATE(2021,1,1),'Trial Database'!$E$2:$E$28727,"Phase 3") -> 0 | H2: =SUMIFS('Trial Database'!$H$2:$H$28727,'Trial Database'!$J$2:$J$28727,">="&DATE(2020,1,1),'Trial Database'!$J$2:$J$28727,"<"&DATE(2021,1,1),'Trial Database'!$E$2:$E$28727,"Phase 4") -> 0 | I2: =SUM(B2:H2) -> 0
A3: 2021 | B3: =SUMIFS('Trial Database'!$H$2:$H$28727,'Trial Database'!$J$2:$J$28727,">="&DATE(2021,1,1),'Trial Database'!$J$2:$J$28727,"<"&DATE(2022,1,1),'Trial Database'!$E$2:$E$28727,"Early Phase 1") -> 0 | C3: =SUMIFS('Trial Database'!$H$2:$H$28727,'Trial Database'!$J$2:$J$28727,">="&DATE(2021,1,1),'Trial Database'!$J$2:$J$28727,"<"&DATE(2022,1,1),'Trial Database'!$E$2:$E$28727,"Phase 1") -> 0 | D3: =SUMIFS('Trial Database'!$H$2:$H$28727,'Trial Database'!$J$2:$J$28727,">="&DATE(2021,1,1),'Trial Database'!$J$2:$J$28727,"<"&DATE(2022,1,1),'Trial Database'!$E$2:$E$28727,"Phase 1/2") -> 0 | E3: =SUMIFS('Trial Database'!$H$2:$H$28727,'Trial Database'!$J$2:$J$28727,">="&DATE(2021,1,1),'Trial Database'!$J$2:$J$28727,"<"&DATE(2022,1,1),'Trial Database'!$E$2:$E$28727,"Phase 2") -> 0 | F3: =SUMIFS('Trial Database'!$H$2:$H$28727,'Trial Database'!$J$2:$J$28727,">="&DATE(2021,1,1),'Trial Database'!$J$2:$J$28727,"<"&DATE(2022,1,1),'Trial Database'!$E$2:$E$28727,"Phase 2/3") -> 0 | G3: =SUMIFS('Trial Database'!$H$2:$H$28727,'Trial Database'!$J$2:$J$28727,">="&DATE(2021,1,1),'Trial Database'!$J$2:$J$28727,"<"&DATE(2022,1,1),'Trial Database'!$E$2:$E$28727,"Phase 3") -> 0 | H3: =SUMIFS('Trial Database'!$H$2:$H$28727,'Trial Database'!$J$2:$J$28727,">="&DATE(2021,1,1),'Trial Database'!$J$2:$J$28727,"<"&DATE(2022,1,1),'Trial Database'!$E$2:$E$28727,"Phase 4") -> 0 | I3: =SUM(B3:H3) -> 0
A4: 2022 | B4: =SUMIFS('Trial Database'!$H$2:$H$28727,'Trial Database'!$J$2:$J$28727,">="&DATE(2022,1,1),'Trial Database'!$J$2:$J$28727,"<"&DATE(2023,1,1),'Trial Database'!$E$2:$E$28727,"Early Phase 1") -> 0 | C4: =SUMIFS('Trial Database'!$H$2:$H$28727,'Trial Database'!$J$2:$J$28727,">="&DATE(2022,1,1),'Trial Database'!$J$2:$J$28727,"<"&DATE(2023,1,1),'Trial Database'!$E$2:$E$28727,"Phase 1") -> 0 | D4: =SUMIFS('Trial Database'!$H$2:$H$28727,'Trial Database'!$J$2:$J$28727,">="&DATE(2022,1,1),'Trial Database'!$J$2:$J$28727,"<"&DATE(2023,1,1),'Trial Database'!$E$2:$E$28727,"Phase 1/2") -> 0 | E4: =SUMIFS('Trial Database'!$H$2:$H$28727,'Trial Database'!$J$2:$J$28727,">="&DATE(2022,1,1),'Trial Database'!$J$2:$J$28727,"<"&DATE(2023,1,1),'Trial Database'!$E$2:$E$28727,"Phase 2") -> 0 | F4: =SUMIFS('Trial Database'!$H$2:$H$28727,'Trial Database'!$J$2:$J$28727,">="&DATE(2022,1,1),'Trial Database'!$J$2:$J$28727,"<"&DATE(2023,1,1),'Trial Database'!$E$2:$E$28727,"Phase 2/3") -> 0 | G4: =SUMIFS('Trial Database'!$H$2:$H$28727,'Trial Database'!$J$2:$J$28727,">="&DATE(2022,1,1),'Trial Database'!$J$2:$J$28727,"<"&DATE(2023,1,1),'Trial Database'!$E$2:$E$28727,"Phase 3") -> 0 | H4: =SUMIFS('Trial Database'!$H$2:$H$28727,'Trial Database'!$J$2:$J$28727,">="&DATE(2022,1,1),'Trial Database'!$J$2:$J$28727,"<"&DATE(2023,1,1),'Trial Database'!$E$2:$E$28727,"Phase 4") -> 0 | I4: =SUM(B4:H4) -> 0
A5: 2023 | B5: =SUMIFS('Trial Database'!$H$2:$H$28727,'Trial Database'!$J$2:$J$28727,">="&DATE(2023,1,1),'Trial Database'!$J$2:$J$28727,"<"&DATE(2024,1,1),'Trial Database'!$E$2:$E$28727,"Early Phase 1") -> 0 | C5: =SUMIFS('Trial Database'!$H$2:$H$28727,'Trial Database'!$J$2:$J$28727,">="&DATE(2023,1,1),'Trial Database'!$J$2:$J$28727,"<"&DATE(2024,1,1),'Trial Database'!$E$2:$E$28727,"Phase 1") -> 0 | D5: =SUMIFS('Trial Database'!$H$2:$H$28727,'Trial Database'!$J$2:$J$28727,">="&DATE(2023,1,1),'Trial Database'!$J$2:$J$28727,"<"&DATE(2024,1,1),'Trial Database'!$E$2:$E$28727,"Phase 1/2") -> 0 | E5: =SUMIFS('Trial Database'!$H$2:$H$28727,'Trial Database'!$J$2:$J$28727,">="&DATE(2023,1,1),'Trial Database'!$J$2:$J$28727,"<"&DATE(2024,1,1),'Trial Database'!$E$2:$E$28727,"Phase 2") -> 0 | F5: =SUMIFS('Trial Database'!$H$2:$H$28727,'Trial Database'!$J$2:$J$28727,">="&DATE(2023,1,1),'Trial Database'!$J$2:$J$28727,"<"&DATE(2024,1,1),'Trial Database'!$E$2:$E$28727,"Phase 2/3") -> 0 | G5: =SUMIFS('Trial Database'!$H$2:$H$28727,'Trial Database'!$J$2:$J$28727,">="&DATE(2023,1,1),'Trial Database'!$J$2:$J$28727,"<"&DATE(2024,1,1),'Trial Database'!$E$2:$E$28727,"Phase 3") -> 0 | H5: =SUMIFS('Trial Database'!$H$2:$H$28727,'Trial Database'!$J$2:$J$28727,">="&DATE(2023,1,1),'Trial Database'!$J$2:$J$28727,"<"&DATE(2024,1,1),'Trial Database'!$E$2:$E$28727,"Phase 4") -> 0 | I5: =SUM(B5:H5) -> 0
A6: 2024 | B6: =SUMIFS('Trial Database'!$H$2:$H$28727,'Trial Database'!$J$2:$J$28727,">="&DATE(2024,1,1),'Trial Database'!$J$2:$J$28727,"<"&DATE(2025,1,1),'Trial Database'!$E$2:$E$28727,"Early Phase 1") -> 0 | C6: =SUMIFS('Trial Database'!$H$2:$H$28727,'Trial Database'!$J$2:$J$28727,">="&DATE(2024,1,1),'Trial Database'!$J$2:$J$28727,"<"&DATE(2025,1,1),'Trial Database'!$E$2:$E$28727,"Phase 1") -> 0 | D6: =SUMIFS('Trial Database'!$H$2:$H$28727,'Trial Database'!$J$2:$J$28727,">="&DATE(2024,1,1),'Trial Database'!$J$2:$J$28727,"<"&DATE(2025,1,1),'Trial Database'!$E$2:$E$28727,"Phase 1/2") -> 0 | E6: =SUMIFS('Trial Database'!$H$2:$H$28727,'Trial Database'!$J$2:$J$28727,">="&DATE(2024,1,1),'Trial Database'!$J$2:$J$28727,"<"&DATE(2025,1,1),'Trial Database'!$E$2:$E$28727,"Phase 2") -> 0 | F6: =SUMIFS('Trial Database'!$H$2:$H$28727,'Trial Database'!$J$2:$J$28727,">="&DATE(2024,1,1),'Trial Database'!$J$2:$J$28727,"<"&DATE(2025,1,1),'Trial Database'!$E$2:$E$28727,"Phase 2/3") -> 0 | G6: =SUMIFS('Trial Database'!$H$2:$H$28727,'Trial Database'!$J$2:$J$28727,">="&DATE(2024,1,1),'Trial Database'!$J$2:$J$28727,"<"&DATE(2025,1,1),'Trial Database'!$E$2:$E$28727,"Phase 3") -> 0 | H6: =SUMIFS('Trial Database'!$H$2:$H$28727,'Trial Database'!$J$2:$J$28727,">="&DATE(2024,1,1),'Trial Database'!$J$2:$J$28727,"<"&DATE(2025,1,1),'Trial Database'!$E$2:$E$28727,"Phase 4") -> 0 | I6: =SUM(B6:H6) -> 0
A7: 2025 | B7: =SUMIFS('Trial Database'!$H$2:$H$28727,'Trial Database'!$J$2:$J$28727,">="&DATE(2025,1,1),'Trial Database'!$J$2:$J$28727,"<"&DATE(2026,1,1),'Trial Database'!$E$2:$E$28727,"Early Phase 1") -> 0 | C7: =SUMIFS('Trial Database'!$H$2:$H$28727,'Trial Database'!$J$2:$J$28727,">="&DATE(2025,1,1),'Trial Database'!$J$2:$J$28727,"<"&DATE(2026,1,1),'Trial Database'!$E$2:$E$28727,"Phase 1") -> 0 | D7: =SUMIFS('Trial Database'!$H$2:$H$28727,'Trial Database'!$J$2:$J$28727,">="&DATE(2025,1,1),'Trial Database'!$J$2:$J$28727,"<"&DATE(2026,1,1),'Trial Database'!$E$2:$E$28727,"Phase 1/2") -> 0 | E7: =SUMIFS('Trial Database'!$H$2:$H$28727,'Trial Database'!$J$2:$J$28727,">="&DATE(2025,1,1),'Trial Database'!$J$2:$J$28727,"<"&DATE(2026,1,1),'Trial Database'!$E$2:$E$28727,"Phase 2") -> 0 | F7: =SUMIFS('Trial Database'!$H$2:$H$28727,'Trial Database'!$J$2:$J$28727,">="&DATE(2025,1,1),'Trial Database'!$J$2:$J$28727,"<"&DATE(2026,1,1),'Trial Database'!$E$2:$E$28727,"Phase 2/3") -> 0 | G7: =SUMIFS('Trial Database'!$H$2:$H$28727,'Trial Database'!$J$2:$J$28727,">="&DATE(2025,1,1),'Trial Database'!$J$2:$J$28727,"<"&DATE(2026,1,1),'Trial Database'!$E$2:$E$28727,"Phase 3") -> 0 | H7: =SUMIFS('Trial Database'!$H$2:$H$28727,'Trial Database'!$J$2:$J$28727,">="&DATE(2025,1,1),'Trial Database'!$J$2:$J$28727,"<"&DATE(2026,1,1),'Trial Database'!$E$2:$E$28727,"Phase 4") -> 0 | I7: =SUM(B7:H7) -> 0
A8: 2026 through July | B8: =SUMIFS('Trial Database'!$H$2:$H$28727,'Trial Database'!$J$2:$J$28727,">="&DATE(2026,1,1),'Trial Database'!$J$2:$J$28727,"<"&DATE(2027,1,1),'Trial Database'!$E$2:$E$28727,"Early Phase 1") -> 0 | C8: =SUMIFS('Trial Database'!$H$2:$H$28727,'Trial Database'!$J$2:$J$28727,">="&DATE(2026,1,1),'Trial Database'!$J$2:$J$28727,"<"&DATE(2027,1,1),'Trial Database'!$E$2:$E$28727,"Phase 1") -> 0 | D8: =SUMIFS('Trial Database'!$H$2:$H$28727,'Trial Database'!$J$2:$J$28727,">="&DATE(2026,1,1),'Trial Database'!$J$2:$J$28727,"<"&DATE(2027,1,1),'Trial Database'!$E$2:$E$28727,"Phase 1/2") -> 0 | E8: =SUMIFS('Trial Database'!$H$2:$H$28727,'Trial Database'!$J$2:$J$28727,">="&DATE(2026,1,1),'Trial Database'!$J$2:$J$28727,"<"&DATE(2027,1,1),'Trial Database'!$E$2:$E$28727,"Phase 2") -> 0 | F8: =SUMIFS('Trial Database'!$H$2:$H$28727,'Trial Database'!$J$2:$J$28727,">="&DATE(2026,1,1),'Trial Database'!$J$2:$J$28727,"<"&DATE(2027,1,1),'Trial Database'!$E$2:$E$28727,"Phase 2/3") -> 0 | G8: =SUMIFS('Trial Database'!$H$2:$H$28727,'Trial Database'!$J$2:$J$28727,">="&DATE(2026,1,1),'Trial Database'!$J$2:$J$28727,"<"&DATE(2027,1,1),'Trial Database'!$E$2:$E$28727,"Phase 3") -> 0 | H8: =SUMIFS('Trial Database'!$H$2:$H$28727,'Trial Database'!$J$2:$J$28727,">="&DATE(2026,1,1),'Trial Database'!$J$2:$J$28727,"<"&DATE(2027,1,1),'Trial Database'!$E$2:$E$28727,"Phase 4") -> 0 | I8: =SUM(B8:H8) -> 0
A9: 2026 Annualized | B9: =ROUND(B8*12/MONTH(EOMONTH(TODAY(),-1)),0) -> 0 | C9: =ROUND(C8*12/MONTH(EOMONTH(TODAY(),-1)),0) -> 0 | D9: =ROUND(D8*12/MONTH(EOMONTH(TODAY(),-1)),0) -> 0 | E9: =ROUND(E8*12/MONTH(EOMONTH(TODAY(),-1)),0) -> 0 | F9: =ROUND(F8*12/MONTH(EOMONTH(TODAY(),-1)),0) -> 0 | G9: =ROUND(G8*12/MONTH(EOMONTH(TODAY(),-1)),0) -> 0 | H9: =ROUND(H8*12/MONTH(EOMONTH(TODAY(),-1)),0) -> 0 | I9: =SUM(B9:H9) -> 0
A12: Rolling Metrics | B12: Value
A13: T12M (Aug 2025 – Jul 2026) | B13: =SUMIFS('Trial Database'!$H$2:$H$28727,'Trial Database'!$J$2:$J$28727,">="&DATE(2025,8,1),'Trial Database'!$J$2:$J$28727,"<="&DATE(2026,7,31)) -> 0
A14: T12M Prior (Aug 2024 – Jul 2025) | B14: =SUMIFS('Trial Database'!$H$2:$H$28727,'Trial Database'!$J$2:$J$28727,">="&DATE(2024,8,1),'Trial Database'!$J$2:$J$28727,"<="&DATE(2025,7,31)) -> 0
A15: T12M vs T12M Prior % | B15: =IFERROR((B13-B14)/B14,"N/A") -> 0
A16: YoY % enroll/day (Jul 2026 vs Jul 2025) | B16: =IFERROR(((SUMIFS('Trial Database'!$H$2:$H$28727,'Trial Database'!$J$2:$J$28727,">="&DATE(2026,7,1),'Trial Database'!$J$2:$J$28727,"<="&DATE(2026,7,31))/DAY(EOMONTH(DATE(2026,7,1),0)))-(SUMIFS('Trial Database'!$H$2:$H$28727,'Trial Database'!$J$2:$J$28727,">="&DATE(2025,7,1),'Trial Database'!$J$2:$J$28727,"<="&DATE(2025,7,31))/DAY(EOMONTH(DATE(2025,7,1),0))))/(SUMIFS('Trial Database'!$H$2:$H$28727,'Trial Database'!$J$2:$J$28727,">="&DATE(2025,7,1),'Trial Database'!$J$2:$J$28727,"<="&DATE(2025,7,31))/DAY(EOMONTH(DATE(2025,7,1),0))),"N/A") -> 0
A17: MoM % enroll/day (Jul 2026 vs Jun 2026) | B17: =IFERROR(((SUMIFS('Trial Database'!$H$2:$H$28727,'Trial Database'!$J$2:$J$28727,">="&DATE(2026,7,1),'Trial Database'!$J$2:$J$28727,"<="&DATE(2026,7,31))/DAY(EOMONTH(DATE(2026,7,1),0)))-(SUMIFS('Trial Database'!$H$2:$H$28727,'Trial Database'!$J$2:$J$28727,">="&DATE(2026,6,1),'Trial Database'!$J$2:$J$28727,"<="&DATE(2026,6,30))/DAY(EOMONTH(DATE(2026,6,1),0))))/(SUMIFS('Trial Database'!$H$2:$H$28727,'Trial Database'!$J$2:$J$28727,">="&DATE(2026,6,1),'Trial Database'!$J$2:$J$28727,"<="&DATE(2026,6,30))/DAY(EOMONTH(DATE(2026,6,1),0))),"N/A") -> 0
A18: MoM Prior % enroll/day (Jun 2026 vs May 2026) | B18: =IFERROR(((SUMIFS('Trial Database'!$H$2:$H$28727,'Trial Database'!$J$2:$J$28727,">="&DATE(2026,6,1),'Trial Database'!$J$2:$J$28727,"<="&DATE(2026,6,30))/DAY(EOMONTH(DATE(2026,6,1),0)))-(SUMIFS('Trial Database'!$H$2:$H$28727,'Trial Database'!$J$2:$J$28727,">="&DATE(2026,5,1),'Trial Database'!$J$2:$J$28727,"<="&DATE(2026,5,31))/DAY(EOMONTH(DATE(2026,5,1),0))))/(SUMIFS('Trial Database'!$H$2:$H$28727,'Trial Database'!$J$2:$J$28727,">="&DATE(2026,5,1),'Trial Database'!$J$2:$J$28727,"<="&DATE(2026,5,31))/DAY(EOMONTH(DATE(2026,5,1),0))),"N/A") -> 0
A21: Month | B21: Early Phase 1 | C21: Phase 1 | D21: Phase 1/2 | E21: Phase 2 | F21: Phase 2/3 | G21: Phase 3 | H21: Phase 4 | I21: Total | J21: Days | K21: Enroll/Day
A22: 43831 | B22: =SUMIFS('Trial Database'!$H$2:$H$28727,'Trial Database'!$J$2:$J$28727,">="&DATE(2020,1,1),'Trial Database'!$J$2:$J$28727,"<"&DATE(2020,2,1),'Trial Database'!$E$2:$E$28727,"Early Phase 1") -> 0 | C22: =SUMIFS('Trial Database'!$H$2:$H$28727,'Trial Database'!$J$2:$J$28727,">="&DATE(2020,1,1),'Trial Database'!$J$2:$J$28727,"<"&DATE(2020,2,1),'Trial Database'!$E$2:$E$28727,"Phase 1") -> 0 | D22: =SUMIFS('Trial Database'!$H$2:$H$28727,'Trial Database'!$J$2:$J$28727,">="&DATE(2020,1,1),'Trial Database'!$J$2:$J$28727,"<"&DATE(2020,2,1),'Trial Database'!$E$2:$E$28727,"Phase 1/2") -> 0 | E22: =SUMIFS('Trial Database'!$H$2:$H$28727,'Trial Database'!$J$2:$J$28727,">="&DATE(2020,1,1),'Trial Database'!$J$2:$J$28727,"<"&DATE(2020,2,1),'Trial Database'!$E$2:$E$28727,"Phase 2") -> 0 | F22: =SUMIFS('Trial Database'!$H$2:$H$28727,'Trial Database'!$J$2:$J$28727,">="&DATE(2020,1,1),'Trial Database'!$J$2:$J$28727,"<"&DATE(2020,2,1),'Trial Database'!$E$2:$E$28727,"Phase 2/3") -> 0 | G22: =SUMIFS('Trial Database'!$H$2:$H$28727,'Trial Database'!$J$2:$J$28727,">="&DATE(2020,1,1),'Trial Database'!$J$2:$J$28727,"<"&DATE(2020,2,1),'Trial Database'!$E$2:$E$28727,"Phase 3") -> 0 | H22: =SUMIFS('Trial Database'!$H$2:$H$28727,'Trial Database'!$J$2:$J$28727,">="&DATE(2020,1,1),'Trial Database'!$J$2:$J$28727,"<"&DATE(2020,2,1),'Trial Database'!$E$2:$E$28727,"Phase 4") -> 0 | I22: =SUM(B22:H22) -> 0 | J22: =DAY(EOMONTH(A22,0)) -> 0 | K22: =IF(J22=0,0,I22/J22) -> 0
A23: 43862 | B23: =SUMIFS('Trial Database'!$H$2:$H$28727,'Trial Database'!$J$2:$J$28727,">="&DATE(2020,2,1),'Trial Database'!$J$2:$J$28727,"<"&DATE(2020,3,1),'Trial Database'!$E$2:$E$28727,"Early Phase 1") -> 0 | C23: =SUMIFS('Trial Database'!$H$2:$H$28727,'Trial Database'!$J$2:$J$28727,">="&DATE(2020,2,1),'Trial Database'!$J$2:$J$28727,"<"&DATE(2020,3,1),'Trial Database'!$E$2:$E$28727,"Phase 1") -> 0 | D23: =SUMIFS('Trial Database'!$H$2:$H$28727,'Trial Database'!$J$2:$J$28727,">="&DATE(2020,2,1),'Trial Database'!$J$2:$J$28727,"<"&DATE(2020,3,1),'Trial Database'!$E$2:$E$28727,"Phase 1/2") -> 0 | E23: =SUMIFS('Trial Database'!$H$2:$H$28727,'Trial Database'!$J$2:$J$28727,">="&DATE(2020,2,1),'Trial Database'!$J$2:$J$28727,"<"&DATE(2020,3,1),'Trial Database'!$E$2:$E$28727,"Phase 2") -> 0 | F23: =SUMIFS('Trial Database'!$H$2:$H$28727,'Trial Database'!$J$2:$J$28727,">="&DATE(2020,2,1),'Trial Database'!$J$2:$J$28727,"<"&DATE(2020,3,1),'Trial Database'!$E$2:$E$28727,"Phase 2/3") -> 0 | G23: =SUMIFS('Trial Database'!$H$2:$H$28727,'Trial Database'!$J$2:$J$28727,">="&DATE(2020,2,1),'Trial Database'!$J$2:$J$28727,"<"&DATE(2020,3,1),'Trial Database'!$E$2:$E$28727,"Phase 3") -> 0 | H23: =SUMIFS('Trial Database'!$H$2:$H$28727,'Trial Database'!$J$2:$J$28727,">="&DATE(2020,2,1),'Trial Database'!$J$2:$J$28727,"<"&DATE(2020,3,1),'Trial Database'!$E$2:$E$28727,"Phase 4") -> 0 | I23: =SUM(B23:H23) -> 0 | J23: =DAY(EOMONTH(A23,0)) -> 0 | K23: =IF(J23=0,0,I23/J23) -> 0
A24: 43891 | B24: =SUMIFS('Trial Database'!$H$2:$H$28727,'Trial Database'!$J$2:$J$28727,">="&DATE(2020,3,1),'Trial Database'!$J$2:$J$28727,"<"&DATE(2020,4,1),'Trial Database'!$E$2:$E$28727,"Early Phase 1") -> 0 | C24: =SUMIFS('Trial Database'!$H$2:$H$28727,'Trial Database'!$J$2:$J$28727,">="&DATE(2020,3,1),'Trial Database'!$J$2:$J$28727,"<"&DATE(2020,4,1),'Trial Database'!$E$2:$E$28727,"Phase 1") -> 0 | D24: =SUMIFS('Trial Database'!$H$2:$H$28727,'Trial Database'!$J$2:$J$28727,">="&DATE(2020,3,1),'Trial Database'!$J$2:$J$28727,"<"&DATE(2020,4,1),'Trial Database'!$E$2:$E$28727,"Phase 1/2") -> 0 | E24: =SUMIFS('Trial Database'!$H$2:$H$28727,'Trial Database'!$J$2:$J$28727,">="&DATE(2020,3,1),'Trial Database'!$J$2:$J$28727,"<"&DATE(2020,4,1),'Trial Database'!$E$2:$E$28727,"Phase 2") -> 0 | F24: =SUMIFS('Trial Database'!$H$2:$H$28727,'Trial Database'!$J$2:$J$28727,">="&DATE(2020,3,1),'Trial Database'!$J$2:$J$28727,"<"&DATE(2020,4,1),'Trial Database'!$E$2:$E$28727,"Phase 2/3") -> 0 | G24: =SUMIFS('Trial Database'!$H$2:$H$28727,'Trial Database'!$J$2:$J$28727,">="&DATE(2020,3,1),'Trial Database'!$J$2:$J$28727,"<"&DATE(2020,4,1),'Trial Database'!$E$2:$E$28727,"Phase 3") -> 0 | H24: =SUMIFS('Trial Database'!$H$2:$H$28727,'Trial Database'!$J$2:$J$28727,">="&DATE(2020,3,1),'Trial Database'!$J$2:$J$28727,"<"&DATE(2020,4,1),'Trial Database'!$E$2:$E$28727,"Phase 4") -> 0 | I24: =SUM(B24:H24) -> 0 | J24: =DAY(EOMONTH(A24,0)) -> 0 | K24: =IF(J24=0,0,I24/J24) -> 0
