Workbook

Sheet Cover
A1: Life Science Tools Monthly Tracker
A4: Date Range: Jan 01, 2015 to Jul 31, 2026 | Generated: August 13, 2026
B7: Module Status
B8: Module | C8: Details | D8: Status
B9: Clinical Trials | C9: Not selected | D9: SKIPPED
B10: FDA Novel Approvals | C10: Not selected | D10: SKIPPED
B11: FDA Biosimilars | C11: Not selected | D11: SKIPPED
B12: NIH Outlays | C12: 137 NIH monthly records | D12: OK
B15: Report Contents
B16: Charts
C17: MTS Charts
B18: Summary
C19: MTS Summary Statistics
B20: Database
C21: MTS Database

Sheet ── Charts ──
A1: Charts

Sheet _MTS_ChartData
A1: 2015 | B1: 24.441726 | D1: Aug 24 | E1: 4.5237147
A2: 2016 | B2: 29.878283 | D2: Sep 24 | E2: 4.2577705
A3: 2017 | B3: 32.246542 | D3: Oct 24 | E3: 4.2827096
A4: 2018 | B4: 33.836322 | D4: Nov 24 | E4: 3.9062613
A5: 2019 | B5: 35.882103 | D5: Dec 24 | E5: 3.9532513
A6: 2020 | B6: 36.692828 | D6: Jan 25 | E6: 3.5543499
A7: 2021 | B7: 39.350215 | D7: Feb 25 | E7: 3.7391572
A8: 2022 | B8: 41.942182 | D8: Mar 25 | E8: 3.5495495
A9: 2023 | B9: 46.479341 | D9: Apr 25 | E9: 3.8495311
A10: 2024 | B10: 48.980222 | D10: May 25 | E10: 2.7680988
A11: 2025 | B11: 46.748458 | D11: Jun 25 | E11: 4.2518099
A12: 2026 | B12: 26.005366 | D12: Jul 25 | E12: 4.5197167
A13: 2026 Ann. | B13: 44.6 | D13: Aug 25 | E13: 4.3715123
D14: Sep 25 | E14: 4.5950414
D15: Oct 25 | E15: 3.3139684
D16: Nov 25 | E16: 3.5981446
D17: Dec 25 | E17: 4.6375781
D18: Jan 26 | E18: 3.559405
D19: Feb 26 | E19: 3.4114674
D20: Mar 26 | E20: 4.0391356
D21: Apr 26 | E21: 3.6817412
D22: May 26 | E22: 3.6044355
D23: Jun 26 | E23: 4.0956267
D24: Jul 26 | E24: 3.6135542

Sheet MTS Charts

Sheet ── Summary ──
A1: Summary

Sheet MTS Summary Statistics
A1: NIH Monthly Treasury Outlays — Annual Summary
A2: Year | B2: NIH Outlays ($) | C2: Months Reported
A3: 2015 | B3: =SUMPRODUCT(('MTS Database'!$H$2:$H$138=2015)*('MTS Database'!$D$2:$D$138)) -> 0 | C3: =COUNTIF('MTS Database'!$H$2:$H$138,2015) -> 0
A4: 2016 | B4: =SUMPRODUCT(('MTS Database'!$H$2:$H$138=2016)*('MTS Database'!$D$2:$D$138)) -> 0 | C4: =COUNTIF('MTS Database'!$H$2:$H$138,2016) -> 0
A5: 2017 | B5: =SUMPRODUCT(('MTS Database'!$H$2:$H$138=2017)*('MTS Database'!$D$2:$D$138)) -> 0 | C5: =COUNTIF('MTS Database'!$H$2:$H$138,2017) -> 0
A6: 2018 | B6: =SUMPRODUCT(('MTS Database'!$H$2:$H$138=2018)*('MTS Database'!$D$2:$D$138)) -> 0 | C6: =COUNTIF('MTS Database'!$H$2:$H$138,2018) -> 0
A7: 2019 | B7: =SUMPRODUCT(('MTS Database'!$H$2:$H$138=2019)*('MTS Database'!$D$2:$D$138)) -> 0 | C7: =COUNTIF('MTS Database'!$H$2:$H$138,2019) -> 0
A8: 2020 | B8: =SUMPRODUCT(('MTS Database'!$H$2:$H$138=2020)*('MTS Database'!$D$2:$D$138)) -> 0 | C8: =COUNTIF('MTS Database'!$H$2:$H$138,2020) -> 0
A9: 2021 | B9: =SUMPRODUCT(('MTS Database'!$H$2:$H$138=2021)*('MTS Database'!$D$2:$D$138)) -> 0 | C9: =COUNTIF('MTS Database'!$H$2:$H$138,2021) -> 0
A10: 2022 | B10: =SUMPRODUCT(('MTS Database'!$H$2:$H$138=2022)*('MTS Database'!$D$2:$D$138)) -> 0 | C10: =COUNTIF('MTS Database'!$H$2:$H$138,2022) -> 0
A11: 2023 | B11: =SUMPRODUCT(('MTS Database'!$H$2:$H$138=2023)*('MTS Database'!$D$2:$D$138)) -> 0 | C11: =COUNTIF('MTS Database'!$H$2:$H$138,2023) -> 0
A12: 2024 | B12: =SUMPRODUCT(('MTS Database'!$H$2:$H$138=2024)*('MTS Database'!$D$2:$D$138)) -> 0 | C12: =COUNTIF('MTS Database'!$H$2:$H$138,2024) -> 0
A13: 2025 | B13: =SUMPRODUCT(('MTS Database'!$H$2:$H$138=2025)*('MTS Database'!$D$2:$D$138)) -> 0 | C13: =COUNTIF('MTS Database'!$H$2:$H$138,2025) -> 0
A14: 2026 | B14: =SUMPRODUCT(('MTS Database'!$H$2:$H$138=2026)*('MTS Database'!$D$2:$D$138)) -> 0 | C14: =COUNTIF('MTS Database'!$H$2:$H$138,2026) -> 0
A15: 2026 Ann. | B15: =ROUND(B14*12/MONTH(EOMONTH(TODAY(),-1)),0) -> 0 | C15: Annualized
A18: NIH Outlays — Rolling Metrics
A19: Metric | B19: Value | C19: Anchor: Jul 2026
A20: T12M Outlays ($) | B20: 4.6521611e+10
A21: T12M Prior ($) | B21: 4.715592e+10
A22: T12M vs Prior % | B22: -0.013451331
A23: YoY % (per-day) | B23: -0.013451331
A24: MoM % (per-day) | B24: -0.14616535
A27: NIH Outlays — Monthly Detail
A28: Month | B28: NIH Outlays ($) | C28: Days | D28: Outlays/Day ($)
A29: Jan 2015 | B29: =SUMPRODUCT(('MTS Database'!$H$2:$H$138=2015)*('MTS Database'!$I$2:$I$138=1)*('MTS Database'!$D$2:$D$138)) -> 0 | C29: 31 | D29: =IF(C29=0,0,B29/C29) -> 0
A30: Feb 2015 | B30: =SUMPRODUCT(('MTS Database'!$H$2:$H$138=2015)*('MTS Database'!$I$2:$I$138=2)*('MTS Database'!$D$2:$D$138)) -> 0 | C30: 28 | D30: =IF(C30=0,0,B30/C30) -> 0
A31: Mar 2015 | B31: =SUMPRODUCT(('MTS Database'!$H$2:$H$138=2015)*('MTS Database'!$I$2:$I$138=3)*('MTS Database'!$D$2:$D$138)) -> 0 | C31: 31 | D31: =IF(C31=0,0,B31/C31) -> 0
A32: Apr 2015 | B32: =SUMPRODUCT(('MTS Database'!$H$2:$H$138=2015)*('MTS Database'!$I$2:$I$138=4)*('MTS Database'!$D$2:$D$138)) -> 0 | C32: 30 | D32: =IF(C32=0,0,B32/C32) -> 0
A33: May 2015 | B33: =SUMPRODUCT(('MTS Database'!$H$2:$H$138=2015)*('MTS Database'!$I$2:$I$138=5)*('MTS Database'!$D$2:$D$138)) -> 0 | C33: 31 | D33: =IF(C33=0,0,B33/C33) -> 0
A34: Jun 2015 | B34: =SUMPRODUCT(('MTS Database'!$H$2:$H$138=2015)*('MTS Database'!$I$2:$I$138=6)*('MTS Database'!$D$2:$D$138)) -> 0 | C34: 30 | D34: =IF(C34=0,0,B34/C34) -> 0
A35: Jul 2015 | B35: =SUMPRODUCT(('MTS Database'!$H$2:$H$138=2015)*('MTS Database'!$I$2:$I$138=7)*('MTS Database'!$D$2:$D$138)) -> 0 | C35: 31 | D35: =IF(C35=0,0,B35/C35) -> 0
A36: Aug 2015 | B36: =SUMPRODUCT(('MTS Database'!$H$2:$H$138=2015)*('MTS Database'!$I$2:$I$138=8)*('MTS Database'!$D$2:$D$138)) -> 0 | C36: 31 | D36: =IF(C36=0,0,B36/C36) -> 0
A37: Sep 2015 | B37: =SUMPRODUCT(('MTS Database'!$H$2:$H$138=2015)*('MTS Database'!$I$2:$I$138=9)*('MTS Database'!$D$2:$D$138)) -> 0 | C37: 30 | D37: =IF(C37=0,0,B37/C37) -> 0
A38: Oct 2015 | B38: =SUMPRODUCT(('MTS Database'!$H$2:$H$138=2015)*('MTS Database'!$I$2:$I$138=10)*('MTS Database'!$D$2:$D$138)) -> 0 | C38: 31 | D38: =IF(C38=0,0,B38/C38) -> 0
A39: Nov 2015 | B39: =SUMPRODUCT(('MTS Database'!$H$2:$H$138=2015)*('MTS Database'!$I$2:$I$138=11)*('MTS Database'!$D$2:$D$138)) -> 0 | C39: 30 | D39: =IF(C39=0,0,B39/C39) -> 0
A40: Dec 2015 | B40: =SUMPRODUCT(('MTS Database'!$H$2:$H$138=2015)*('MTS Database'!$I$2:$I$138=12)*('MTS Database'!$D$2:$D$138)) -> 0 | C40: 31 | D40: =IF(C40=0,0,B40/C40) -> 0
A41: Jan 2016 | B41: =SUMPRODUCT(('MTS Database'!$H$2:$H$138=2016)*('MTS Database'!$I$2:$I$138=1)*('MTS Database'!$D$2:$D$138)) -> 0 | C41: 31 | D41: =IF(C41=0,0,B41/C41) -> 0
A42: Feb 2016 | B42: =SUMPRODUCT(('MTS Database'!$H$2:$H$138=2016)*('MTS Database'!$I$2:$I$138=2)*('MTS Database'!$D$2:$D$138)) -> 0 | C42: 29 | D42: =IF(C42=0,0,B42/C42) -> 0
A43: Mar 2016 | B43: =SUMPRODUCT(('MTS Database'!$H$2:$H$138=2016)*('MTS Database'!$I$2:$I$138=3)*('MTS Database'!$D$2:$D$138)) -> 0 | C43: 31 | D43: =IF(C43=0,0,B43/C43) -> 0
A44: Apr 2016 | B44: =SUMPRODUCT(('MTS Database'!$H$2:$H$138=2016)*('MTS Database'!$I$2:$I$138=4)*('MTS Database'!$D$2:$D$138)) -> 0 | C44: 30 | D44: =IF(C44=0,0,B44/C44) -> 0
...

Sheet ── Database ──
A1: Database

Sheet MTS Database
A1: Record Date | B1: Agency | C1: Parent Agency | D1: Monthly Net Outlays ($) | E1: FYTD Net Outlays ($) | F1: Prior FYTD Outlays ($) | G1: Fiscal Year | H1: Calendar Year | I1: Calendar Month
A2: 42094 | B2: National Institutes of Health | C2: Department of Health and Human Services: | D2: 2.3948246e+09 | E2: 1.4181538e+10 | F2: 1.4483651e+10 | G2: 2015 | H2: 2015 | I2: 3
A3: 42124 | B3: National Institutes of Health | C3: Department of Health and Human Services: | D3: 2.4721524e+09 | E3: 1.6653691e+10 | F3: 1.7412952e+10 | G3: 2015 | H3: 2015 | I3: 4
A4: 42155 | B4: National Institutes of Health | C4: Department of Health and Human Services: | D4: 2.2503416e+09 | E4: 1.8904032e+10 | F4: 1.9883966e+10 | G4: 2015 | H4: 2015 | I4: 5
A5: 42185 | B5: National Institutes of Health | C5: Department of Health and Human Services: | D5: 2.4940158e+09 | E5: 2.1398048e+10 | F5: 2.2425039e+10 | G5: 2015 | H5: 2015 | I5: 6
A6: 42216 | B6: National Institutes of Health | C6: Department of Health and Human Services: | D6: 2.6522767e+09 | E6: 2.4050325e+10 | F6: 2.4869408e+10 | G6: 2015 | H6: 2015 | I6: 7
A7: 42247 | B7: National Institutes of Health | C7: Department of Health and Human Services: | D7: 2.4344556e+09 | E7: 2.6484781e+10 | F7: 2.74272e+10 | G7: 2015 | H7: 2015 | I7: 8
A8: 42277 | B8: National Institutes of Health | C8: Department of Health and Human Services: | D8: 2.8089068e+09 | E8: 2.9293687e+10 | F8: 2.934836e+10 | G8: 2015 | H8: 2015 | I8: 9
A9: 42308 | B9: National Institutes of Health | C9: Department of Health and Human Services: | D9: 2.2179445e+09 | E9: 2.2179445e+09 | F9: 2.37169e+09 | G9: 2016 | H9: 2015 | I9: 10
A10: 42338 | B10: National Institutes of Health | C10: Department of Health and Human Services: | D10: 2.3364837e+09 | E10: 4.5544282e+09 | F10: 4.6464758e+09 | G10: 2016 | H10: 2015 | I10: 11
A11: 42369 | B11: National Institutes of Health | C11: Department of Health and Human Services: | D11: 2.3803241e+09 | E11: 6.9347523e+09 | F11: 7.1440907e+09 | G11: 2016 | H11: 2015 | I11: 12
A12: 42400 | B12: National Institutes of Health | C12: Department of Health and Human Services: | D12: 2.2551348e+09 | E12: 9.1898872e+09 | F12: 9.4300452e+09 | G12: 2016 | H12: 2016 | I12: 1
A13: 42429 | B13: National Institutes of Health | C13: Department of Health and Human Services: | D13: 2.35813e+09 | E13: 1.1548017e+10 | F13: 1.1786714e+10 | G13: 2016 | H13: 2016 | I13: 2
... A138: 46234 | B138: National Institutes of Health | C138: Department of Health and Human Services: | D138: 3.6135542e+09 | E138: 3.7555057e+10 | F138: 3.8374435e+10 | G138: 2026 | H138: 2026 | I138: 7
