Workbook

Sheet Cover
A1: Biopharma Monthly Intelligence Report
A4: Date Range: Jan 01, 2024 to Feb 28, 2026 | Generated: March 19, 2026
B7: Module Status
B8: Module | C8: Details | D8: Status
B9: Clinical Trials | C9: 9,252 trials fetched | D9: OK
B10: FDA Approvals | C10: 123 novel, 37 biosimilar entries | D10: OK
B11: NIH Outlays | C11: 38 NIH monthly records | D11: OK
B14: Report Contents
B15: Charts
C16: CT Charts
C17: FDA Charts
C18: MTS Charts
B19: Summary
C20: Summary Statistics
C21: Summary Statistics - Enrollment
C22: FDA Approval Summary
C23: MTS Summary Statistics
B24: Database
C25: Trial Database
C26: Novel Approval Database
C27: Biosimilar Approval Database
C28: MTS Database

Sheet ── Charts ──
A1: Charts

Sheet CT Charts

Sheet FDA Charts

Sheet _MTS_ChartData
A1: 2023 | B1: 46.479341 | D1: Mar 24 | E1: 4.0653265
A2: 2024 | B2: 48.980222 | D2: Apr 24 | E2: 4.2044747
A3: 2025 | B3: 46.748458 | D3: May 24 | E3: 4.0512583
A4: 2026 | B4: 6.9708724 | D4: Jun 24 | E4: 4.2175937
A5: 2026 Ann. | B5: 41.8 | D5: Jul 24 | E5: 4.1120842
D6: Aug 24 | E6: 4.5237147
D7: Sep 24 | E7: 4.2577705
D8: Oct 24 | E8: 4.2827096
D9: Nov 24 | E9: 3.9062613
D10: Dec 24 | E10: 3.9532513
D11: Jan 25 | E11: 3.5543499
D12: Feb 25 | E12: 3.7391572
D13: Mar 25 | E13: 3.5495495
D14: Apr 25 | E14: 3.8495311
D15: May 25 | E15: 2.7680988
D16: Jun 25 | E16: 4.2518099
D17: Jul 25 | E17: 4.5197167
... D24: Feb 26 | E24: 3.4114674

Sheet MTS Charts

Sheet ── Summary ──
A1: Summary

Sheet Summary Statistics
A1: Year | B1: Early Phase 1 | C1: Phase 1 | D1: Phase 1/2 | E1: Phase 2 | F1: Phase 2/3 | G1: Phase 3 | H1: Phase 4 | I1: Total
A2: 2024 | B2: =COUNTIFS('Trial Database'!$J$2:$J$9253,">="&DATE(2024,1,1),'Trial Database'!$J$2:$J$9253,"<"&DATE(2025,1,1),'Trial Database'!$E$2:$E$9253,"Early Phase 1") -> 73 | C2: =COUNTIFS('Trial Database'!$J$2:$J$9253,">="&DATE(2024,1,1),'Trial Database'!$J$2:$J$9253,"<"&DATE(2025,1,1),'Trial Database'!$E$2:$E$9253,"Phase 1") -> 1659 | D2: =COUNTIFS('Trial Database'!$J$2:$J$9253,">="&DATE(2024,1,1),'Trial Database'!$J$2:$J$9253,"<"&DATE(2025,1,1),'Trial Database'!$E$2:$E$9253,"Phase 1/2") -> 419 | E2: =COUNTIFS('Trial Database'!$J$2:$J$9253,">="&DATE(2024,1,1),'Trial Database'!$J$2:$J$9253,"<"&DATE(2025,1,1),'Trial Database'!$E$2:$E$9253,"Phase 2") -> 866 | F2: =COUNTIFS('Trial Database'!$J$2:$J$9253,">="&DATE(2024,1,1),'Trial Database'!$J$2:$J$9253,"<"&DATE(2025,1,1),'Trial Database'!$E$2:$E$9253,"Phase 2/3") -> 94 | G2: =COUNTIFS('Trial Database'!$J$2:$J$9253,">="&DATE(2024,1,1),'Trial Database'!$J$2:$J$9253,"<"&DATE(2025,1,1),'Trial Database'!$E$2:$E$9253,"Phase 3") -> 852 | H2: =COUNTIFS('Trial Database'!$J$2:$J$9253,">="&DATE(2024,1,1),'Trial Database'!$J$2:$J$9253,"<"&DATE(2025,1,1),'Trial Database'!$E$2:$E$9253,"Phase 4") -> 145 | I2: =SUM(B2:H2) -> 4108
A3: 2025 | B3: =COUNTIFS('Trial Database'!$J$2:$J$9253,">="&DATE(2025,1,1),'Trial Database'!$J$2:$J$9253,"<"&DATE(2026,1,1),'Trial Database'!$E$2:$E$9253,"Early Phase 1") -> 91 | C3: =COUNTIFS('Trial Database'!$J$2:$J$9253,">="&DATE(2025,1,1),'Trial Database'!$J$2:$J$9253,"<"&DATE(2026,1,1),'Trial Database'!$E$2:$E$9253,"Phase 1") -> 1621 | D3: =COUNTIFS('Trial Database'!$J$2:$J$9253,">="&DATE(2025,1,1),'Trial Database'!$J$2:$J$9253,"<"&DATE(2026,1,1),'Trial Database'!$E$2:$E$9253,"Phase 1/2") -> 496 | E3: =COUNTIFS('Trial Database'!$J$2:$J$9253,">="&DATE(2025,1,1),'Trial Database'!$J$2:$J$9253,"<"&DATE(2026,1,1),'Trial Database'!$E$2:$E$9253,"Phase 2") -> 1031 | F3: =COUNTIFS('Trial Database'!$J$2:$J$9253,">="&DATE(2025,1,1),'Trial Database'!$J$2:$J$9253,"<"&DATE(2026,1,1),'Trial Database'!$E$2:$E$9253,"Phase 2/3") -> 86 | G3: =COUNTIFS('Trial Database'!$J$2:$J$9253,">="&DATE(2025,1,1),'Trial Database'!$J$2:$J$9253,"<"&DATE(2026,1,1),'Trial Database'!$E$2:$E$9253,"Phase 3") -> 923 | H3: =COUNTIFS('Trial Database'!$J$2:$J$9253,">="&DATE(2025,1,1),'Trial Database'!$J$2:$J$9253,"<"&DATE(2026,1,1),'Trial Database'!$E$2:$E$9253,"Phase 4") -> 149 | I3: =SUM(B3:H3) -> 4397
A4: 2026 | B4: =COUNTIFS('Trial Database'!$J$2:$J$9253,">="&DATE(2026,1,1),'Trial Database'!$J$2:$J$9253,"<"&DATE(2027,1,1),'Trial Database'!$E$2:$E$9253,"Early Phase 1") -> 15 | C4: =COUNTIFS('Trial Database'!$J$2:$J$9253,">="&DATE(2026,1,1),'Trial Database'!$J$2:$J$9253,"<"&DATE(2027,1,1),'Trial Database'!$E$2:$E$9253,"Phase 1") -> 252 | D4: =COUNTIFS('Trial Database'!$J$2:$J$9253,">="&DATE(2026,1,1),'Trial Database'!$J$2:$J$9253,"<"&DATE(2027,1,1),'Trial Database'!$E$2:$E$9253,"Phase 1/2") -> 111 | E4: =COUNTIFS('Trial Database'!$J$2:$J$9253,">="&DATE(2026,1,1),'Trial Database'!$J$2:$J$9253,"<"&DATE(2027,1,1),'Trial Database'!$E$2:$E$9253,"Phase 2") -> 173 | F4: =COUNTIFS('Trial Database'!$J$2:$J$9253,">="&DATE(2026,1,1),'Trial Database'!$J$2:$J$9253,"<"&DATE(2027,1,1),'Trial Database'!$E$2:$E$9253,"Phase 2/3") -> 18 | G4: =COUNTIFS('Trial Database'!$J$2:$J$9253,">="&DATE(2026,1,1),'Trial Database'!$J$2:$J$9253,"<"&DATE(2027,1,1),'Trial Database'!$E$2:$E$9253,"Phase 3") -> 152 | H4: =COUNTIFS('Trial Database'!$J$2:$J$9253,">="&DATE(2026,1,1),'Trial Database'!$J$2:$J$9253,"<"&DATE(2027,1,1),'Trial Database'!$E$2:$E$9253,"Phase 4") -> 26 | I4: =SUM(B4:H4) -> 747
A5: 2026 Annualized | B5: =ROUND(B4*12/MONTH(EOMONTH(TODAY(),-1)),0) -> 90 | C5: =ROUND(C4*12/MONTH(EOMONTH(TODAY(),-1)),0) -> 1512 | D5: =ROUND(D4*12/MONTH(EOMONTH(TODAY(),-1)),0) -> 666 | E5: =ROUND(E4*12/MONTH(EOMONTH(TODAY(),-1)),0) -> 1038 | F5: =ROUND(F4*12/MONTH(EOMONTH(TODAY(),-1)),0) -> 108 | G5: =ROUND(G4*12/MONTH(EOMONTH(TODAY(),-1)),0) -> 912 | H5: =ROUND(H4*12/MONTH(EOMONTH(TODAY(),-1)),0) -> 156 | I5: =SUM(B5:H5) -> 4482
A8: Rolling Metrics | B8: Value
A9: T12M (Mar 2025 – Feb 2026) | B9: 4523
A10: T12M Prior (Mar 2024 – Feb 2025) | B10: 4133
A11: T12M vs T12M Prior % | B11: 0.094362449
A12: YoY % trials/day (Feb 2026 vs Feb 2025) | B12: 0.12786885
A13: MoM % trials/day (Feb 2026 vs Jan 2026) | B13: -0.054945055
A14: MoM Prior % trials/day (Jan 2026 vs Dec 2025) | B14: -0.15157895
A17: Month | B17: Early Phase 1 | C17: Phase 1 | D17: Phase 1/2 | E17: Phase 2 | F17: Phase 2/3 | G17: Phase 3 | H17: Phase 4 | I17: Total | J17: Days | K17: Trials/Day
A18: 45292 | B18: =COUNTIFS('Trial Database'!$J$2:$J$9253,">="&DATE(2024,1,1),'Trial Database'!$J$2:$J$9253,"<"&DATE(2024,2,1),'Trial Database'!$E$2:$E$9253,"Early Phase 1") -> 7 | C18: =COUNTIFS('Trial Database'!$J$2:$J$9253,">="&DATE(2024,1,1),'Trial Database'!$J$2:$J$9253,"<"&DATE(2024,2,1),'Trial Database'!$E$2:$E$9253,"Phase 1") -> 136 | D18: =COUNTIFS('Trial Database'!$J$2:$J$9253,">="&DATE(2024,1,1),'Trial Database'!$J$2:$J$9253,"<"&DATE(2024,2,1),'Trial Database'!$E$2:$E$9253,"Phase 1/2") -> 32 | E18: =COUNTIFS('Trial Database'!$J$2:$J$9253,">="&DATE(2024,1,1),'Trial Database'!$J$2:$J$9253,"<"&DATE(2024,2,1),'Trial Database'!$E$2:$E$9253,"Phase 2") -> 70 | F18: =COUNTIFS('Trial Database'!$J$2:$J$9253,">="&DATE(2024,1,1),'Trial Database'!$J$2:$J$9253,"<"&DATE(2024,2,1),'Trial Database'!$E$2:$E$9253,"Phase 2/3") -> 5 | G18: =COUNTIFS('Trial Database'!$J$2:$J$9253,">="&DATE(2024,1,1),'Trial Database'!$J$2:$J$9253,"<"&DATE(2024,2,1),'Trial Database'!$E$2:$E$9253,"Phase 3") -> 57 | H18: =COUNTIFS('Trial Database'!$J$2:$J$9253,">="&DATE(2024,1,1),'Trial Database'!$J$2:$J$9253,"<"&DATE(2024,2,1),'Trial Database'!$E$2:$E$9253,"Phase 4") -> 10 | I18: =SUM(B18:H18) -> 317 | J18: =DAY(EOMONTH(A18,0)) -> 31 | K18: =IF(J18=0,0,I18/J18) -> 10.225806
A19: 45323 | B19: =COUNTIFS('Trial Database'!$J$2:$J$9253,">="&DATE(2024,2,1),'Trial Database'!$J$2:$J$9253,"<"&DATE(2024,3,1),'Trial Database'!$E$2:$E$9253,"Early Phase 1") -> 2 | C19: =COUNTIFS('Trial Database'!$J$2:$J$9253,">="&DATE(2024,2,1),'Trial Database'!$J$2:$J$9253,"<"&DATE(2024,3,1),'Trial Database'!$E$2:$E$9253,"Phase 1") -> 111 | D19: =COUNTIFS('Trial Database'!$J$2:$J$9253,">="&DATE(2024,2,1),'Trial Database'!$J$2:$J$9253,"<"&DATE(2024,3,1),'Trial Database'!$E$2:$E$9253,"Phase 1/2") -> 30 | E19: =COUNTIFS('Trial Database'!$J$2:$J$9253,">="&DATE(2024,2,1),'Trial Database'!$J$2:$J$9253,"<"&DATE(2024,3,1),'Trial Database'!$E$2:$E$9253,"Phase 2") -> 71 | F19: =COUNTIFS('Trial Database'!$J$2:$J$9253,">="&DATE(2024,2,1),'Trial Database'!$J$2:$J$9253,"<"&DATE(2024,3,1),'Trial Database'!$E$2:$E$9253,"Phase 2/3") -> 4 | G19: =COUNTIFS('Trial Database'!$J$2:$J$9253,">="&DATE(2024,2,1),'Trial Database'!$J$2:$J$9253,"<"&DATE(2024,3,1),'Trial Database'!$E$2:$E$9253,"Phase 3") -> 49 | H19: =COUNTIFS('Trial Database'!$J$2:$J$9253,">="&DATE(2024,2,1),'Trial Database'!$J$2:$J$9253,"<"&DATE(2024,3,1),'Trial Database'!$E$2:$E$9253,"Phase 4") -> 12 | I19: =SUM(B19:H19) -> 279 | J19: =DAY(EOMONTH(A19,0)) -> 29 | K19: =IF(J19=0,0,I19/J19) -> 9.6206897
A20: 45352 | B20: =COUNTIFS('Trial Database'!$J$2:$J$9253,">="&DATE(2024,3,1),'Trial Database'!$J$2:$J$9253,"<"&DATE(2024,4,1),'Trial Database'!$E$2:$E$9253,"Early Phase 1") -> 5 | C20: =COUNTIFS('Trial Database'!$J$2:$J$9253,">="&DATE(2024,3,1),'Trial Database'!$J$2:$J$9253,"<"&DATE(2024,4,1),'Trial Database'!$E$2:$E$9253,"Phase 1") -> 136 | D20: =COUNTIFS('Trial Database'!$J$2:$J$9253,">="&DATE(2024,3,1),'Trial Database'!$J$2:$J$9253,"<"&DATE(2024,4,1),'Trial Database'!$E$2:$E$9253,"Phase 1/2") -> 36 | E20: =COUNTIFS('Trial Database'!$J$2:$J$9253,">="&DATE(2024,3,1),'Trial Database'!$J$2:$J$9253,"<"&DATE(2024,4,1),'Trial Database'!$E$2:$E$9253,"Phase 2") -> 73 | F20: =COUNTIFS('Trial Database'!$J$2:$J$9253,">="&DATE(2024,3,1),'Trial Database'!$J$2:$J$9253,"<"&DATE(2024,4,1),'Trial Database'!$E$2:$E$9253,"Phase 2/3") -> 8 | G20: =COUNTIFS('Trial Database'!$J$2:$J$9253,">="&DATE(2024,3,1),'Trial Database'!$J$2:$J$9253,"<"&DATE(2024,4,1),'Trial Database'!$E$2:$E$9253,"Phase 3") -> 86 | H20: =COUNTIFS('Trial Database'!$J$2:$J$9253,">="&DATE(2024,3,1),'Trial Database'!$J$2:$J$9253,"<"&DATE(2024,4,1),'Trial Database'!$E$2:$E$9253,"Phase 4") -> 10 | I20: =SUM(B20:H20) -> 354 | J20: =DAY(EOMONTH(A20,0)) -> 31 | K20: =IF(J20=0,0,I20/J20) -> 11.419355
A21: 45383 | B21: =COUNTIFS('Trial Database'!$J$2:$J$9253,">="&DATE(2024,4,1),'Trial Database'!$J$2:$J$9253,"<"&DATE(2024,5,1),'Trial Database'!$E$2:$E$9253,"Early Phase 1") -> 4 | C21: =COUNTIFS('Trial Database'!$J$2:$J$9253,">="&DATE(2024,4,1),'Trial Database'!$J$2:$J$9253,"<"&DATE(2024,5,1),'Trial Database'!$E$2:$E$9253,"Phase 1") -> 143 | D21: =COUNTIFS('Trial Database'!$J$2:$J$9253,">="&DATE(2024,4,1),'Trial Database'!$J$2:$J$9253,"<"&DATE(2024,5,1),'Trial Database'!$E$2:$E$9253,"Phase 1/2") -> 35 | E21: =COUNTIFS('Trial Database'!$J$2:$J$9253,">="&DATE(2024,4,1),'Trial Database'!$J$2:$J$9253,"<"&DATE(2024,5,1),'Trial Database'!$E$2:$E$9253,"Phase 2") -> 66 | F21: =COUNTIFS('Trial Database'!$J$2:$J$9253,">="&DATE(2024,4,1),'Trial Database'!$J$2:$J$9253,"<"&DATE(2024,5,1),'Trial Database'!$E$2:$E$9253,"Phase 2/3") -> 9 | G21: =COUNTIFS('Trial Database'!$J$2:$J$9253,">="&DATE(2024,4,1),'Trial Database'!$J$2:$J$9253,"<"&DATE(2024,5,1),'Trial Database'!$E$2:$E$9253,"Phase 3") -> 78 | H21: =COUNTIFS('Trial Database'!$J$2:$J$9253,">="&DATE(2024,4,1),'Trial Database'!$J$2:$J$9253,"<"&DATE(2024,5,1),'Trial Database'!$E$2:$E$9253,"Phase 4") -> 17 | I21: =SUM(B21:H21) -> 352 | J21: =DAY(EOMONTH(A21,0)) -> 30 | K21: =IF(J21=0,0,I21/J21) -> 11.733333
A22: 45413 | B22: =COUNTIFS('Trial Database'!$J$2:$J$9253,">="&DATE(2024,5,1),'Trial Database'!$J$2:$J$9253,"<"&DATE(2024,6,1),'Trial Database'!$E$2:$E$9253,"Early Phase 1") -> 7 | C22: =COUNTIFS('Trial Database'!$J$2:$J$9253,">="&DATE(2024,5,1),'Trial Database'!$J$2:$J$9253,"<"&DATE(2024,6,1),'Trial Database'!$E$2:$E$9253,"Phase 1") -> 148 | D22: =COUNTIFS('Trial Database'!$J$2:$J$9253,">="&DATE(2024,5,1),'Trial Database'!$J$2:$J$9253,"<"&DATE(2024,6,1),'Trial Database'!$E$2:$E$9253,"Phase 1/2") -> 36 | E22: =COUNTIFS('Trial Database'!$J$2:$J$9253,">="&DATE(2024,5,1),'Trial Database'!$J$2:$J$9253,"<"&DATE(2024,6,1),'Trial Database'!$E$2:$E$9253,"Phase 2") -> 45 | F22: =COUNTIFS('Trial Database'!$J$2:$J$9253,">="&DATE(2024,5,1),'Trial Database'!$J$2:$J$9253,"<"&DATE(2024,6,1),'Trial Database'!$E$2:$E$9253,"Phase 2/3") -> 14 | G22: =COUNTIFS('Trial Database'!$J$2:$J$9253,">="&DATE(2024,5,1),'Trial Database'!$J$2:$J$9253,"<"&DATE(2024,6,1),'Trial Database'!$E$2:$E$9253,"Phase 3") -> 67 | H22: =COUNTIFS('Trial Database'!$J$2:$J$9253,">="&DATE(2024,5,1),'Trial Database'!$J$2:$J$9253,"<"&DATE(2024,6,1),'Trial Database'!$E$2:$E$9253,"Phase 4") -> 11 | I22: =SUM(B22:H22) -> 328 | J22: =DAY(EOMONTH(A22,0)) -> 31 | K22: =IF(J22=0,0,I22/J22) -> 10.580645
A23: 45444 | B23: =COUNTIFS('Trial Database'!$J$2:$J$9253,">="&DATE(2024,6,1),'Trial Database'!$J$2:$J$9253,"<"&DATE(2024,7,1),'Trial Database'!$E$2:$E$9253,"Early Phase 1") -> 6 | C23: =COUNTIFS('Trial Database'!$J$2:$J$9253,">="&DATE(2024,6,1),'Trial Database'!$J$2:$J$9253,"<"&DATE(2024,7,1),'Trial Database'!$E$2:$E$9253,"Phase 1") -> 127 | D23: =COUNTIFS('Trial Database'!$J$2:$J$9253,">="&DATE(2024,6,1),'Trial Database'!$J$2:$J$9253,"<"&DATE(2024,7,1),'Trial Database'!$E$2:$E$9253,"Phase 1/2") -> 41 | E23: =COUNTIFS('Trial Database'!$J$2:$J$9253,">="&DATE(2024,6,1),'Trial Database'!$J$2:$J$9253,"<"&DATE(2024,7,1),'Trial Database'!$E$2:$E$9253,"Phase 2") -> 58 | F23: =COUNTIFS('Trial Database'!$J$2:$J$9253,">="&DATE(2024,6,1),'Trial Database'!$J$2:$J$9253,"<"&DATE(2024,7,1),'Trial Database'!$E$2:$E$9253,"Phase 2/3") -> 8 | G23: =COUNTIFS('Trial Database'!$J$2:$J$9253,">="&DATE(2024,6,1),'Trial Database'!$J$2:$J$9253,"<"&DATE(2024,7,1),'Trial Database'!$E$2:$E$9253,"Phase 3") -> 72 | H23: =COUNTIFS('Trial Database'!$J$2:$J$9253,">="&DATE(2024,6,1),'Trial Database'!$J$2:$J$9253,"<"&DATE(2024,7,1),'Trial Database'!$E$2:$E$9253,"Phase 4") -> 10 | I23: =SUM(B23:H23) -> 322 | J23: =DAY(EOMONTH(A23,0)) -> 30 | K23: =IF(J23=0,0,I23/J23) -> 10.733333
A24: 45474 | B24: =COUNTIFS('Trial Database'!$J$2:$J$9253,">="&DATE(2024,7,1),'Trial Database'!$J$2:$J$9253,"<"&DATE(2024,8,1),'Trial Database'!$E$2:$E$9253,"Early Phase 1") -> 2 | C24: =COUNTIFS('Trial Database'!$J$2:$J$9253,">="&DATE(2024,7,1),'Trial Database'!$J$2:$J$9253,"<"&DATE(2024,8,1),'Trial Database'!$E$2:$E$9253,"Phase 1") -> 139 | D24: =COUNTIFS('Trial Database'!$J$2:$J$9253,">="&DATE(2024,7,1),'Trial Database'!$J$2:$J$9253,"<"&DATE(2024,8,1),'Trial Database'!$E$2:$E$9253,"Phase 1/2") -> 32 | E24: =COUNTIFS('Trial Database'!$J$2:$J$9253,">="&DATE(2024,7,1),'Trial Database'!$J$2:$J$9253,"<"&DATE(2024,8,1),'Trial Database'!$E$2:$E$9253,"Phase 2") -> 69 | F24: =COUNTIFS('Trial Database'!$J$2:$J$9253,">="&DATE(2024,7,1),'Trial Database'!$J$2:$J$9253,"<"&DATE(2024,8,1),'Trial Database'!$E$2:$E$9253,"Phase 2/3") -> 7 | G24: =COUNTIFS('Trial Database'!$J$2:$J$9253,">="&DATE(2024,7,1),'Trial Database'!$J$2:$J$9253,"<"&DATE(2024,8,1),'Trial Database'!$E$2:$E$9253,"Phase 3") -> 71 | H24: =COUNTIFS('Trial Database'!$J$2:$J$9253,">="&DATE(2024,7,1),'Trial Database'!$J$2:$J$9253,"<"&DATE(2024,8,1),'Trial Database'!$E$2:$E$9253,"Phase 4") -> 9 | I24: =SUM(B24:H24) -> 329 | J24: =DAY(EOMONTH(A24,0)) -> 31 | K24: =IF(J24=0,0,I24/J24) -> 10.612903
A25: 45505 | B25: =COUNTIFS('Trial Database'!$J$2:$J$9253,">="&DATE(2024,8,1),'Trial Database'!$J$2:$J$9253,"<"&DATE(2024,9,1),'Trial Database'!$E$2:$E$9253,"Early Phase 1") -> 8 | C25: =COUNTIFS('Trial Database'!$J$2:$J$9253,">="&DATE(2024,8,1),'Trial Database'!$J$2:$J$9253,"<"&DATE(2024,9,1),'Trial Database'!$E$2:$E$9253,"Phase 1") -> 150 | D25: =COUNTIFS('Trial Database'!$J$2:$J$9253,">="&DATE(2024,8,1),'Trial Database'!$J$2:$J$9253,"<"&DATE(2024,9,1),'Trial Database'!$E$2:$E$9253,"Phase 1/2") -> 35 | E25: =COUNTIFS('Trial Database'!$J$2:$J$9253,">="&DATE(2024,8,1),'Trial Database'!$J$2:$J$9253,"<"&DATE(2024,9,1),'Trial Database'!$E$2:$E$9253,"Phase 2") -> 85 | F25: =COUNTIFS('Trial Database'!$J$2:$J$9253,">="&DATE(2024,8,1),'Trial Database'!$J$2:$J$9253,"<"&DATE(2024,9,1),'Trial Database'!$E$2:$E$9253,"Phase 2/3") -> 7 | G25: =COUNTIFS('Trial Database'!$J$2:$J$9253,">="&DATE(2024,8,1),'Trial Database'!$J$2:$J$9253,"<"&DATE(2024,9,1),'Trial Database'!$E$2:$E$9253,"Phase 3") -> 62 | H25: =COUNTIFS('Trial Database'!$J$2:$J$9253,">="&DATE(2024,8,1),'Trial Database'!$J$2:$J$9253,"<"&DATE(2024,9,1),'Trial Database'!$E$2:$E$9253,"Phase 4") -> 14 | I25: =SUM(B25:H25) -> 361 | J25: =DAY(EOMONTH(A25,0)) -> 31 | K25: =IF(J25=0,0,I25/J25) -> 11.645161
A26: 45536 | B26: =COUNTIFS('Trial Database'!$J$2:$J$9253,">="&DATE(2024,9,1),'Trial Database'!$J$2:$J$9253,"<"&DATE(2024,10,1),'Trial Database'!$E$2:$E$9253,"Early Phase 1") -> 4 | C26: =COUNTIFS('Trial Database'!$J$2:$J$9253,">="&DATE(2024,9,1),'Trial Database'!$J$2:$J$9253,"<"&DATE(2024,10,1),'Trial Database'!$E$2:$E$9253,"Phase 1") -> 134 | D26: =COUNTIFS('Trial Database'!$J$2:$J$9253,">="&DATE(2024,9,1),'Trial Database'!$J$2:$J$9253,"<"&DATE(2024,10,1),'Trial Database'!$E$2:$E$9253,"Phase 1/2") -> 36 | E26: =COUNTIFS('Trial Database'!$J$2:$J$9253,">="&DATE(2024,9,1),'Trial Database'!$J$2:$J$9253,"<"&DATE(2024,10,1),'Trial Database'!$E$2:$E$9253,"Phase 2") -> 72 | F26: =COUNTIFS('Trial Database'!$J$2:$J$9253,">="&DATE(2024,9,1),'Trial Database'!$J$2:$J$9253,"<"&DATE(2024,10,1),'Trial Database'!$E$2:$E$9253,"Phase 2/3") -> 8 | G26: =COUNTIFS('Trial Database'!$J$2:$J$9253,">="&DATE(2024,9,1),'Trial Database'!$J$2:$J$9253,"<"&DATE(2024,10,1),'Trial Database'!$E$2:$E$9253,"Phase 3") -> 76 | H26: =COUNTIFS('Trial Database'!$J$2:$J$9253,">="&DATE(2024,9,1),'Trial Database'!$J$2:$J$9253,"<"&DATE(2024,10,1),'Trial Database'!$E$2:$E$9253,"Phase 4") -> 14 | I26: =SUM(B26:H26) -> 344 | J26: =DAY(EOMONTH(A26,0)) -> 30 | K26: =IF(J26=0,0,I26/J26) -> 11.466667
A27: 45566 | B27: =COUNTIFS('Trial Database'!$J$2:$J$9253,">="&DATE(2024,10,1),'Trial Database'!$J$2:$J$9253,"<"&DATE(2024,11,1),'Trial Database'!$E$2:$E$9253,"Early Phase 1") -> 9 | C27: =COUNTIFS('Trial Database'!$J$2:$J$9253,">="&DATE(2024,10,1),'Trial Database'!$J$2:$J$9253,"<"&DATE(2024,11,1),'Trial Database'!$E$2:$E$9253,"Phase 1") -> 149 | D27: =COUNTIFS('Trial Database'!$J$2:$J$9253,">="&DATE(2024,10,1),'Trial Database'!$J$2:$J$9253,"<"&DATE(2024,11,1),'Trial Database'!$E$2:$E$9253,"Phase 1/2") -> 29 | E27: =COUNTIFS('Trial Database'!$J$2:$J$9253,">="&DATE(2024,10,1),'Trial Database'!$J$2:$J$9253,"<"&DATE(2024,11,1),'Trial Database'!$E$2:$E$9253,"Phase 2") -> 92 | F27: =COUNTIFS('Trial Database'!$J$2:$J$9253,">="&DATE(2024,10,1),'Trial Database'!$J$2:$J$9253,"<"&DATE(2024,11,1),'Trial Database'!$E$2:$E$9253,"Phase 2/3") -> 9 | G27: =COUNTIFS('Trial Database'!$J$2:$J$9253,">="&DATE(2024,10,1),'Trial Database'!$J$2:$J$9253,"<"&DATE(2024,11,1),'Trial Database'!$E$2:$E$9253,"Phase 3") -> 77 | H27: =COUNTIFS('Trial Database'!$J$2:$J$9253,">="&DATE(2024,10,1),'Trial Database'!$J$2:$J$9253,"<"&DATE(2024,11,1),'Trial Database'!$E$2:$E$9253,"Phase 4") -> 14 | I27: =SUM(B27:H27) -> 379 | J27: =DAY(EOMONTH(A27,0)) -> 31 | K27: =IF(J27=0,0,I27/J27) -> 12.225806
A28: 45597 | B28: =COUNTIFS('Trial Database'!$J$2:$J$9253,">="&DATE(2024,11,1),'Trial Database'!$J$2:$J$9253,"<"&DATE(2024,12,1),'Trial Database'!$E$2:$E$9253,"Early Phase 1") -> 12 | C28: =COUNTIFS('Trial Database'!$J$2:$J$9253,">="&DATE(2024,11,1),'Trial Database'!$J$2:$J$9253,"<"&DATE(2024,12,1),'Trial Database'!$E$2:$E$9253,"Phase 1") -> 143 | D28: =COUNTIFS('Trial Database'!$J$2:$J$9253,">="&DATE(2024,11,1),'Trial Database'!$J$2:$J$9253,"<"&DATE(2024,12,1),'Trial Database'!$E$2:$E$9253,"Phase 1/2") -> 41 | E28: =COUNTIFS('Trial Database'!$J$2:$J$9253,">="&DATE(2024,11,1),'Trial Database'!$J$2:$J$9253,"<"&DATE(2024,12,1),'Trial Database'!$E$2:$E$9253,"Phase 2") -> 72 | F28: =COUNTIFS('Trial Database'!$J$2:$J$9253,">="&DATE(2024,11,1),'Trial Database'!$J$2:$J$9253,"<"&DATE(2024,12,1),'Trial Database'!$E$2:$E$9253,"Phase 2/3") -> 6 | G28: =COUNTIFS('Trial Database'!$J$2:$J$9253,">="&DATE(2024,11,1),'Trial Database'!$J$2:$J$9253,"<"&DATE(2024,12,1),'Trial Database'!$E$2:$E$9253,"Phase 3") -> 80 | H28: =COUNTIFS('Trial Database'!$J$2:$J$9253,">="&DATE(2024,11,1),'Trial Database'!$J$2:$J$9253,"<"&DATE(2024,12,1),'Trial Database'!$E$2:$E$9253,"Phase 4") -> 12 | I28: =SUM(B28:H28) -> 366 | J28: =DAY(EOMONTH(A28,0)) -> 30 | K28: =IF(J28=0,0,I28/J28) -> 12.2
A29: 45627 | B29: =COUNTIFS('Trial Database'!$J$2:$J$9253,">="&DATE(2024,12,1),'Trial Database'!$J$2:$J$9253,"<"&DATE(2024,13,1),'Trial Database'!$E$2:$E$9253,"Early Phase 1") -> 7 | C29: =COUNTIFS('Trial Database'!$J$2:$J$9253,">="&DATE(2024,12,1),'Trial Database'!$J$2:$J$9253,"<"&DATE(2024,13,1),'Trial Database'!$E$2:$E$9253,"Phase 1") -> 143 | D29: =COUNTIFS('Trial Database'!$J$2:$J$9253,">="&DATE(2024,12,1),'Trial Database'!$J$2:$J$9253,"<"&DATE(2024,13,1),'Trial Database'!$E$2:$E$9253,"Phase 1/2") -> 36 | E29: =COUNTIFS('Trial Database'!$J$2:$J$9253,">="&DATE(2024,12,1),'Trial Database'!$J$2:$J$9253,"<"&DATE(2024,13,1),'Trial Database'!$E$2:$E$9253,"Phase 2") -> 93 | F29: =COUNTIFS('Trial Database'!$J$2:$J$9253,">="&DATE(2024,12,1),'Trial Database'!$J$2:$J$9253,"<"&DATE(2024,13,1),'Trial Database'!$E$2:$E$9253,"Phase 2/3") -> 9 | G29: =COUNTIFS('Trial Database'!$J$2:$J$9253,">="&DATE(2024,12,1),'Trial Database'!$J$2:$J$9253,"<"&DATE(2024,13,1),'Trial Database'!$E$2:$E$9253,"Phase 3") -> 77 | H29: =COUNTIFS('Trial Database'!$J$2:$J$9253,">="&DATE(2024,12,1),'Trial Database'!$J$2:$J$9253,"<"&DATE(2024,13,1),'Trial Database'!$E$2:$E$9253,"Phase 4") -> 12 | I29: =SUM(B29:H29) -> 377 | J29: =DAY(EOMONTH(A29,0)) -> 31 | K29: =IF(J29=0,0,I29/J29) -> 12.16129
A30: 45658 | B30: =COUNTIFS('Trial Database'!$J$2:$J$9253,">="&DATE(2025,1,1),'Trial Database'!$J$2:$J$9253,"<"&DATE(2025,2,1),'Trial Database'!$E$2:$E$9253,"Early Phase 1") -> 4 | C30: =COUNTIFS('Trial Database'!$J$2:$J$9253,">="&DATE(2025,1,1),'Trial Database'!$J$2:$J$9253,"<"&DATE(2025,2,1),'Trial Database'!$E$2:$E$9253,"Phase 1") -> 116 | D30: =COUNTIFS('Trial Database'!$J$2:$J$9253,">="&DATE(2025,1,1),'Trial Database'!$J$2:$J$9253,"<"&DATE(2025,2,1),'Trial Database'!$E$2:$E$9253,"Phase 1/2") -> 39 | E30: =COUNTIFS('Trial Database'!$J$2:$J$9253,">="&DATE(2025,1,1),'Trial Database'!$J$2:$J$9253,"<"&DATE(2025,2,1),'Trial Database'!$E$2:$E$9253,"Phase 2") -> 75 | F30: =COUNTIFS('Trial Database'!$J$2:$J$9253,">="&DATE(2025,1,1),'Trial Database'!$J$2:$J$9253,"<"&DATE(2025,2,1),'Trial Database'!$E$2:$E$9253,"Phase 2/3") -> 7 | G30: =COUNTIFS('Trial Database'!$J$2:$J$9253,">="&DATE(2025,1,1),'Trial Database'!$J$2:$J$9253,"<"&DATE(2025,2,1),'Trial Database'!$E$2:$E$9253,"Phase 3") -> 62 | H30: =COUNTIFS('Trial Database'!$J$2:$J$9253,">="&DATE(2025,1,1),'Trial Database'!$J$2:$J$9253,"<"&DATE(2025,2,1),'Trial Database'!$E$2:$E$9253,"Phase 4") -> 13 | I30: =SUM(B30:H30) -> 316 | J30: =DAY(EOMONTH(A30,0)) -> 31 | K30: =IF(J30=0,0,I30/J30) -> 10.193548
A31: 45689 | B31: =COUNTIFS('Trial Database'!$J$2:$J$9253,">="&DATE(2025,2,1),'Trial Database'!$J$2:$J$9253,"<"&DATE(2025,3,1),'Trial Database'!$E$2:$E$9253,"Early Phase 1") -> 5 | C31: =COUNTIFS('Trial Database'!$J$2:$J$9253,">="&DATE(2025,2,1),'Trial Database'!$J$2:$J$9253,"<"&DATE(2025,3,1),'Trial Database'!$E$2:$E$9253,"Phase 1") -> 116 | D31: =COUNTIFS('Trial Database'!$J$2:$J$9253,">="&DATE(2025,2,1),'Trial Database'!$J$2:$J$9253,"<"&DATE(2025,3,1),'Trial Database'!$E$2:$E$9253,"Phase 1/2") -> 36 | E31: =COUNTIFS('Trial Database'!$J$2:$J$9253,">="&DATE(2025,2,1),'Trial Database'!$J$2:$J$9253,"<"&DATE(2025,3,1),'Trial Database'!$E$2:$E$9253,"Phase 2") -> 63 | F31: =COUNTIFS('Trial Database'!$J$2:$J$9253,">="&DATE(2025,2,1),'Trial Database'!$J$2:$J$9253,"<"&DATE(2025,3,1),'Trial Database'!$E$2:$E$9253,"Phase 2/3") -> 4 | G31: =COUNTIFS('Trial Database'!$J$2:$J$9253,">="&DATE(2025,2,1),'Trial Database'!$J$2:$J$9253,"<"&DATE(2025,3,1),'Trial Database'!$E$2:$E$9253,"Phase 3") -> 70 | H31: =COUNTIFS('Trial Database'!$J$2:$J$9253,">="&DATE(2025,2,1),'Trial Database'!$J$2:$J$9253,"<"&DATE(2025,3,1),'Trial Database'!$E$2:$E$9253,"Phase 4") -> 11 | I31: =SUM(B31:H31) -> 305 | J31: =DAY(EOMONTH(A31,0)) -> 28 | K31: =IF(J31=0,0,I31/J31) -> 10.892857
A32: 45717 | B32: =COUNTIFS('Trial Database'!$J$2:$J$9253,">="&DATE(2025,3,1),'Trial Database'!$J$2:$J$9253,"<"&DATE(2025,4,1),'Trial Database'!$E$2:$E$9253,"Early Phase 1") -> 11 | C32: =COUNTIFS('Trial Database'!$J$2:$J$9253,">="&DATE(2025,3,1),'Trial Database'!$J$2:$J$9253,"<"&DATE(2025,4,1),'Trial Database'!$E$2:$E$9253,"Phase 1") -> 145 | D32: =COUNTIFS('Trial Database'!$J$2:$J$9253,">="&DATE(2025,3,1),'Trial Database'!$J$2:$J$9253,"<"&DATE(2025,4,1),'Trial Database'!$E$2:$E$9253,"Phase 1/2") -> 44 | E32: =COUNTIFS('Trial Database'!$J$2:$J$9253,">="&DATE(2025,3,1),'Trial Database'!$J$2:$J$9253,"<"&DATE(2025,4,1),'Trial Database'!$E$2:$E$9253,"Phase 2") -> 84 | F32: =COUNTIFS('Trial Database'!$J$2:$J$9253,">="&DATE(2025,3,1),'Trial Database'!$J$2:$J$9253,"<"&DATE(2025,4,1),'Trial Database'!$E$2:$E$9253,"Phase 2/3") -> 4 | G32: =COUNTIFS('Trial Database'!$J$2:$J$9253,">="&DATE(2025,3,1),'Trial Database'!$J$2:$J$9253,"<"&DATE(2025,4,1),'Trial Database'!$E$2:$E$9253,"Phase 3") -> 80 | H32: =COUNTIFS('Trial Database'!$J$2:$J$9253,">="&DATE(2025,3,1),'Trial Database'!$J$2:$J$9253,"<"&DATE(2025,4,1),'Trial Database'!$E$2:$E$9253,"Phase 4") -> 9 | I32: =SUM(B32:H32) -> 377 | J32: =DAY(EOMONTH(A32,0)) -> 31 | K32: =IF(J32=0,0,I32/J32) -> 12.16129
A33: 45748 | B33: =COUNTIFS('Trial Database'!$J$2:$J$9253,">="&DATE(2025,4,1),'Trial Database'!$J$2:$J$9253,"<"&DATE(2025,5,1),'Trial Database'!$E$2:$E$9253,"Early Phase 1") -> 2 | C33: =COUNTIFS('Trial Database'!$J$2:$J$9253,">="&DATE(2025,4,1),'Trial Database'!$J$2:$J$9253,"<"&DATE(2025,5,1),'Trial Database'!$E$2:$E$9253,"Phase 1") -> 140 | D33: =COUNTIFS('Trial Database'!$J$2:$J$9253,">="&DATE(2025,4,1),'Trial Database'!$J$2:$J$9253,"<"&DATE(2025,5,1),'Trial Database'!$E$2:$E$9253,"Phase 1/2") -> 47 | E33: =COUNTIFS('Trial Database'!$J$2:$J$9253,">="&DATE(2025,4,1),'Trial Database'!$J$2:$J$9253,"<"&DATE(2025,5,1),'Trial Database'!$E$2:$E$9253,"Phase 2") -> 78 | F33: =COUNTIFS('Trial Database'!$J$2:$J$9253,">="&DATE(2025,4,1),'Trial Database'!$J$2:$J$9253,"<"&DATE(2025,5,1),'Trial Database'!$E$2:$E$9253,"Phase 2/3") -> 8 | G33: =COUNTIFS('Trial Database'!$J$2:$J$9253,">="&DATE(2025,4,1),'Trial Database'!$J$2:$J$9253,"<"&DATE(2025,5,1),'Trial Database'!$E$2:$E$9253,"Phase 3") -> 77 | H33: =COUNTIFS('Trial Database'!$J$2:$J$9253,">="&DATE(2025,4,1),'Trial Database'!$J$2:$J$9253,"<"&DATE(2025,5,1),'Trial Database'!$E$2:$E$9253,"Phase 4") -> 7 | I33: =SUM(B33:H33) -> 359 | J33: =DAY(EOMONTH(A33,0)) -> 30 | K33: =IF(J33=0,0,I33/J33) -> 11.966667
A34: 45778 | B34: =COUNTIFS('Trial Database'!$J$2:$J$9253,">="&DATE(2025,5,1),'Trial Database'!$J$2:$J$9253,"<"&DATE(2025,6,1),'Trial Database'!$E$2:$E$9253,"Early Phase 1") -> 8 | C34: =COUNTIFS('Trial Database'!$J$2:$J$9253,">="&DATE(2025,5,1),'Trial Database'!$J$2:$J$9253,"<"&DATE(2025,6,1),'Trial Database'!$E$2:$E$9253,"Phase 1") -> 157 | D34: =COUNTIFS('Trial Database'!$J$2:$J$9253,">="&DATE(2025,5,1),'Trial Database'!$J$2:$J$9253,"<"&DATE(2025,6,1),'Trial Database'!$E$2:$E$9253,"Phase 1/2") -> 39 | E34: =COUNTIFS('Trial Database'!$J$2:$J$9253,">="&DATE(2025,5,1),'Trial Database'!$J$2:$J$9253,"<"&DATE(2025,6,1),'Trial Database'!$E$2:$E$9253,"Phase 2") -> 74 | F34: =COUNTIFS('Trial Database'!$J$2:$J$9253,">="&DATE(2025,5,1),'Trial Database'!$J$2:$J$9253,"<"&DATE(2025,6,1),'Trial Database'!$E$2:$E$9253,"Phase 2/3") -> 7 | G34: =COUNTIFS('Trial Database'!$J$2:$J$9253,">="&DATE(2025,5,1),'Trial Database'!$J$2:$J$9253,"<"&DATE(2025,6,1),'Trial Database'!$E$2:$E$9253,"Phase 3") -> 64 | H34: =COUNTIFS('Trial Database'!$J$2:$J$9253,">="&DATE(2025,5,1),'Trial Database'!$J$2:$J$9253,"<"&DATE(2025,6,1),'Trial Database'!$E$2:$E$9253,"Phase 4") -> 16 | I34: =SUM(B34:H34) -> 365 | J34: =DAY(EOMONTH(A34,0)) -> 31 | K34: =IF(J34=0,0,I34/J34) -> 11.774194
A35: 45809 | B35: =COUNTIFS('Trial Database'!$J$2:$J$9253,">="&DATE(2025,6,1),'Trial Database'!$J$2:$J$9253,"<"&DATE(2025,7,1),'Trial Database'!$E$2:$E$9253,"Early Phase 1") -> 9 | C35: =COUNTIFS('Trial Database'!$J$2:$J$9253,">="&DATE(2025,6,1),'Trial Database'!$J$2:$J$9253,"<"&DATE(2025,7,1),'Trial Database'!$E$2:$E$9253,"Phase 1") -> 142 | D35: =COUNTIFS('Trial Database'!$J$2:$J$9253,">="&DATE(2025,6,1),'Trial Database'!$J$2:$J$9253,"<"&DATE(2025,7,1),'Trial Database'!$E$2:$E$9253,"Phase 1/2") -> 41 | E35: =COUNTIFS('Trial Database'!$J$2:$J$9253,">="&DATE(2025,6,1),'Trial Database'!$J$2:$J$9253,"<"&DATE(2025,7,1),'Trial Database'!$E$2:$E$9253,"Phase 2") -> 90 | F35: =COUNTIFS('Trial Database'!$J$2:$J$9253,">="&DATE(2025,6,1),'Trial Database'!$J$2:$J$9253,"<"&DATE(2025,7,1),'Trial Database'!$E$2:$E$9253,"Phase 2/3") -> 8 | G35: =COUNTIFS('Trial Database'!$J$2:$J$9253,">="&DATE(2025,6,1),'Trial Database'!$J$2:$J$9253,"<"&DATE(2025,7,1),'Trial Database'!$E$2:$E$9253,"Phase 3") -> 89 | H35: =COUNTIFS('Trial Database'!$J$2:$J$9253,">="&DATE(2025,6,1),'Trial Database'!$J$2:$J$9253,"<"&DATE(2025,7,1),'Trial Database'!$E$2:$E$9253,"Phase 4") -> 10 | I35: =SUM(B35:H35) -> 389 | J35: =DAY(EOMONTH(A35,0)) -> 30 | K35: =IF(J35=0,0,I35/J35) -> 12.966667
A36: 45839 | B36: =COUNTIFS('Trial Database'!$J$2:$J$9253,">="&DATE(2025,7,1),'Trial Database'!$J$2:$J$9253,"<"&DATE(2025,8,1),'Trial Database'!$E$2:$E$9253,"Early Phase 1") -> 7 | C36: =COUNTIFS('Trial Database'!$J$2:$J$9253,">="&DATE(2025,7,1),'Trial Database'!$J$2:$J$9253,"<"&DATE(2025,8,1),'Trial Database'!$E$2:$E$9253,"Phase 1") -> 125 | D36: =COUNTIFS('Trial Database'!$J$2:$J$9253,">="&DATE(2025,7,1),'Trial Database'!$J$2:$J$9253,"<"&DATE(2025,8,1),'Trial Database'!$E$2:$E$9253,"Phase 1/2") -> 43 | E36: =COUNTIFS('Trial Database'!$J$2:$J$9253,">="&DATE(2025,7,1),'Trial Database'!$J$2:$J$9253,"<"&DATE(2025,8,1),'Trial Database'!$E$2:$E$9253,"Phase 2") -> 81 | F36: =COUNTIFS('Trial Database'!$J$2:$J$9253,">="&DATE(2025,7,1),'Trial Database'!$J$2:$J$9253,"<"&DATE(2025,8,1),'Trial Database'!$E$2:$E$9253,"Phase 2/3") -> 8 | G36: =COUNTIFS('Trial Database'!$J$2:$J$9253,">="&DATE(2025,7,1),'Trial Database'!$J$2:$J$9253,"<"&DATE(2025,8,1),'Trial Database'!$E$2:$E$9253,"Phase 3") -> 86 | H36: =COUNTIFS('Trial Database'!$J$2:$J$9253,">="&DATE(2025,7,1),'Trial Database'!$J$2:$J$9253,"<"&DATE(2025,8,1),'Trial Database'!$E$2:$E$9253,"Phase 4") -> 21 | I36: =SUM(B36:H36) -> 371 | J36: =DAY(EOMONTH(A36,0)) -> 31 | K36: =IF(J36=0,0,I36/J36) -> 11.967742
A37: 45870 | B37: =COUNTIFS('Trial Database'!$J$2:$J$9253,">="&DATE(2025,8,1),'Trial Database'!$J$2:$J$9253,"<"&DATE(2025,9,1),'Trial Database'!$E$2:$E$9253,"Early Phase 1") -> 7 | C37: =COUNTIFS('Trial Database'!$J$2:$J$9253,">="&DATE(2025,8,1),'Trial Database'!$J$2:$J$9253,"<"&DATE(2025,9,1),'Trial Database'!$E$2:$E$9253,"Phase 1") -> 144 | D37: =COUNTIFS('Trial Database'!$J$2:$J$9253,">="&DATE(2025,8,1),'Trial Database'!$J$2:$J$9253,"<"&DATE(2025,9,1),'Trial Database'!$E$2:$E$9253,"Phase 1/2") -> 38 | E37: =COUNTIFS('Trial Database'!$J$2:$J$9253,">="&DATE(2025,8,1),'Trial Database'!$J$2:$J$9253,"<"&DATE(2025,9,1),'Trial Database'!$E$2:$E$9253,"Phase 2") -> 112 | F37: =COUNTIFS('Trial Database'!$J$2:$J$9253,">="&DATE(2025,8,1),'Trial Database'!$J$2:$J$9253,"<"&DATE(2025,9,1),'Trial Database'!$E$2:$E$9253,"Phase 2/3") -> 7 | G37: =COUNTIFS('Trial Database'!$J$2:$J$9253,">="&DATE(2025,8,1),'Trial Database'!$J$2:$J$9253,"<"&DATE(2025,9,1),'Trial Database'!$E$2:$E$9253,"Phase 3") -> 72 | H37: =COUNTIFS('Trial Database'!$J$2:$J$9253,">="&DATE(2025,8,1),'Trial Database'!$J$2:$J$9253,"<"&DATE(2025,9,1),'Trial Database'!$E$2:$E$9253,"Phase 4") -> 14 | I37: =SUM(B37:H37) -> 394 | J37: =DAY(EOMONTH(A37,0)) -> 31 | K37: =IF(J37=0,0,I37/J37) -> 12.709677
A38: 45901 | B38: =COUNTIFS('Trial Database'!$J$2:$J$9253,">="&DATE(2025,9,1),'Trial Database'!$J$2:$J$9253,"<"&DATE(2025,10,1),'Trial Database'!$E$2:$E$9253,"Early Phase 1") -> 13 | C38: =COUNTIFS('Trial Database'!$J$2:$J$9253,">="&DATE(2025,9,1),'Trial Database'!$J$2:$J$9253,"<"&DATE(2025,10,1),'Trial Database'!$E$2:$E$9253,"Phase 1") -> 107 | D38: =COUNTIFS('Trial Database'!$J$2:$J$9253,">="&DATE(2025,9,1),'Trial Database'!$J$2:$J$9253,"<"&DATE(2025,10,1),'Trial Database'!$E$2:$E$9253,"Phase 1/2") -> 41 | E38: =COUNTIFS('Trial Database'!$J$2:$J$9253,">="&DATE(2025,9,1),'Trial Database'!$J$2:$J$9253,"<"&DATE(2025,10,1),'Trial Database'!$E$2:$E$9253,"Phase 2") -> 93 | F38: =COUNTIFS('Trial Database'!$J$2:$J$9253,">="&DATE(2025,9,1),'Trial Database'!$J$2:$J$9253,"<"&DATE(2025,10,1),'Trial Database'!$E$2:$E$9253,"Phase 2/3") -> 9 | G38: =COUNTIFS('Trial Database'!$J$2:$J$9253,">="&DATE(2025,9,1),'Trial Database'!$J$2:$J$9253,"<"&DATE(2025,10,1),'Trial Database'!$E$2:$E$9253,"Phase 3") -> 82 | H38: =COUNTIFS('Trial Database'!$J$2:$J$9253,">="&DATE(2025,9,1),'Trial Database'!$J$2:$J$9253,"<"&DATE(2025,10,1),'Trial Database'!$E$2:$E$9253,"Phase 4") -> 14 | I38: =SUM(B38:H38) -> 359 | J38: =DAY(EOMONTH(A38,0)) -> 30 | K38: =IF(J38=0,0,I38/J38) -> 11.966667
A39: 45931 | B39: =COUNTIFS('Trial Database'!$J$2:$J$9253,">="&DATE(2025,10,1),'Trial Database'!$J$2:$J$9253,"<"&DATE(2025,11,1),'Trial Database'!$E$2:$E$9253,"Early Phase 1") -> 6 | C39: =COUNTIFS('Trial Database'!$J$2:$J$9253,">="&DATE(2025,10,1),'Trial Database'!$J$2:$J$9253,"<"&DATE(2025,11,1),'Trial Database'!$E$2:$E$9253,"Phase 1") -> 136 | D39: =COUNTIFS('Trial Database'!$J$2:$J$9253,">="&DATE(2025,10,1),'Trial Database'!$J$2:$J$9253,"<"&DATE(2025,11,1),'Trial Database'!$E$2:$E$9253,"Phase 1/2") -> 43 | E39: =COUNTIFS('Trial Database'!$J$2:$J$9253,">="&DATE(2025,10,1),'Trial Database'!$J$2:$J$9253,"<"&DATE(2025,11,1),'Trial Database'!$E$2:$E$9253,"Phase 2") -> 83 | F39: =COUNTIFS('Trial Database'!$J$2:$J$9253,">="&DATE(2025,10,1),'Trial Database'!$J$2:$J$9253,"<"&DATE(2025,11,1),'Trial Database'!$E$2:$E$9253,"Phase 2/3") -> 8 | G39: =COUNTIFS('Trial Database'!$J$2:$J$9253,">="&DATE(2025,10,1),'Trial Database'!$J$2:$J$9253,"<"&DATE(2025,11,1),'Trial Database'!$E$2:$E$9253,"Phase 3") -> 76 | H39: =COUNTIFS('Trial Database'!$J$2:$J$9253,">="&DATE(2025,10,1),'Trial Database'!$J$2:$J$9253,"<"&DATE(2025,11,1),'Trial Database'!$E$2:$E$9253,"Phase 4") -> 8 | I39: =SUM(B39:H39) -> 360 | J39: =DAY(EOMONTH(A39,0)) -> 31 | K39: =IF(J39=0,0,I39/J39) -> 11.612903
A40: 45962 | B40: =COUNTIFS('Trial Database'!$J$2:$J$9253,">="&DATE(2025,11,1),'Trial Database'!$J$2:$J$9253,"<"&DATE(2025,12,1),'Trial Database'!$E$2:$E$9253,"Early Phase 1") -> 6 | C40: =COUNTIFS('Trial Database'!$J$2:$J$9253,">="&DATE(2025,11,1),'Trial Database'!$J$2:$J$9253,"<"&DATE(2025,12,1),'Trial Database'!$E$2:$E$9253,"Phase 1") -> 124 | D40: =COUNTIFS('Trial Database'!$J$2:$J$9253,">="&DATE(2025,11,1),'Trial Database'!$J$2:$J$9253,"<"&DATE(2025,12,1),'Trial Database'!$E$2:$E$9253,"Phase 1/2") -> 31 | E40: =COUNTIFS('Trial Database'!$J$2:$J$9253,">="&DATE(2025,11,1),'Trial Database'!$J$2:$J$9253,"<"&DATE(2025,12,1),'Trial Database'!$E$2:$E$9253,"Phase 2") -> 75 | F40: =COUNTIFS('Trial Database'!$J$2:$J$9253,">="&DATE(2025,11,1),'Trial Database'!$J$2:$J$9253,"<"&DATE(2025,12,1),'Trial Database'!$E$2:$E$9253,"Phase 2/3") -> 4 | G40: =COUNTIFS('Trial Database'!$J$2:$J$9253,">="&DATE(2025,11,1),'Trial Database'!$J$2:$J$9253,"<"&DATE(2025,12,1),'Trial Database'!$E$2:$E$9253,"Phase 3") -> 74 | H40: =COUNTIFS('Trial Database'!$J$2:$J$9253,">="&DATE(2025,11,1),'Trial Database'!$J$2:$J$9253,"<"&DATE(2025,12,1),'Trial Database'!$E$2:$E$9253,"Phase 4") -> 13 | I40: =SUM(B40:H40) -> 327 | J40: =DAY(EOMONTH(A40,0)) -> 30 | K40: =IF(J40=0,0,I40/J40) -> 10.9
A41: 45992 | B41: =COUNTIFS('Trial Database'!$J$2:$J$9253,">="&DATE(2025,12,1),'Trial Database'!$J$2:$J$9253,"<"&DATE(2025,13,1),'Trial Database'!$E$2:$E$9253,"Early Phase 1") -> 13 | C41: =COUNTIFS('Trial Database'!$J$2:$J$9253,">="&DATE(2025,12,1),'Trial Database'!$J$2:$J$9253,"<"&DATE(2025,13,1),'Trial Database'!$E$2:$E$9253,"Phase 1") -> 169 | D41: =COUNTIFS('Trial Database'!$J$2:$J$9253,">="&DATE(2025,12,1),'Trial Database'!$J$2:$J$9253,"<"&DATE(2025,13,1),'Trial Database'!$E$2:$E$9253,"Phase 1/2") -> 54 | E41: =COUNTIFS('Trial Database'!$J$2:$J$9253,">="&DATE(2025,12,1),'Trial Database'!$J$2:$J$9253,"<"&DATE(2025,13,1),'Trial Database'!$E$2:$E$9253,"Phase 2") -> 123 | F41: =COUNTIFS('Trial Database'!$J$2:$J$9253,">="&DATE(2025,12,1),'Trial Database'!$J$2:$J$9253,"<"&DATE(2025,13,1),'Trial Database'!$E$2:$E$9253,"Phase 2/3") -> 12 | G41: =COUNTIFS('Trial Database'!$J$2:$J$9253,">="&DATE(2025,12,1),'Trial Database'!$J$2:$J$9253,"<"&DATE(2025,13,1),'Trial Database'!$E$2:$E$9253,"Phase 3") -> 91 | H41: =COUNTIFS('Trial Database'!$J$2:$J$9253,">="&DATE(2025,12,1),'Trial Database'!$J$2:$J$9253,"<"&DATE(2025,13,1),'Trial Database'!$E$2:$E$9253,"Phase 4") -> 13 | I41: =SUM(B41:H41) -> 475 | J41: =DAY(EOMONTH(A41,0)) -> 31 | K41: =IF(J41=0,0,I41/J41) -> 15.322581
A42: 46023 | B42: =COUNTIFS('Trial Database'!$J$2:$J$9253,">="&DATE(2026,1,1),'Trial Database'!$J$2:$J$9253,"<"&DATE(2026,2,1),'Trial Database'!$E$2:$E$9253,"Early Phase 1") -> 4 | C42: =COUNTIFS('Trial Database'!$J$2:$J$9253,">="&DATE(2026,1,1),'Trial Database'!$J$2:$J$9253,"<"&DATE(2026,2,1),'Trial Database'!$E$2:$E$9253,"Phase 1") -> 147 | D42: =COUNTIFS('Trial Database'!$J$2:$J$9253,">="&DATE(2026,1,1),'Trial Database'!$J$2:$J$9253,"<"&DATE(2026,2,1),'Trial Database'!$E$2:$E$9253,"Phase 1/2") -> 59 | E42: =COUNTIFS('Trial Database'!$J$2:$J$9253,">="&DATE(2026,1,1),'Trial Database'!$J$2:$J$9253,"<"&DATE(2026,2,1),'Trial Database'!$E$2:$E$9253,"Phase 2") -> 87 | F42: =COUNTIFS('Trial Database'!$J$2:$J$9253,">="&DATE(2026,1,1),'Trial Database'!$J$2:$J$9253,"<"&DATE(2026,2,1),'Trial Database'!$E$2:$E$9253,"Phase 2/3") -> 11 | G42: =COUNTIFS('Trial Database'!$J$2:$J$9253,">="&DATE(2026,1,1),'Trial Database'!$J$2:$J$9253,"<"&DATE(2026,2,1),'Trial Database'!$E$2:$E$9253,"Phase 3") -> 81 | H42: =COUNTIFS('Trial Database'!$J$2:$J$9253,">="&DATE(2026,1,1),'Trial Database'!$J$2:$J$9253,"<"&DATE(2026,2,1),'Trial Database'!$E$2:$E$9253,"Phase 4") -> 14 | I42: =SUM(B42:H42) -> 403 | J42: =DAY(EOMONTH(A42,0)) -> 31 | K42: =IF(J42=0,0,I42/J42) -> 13
A43: 46054 | B43: =COUNTIFS('Trial Database'!$J$2:$J$9253,">="&DATE(2026,2,1),'Trial Database'!$J$2:$J$9253,"<"&DATE(2026,3,1),'Trial Database'!$E$2:$E$9253,"Early Phase 1") -> 11 | C43: =COUNTIFS('Trial Database'!$J$2:$J$9253,">="&DATE(2026,2,1),'Trial Database'!$J$2:$J$9253,"<"&DATE(2026,3,1),'Trial Database'!$E$2:$E$9253,"Phase 1") -> 105 | D43: =COUNTIFS('Trial Database'!$J$2:$J$9253,">="&DATE(2026,2,1),'Trial Database'!$J$2:$J$9253,"<"&DATE(2026,3,1),'Trial Database'!$E$2:$E$9253,"Phase 1/2") -> 52 | E43: =COUNTIFS('Trial Database'!$J$2:$J$9253,">="&DATE(2026,2,1),'Trial Database'!$J$2:$J$9253,"<"&DATE(2026,3,1),'Trial Database'!$E$2:$E$9253,"Phase 2") -> 86 | F43: =COUNTIFS('Trial Database'!$J$2:$J$9253,">="&DATE(2026,2,1),'Trial Database'!$J$2:$J$9253,"<"&DATE(2026,3,1),'Trial Database'!$E$2:$E$9253,"Phase 2/3") -> 7 | G43: =COUNTIFS('Trial Database'!$J$2:$J$9253,">="&DATE(2026,2,1),'Trial Database'!$J$2:$J$9253,"<"&DATE(2026,3,1),'Trial Database'!$E$2:$E$9253,"Phase 3") -> 71 | H43: =COUNTIFS('Trial Database'!$J$2:$J$9253,">="&DATE(2026,2,1),'Trial Database'!$J$2:$J$9253,"<"&DATE(2026,3,1),'Trial Database'!$E$2:$E$9253,"Phase 4") -> 12 | I43: =SUM(B43:H43) -> 344 | J43: =DAY(EOMONTH(A43,0)) -> 28 | K43: =IF(J43=0,0,I43/J43) -> 12.285714

Sheet Summary Statistics - Enrollment
A1: Year | B1: Early Phase 1 | C1: Phase 1 | D1: Phase 1/2 | E1: Phase 2 | F1: Phase 2/3 | G1: Phase 3 | H1: Phase 4 | I1: Total
A2: 2024 | B2: =SUMIFS('Trial Database'!$H$2:$H$9253,'Trial Database'!$J$2:$J$9253,">="&DATE(2024,1,1),'Trial Database'!$J$2:$J$9253,"<"&DATE(2025,1,1),'Trial Database'!$E$2:$E$9253,"Early Phase 1") -> 2488 | C2: =SUMIFS('Trial Database'!$H$2:$H$9253,'Trial Database'!$J$2:$J$9253,">="&DATE(2024,1,1),'Trial Database'!$J$2:$J$9253,"<"&DATE(2025,1,1),'Trial Database'!$E$2:$E$9253,"Phase 1") -> 116152 | D2: =SUMIFS('Trial Database'!$H$2:$H$9253,'Trial Database'!$J$2:$J$9253,">="&DATE(2024,1,1),'Trial Database'!$J$2:$J$9253,"<"&DATE(2025,1,1),'Trial Database'!$E$2:$E$9253,"Phase 1/2") -> 54047 | E2: =SUMIFS('Trial Database'!$H$2:$H$9253,'Trial Database'!$J$2:$J$9253,">="&DATE(2024,1,1),'Trial Database'!$J$2:$J$9253,"<"&DATE(2025,1,1),'Trial Database'!$E$2:$E$9253,"Phase 2") -> 149047 | F2: =SUMIFS('Trial Database'!$H$2:$H$9253,'Trial Database'!$J$2:$J$9253,">="&DATE(2024,1,1),'Trial Database'!$J$2:$J$9253,"<"&DATE(2025,1,1),'Trial Database'!$E$2:$E$9253,"Phase 2/3") -> 28947 | G2: =SUMIFS('Trial Database'!$H$2:$H$9253,'Trial Database'!$J$2:$J$9253,">="&DATE(2024,1,1),'Trial Database'!$J$2:$J$9253,"<"&DATE(2025,1,1),'Trial Database'!$E$2:$E$9253,"Phase 3") -> 560365 | H2: =SUMIFS('Trial Database'!$H$2:$H$9253,'Trial Database'!$J$2:$J$9253,">="&DATE(2024,1,1),'Trial Database'!$J$2:$J$9253,"<"&DATE(2025,1,1),'Trial Database'!$E$2:$E$9253,"Phase 4") -> 96419 | I2: =SUM(B2:H2) -> 1007465
A3: 2025 | B3: =SUMIFS('Trial Database'!$H$2:$H$9253,'Trial Database'!$J$2:$J$9253,">="&DATE(2025,1,1),'Trial Database'!$J$2:$J$9253,"<"&DATE(2026,1,1),'Trial Database'!$E$2:$E$9253,"Early Phase 1") -> 2595 | C3: =SUMIFS('Trial Database'!$H$2:$H$9253,'Trial Database'!$J$2:$J$9253,">="&DATE(2025,1,1),'Trial Database'!$J$2:$J$9253,"<"&DATE(2026,1,1),'Trial Database'!$E$2:$E$9253,"Phase 1") -> 111734 | D3: =SUMIFS('Trial Database'!$H$2:$H$9253,'Trial Database'!$J$2:$J$9253,">="&DATE(2025,1,1),'Trial Database'!$J$2:$J$9253,"<"&DATE(2026,1,1),'Trial Database'!$E$2:$E$9253,"Phase 1/2") -> 70043 | E3: =SUMIFS('Trial Database'!$H$2:$H$9253,'Trial Database'!$J$2:$J$9253,">="&DATE(2025,1,1),'Trial Database'!$J$2:$J$9253,"<"&DATE(2026,1,1),'Trial Database'!$E$2:$E$9253,"Phase 2") -> 145973 | F3: =SUMIFS('Trial Database'!$H$2:$H$9253,'Trial Database'!$J$2:$J$9253,">="&DATE(2025,1,1),'Trial Database'!$J$2:$J$9253,"<"&DATE(2026,1,1),'Trial Database'!$E$2:$E$9253,"Phase 2/3") -> 37515 | G3: =SUMIFS('Trial Database'!$H$2:$H$9253,'Trial Database'!$J$2:$J$9253,">="&DATE(2025,1,1),'Trial Database'!$J$2:$J$9253,"<"&DATE(2026,1,1),'Trial Database'!$E$2:$E$9253,"Phase 3") -> 675336 | H3: =SUMIFS('Trial Database'!$H$2:$H$9253,'Trial Database'!$J$2:$J$9253,">="&DATE(2025,1,1),'Trial Database'!$J$2:$J$9253,"<"&DATE(2026,1,1),'Trial Database'!$E$2:$E$9253,"Phase 4") -> 134761 | I3: =SUM(B3:H3) -> 1177957
A4: 2026 | B4: =SUMIFS('Trial Database'!$H$2:$H$9253,'Trial Database'!$J$2:$J$9253,">="&DATE(2026,1,1),'Trial Database'!$J$2:$J$9253,"<"&DATE(2027,1,1),'Trial Database'!$E$2:$E$9253,"Early Phase 1") -> 843 | C4: =SUMIFS('Trial Database'!$H$2:$H$9253,'Trial Database'!$J$2:$J$9253,">="&DATE(2026,1,1),'Trial Database'!$J$2:$J$9253,"<"&DATE(2027,1,1),'Trial Database'!$E$2:$E$9253,"Phase 1") -> 16339 | D4: =SUMIFS('Trial Database'!$H$2:$H$9253,'Trial Database'!$J$2:$J$9253,">="&DATE(2026,1,1),'Trial Database'!$J$2:$J$9253,"<"&DATE(2027,1,1),'Trial Database'!$E$2:$E$9253,"Phase 1/2") -> 14042 | E4: =SUMIFS('Trial Database'!$H$2:$H$9253,'Trial Database'!$J$2:$J$9253,">="&DATE(2026,1,1),'Trial Database'!$J$2:$J$9253,"<"&DATE(2027,1,1),'Trial Database'!$E$2:$E$9253,"Phase 2") -> 24094 | F4: =SUMIFS('Trial Database'!$H$2:$H$9253,'Trial Database'!$J$2:$J$9253,">="&DATE(2026,1,1),'Trial Database'!$J$2:$J$9253,"<"&DATE(2027,1,1),'Trial Database'!$E$2:$E$9253,"Phase 2/3") -> 6968 | G4: =SUMIFS('Trial Database'!$H$2:$H$9253,'Trial Database'!$J$2:$J$9253,">="&DATE(2026,1,1),'Trial Database'!$J$2:$J$9253,"<"&DATE(2027,1,1),'Trial Database'!$E$2:$E$9253,"Phase 3") -> 71173 | H4: =SUMIFS('Trial Database'!$H$2:$H$9253,'Trial Database'!$J$2:$J$9253,">="&DATE(2026,1,1),'Trial Database'!$J$2:$J$9253,"<"&DATE(2027,1,1),'Trial Database'!$E$2:$E$9253,"Phase 4") -> 4921 | I4: =SUM(B4:H4) -> 138380
A5: 2026 Annualized | B5: =ROUND(B4*12/MONTH(EOMONTH(TODAY(),-1)),0) -> 5058 | C5: =ROUND(C4*12/MONTH(EOMONTH(TODAY(),-1)),0) -> 98034 | D5: =ROUND(D4*12/MONTH(EOMONTH(TODAY(),-1)),0) -> 84252 | E5: =ROUND(E4*12/MONTH(EOMONTH(TODAY(),-1)),0) -> 144564 | F5: =ROUND(F4*12/MONTH(EOMONTH(TODAY(),-1)),0) -> 41808 | G5: =ROUND(G4*12/MONTH(EOMONTH(TODAY(),-1)),0) -> 427038 | H5: =ROUND(H4*12/MONTH(EOMONTH(TODAY(),-1)),0) -> 29526 | I5: =SUM(B5:H5) -> 830280
A8: Rolling Metrics | B8: Value
A9: T12M (Mar 2025 – Feb 2026) | B9: 1203920
A10: T12M Prior (Mar 2024 – Feb 2025) | B10: 1011935
A11: T12M vs T12M Prior % | B11: 0.18972068
A12: YoY % enroll/day (Feb 2026 vs Feb 2025) | B12: 0.0024014899
A13: MoM % enroll/day (Feb 2026 vs Jan 2026) | B13: -0.11799148
A14: MoM Prior % enroll/day (Jan 2026 vs Dec 2025) | B14: -0.5184472
A17: Month | B17: Early Phase 1 | C17: Phase 1 | D17: Phase 1/2 | E17: Phase 2 | F17: Phase 2/3 | G17: Phase 3 | H17: Phase 4 | I17: Total | J17: Days | K17: Enroll/Day
A18: 45292 | B18: =SUMIFS('Trial Database'!$H$2:$H$9253,'Trial Database'!$J$2:$J$9253,">="&DATE(2024,1,1),'Trial Database'!$J$2:$J$9253,"<"&DATE(2024,2,1),'Trial Database'!$E$2:$E$9253,"Early Phase 1") -> 189 | C18: =SUMIFS('Trial Database'!$H$2:$H$9253,'Trial Database'!$J$2:$J$9253,">="&DATE(2024,1,1),'Trial Database'!$J$2:$J$9253,"<"&DATE(2024,2,1),'Trial Database'!$E$2:$E$9253,"Phase 1") -> 9940 | D18: =SUMIFS('Trial Database'!$H$2:$H$9253,'Trial Database'!$J$2:$J$9253,">="&DATE(2024,1,1),'Trial Database'!$J$2:$J$9253,"<"&DATE(2024,2,1),'Trial Database'!$E$2:$E$9253,"Phase 1/2") -> 3557 | E18: =SUMIFS('Trial Database'!$H$2:$H$9253,'Trial Database'!$J$2:$J$9253,">="&DATE(2024,1,1),'Trial Database'!$J$2:$J$9253,"<"&DATE(2024,2,1),'Trial Database'!$E$2:$E$9253,"Phase 2") -> 8163 | F18: =SUMIFS('Trial Database'!$H$2:$H$9253,'Trial Database'!$J$2:$J$9253,">="&DATE(2024,1,1),'Trial Database'!$J$2:$J$9253,"<"&DATE(2024,2,1),'Trial Database'!$E$2:$E$9253,"Phase 2/3") -> 2219 | G18: =SUMIFS('Trial Database'!$H$2:$H$9253,'Trial Database'!$J$2:$J$9253,">="&DATE(2024,1,1),'Trial Database'!$J$2:$J$9253,"<"&DATE(2024,2,1),'Trial Database'!$E$2:$E$9253,"Phase 3") -> 21448 | H18: =SUMIFS('Trial Database'!$H$2:$H$9253,'Trial Database'!$J$2:$J$9253,">="&DATE(2024,1,1),'Trial Database'!$J$2:$J$9253,"<"&DATE(2024,2,1),'Trial Database'!$E$2:$E$9253,"Phase 4") -> 9366 | I18: =SUM(B18:H18) -> 54882 | J18: =DAY(EOMONTH(A18,0)) -> 31 | K18: =IF(J18=0,0,I18/J18) -> 1770.3871
A19: 45323 | B19: =SUMIFS('Trial Database'!$H$2:$H$9253,'Trial Database'!$J$2:$J$9253,">="&DATE(2024,2,1),'Trial Database'!$J$2:$J$9253,"<"&DATE(2024,3,1),'Trial Database'!$E$2:$E$9253,"Early Phase 1") -> 22 | C19: =SUMIFS('Trial Database'!$H$2:$H$9253,'Trial Database'!$J$2:$J$9253,">="&DATE(2024,2,1),'Trial Database'!$J$2:$J$9253,"<"&DATE(2024,3,1),'Trial Database'!$E$2:$E$9253,"Phase 1") -> 6820 | D19: =SUMIFS('Trial Database'!$H$2:$H$9253,'Trial Database'!$J$2:$J$9253,">="&DATE(2024,2,1),'Trial Database'!$J$2:$J$9253,"<"&DATE(2024,3,1),'Trial Database'!$E$2:$E$9253,"Phase 1/2") -> 2804 | E19: =SUMIFS('Trial Database'!$H$2:$H$9253,'Trial Database'!$J$2:$J$9253,">="&DATE(2024,2,1),'Trial Database'!$J$2:$J$9253,"<"&DATE(2024,3,1),'Trial Database'!$E$2:$E$9253,"Phase 2") -> 11491 | F19: =SUMIFS('Trial Database'!$H$2:$H$9253,'Trial Database'!$J$2:$J$9253,">="&DATE(2024,2,1),'Trial Database'!$J$2:$J$9253,"<"&DATE(2024,3,1),'Trial Database'!$E$2:$E$9253,"Phase 2/3") -> 1734 | G19: =SUMIFS('Trial Database'!$H$2:$H$9253,'Trial Database'!$J$2:$J$9253,">="&DATE(2024,2,1),'Trial Database'!$J$2:$J$9253,"<"&DATE(2024,3,1),'Trial Database'!$E$2:$E$9253,"Phase 3") -> 29093 | H19: =SUMIFS('Trial Database'!$H$2:$H$9253,'Trial Database'!$J$2:$J$9253,">="&DATE(2024,2,1),'Trial Database'!$J$2:$J$9253,"<"&DATE(2024,3,1),'Trial Database'!$E$2:$E$9253,"Phase 4") -> 1101 | I19: =SUM(B19:H19) -> 53065 | J19: =DAY(EOMONTH(A19,0)) -> 29 | K19: =IF(J19=0,0,I19/J19) -> 1829.8276
A20: 45352 | B20: =SUMIFS('Trial Database'!$H$2:$H$9253,'Trial Database'!$J$2:$J$9253,">="&DATE(2024,3,1),'Trial Database'!$J$2:$J$9253,"<"&DATE(2024,4,1),'Trial Database'!$E$2:$E$9253,"Early Phase 1") -> 144 | C20: =SUMIFS('Trial Database'!$H$2:$H$9253,'Trial Database'!$J$2:$J$9253,">="&DATE(2024,3,1),'Trial Database'!$J$2:$J$9253,"<"&DATE(2024,4,1),'Trial Database'!$E$2:$E$9253,"Phase 1") -> 9198 | D20: =SUMIFS('Trial Database'!$H$2:$H$9253,'Trial Database'!$J$2:$J$9253,">="&DATE(2024,3,1),'Trial Database'!$J$2:$J$9253,"<"&DATE(2024,4,1),'Trial Database'!$E$2:$E$9253,"Phase 1/2") -> 3688 | E20: =SUMIFS('Trial Database'!$H$2:$H$9253,'Trial Database'!$J$2:$J$9253,">="&DATE(2024,3,1),'Trial Database'!$J$2:$J$9253,"<"&DATE(2024,4,1),'Trial Database'!$E$2:$E$9253,"Phase 2") -> 11647 | F20: =SUMIFS('Trial Database'!$H$2:$H$9253,'Trial Database'!$J$2:$J$9253,">="&DATE(2024,3,1),'Trial Database'!$J$2:$J$9253,"<"&DATE(2024,4,1),'Trial Database'!$E$2:$E$9253,"Phase 2/3") -> 1554 | G20: =SUMIFS('Trial Database'!$H$2:$H$9253,'Trial Database'!$J$2:$J$9253,">="&DATE(2024,3,1),'Trial Database'!$J$2:$J$9253,"<"&DATE(2024,4,1),'Trial Database'!$E$2:$E$9253,"Phase 3") -> 51776 | H20: =SUMIFS('Trial Database'!$H$2:$H$9253,'Trial Database'!$J$2:$J$9253,">="&DATE(2024,3,1),'Trial Database'!$J$2:$J$9253,"<"&DATE(2024,4,1),'Trial Database'!$E$2:$E$9253,"Phase 4") -> 2893 | I20: =SUM(B20:H20) -> 80900 | J20: =DAY(EOMONTH(A20,0)) -> 31 | K20: =IF(J20=0,0,I20/J20) -> 2609.6774
A21: 45383 | B21: =SUMIFS('Trial Database'!$H$2:$H$9253,'Trial Database'!$J$2:$J$9253,">="&DATE(2024,4,1),'Trial Database'!$J$2:$J$9253,"<"&DATE(2024,5,1),'Trial Database'!$E$2:$E$9253,"Early Phase 1") -> 300 | C21: =SUMIFS('Trial Database'!$H$2:$H$9253,'Trial Database'!$J$2:$J$9253,">="&DATE(2024,4,1),'Trial Database'!$J$2:$J$9253,"<"&DATE(2024,5,1),'Trial Database'!$E$2:$E$9253,"Phase 1") -> 10812 | D21: =SUMIFS('Trial Database'!$H$2:$H$9253,'Trial Database'!$J$2:$J$9253,">="&DATE(2024,4,1),'Trial Database'!$J$2:$J$9253,"<"&DATE(2024,5,1),'Trial Database'!$E$2:$E$9253,"Phase 1/2") -> 7287 | E21: =SUMIFS('Trial Database'!$H$2:$H$9253,'Trial Database'!$J$2:$J$9253,">="&DATE(2024,4,1),'Trial Database'!$J$2:$J$9253,"<"&DATE(2024,5,1),'Trial Database'!$E$2:$E$9253,"Phase 2") -> 13634 | F21: =SUMIFS('Trial Database'!$H$2:$H$9253,'Trial Database'!$J$2:$J$9253,">="&DATE(2024,4,1),'Trial Database'!$J$2:$J$9253,"<"&DATE(2024,5,1),'Trial Database'!$E$2:$E$9253,"Phase 2/3") -> 4863 | G21: =SUMIFS('Trial Database'!$H$2:$H$9253,'Trial Database'!$J$2:$J$9253,">="&DATE(2024,4,1),'Trial Database'!$J$2:$J$9253,"<"&DATE(2024,5,1),'Trial Database'!$E$2:$E$9253,"Phase 3") -> 43742 | H21: =SUMIFS('Trial Database'!$H$2:$H$9253,'Trial Database'!$J$2:$J$9253,">="&DATE(2024,4,1),'Trial Database'!$J$2:$J$9253,"<"&DATE(2024,5,1),'Trial Database'!$E$2:$E$9253,"Phase 4") -> 3096 | I21: =SUM(B21:H21) -> 83734 | J21: =DAY(EOMONTH(A21,0)) -> 30 | K21: =IF(J21=0,0,I21/J21) -> 2791.1333
A22: 45413 | B22: =SUMIFS('Trial Database'!$H$2:$H$9253,'Trial Database'!$J$2:$J$9253,">="&DATE(2024,5,1),'Trial Database'!$J$2:$J$9253,"<"&DATE(2024,6,1),'Trial Database'!$E$2:$E$9253,"Early Phase 1") -> 606 | C22: =SUMIFS('Trial Database'!$H$2:$H$9253,'Trial Database'!$J$2:$J$9253,">="&DATE(2024,5,1),'Trial Database'!$J$2:$J$9253,"<"&DATE(2024,6,1),'Trial Database'!$E$2:$E$9253,"Phase 1") -> 10536 | D22: =SUMIFS('Trial Database'!$H$2:$H$9253,'Trial Database'!$J$2:$J$9253,">="&DATE(2024,5,1),'Trial Database'!$J$2:$J$9253,"<"&DATE(2024,6,1),'Trial Database'!$E$2:$E$9253,"Phase 1/2") -> 4074 | E22: =SUMIFS('Trial Database'!$H$2:$H$9253,'Trial Database'!$J$2:$J$9253,">="&DATE(2024,5,1),'Trial Database'!$J$2:$J$9253,"<"&DATE(2024,6,1),'Trial Database'!$E$2:$E$9253,"Phase 2") -> 7299 | F22: =SUMIFS('Trial Database'!$H$2:$H$9253,'Trial Database'!$J$2:$J$9253,">="&DATE(2024,5,1),'Trial Database'!$J$2:$J$9253,"<"&DATE(2024,6,1),'Trial Database'!$E$2:$E$9253,"Phase 2/3") -> 4836 | G22: =SUMIFS('Trial Database'!$H$2:$H$9253,'Trial Database'!$J$2:$J$9253,">="&DATE(2024,5,1),'Trial Database'!$J$2:$J$9253,"<"&DATE(2024,6,1),'Trial Database'!$E$2:$E$9253,"Phase 3") -> 32472 | H22: =SUMIFS('Trial Database'!$H$2:$H$9253,'Trial Database'!$J$2:$J$9253,">="&DATE(2024,5,1),'Trial Database'!$J$2:$J$9253,"<"&DATE(2024,6,1),'Trial Database'!$E$2:$E$9253,"Phase 4") -> 3730 | I22: =SUM(B22:H22) -> 63553 | J22: =DAY(EOMONTH(A22,0)) -> 31 | K22: =IF(J22=0,0,I22/J22) -> 2050.0968
A23: 45444 | B23: =SUMIFS('Trial Database'!$H$2:$H$9253,'Trial Database'!$J$2:$J$9253,">="&DATE(2024,6,1),'Trial Database'!$J$2:$J$9253,"<"&DATE(2024,7,1),'Trial Database'!$E$2:$E$9253,"Early Phase 1") -> 104 | C23: =SUMIFS('Trial Database'!$H$2:$H$9253,'Trial Database'!$J$2:$J$9253,">="&DATE(2024,6,1),'Trial Database'!$J$2:$J$9253,"<"&DATE(2024,7,1),'Trial Database'!$E$2:$E$9253,"Phase 1") -> 11028 | D23: =SUMIFS('Trial Database'!$H$2:$H$9253,'Trial Database'!$J$2:$J$9253,">="&DATE(2024,6,1),'Trial Database'!$J$2:$J$9253,"<"&DATE(2024,7,1),'Trial Database'!$E$2:$E$9253,"Phase 1/2") -> 4967 | E23: =SUMIFS('Trial Database'!$H$2:$H$9253,'Trial Database'!$J$2:$J$9253,">="&DATE(2024,6,1),'Trial Database'!$J$2:$J$9253,"<"&DATE(2024,7,1),'Trial Database'!$E$2:$E$9253,"Phase 2") -> 8541 | F23: =SUMIFS('Trial Database'!$H$2:$H$9253,'Trial Database'!$J$2:$J$9253,">="&DATE(2024,6,1),'Trial Database'!$J$2:$J$9253,"<"&DATE(2024,7,1),'Trial Database'!$E$2:$E$9253,"Phase 2/3") -> 1280 | G23: =SUMIFS('Trial Database'!$H$2:$H$9253,'Trial Database'!$J$2:$J$9253,">="&DATE(2024,6,1),'Trial Database'!$J$2:$J$9253,"<"&DATE(2024,7,1),'Trial Database'!$E$2:$E$9253,"Phase 3") -> 42187 | H23: =SUMIFS('Trial Database'!$H$2:$H$9253,'Trial Database'!$J$2:$J$9253,">="&DATE(2024,6,1),'Trial Database'!$J$2:$J$9253,"<"&DATE(2024,7,1),'Trial Database'!$E$2:$E$9253,"Phase 4") -> 4096 | I23: =SUM(B23:H23) -> 72203 | J23: =DAY(EOMONTH(A23,0)) -> 30 | K23: =IF(J23=0,0,I23/J23) -> 2406.7667
A24: 45474 | B24: =SUMIFS('Trial Database'!$H$2:$H$9253,'Trial Database'!$J$2:$J$9253,">="&DATE(2024,7,1),'Trial Database'!$J$2:$J$9253,"<"&DATE(2024,8,1),'Trial Database'!$E$2:$E$9253,"Early Phase 1") -> 18 | C24: =SUMIFS('Trial Database'!$H$2:$H$9253,'Trial Database'!$J$2:$J$9253,">="&DATE(2024,7,1),'Trial Database'!$J$2:$J$9253,"<"&DATE(2024,8,1),'Trial Database'!$E$2:$E$9253,"Phase 1") -> 8820 | D24: =SUMIFS('Trial Database'!$H$2:$H$9253,'Trial Database'!$J$2:$J$9253,">="&DATE(2024,7,1),'Trial Database'!$J$2:$J$9253,"<"&DATE(2024,8,1),'Trial Database'!$E$2:$E$9253,"Phase 1/2") -> 2841 | E24: =SUMIFS('Trial Database'!$H$2:$H$9253,'Trial Database'!$J$2:$J$9253,">="&DATE(2024,7,1),'Trial Database'!$J$2:$J$9253,"<"&DATE(2024,8,1),'Trial Database'!$E$2:$E$9253,"Phase 2") -> 9681 | F24: =SUMIFS('Trial Database'!$H$2:$H$9253,'Trial Database'!$J$2:$J$9253,">="&DATE(2024,7,1),'Trial Database'!$J$2:$J$9253,"<"&DATE(2024,8,1),'Trial Database'!$E$2:$E$9253,"Phase 2/3") -> 809 | G24: =SUMIFS('Trial Database'!$H$2:$H$9253,'Trial Database'!$J$2:$J$9253,">="&DATE(2024,7,1),'Trial Database'!$J$2:$J$9253,"<"&DATE(2024,8,1),'Trial Database'!$E$2:$E$9253,"Phase 3") -> 62047 | H24: =SUMIFS('Trial Database'!$H$2:$H$9253,'Trial Database'!$J$2:$J$9253,">="&DATE(2024,7,1),'Trial Database'!$J$2:$J$9253,"<"&DATE(2024,8,1),'Trial Database'!$E$2:$E$9253,"Phase 4") -> 1438 | I24: =SUM(B24:H24) -> 85654 | J24: =DAY(EOMONTH(A24,0)) -> 31 | K24: =IF(J24=0,0,I24/J24) -> 2763.0323
A25: 45505 | B25: =SUMIFS('Trial Database'!$H$2:$H$9253,'Trial Database'!$J$2:$J$9253,">="&DATE(2024,8,1),'Trial Database'!$J$2:$J$9253,"<"&DATE(2024,9,1),'Trial Database'!$E$2:$E$9253,"Early Phase 1") -> 279 | C25: =SUMIFS('Trial Database'!$H$2:$H$9253,'Trial Database'!$J$2:$J$9253,">="&DATE(2024,8,1),'Trial Database'!$J$2:$J$9253,"<"&DATE(2024,9,1),'Trial Database'!$E$2:$E$9253,"Phase 1") -> 9692 | D25: =SUMIFS('Trial Database'!$H$2:$H$9253,'Trial Database'!$J$2:$J$9253,">="&DATE(2024,8,1),'Trial Database'!$J$2:$J$9253,"<"&DATE(2024,9,1),'Trial Database'!$E$2:$E$9253,"Phase 1/2") -> 3495 | E25: =SUMIFS('Trial Database'!$H$2:$H$9253,'Trial Database'!$J$2:$J$9253,">="&DATE(2024,8,1),'Trial Database'!$J$2:$J$9253,"<"&DATE(2024,9,1),'Trial Database'!$E$2:$E$9253,"Phase 2") -> 10916 | F25: =SUMIFS('Trial Database'!$H$2:$H$9253,'Trial Database'!$J$2:$J$9253,">="&DATE(2024,8,1),'Trial Database'!$J$2:$J$9253,"<"&DATE(2024,9,1),'Trial Database'!$E$2:$E$9253,"Phase 2/3") -> 2700 | G25: =SUMIFS('Trial Database'!$H$2:$H$9253,'Trial Database'!$J$2:$J$9253,">="&DATE(2024,8,1),'Trial Database'!$J$2:$J$9253,"<"&DATE(2024,9,1),'Trial Database'!$E$2:$E$9253,"Phase 3") -> 45305 | H25: =SUMIFS('Trial Database'!$H$2:$H$9253,'Trial Database'!$J$2:$J$9253,">="&DATE(2024,8,1),'Trial Database'!$J$2:$J$9253,"<"&DATE(2024,9,1),'Trial Database'!$E$2:$E$9253,"Phase 4") -> 59307 | I25: =SUM(B25:H25) -> 131694 | J25: =DAY(EOMONTH(A25,0)) -> 31 | K25: =IF(J25=0,0,I25/J25) -> 4248.1935
A26: 45536 | B26: =SUMIFS('Trial Database'!$H$2:$H$9253,'Trial Database'!$J$2:$J$9253,">="&DATE(2024,9,1),'Trial Database'!$J$2:$J$9253,"<"&DATE(2024,10,1),'Trial Database'!$E$2:$E$9253,"Early Phase 1") -> 45 | C26: =SUMIFS('Trial Database'!$H$2:$H$9253,'Trial Database'!$J$2:$J$9253,">="&DATE(2024,9,1),'Trial Database'!$J$2:$J$9253,"<"&DATE(2024,10,1),'Trial Database'!$E$2:$E$9253,"Phase 1") -> 9127 | D26: =SUMIFS('Trial Database'!$H$2:$H$9253,'Trial Database'!$J$2:$J$9253,">="&DATE(2024,9,1),'Trial Database'!$J$2:$J$9253,"<"&DATE(2024,10,1),'Trial Database'!$E$2:$E$9253,"Phase 1/2") -> 3723 | E26: =SUMIFS('Trial Database'!$H$2:$H$9253,'Trial Database'!$J$2:$J$9253,">="&DATE(2024,9,1),'Trial Database'!$J$2:$J$9253,"<"&DATE(2024,10,1),'Trial Database'!$E$2:$E$9253,"Phase 2") -> 15421 | F26: =SUMIFS('Trial Database'!$H$2:$H$9253,'Trial Database'!$J$2:$J$9253,">="&DATE(2024,9,1),'Trial Database'!$J$2:$J$9253,"<"&DATE(2024,10,1),'Trial Database'!$E$2:$E$9253,"Phase 2/3") -> 2603 | G26: =SUMIFS('Trial Database'!$H$2:$H$9253,'Trial Database'!$J$2:$J$9253,">="&DATE(2024,9,1),'Trial Database'!$J$2:$J$9253,"<"&DATE(2024,10,1),'Trial Database'!$E$2:$E$9253,"Phase 3") -> 110266 | H26: =SUMIFS('Trial Database'!$H$2:$H$9253,'Trial Database'!$J$2:$J$9253,">="&DATE(2024,9,1),'Trial Database'!$J$2:$J$9253,"<"&DATE(2024,10,1),'Trial Database'!$E$2:$E$9253,"Phase 4") -> 5010 | I26: =SUM(B26:H26) -> 146195 | J26: =DAY(EOMONTH(A26,0)) -> 30 | K26: =IF(J26=0,0,I26/J26) -> 4873.1667
A27: 45566 | B27: =SUMIFS('Trial Database'!$H$2:$H$9253,'Trial Database'!$J$2:$J$9253,">="&DATE(2024,10,1),'Trial Database'!$J$2:$J$9253,"<"&DATE(2024,11,1),'Trial Database'!$E$2:$E$9253,"Early Phase 1") -> 324 | C27: =SUMIFS('Trial Database'!$H$2:$H$9253,'Trial Database'!$J$2:$J$9253,">="&DATE(2024,10,1),'Trial Database'!$J$2:$J$9253,"<"&DATE(2024,11,1),'Trial Database'!$E$2:$E$9253,"Phase 1") -> 10304 | D27: =SUMIFS('Trial Database'!$H$2:$H$9253,'Trial Database'!$J$2:$J$9253,">="&DATE(2024,10,1),'Trial Database'!$J$2:$J$9253,"<"&DATE(2024,11,1),'Trial Database'!$E$2:$E$9253,"Phase 1/2") -> 3433 | E27: =SUMIFS('Trial Database'!$H$2:$H$9253,'Trial Database'!$J$2:$J$9253,">="&DATE(2024,10,1),'Trial Database'!$J$2:$J$9253,"<"&DATE(2024,11,1),'Trial Database'!$E$2:$E$9253,"Phase 2") -> 26679 | F27: =SUMIFS('Trial Database'!$H$2:$H$9253,'Trial Database'!$J$2:$J$9253,">="&DATE(2024,10,1),'Trial Database'!$J$2:$J$9253,"<"&DATE(2024,11,1),'Trial Database'!$E$2:$E$9253,"Phase 2/3") -> 2061 | G27: =SUMIFS('Trial Database'!$H$2:$H$9253,'Trial Database'!$J$2:$J$9253,">="&DATE(2024,10,1),'Trial Database'!$J$2:$J$9253,"<"&DATE(2024,11,1),'Trial Database'!$E$2:$E$9253,"Phase 3") -> 31120 | H27: =SUMIFS('Trial Database'!$H$2:$H$9253,'Trial Database'!$J$2:$J$9253,">="&DATE(2024,10,1),'Trial Database'!$J$2:$J$9253,"<"&DATE(2024,11,1),'Trial Database'!$E$2:$E$9253,"Phase 4") -> 3347 | I27: =SUM(B27:H27) -> 77268 | J27: =DAY(EOMONTH(A27,0)) -> 31 | K27: =IF(J27=0,0,I27/J27) -> 2492.5161
