Workbook

Sheet Primer
A1: Why Higher Credit Ratings — Quick Reference
A3: 1. Lower cost of debt | B3: Each notch typically saves 5–25 bps on issuance. AA- vs A+ is roughly 10–20 bps. On LLY's $42.5B debt stack, 10 bps = ~$42M/year on a fully refinanced book.
A4: 2. Broader investor base | B4: Insurance general accounts, pensions, and tiered IG mandates favor AA paper. Bigger order books, tighter pricing on jumbo deals.
A5: 3. CP & short-term funding access | B5: AA-tier issuers get better CP tiering and remain accessible during stress. LLY had $0 CP at YE25 (vs $4.3B YE24), but optionality has value.
A6: 4. Counterparty / operational | B6: Lower ISDA collateral on FX hedges (LLY has EUR/GBP/JPY/CHF debt), better trade finance, lower D&O insurance.
A7: 5. M&A firepower | B7: AA rating allows absorbing a 1–2 notch downgrade post-deal while staying solidly IG — critical for biopharma's episodic mega-deals.
A8: 6. Signaling | B8: Third-party validation of capital allocation discipline. For LLY, AA- signals S&P views the incretin franchise as durable enough for AA-category underwriting.
A9: Why most pharma stops at A/A- | B9: Going above AA- requires very low leverage (<1.0x), leaving capital underdeployed. Interest savings AA- → AA are only 5–10 bps vs. large opportunity cost. Most peers (PFE, MRK, ABBV, BMY, AMGN, GILD) target A/A-. LLY's AA- is unusual and reflects incretin EBITDA outpacing debt.

Sheet EBITDA Bridge
A1: Deriving 2026E EBITDA from LLY Guidance — Two Methods
A2: Source: Q1 2026 earnings release (4/30/2026), Q4 2025 8-K guidance schedule
A4: LLY 2026 Full-Year Guidance (raised Q1 2026)
A5: Metric | B5: Low | C5: High | D5: Midpoint | E5: Source / Note
A6: Revenue ($M) | B6: 82000 | C6: 85000 | D6: =AVERAGE(B6:C6) -> 83500 | E6: Q1'26 raised from $80–83B prior
A7: Non-GAAP Performance Margin | B7: 0.47 | C7: 0.485 | D7: =AVERAGE(B7:C7) -> 0.4775 | E7: Excludes amortization of intangibles per LLY definition
A8: Non-GAAP EPS | B8: 35.5 | C8: 37 | D8: =AVERAGE(B8:C8) -> 36.25 | E8: Q1'26 raised from $33.50–35.00 prior
A9: Diluted shares (M) | B9: 894 | C9: 894 | D9: =AVERAGE(B9:C9) -> 894 | E9: Per Q4'25 guidance schedule
A10: Effective tax rate (non-GAAP) | B10: 0.15 | C10: 0.16 | D10: =AVERAGE(B10:C10) -> 0.155 | E10: LLY-disclosed range; held flat in Q1'26 update
A12: D&A Assumption
A13: Total D&A FY2026E ($M) | B13: 2200 | C13: H1'25 D&A was $941M, Q1'25 was $463M annualizing to ~$1.85B; ramping with capex build
A14: Amortization of intangibles ($M) | B14: 540 | C14: Per LLY non-GAAP recon: ~$124–136M/quarter pre-tax = ~$540M annual
A15: Depreciation only ($M) | B15: =B13-B14 -> 1660 | C15: Implied: total D&A less intangibles amort
A17: Method 1: Top-Down — Revenue × Performance Margin → EBIT(non-GAAP) → EBITDA
A18: Build | B18: Low | C18: High | D18: Midpoint | E18: Logic
A19: Revenue | B19: =B6 -> 82000 | C19: =C6 -> 85000 | D19: =D6 -> 83500 | E19: From guidance row 6
A20: × Performance margin | B20: =B7 -> 0.47 | C20: =C7 -> 0.485 | D20: =D7 -> 0.4775 | E20: From guidance row 7
A21: = Non-GAAP operating income (EBIT, ex-amort) | B21: =B19*B20 -> 38540 | C21: =C19*C20 -> 41225 | D21: =D19*D20 -> 39871.25 | E21: Approximation of non-GAAP EBIT
A22: + Depreciation | B22: =$B$15 -> 1660 | C22: =$B$15 -> 1660 | D22: =$B$15 -> 1660 | E22: Already excluded from perf margin? NO — perf margin includes COGS/opex which include depreciation. Add back below.
A23: = EBITDA (non-GAAP, ex-intangibles-amort) | B23: =B21+B22 -> 40200 | C23: =C21+C22 -> 42885 | D23: =D21+D22 -> 41531.25 | E23: This is the cleanest 'cash EBITDA' figure
A24: + Amortization of intangibles | B24: =$B$14 -> 540 | C24: =$B$14 -> 540 | D24: =$B$14 -> 540 | E24: Add back to get GAAP EBITDA equivalent
A25: = EBITDA (GAAP-equivalent) | B25: =B23+B24 -> 40740 | C25: =C23+C24 -> 43425 | D25: =D23+D24 -> 42071.25 | E25: EBITDA most commonly cited by rating agencies
A27: Method 2: Bottom-Up — Non-GAAP EPS → Net Income → EBIT → EBITDA
A28: Build | B28: Low | C28: High | D28: Midpoint | E28: Logic
A29: Interest expense ($M) | B29: 900 | C29: Estimate ~2.1% blended rate × $42.5B debt
A30: Non-GAAP EPS ($) | B30: =B8 -> 35.5 | C30: =C8 -> 37 | D30: =D8 -> 36.25 | E30: From guidance
A31: × Diluted shares (M) | B31: =B9 -> 894 | C31: =C9 -> 894 | D31: =D9 -> 894 | E31: From guidance
A32: = Non-GAAP net income | B32: =B30*B31 -> 31737 | C32: =C30*C31 -> 33078 | D32: =D30*D31 -> 32407.5
A33: ÷ (1 − tax rate) | B33: =1-B10 -> 0.85 | C33: =1-C10 -> 0.84 | D33: =1-D10 -> 0.845
A34: = Non-GAAP pre-tax income | B34: =B32/B33 -> 37337.647 | C34: =C32/C33 -> 39378.571 | D34: =D32/D33 -> 38352.071
A35: + Interest expense | B35: =$B$29 -> 900 | C35: =$B$29 -> 900 | D35: =$B$29 -> 900 | E35: Add back to derive EBIT
A36: = EBIT (non-GAAP) | B36: =B34+B35 -> 38237.647 | C36: =C34+C35 -> 40278.571 | D36: =D34+D35 -> 39252.071
A37: + D&A (total) | B37: =$B$13 -> 2200 | C37: =$B$13 -> 2200 | D37: =$B$13 -> 2200 | E37: Includes intangibles amort to match GAAP EBITDA
A38: = EBITDA (GAAP-equivalent) | B38: =B36+B37 -> 40437.647 | C38: =C36+C37 -> 42478.571 | D38: =D36+D37 -> 41452.071 | E38: Cross-check against Method 1 row 25
A40: Triangulation — Final EBITDA for Firepower Analysis
A41: Method 1 — Top-down EBITDA (midpoint) | B41: =D25 -> 42071.25
A42: Method 2 — Bottom-up EBITDA (midpoint) | B42: =D38 -> 41452.071
A43: Variance | B43: =B41-B42 -> 619.17899
A44: EBITDA used for firepower (low case) | B44: =MIN(B25,B38) -> 40437.647
A45: EBITDA used for firepower (mid case) | B45: =AVERAGE(D25,D38) -> 41761.661
...

Sheet Inputs
A1: Balance Sheet & S&P Rating Thresholds
A3: Current Balance Sheet (12/31/2025)
A4: Total debt | B4: 42503 | C4: 10-K FY2025
A5: Long-term debt | B5: 40868 | C5: 10-K FY2025
A6: Current portion of LT debt | B6: 1635 | C6: 10-K FY2025
A7: Short-term commercial paper | B7: 0 | C7: 10-K FY2025 (was $4,338M YE24)
A8: Cash & equivalents | B8: 3268 | C8: 10-K FY2025 — verify with latest 10-Q
A9: Short-term investments | B9: 155 | C9: 10-K FY2025
A10: Cash + ST investments | B10: =B8+B9 -> 3423
A11: Net debt | B11: =B4-B10 -> 39080
A14: S&P Pharma Industry — Indicative Leverage Thresholds
A15: Rating | B15: Max Total Debt/EBITDA | C15: Indicative Range | D15: Notes
A16: AA / AA+ | B16: 1 | C16: < 1.0x | D16: Conservative; rare for large pharma
A17: AA- | B17: 1.5 | C17: 1.0x – 1.5x | D17: LLY's NEW rating (S&P upgrade)
A18: A+ | B18: 2 | C18: 1.5x – 2.0x | D18: LLY's PRIOR rating
A19: A | B19: 2.5 | C19: 2.0x – 2.5x | D19: Most large-cap pharma median
A20: A- | B20: 3 | C20: 2.5x – 3.0x | D20: Post-mega-deal (BMY, AMGN post-Horizon)
A21: BBB+ | B21: 3.5 | C21: 3.0x – 3.5x | D21: Stretched IG
A23: Note: Rating agencies look at total debt/EBITDA AND FFO/Debt jointly, plus business risk profile.

Sheet Firepower
A1: Incremental Debt Firepower — How Much Can LLY Borrow Before Rating Drops?
A2: Firepower = (Target Leverage × EBITDA) − Current Debt. This is the INCREMENTAL debt LLY can add before crossing the rating threshold.
A4: Rating Scenario | B4: Target Debt/EBITDA | C4: EBITDA case (Low) | D4: EBITDA case (Mid) | E4: EBITDA case (High) | F4: Firepower (Low) | G4: Firepower (Mid) | H4: Firepower (High)
A5: EBITDA used ($M) | B5: (from EBITDA Bridge sheet) | C5: ='EBITDA Bridge'!B44 -> 40437.647 | D5: ='EBITDA Bridge'!B45 -> 41761.661 | E5: ='EBITDA Bridge'!B46 -> 43425
A6: Maximize rating to AA / AA+ | B6: 1 | C6: =C5 -> 40437.647 | D6: =D5 -> 41761.661 | E6: =E5 -> 43425 | F6: =$B6*C6-Inputs!$B$4 -> -2065.3529 | G6: =$B6*D6-Inputs!$B$4 -> -741.3395 | H6: =$B6*E6-Inputs!$B$4 -> 922
A7: Maintain new AA- rating | B7: 1.5 | C7: =C5 -> 40437.647 | D7: =D5 -> 41761.661 | E7: =E5 -> 43425 | F7: =$B7*C7-Inputs!$B$4 -> 18153.471 | G7: =$B7*D7-Inputs!$B$4 -> 20139.491 | H7: =$B7*E7-Inputs!$B$4 -> 22634.5
A8: Accept downgrade to A+ (prior) | B8: 2 | C8: =C5 -> 40437.647 | D8: =D5 -> 41761.661 | E8: =E5 -> 43425 | F8: =$B8*C8-Inputs!$B$4 -> 38372.294 | G8: =$B8*D8-Inputs!$B$4 -> 41020.321 | H8: =$B8*E8-Inputs!$B$4 -> 44347
A9: Accept downgrade to A | B9: 2.5 | C9: =C5 -> 40437.647 | D9: =D5 -> 41761.661 | E9: =E5 -> 43425 | F9: =$B9*C9-Inputs!$B$4 -> 58591.118 | G9: =$B9*D9-Inputs!$B$4 -> 61901.151 | H9: =$B9*E9-Inputs!$B$4 -> 66059.5
A10: Accept downgrade to A- | B10: 3 | C10: =C5 -> 40437.647 | D10: =D5 -> 41761.661 | E10: =E5 -> 43425 | F10: =$B10*C10-Inputs!$B$4 -> 78809.941 | G10: =$B10*D10-Inputs!$B$4 -> 82781.982 | H10: =$B10*E10-Inputs!$B$4 -> 87772
A11: Accept downgrade to BBB+ | B11: 3.5 | C11: =C5 -> 40437.647 | D11: =D5 -> 41761.661 | E11: =E5 -> 43425 | F11: =$B11*C11-Inputs!$B$4 -> 99028.765 | G11: =$B11*D11-Inputs!$B$4 -> 103662.81 | H11: =$B11*E11-Inputs!$B$4 -> 109484.5
A14: HEADLINE: Firepower at AA- (mid case) | F14: =G7 -> 20139.491
A15: Trade-up to AA / AA+ (mid case) — pay down required | F15: =G6 -> -741.3395
A16: Drop to A+ (prior rating) (mid case) — extra firepower | F16: =G8 -> 41020.321
A17: Mega-deal capacity (drop to A-) (mid case) | F17: =G10 -> 82781.982
A19: Caveats
A20: • Firepower assumes 100% debt-funded transaction at target leverage — equity component would expand capacity
A21: • Does NOT include target's EBITDA contribution: in real M&A, target adds to denominator (raising firepower further)
A22: • Does NOT include synergies: realized cost synergies further increase pro-forma EBITDA
A23: • S&P expects deleveraging trajectory within 18–24 months post-close — firms can temporarily exceed thresholds with credible plan
A24: • Cash on balance sheet (~$3.4B) is supplementary firepower beyond debt capacity; we exclude it here to stay strict on credit metric definition
A25: • Real S&P decision combines Total Debt/EBITDA AND FFO/Debt — this model focuses on the leverage metric only

Sheet Sensitivity
A1: Firepower Sensitivity — EBITDA × Target Leverage
A2: Each cell = (Leverage × EBITDA) − Current Debt. Negative = LLY already above that threshold.
A4: EBITDA ($M) ↓ / Leverage → | B4: 1 | C4: 1.5 | D4: 2 | E4: 2.5 | F4: 3 | G4: 3.5 | H4: 4
B5: AA / AA+ | C5: AA- | D5: A+ | E5: A | F5: A- | G5: BBB+ | H5: BBB
A6: 28000 | B6: =$B$4*$A6-Inputs!$B$4 -> -14503 | C6: =$C$4*$A6-Inputs!$B$4 -> -503 | D6: =$D$4*$A6-Inputs!$B$4 -> 13497 | E6: =$E$4*$A6-Inputs!$B$4 -> 27497 | F6: =$F$4*$A6-Inputs!$B$4 -> 41497 | G6: =$G$4*$A6-Inputs!$B$4 -> 55497 | H6: =$H$4*$A6-Inputs!$B$4 -> 69497
A7: 30000 | B7: =$B$4*$A7-Inputs!$B$4 -> -12503 | C7: =$C$4*$A7-Inputs!$B$4 -> 2497 | D7: =$D$4*$A7-Inputs!$B$4 -> 17497 | E7: =$E$4*$A7-Inputs!$B$4 -> 32497 | F7: =$F$4*$A7-Inputs!$B$4 -> 47497 | G7: =$G$4*$A7-Inputs!$B$4 -> 62497 | H7: =$H$4*$A7-Inputs!$B$4 -> 77497
A8: 32000 | B8: =$B$4*$A8-Inputs!$B$4 -> -10503 | C8: =$C$4*$A8-Inputs!$B$4 -> 5497 | D8: =$D$4*$A8-Inputs!$B$4 -> 21497 | E8: =$E$4*$A8-Inputs!$B$4 -> 37497 | F8: =$F$4*$A8-Inputs!$B$4 -> 53497 | G8: =$G$4*$A8-Inputs!$B$4 -> 69497 | H8: =$H$4*$A8-Inputs!$B$4 -> 85497
A9: 34000 | B9: =$B$4*$A9-Inputs!$B$4 -> -8503 | C9: =$C$4*$A9-Inputs!$B$4 -> 8497 | D9: =$D$4*$A9-Inputs!$B$4 -> 25497 | E9: =$E$4*$A9-Inputs!$B$4 -> 42497 | F9: =$F$4*$A9-Inputs!$B$4 -> 59497 | G9: =$G$4*$A9-Inputs!$B$4 -> 76497 | H9: =$H$4*$A9-Inputs!$B$4 -> 93497
A10: 36000 | B10: =$B$4*$A10-Inputs!$B$4 -> -6503 | C10: =$C$4*$A10-Inputs!$B$4 -> 11497 | D10: =$D$4*$A10-Inputs!$B$4 -> 29497 | E10: =$E$4*$A10-Inputs!$B$4 -> 47497 | F10: =$F$4*$A10-Inputs!$B$4 -> 65497 | G10: =$G$4*$A10-Inputs!$B$4 -> 83497 | H10: =$H$4*$A10-Inputs!$B$4 -> 101497
A11: 38000 | B11: =$B$4*$A11-Inputs!$B$4 -> -4503 | C11: =$C$4*$A11-Inputs!$B$4 -> 14497 | D11: =$D$4*$A11-Inputs!$B$4 -> 33497 | E11: =$E$4*$A11-Inputs!$B$4 -> 52497 | F11: =$F$4*$A11-Inputs!$B$4 -> 71497 | G11: =$G$4*$A11-Inputs!$B$4 -> 90497 | H11: =$H$4*$A11-Inputs!$B$4 -> 109497
A12: 40000 | B12: =$B$4*$A12-Inputs!$B$4 -> -2503 | C12: =$C$4*$A12-Inputs!$B$4 -> 17497 | D12: =$D$4*$A12-Inputs!$B$4 -> 37497 | E12: =$E$4*$A12-Inputs!$B$4 -> 57497 | F12: =$F$4*$A12-Inputs!$B$4 -> 77497 | G12: =$G$4*$A12-Inputs!$B$4 -> 97497 | H12: =$H$4*$A12-Inputs!$B$4 -> 117497
A13: 42000 | B13: =$B$4*$A13-Inputs!$B$4 -> -503 | C13: =$C$4*$A13-Inputs!$B$4 -> 20497 | D13: =$D$4*$A13-Inputs!$B$4 -> 41497 | E13: =$E$4*$A13-Inputs!$B$4 -> 62497 | F13: =$F$4*$A13-Inputs!$B$4 -> 83497 | G13: =$G$4*$A13-Inputs!$B$4 -> 104497 | H13: =$H$4*$A13-Inputs!$B$4 -> 125497
A14: 45000 | B14: =$B$4*$A14-Inputs!$B$4 -> 2497 | C14: =$C$4*$A14-Inputs!$B$4 -> 24997 | D14: =$D$4*$A14-Inputs!$B$4 -> 47497 | E14: =$E$4*$A14-Inputs!$B$4 -> 69997 | F14: =$F$4*$A14-Inputs!$B$4 -> 92497 | G14: =$G$4*$A14-Inputs!$B$4 -> 114997 | H14: =$H$4*$A14-Inputs!$B$4 -> 137497
A16: Reading
A17: • Green column (1.5x) = AA- ceiling — incremental debt LLY can add at the new rating
A18: • Blue column (2.0x) = A+ ceiling (prior rating) — capacity given up to earn the upgrade
A19: • 2026E EBITDA (~$33–37B from guidance) gives meaningful headroom even at AA-
A20: • Each $1B of EBITDA growth at 1.5x = $1.5B of incremental firepower
