Workbook

Sheet Q1 2026 Actuals
A1: Q1 2026 Cash Flow Walkthrough — Actuals from 10-Q
A2: All figures from Q1 2026 10-Q filed 4/30/2026 (consolidated condensed statements of cash flows, page 8)
A4: Step 1: Build CFO from Net Income (the operating section)
A5: Line item ($M) | B5: Q1 2026 | C5: Q1 2025 | D5: Note
A6: Net income | B6: 7396 | C6: 2759 | D6: Starting point — from income statement
A7: (+) Depreciation and amortization | B7: 509 | C7: 463 | D7: Non-cash; add back
A8: (+) Stock-based compensation | B8: 161 | C8: 154 | D8: Non-cash; add back
A9: (+) Acquired IPR&D | B9: 584 | C9: 1572 | D9: Non-cash; Ventyx deal in Q1'26 ($1.1B cash but IPR&D portion non-cash)
A10: (−) Change in deferred income taxes | B10: -1478 | C10: -392 | D10: Deferred tax ASSETS grew $1.5B — uses cash now, recover later
A11: (−) Other changes in operating assets/liabilities | B11: -1664 | C11: -3364 | D11: Working capital drag — inventory + A/R build for incretin growth
A12: (−) Other operating activities, net | B12: -175 | C12: 474 | D12: Misc
A13: = Net Cash Provided by Operating Activities (CFO) | B13: =SUM(B6:B12) -> 5333 | C13: =SUM(C6:C12) -> 1666 | D13: TOTAL — what the business actually generated in cash
A15: Step 2: From CFO to Free Cash Flow (subtract capex)
A16: CFO (from above) | B16: =B13 -> 5333 | C16: =C13 -> 1666 | D16: Net cash from operating activities
A17: (−) Purchases of property and equipment (CAPEX) | B17: -2326 | C17: -1510 | D17: Mandatory; LLY's $50B+ US manufacturing build is here
A18: = Free Cash Flow (FCF) | B18: =B16+B17 -> 3007 | C18: =C16+C17 -> 156 | D18: Cash left after running and growing the business
A20: Step 3: From FCF to Discretionary FCF (subtract dividends — committed but technically optional)
A21: FCF (from above) | B21: =B18 -> 3007 | C21: =C18 -> 156
A22: (−) Dividends paid | B22: -1548 | C22: -1346 | D22: $1.73/share Q1'26 × ~895M shares; LLY raises 15%/yr, can't realistically cut
A23: = Discretionary FCF | B23: =B21+B22 -> 1459 | C23: =C21+C22 -> -1190 | D23: What's truly free for buybacks, M&A, or balance sheet build
A25: Step 4: Reconciling — how LLY funded the buyback in Q1'26
A26: Discretionary FCF generated in quarter | B26: =B23 -> 1459 | C26: =C23 -> -1190 | D26: What the business produced
A27: (−) Share repurchases | B27: -2356 | C27: -1200 | D27: Q1'26 buyback at $987/share avg
A28: = Cash surplus / (deficit) from operations | B28: =B26+B27 -> -897 | C28: =C26+C27 -> -2390 | D28: Negative = needed external funding
A30: How the deficit was funded:
A31: (+) Net change in short-term borrowings (CP) | B31: 1775 | C31: -1849 | D31: Drew $1.8B of commercial paper in Q1'26
A32: (−) Repayments of long-term debt | B32: -750 | C32: 0 | D32: Paid off maturing notes
A33: (−) Other financing, net | B33: -591 | C33: -686 | D33: Includes employee stock plan transactions
A34: (+/-) Investing activity beyond capex | B34: -1590 | C34: -1843 | D34: Cash for acquisitions ($1.06B Ventyx) + IPR&D + investments
A35: (+) FX effect on cash | B35: 67 | C35: 132
A36: = Net change in cash & equivalents | B36: =B28+SUM(B31:B35) -> -1986 | C36: =C28+SUM(C31:C35) -> -6636 | D36: Confirms cash balance change Q/Q
A38: KEY TAKEAWAY
A39: Q1 2026 generated $1.5B of discretionary FCF, but LLY spent $2.4B on buybacks.
A40: The $0.9B gap (plus $1.1B Ventyx acquisition + $0.75B debt repayment) was funded by:
A41: • Drawing $1.78B of commercial paper (turning on the CP program — was $0 at YE25)
A42: • Drawing down $2.0B of cash on hand ($7.3B → $5.3B)
A44: This means: At the current EBITDA level, Lilly's organic discretionary FCF is NOT covering the current buyback pace.
A45: Either CFO needs to ramp meaningfully through the year (likely — H2 seasonality is much better),
A46: OR the buyback pace is partially funded by balance sheet/CP rather than pure FCF.
A48: For your IR question: this is REAL evidence that capital allocation is tighter than headline numbers suggest.

Sheet FY2026E Build
A1: FY2026E Discretionary FCF — Building Forward from Q1 Actuals
A2: Q1 2026 actuals + assumed Q2-Q4 ramp = FY2026E. Q1 is seasonally weak; H2 typically much stronger.
A4: Line item ($M) | B4: Q1 2026A | C4: Q2-Q4 2026E | D4: FY 2026E | E4: FY 2025A | F4: Notes / assumptions
A5: Revenue | B5: 19799 | C5: 63701 | D5: =B5+C5 -> 83500 | E5: 65179 | F5: Q1 actual; Q2-Q4 = guidance midpoint $83.5B − Q1
A6: CFO | B6: 5333 | C6: 22667 | D6: =B6+C6 -> 28000 | E6: 16813 | F6: FY26E ~33% revenue conversion as WC drag normalizes (Q1'25 was abnormally low)
A7: (−) Capex | B7: -2326 | C7: -7674 | D7: =B7+C7 -> -10000 | E7: -6856 | F7: FY26E ~$10B per management commentary; ~12% of revenue
A8: = FCF | B8: =B6+B7 -> 3007 | C8: =C6+C7 -> 14993 | D8: =B8+C8 -> 18000 | E8: =E6+E7 -> 9957
A9: (−) Dividends paid | B9: -1548 | C9: -4644 | D9: =B9+C9 -> -6192 | E9: -5364 | F9: Q1 $1.73 × 895M shares; reset higher mid-year typically
A10: = Discretionary FCF | B10: =B8+B9 -> 1459 | C10: =C8+C9 -> 10349 | D10: =B10+C10 -> 11808 | E10: =E8+E9 -> 4593 | F10: What's available for buybacks, M&A, balance sheet build
A11: Memo: Buybacks (planned pace) | B11: -2356 | C11: -7644 | D11: =B11+C11 -> -10000 | E11: -7400 | F11: Q1 actual; Q2-Q4 to use up part of remaining $8.6B auth
A12: = Discretionary FCF after buybacks | B12: =B10+B11 -> -897 | C12: =C10+C11 -> 2705 | D12: =B12+C12 -> 1808 | E12: =E10+E11 -> -2807 | F12: Negative = needs balance sheet or debt to fund
A14: CFO / Revenue conversion | B14: =B6/B5 -> 0.26935704 | C14: =C6/C5 -> 0.35583429 | D14: =D6/D5 -> 0.33532934 | E14: =E6/E5 -> 0.25795118 | F14: Q1 was 27%; FY ramps as WC normalizes

Sheet Firepower
A1: Total LLY Firepower — Updated with Q1 2026 10-Q Actuals
A2: Three components: existing balance sheet liquidity + remaining 2026 discretionary FCF + incremental debt headroom
A4: Balance Sheet at 3/31/2026 (per 10-Q)
A5: Cash and cash equivalents | B5: 5282 | C5: Down from $7.3B at YE25
A6: Short-term investments | B6: 146
A7: Noncurrent investments | B7: 3116 | C7: Includes equity method, marketable equity securities
A8: Total liquidity | B8: =B5+B6+B7 -> 8544 | C8: Sum of above
A10: Short-term borrowings (CP) | B10: 4000 | C10: Up from $1.6B at YE25 — CP turned back on
A11: Long-term debt | B11: 39370 | C11: Down from $40.9B at YE25
A12: Total debt | B12: =B10+B11 -> 43370
A14: Pending acquisition cash commitments | B14: 12000 | C14: Per 10-Q p.28: 'up to ~$12B at closing'
A16: EBITDA Derivation (FY2026E)
A17: Revenue (guidance midpoint) | B17: 83500 | C17: Q1'26 guidance: $82-85B
A18: × Performance margin (midpoint) | B18: 0.4775 | C18: Q1'26 guidance: 47-48.5%
A19: = Non-GAAP operating income | B19: =B17*B18 -> 39871.25 | C19: Approximation of non-GAAP EBIT
A20: (+) D&A | B20: 2200 | C20: Q1 actual $509M annualized + ramp
A21: = EBITDA (GAAP-equivalent) | B21: =B19+B20 -> 42071.25 | C21: Used for leverage analysis
A23: Current Leverage at 3/31/2026
A24: Total Debt / FY26E EBITDA | B24: =B12/B21 -> 1.0308702 | C24: Comfortably within AA- threshold (≤1.5x)
A26: TOTAL FIREPOWER — by Rating Scenario
A27: Component | B27: Maintain AA- | C27: Drop to A+ | D27: Drop to A | E27: Drop to A-
A28: (1) Cash & investments at 3/31/26 | B28: =$B$8 -> 8544 | C28: =$B$8 -> 8544 | D28: =$B$8 -> 8544 | E28: =$B$8 -> 8544
A29: (2) Less: pending acquisition commitments | B29: =-$B$14 -> -12000 | C29: =-$B$14 -> -12000 | D29: =-$B$14 -> -12000 | E29: =-$B$14 -> -12000
A30: (3) Net liquidity available today | B30: =B28+B29 -> -3456 | C30: =C28+C29 -> -3456 | D30: =D28+D29 -> -3456 | E30: =E28+E29 -> -3456
A31: (4) Discretionary FCF Q2-Q4 2026E | B31: ='FY2026E Build'!C10 -> 10349 | C31: ='FY2026E Build'!C10 -> 10349 | D31: ='FY2026E Build'!C10 -> 10349 | E31: ='FY2026E Build'!C10 -> 10349
A32: (5) Incremental debt capacity | B32: =1.5*$B$21-$B$12 -> 19736.875 | C32: =2*$B$21-$B$12 -> 40772.5 | D32: =2.5*$B$21-$B$12 -> 61808.125 | E32: =3*$B$21-$B$12 -> 82843.75
A33: Implied target Debt/EBITDA | B33: 1.5x | C33: 2.0x | D33: 2.5x | E33: 3.0x
A35: Caveats
A36: • Q2-Q4 discretionary FCF estimate is a key driver — change in 'FY2026E Build' tab to flex
A37: • Buyback pace ($8.6B remaining authorization) competes with M&A capacity — every $1B of buyback is $1B less for deals
A38: • Pending $12B of M&A commitments (Centessa, Ajax, Kelonia, Orna) deducts from current liquidity
A39: • Doesn't include target's own EBITDA contribution — would expand denominator and increase capacity
A40: • Doesn't include synergies — typically 5-10% of target opex available within 24 months
A41: • 18-24 month deleveraging window: S&P typically allows temporary leverage spike with credible paydown plan

Sheet Sensitivity
A1: Firepower Sensitivity — Adj. EBITDA × Leverage / Credit Rating
A2: Each cell = (Target leverage × EBITDA) − Current debt of $43.4B. Result is incremental debt capacity at that rating.
A4: Current total debt (from Firepower tab): | B4: =Firepower!B12 -> 43370 | C4: ← override here if testing pro-forma with new debt
A6: Adj. EBITDA ↓ / Rating → | B6: AA / AA+ | C6: AA- | D6: A+ | E6: A | F6: A- | G6: BBB+ | H6: BBB
B7: 1 | C7: 1.5 | D7: 2 | E7: 2.5 | F7: 3 | G7: 3.5 | H7: 4
A8: 30000 | B8: =B$7*$A8-$B$4 -> -13370 | C8: =C$7*$A8-$B$4 -> 1630 | D8: =D$7*$A8-$B$4 -> 16630 | E8: =E$7*$A8-$B$4 -> 31630 | F8: =F$7*$A8-$B$4 -> 46630 | G8: =G$7*$A8-$B$4 -> 61630 | H8: =H$7*$A8-$B$4 -> 76630
A9: 32000 | B9: =B$7*$A9-$B$4 -> -11370 | C9: =C$7*$A9-$B$4 -> 4630 | D9: =D$7*$A9-$B$4 -> 20630 | E9: =E$7*$A9-$B$4 -> 36630 | F9: =F$7*$A9-$B$4 -> 52630 | G9: =G$7*$A9-$B$4 -> 68630 | H9: =H$7*$A9-$B$4 -> 84630
A10: 34000 | B10: =B$7*$A10-$B$4 -> -9370 | C10: =C$7*$A10-$B$4 -> 7630 | D10: =D$7*$A10-$B$4 -> 24630 | E10: =E$7*$A10-$B$4 -> 41630 | F10: =F$7*$A10-$B$4 -> 58630 | G10: =G$7*$A10-$B$4 -> 75630 | H10: =H$7*$A10-$B$4 -> 92630
A11: 36000 | B11: =B$7*$A11-$B$4 -> -7370 | C11: =C$7*$A11-$B$4 -> 10630 | D11: =D$7*$A11-$B$4 -> 28630 | E11: =E$7*$A11-$B$4 -> 46630 | F11: =F$7*$A11-$B$4 -> 64630 | G11: =G$7*$A11-$B$4 -> 82630 | H11: =H$7*$A11-$B$4 -> 100630
A12: 38000 | B12: =B$7*$A12-$B$4 -> -5370 | C12: =C$7*$A12-$B$4 -> 13630 | D12: =D$7*$A12-$B$4 -> 32630 | E12: =E$7*$A12-$B$4 -> 51630 | F12: =F$7*$A12-$B$4 -> 70630 | G12: =G$7*$A12-$B$4 -> 89630 | H12: =H$7*$A12-$B$4 -> 108630
A13: 40000 | B13: =B$7*$A13-$B$4 -> -3370 | C13: =C$7*$A13-$B$4 -> 16630 | D13: =D$7*$A13-$B$4 -> 36630 | E13: =E$7*$A13-$B$4 -> 56630 | F13: =F$7*$A13-$B$4 -> 76630 | G13: =G$7*$A13-$B$4 -> 96630 | H13: =H$7*$A13-$B$4 -> 116630
A14: 42000 | B14: =B$7*$A14-$B$4 -> -1370 | C14: =C$7*$A14-$B$4 -> 19630 | D14: =D$7*$A14-$B$4 -> 40630 | E14: =E$7*$A14-$B$4 -> 61630 | F14: =F$7*$A14-$B$4 -> 82630 | G14: =G$7*$A14-$B$4 -> 103630 | H14: =H$7*$A14-$B$4 -> 124630 | I14: ← FY26E midpoint
A15: 44000 | B15: =B$7*$A15-$B$4 -> 630 | C15: =C$7*$A15-$B$4 -> 22630 | D15: =D$7*$A15-$B$4 -> 44630 | E15: =E$7*$A15-$B$4 -> 66630 | F15: =F$7*$A15-$B$4 -> 88630 | G15: =G$7*$A15-$B$4 -> 110630 | H15: =H$7*$A15-$B$4 -> 132630
A16: 46000 | B16: =B$7*$A16-$B$4 -> 2630 | C16: =C$7*$A16-$B$4 -> 25630 | D16: =D$7*$A16-$B$4 -> 48630 | E16: =E$7*$A16-$B$4 -> 71630 | F16: =F$7*$A16-$B$4 -> 94630 | G16: =G$7*$A16-$B$4 -> 117630 | H16: =H$7*$A16-$B$4 -> 140630
A17: 48000 | B17: =B$7*$A17-$B$4 -> 4630 | C17: =C$7*$A17-$B$4 -> 28630 | D17: =D$7*$A17-$B$4 -> 52630 | E17: =E$7*$A17-$B$4 -> 76630 | F17: =F$7*$A17-$B$4 -> 100630 | G17: =G$7*$A17-$B$4 -> 124630 | H17: =H$7*$A17-$B$4 -> 148630
A18: 50000 | B18: =B$7*$A18-$B$4 -> 6630 | C18: =C$7*$A18-$B$4 -> 31630 | D18: =D$7*$A18-$B$4 -> 56630 | E18: =E$7*$A18-$B$4 -> 81630 | F18: =F$7*$A18-$B$4 -> 106630 | G18: =G$7*$A18-$B$4 -> 131630 | H18: =H$7*$A18-$B$4 -> 156630
A21: Reading the table
A22: • Gold cell = FY26E midpoint EBITDA × AA- ceiling = LLY's incremental debt capacity at the new rating
A23: • Green column = AA- (current rating) — firepower at each EBITDA level
A24: • Blue column = A+ (prior rating) — capacity if LLY accepts a 1-notch downgrade
A25: • Red row = FY26E EBITDA midpoint ($42B from guidance midpoint × ~50% performance margin + D&A)
A26: • Negative cells = LLY already exceeds that rating's leverage ceiling at that EBITDA level
A27: • Each $1B of EBITDA growth at 1.5x AA- ceiling = $1.5B of incremental firepower
A28: • Each notch of acceptable downgrade (~0.5x leverage) at $42B EBITDA = ~$21B more capacity
A31: TOTAL Firepower Sensitivity (incl. liquidity & remaining FCF)
A32: Adds back: net liquidity + Q2-Q4 2026E FCF from Firepower tab. This = total deployable capital at each rating.
A34: Net liquidity (cash − pending M&A): | B34: =Firepower!B30 -> -3456
A35: Q2-Q4 2026E discretionary FCF: | B35: =Firepower!B31 -> 10349
A37: Adj. EBITDA ↓ / Rating → | B37: AA / AA+ | C37: AA- | D37: A+ | E37: A | F37: A- | G37: BBB+ | H37: BBB
B38: 1 | C38: 1.5 | D38: 2 | E38: 2.5 | F38: 3 | G38: 3.5 | H38: 4
A39: 30000 | B39: =B$38*$A39-$B$4+$B$33+$B$34 -> -16826 | C39: =C$38*$A39-$B$4+$B$33+$B$34 -> -1826 | D39: =D$38*$A39-$B$4+$B$33+$B$34 -> 13174 | E39: =E$38*$A39-$B$4+$B$33+$B$34 -> 28174 | F39: =F$38*$A39-$B$4+$B$33+$B$34 -> 43174 | G39: =G$38*$A39-$B$4+$B$33+$B$34 -> 58174 | H39: =H$38*$A39-$B$4+$B$33+$B$34 -> 73174
A40: 32000 | B40: =B$38*$A40-$B$4+$B$33+$B$34 -> -14826 | C40: =C$38*$A40-$B$4+$B$33+$B$34 -> 1174 | D40: =D$38*$A40-$B$4+$B$33+$B$34 -> 17174 | E40: =E$38*$A40-$B$4+$B$33+$B$34 -> 33174 | F40: =F$38*$A40-$B$4+$B$33+$B$34 -> 49174 | G40: =G$38*$A40-$B$4+$B$33+$B$34 -> 65174 | H40: =H$38*$A40-$B$4+$B$33+$B$34 -> 81174
A41: 34000 | B41: =B$38*$A41-$B$4+$B$33+$B$34 -> -12826 | C41: =C$38*$A41-$B$4+$B$33+$B$34 -> 4174 | D41: =D$38*$A41-$B$4+$B$33+$B$34 -> 21174 | E41: =E$38*$A41-$B$4+$B$33+$B$34 -> 38174 | F41: =F$38*$A41-$B$4+$B$33+$B$34 -> 55174 | G41: =G$38*$A41-$B$4+$B$33+$B$34 -> 72174 | H41: =H$38*$A41-$B$4+$B$33+$B$34 -> 89174
A42: 36000 | B42: =B$38*$A42-$B$4+$B$33+$B$34 -> -10826 | C42: =C$38*$A42-$B$4+$B$33+$B$34 -> 7174 | D42: =D$38*$A42-$B$4+$B$33+$B$34 -> 25174 | E42: =E$38*$A42-$B$4+$B$33+$B$34 -> 43174 | F42: =F$38*$A42-$B$4+$B$33+$B$34 -> 61174 | G42: =G$38*$A42-$B$4+$B$33+$B$34 -> 79174 | H42: =H$38*$A42-$B$4+$B$33+$B$34 -> 97174
A43: 38000 | B43: =B$38*$A43-$B$4+$B$33+$B$34 -> -8826 | C43: =C$38*$A43-$B$4+$B$33+$B$34 -> 10174 | D43: =D$38*$A43-$B$4+$B$33+$B$34 -> 29174 | E43: =E$38*$A43-$B$4+$B$33+$B$34 -> 48174 | F43: =F$38*$A43-$B$4+$B$33+$B$34 -> 67174 | G43: =G$38*$A43-$B$4+$B$33+$B$34 -> 86174 | H43: =H$38*$A43-$B$4+$B$33+$B$34 -> 105174
A44: 40000 | B44: =B$38*$A44-$B$4+$B$33+$B$34 -> -6826 | C44: =C$38*$A44-$B$4+$B$33+$B$34 -> 13174 | D44: =D$38*$A44-$B$4+$B$33+$B$34 -> 33174 | E44: =E$38*$A44-$B$4+$B$33+$B$34 -> 53174 | F44: =F$38*$A44-$B$4+$B$33+$B$34 -> 73174 | G44: =G$38*$A44-$B$4+$B$33+$B$34 -> 93174 | H44: =H$38*$A44-$B$4+$B$33+$B$34 -> 113174
A45: 42000 | B45: =B$38*$A45-$B$4+$B$33+$B$34 -> -4826 | C45: =C$38*$A45-$B$4+$B$33+$B$34 -> 16174 | D45: =D$38*$A45-$B$4+$B$33+$B$34 -> 37174 | E45: =E$38*$A45-$B$4+$B$33+$B$34 -> 58174 | F45: =F$38*$A45-$B$4+$B$33+$B$34 -> 79174 | G45: =G$38*$A45-$B$4+$B$33+$B$34 -> 100174 | H45: =H$38*$A45-$B$4+$B$33+$B$34 -> 121174 | I45: ← FY26E midpoint
A46: 44000 | B46: =B$38*$A46-$B$4+$B$33+$B$34 -> -2826 | C46: =C$38*$A46-$B$4+$B$33+$B$34 -> 19174 | D46: =D$38*$A46-$B$4+$B$33+$B$34 -> 41174 | E46: =E$38*$A46-$B$4+$B$33+$B$34 -> 63174 | F46: =F$38*$A46-$B$4+$B$33+$B$34 -> 85174 | G46: =G$38*$A46-$B$4+$B$33+$B$34 -> 107174 | H46: =H$38*$A46-$B$4+$B$33+$B$34 -> 129174
A47: 46000 | B47: =B$38*$A47-$B$4+$B$33+$B$34 -> -826 | C47: =C$38*$A47-$B$4+$B$33+$B$34 -> 22174 | D47: =D$38*$A47-$B$4+$B$33+$B$34 -> 45174 | E47: =E$38*$A47-$B$4+$B$33+$B$34 -> 68174 | F47: =F$38*$A47-$B$4+$B$33+$B$34 -> 91174 | G47: =G$38*$A47-$B$4+$B$33+$B$34 -> 114174 | H47: =H$38*$A47-$B$4+$B$33+$B$34 -> 137174
A48: 48000 | B48: =B$38*$A48-$B$4+$B$33+$B$34 -> 1174 | C48: =C$38*$A48-$B$4+$B$33+$B$34 -> 25174 | D48: =D$38*$A48-$B$4+$B$33+$B$34 -> 49174 | E48: =E$38*$A48-$B$4+$B$33+$B$34 -> 73174 | F48: =F$38*$A48-$B$4+$B$33+$B$34 -> 97174 | G48: =G$38*$A48-$B$4+$B$33+$B$34 -> 121174 | H48: =H$38*$A48-$B$4+$B$33+$B$34 -> 145174
...
