Workbook

Sheet 1L Raw Data
A1: Generic name | B1: Brand EU | C1: Brand US | D1: Company EU | E1: Company US | F1: Sponsors | G1: Tumor | H1: Stage | I1: Other tumor | J1: Line of treatment | K1: Development stage EU | L1: Development stage US | M1: Development stage China | N1: Development stage Japan | O1: Development stage UK | P1: Phase | Q1: NCT Number | R1: Other identifiers | S1: Mechanism of action | T1: Molecular targets | U1: Immuno-Oncology | V1: Biosimilar | W1: Key trial | X1: Combination treatment | Y1: Combined with | Z1: Negative trial | AA1: Budget impact | AB1: Oncology / Hematology | AC1: Development status | AD1: Type of therapy | AE1: Trial name | AF1: Control arm | AG1: Primary endpoint | AH1: ORR | AI1: ORR EA | AJ1: ORR Control | AK1: Source ORR EA | AL1: Source ORR Control | AM1: ORR delta | AN1: PFS (months) | AO1: PFS EA | AP1: PFS Control | AQ1: Source PFS EA | AR1: Source PFS Control | AS1: Difference in PFS (months) | AT1: Hazard ratio (HR) PFS | AU1: OS (months) | AV1: OS EA | AW1: OS Control | AX1: Source OS EA | AY1: Source OS Control | AZ1: Difference in OS (months) | BA1: Hazard ratio (HR) OS | BB1: Status | BC1: Number of patients | BD1: Study start date | BE1: First results | BF1: EU filing date | BG1: EU approval date | BH1: Months needed to gain EU approval | BI1: US filing date | BJ1: US approval date | BK1: Months needed to gain US approval | BL1: China filing date | BM1: China approval date | BN1: Months needed to gain China approval | BO1: Japan filing date | BP1: Japan approval date | BQ1: Months needed to gain Japan approval | BR1: UK filing date | BS1: UK approval date | BT1: Months needed to gain UK approval | BU1: Countries | BV1: Title | BW1: Inclusion and exclusion criteria | BX1: Primary completion date | BY1: Study completion date | BZ1: Study type | CA1: Study Designs | CB1: Biomarkers Inclusion Criteria | CC1: Biomarkers Exclusion Criteria | CD1: Biomarkers Analysis Criteria | CE1: Biomarkers Approval Criteria | CF1: Payload molecule | CG1: Payload molecule group | CH1: Payload MoA | CI1: Payload MoA group | CJ1: Linker cleavability | CK1: Cleav./Non-cleav. component | CL1: Linker cleavage trigger | CM1: Site specific conjugation | CN1: Conjugation method | CO1: ADC technology | CP1: DAR | CQ1: Payload molecule 2 | CR1: Payload molecule group 2 | CS1: Payload MoA 2 | CT1: Payload MoA group 2 | CU1: Linker cleavability 2 | CV1: Cleav./Non-cleav. component 2 | CW1: Linker cleavage trigger 2 | CX1: Site specific conjugation 2 | CY1: Conjugation method 2 | CZ1: ADC technology 2 | DA1: DAR 2
A2: Bevacizumab | B2: Avastin | C2: Avastin | D2: Roche | E2: Genentech | F2: National Cancer Institute (NCI - NIH) | G2: Lung cancer - NSCLC | H2: Stage IIIB,Stage IV | I2: Large-cell lung carcinoma, Lung cancer, Non-squamous NSCLC | J2: First line | K2: Phase III | L2: Approved | M2: Phase III | N2: Phase III | O2: Phase III | P2: Phase III | Q2: NCT00021060 | S2: Anti-VEGF monoclonal antibody | T2: VEGF | U2: No | V2: No | W2: Yes | Z2: No | AA2: A | AB2: Oncology | AC2: Stopped | AD2: Monoclonal antibody | AE2: NCI-2012-02947 | AF2: Paclitaxel + Carboplatin | AG2: Other | AH2: 30.0% | AI2: 30.0% | AK2: NEJM Dec 14, 2006 | AM2: 20 | AN2: 6.20 | AP2: 6.20 | AR2: NEJM Dec 14, 2006 | AS2: 1.7 | AT2: 0.66 | AU2: 12.30 | AV2: 12.30 | AX2: NEJM Dec 14, 2006 | AZ2: 2 | BA2: 0.79 | BB2: Completed | BC2: 842 | BD2: 37469 | BE2: 38687 | BI2: 38818 | BJ2: 39001 | BK2: 6 | BU2: United States | BV2: Randomized Phase II/III Trial of Paclitaxel Plus Carboplatin With or Without Bevacizumab (NSC #704865) in Patients With Advanced Nonsquamous NSCLC | BW2: Inclusion Criteria:* Patients must have histologically or cytologically confirmed non-small cell lung cancer EXCEPT squamous cell carcinoma; mixed tumors will be categorized by the predominant cell type unless small cell elements are present in which case the patient is ineligible; cytologic or histologic elements can be established on metastatic tumor aspirates or biopsy* Patients must have advanced NSCLC (stage IIIB with malignant pleural effusion or stage IV or recurrent disease)* Patients must have measurable or non-measurable disease* ECOG performance status 0 or 1* Patients must not have known central nervous system (CNS) metastases; a head CT is required within 4 weeks prior to study entry; (MRIs are also acceptable)* Patients must not have received prior systemic chemotherapy at any time* ANC \>= 1500/mm\^3* Platelets \>= 100,000/mm\^3* Total bilirubin =\< 1.5 mg/dl* Transaminases =\< 5 x ULN* Serum creatinine less than or equal to 1.5 x upper limit of normal (ULN)* Urine dipstick for proteinuria of less than 1+ (i.e., either 0 or trace); if urine dipstick is \>= 1+ then a 24 hour urine for protein must demonstrate \< 500 mg of protein in 24 hours to allow participation in the study; Note:: urinalysis is also acceptable* Patients must have INR =\< 1.5 and a PTT no greater than upper limits of normal within 1 week prior to randomization* Pregnant and lactating women are excluded from the study* Women of childbearing potential and sexually active males must agree to use an accepted and effective method of contraception (hormonal or barrier methods, abstinence) prior to study entry and for the duration of the study* Patients must not have had immuno, hormonal or radiation therapy within 3 weeks prior to entering the study; those who have not recovered from adverse events due to agents administered more than 3 weeks earlier are ineligible* Patients must not have ongoing or active infection, symptomatic congestive heart failure, unstable angina pectoris, cardiac arrhythmia, or psychiatric illness/social situations that would limit compliance with study requirements* Patients must have no history of thrombotic or hemorrhagic disorders* Patients with history of hypertension must be well-controlled (\< 150/100) on a stable regimen of anti-hypertensive therapy* Patients must not be receiving chronic daily treatment with aspirin (\> 325 mg/day) or nonsteroidal anti-inflammatory agents known to inhibit platelet function; treatment with dipyridamole (Persantine), ticlopidine (Ticlid), clopidogrel (Plavix) and/or cilostazol (Pletal) is also not allowed* Patients must not have serious non-healing wound ulcer, or bone fracture, or major surgical procedure within 21 days prior to starting treatment* Patients must not be on therapeutic anticoagulation; prophylactic anticoagulation of venous access devices is allowed; caution should be taken on treating patients with low dose heparin or low molecular weight heparin for DVT prophylaxis during treatment with bevacizumab as there may be an increased risk of bleeding* Patients with a history of gross hemoptysis (defined as bright red blood of a 1/2 teaspoon or more) will be excluded from this trial | BX2: 38961 | BZ2: Interventional | CA2: Allocation: Randomized | Intervention Model: Parallel Assignment | Masking: None (Open Label) () | Primary Purpose: Treatment
A3: Pemetrexed | B3: Alimta | C3: Alimta | D3: Eli Lilly | E3: Eli Lilly | F3: Eli Lilly | G3: Lung cancer - NSCLC | H3: Stage IIIB,Stage IV | J3: First line | K3: Phase III | L3: Approved | M3: Phase III | N3: Phase III | O3: Phase III | P3: Phase III | Q3: NCT00087711 | S3: Multitargeted antifolate | T3: TS, TYMS | U3: No | V3: No | W3: Yes | Z3: No | AA3: C | AB3: Oncology | AC3: Stopped | AD3: Small molecule | AE3: H3E-MC-JMDB | AF3: Gemcitabine | AG3: OS | AH3: 27.0% | AI3: 27.0% | AK3: US label Sep 26, 2008 | AM3: 2 | AN3: 4.80 | AP3: 4.80 | AR3: US label Sep 26, 2008 | AS3: -0.3 | AT3: 1.04 | AU3: 10.30 | AV3: 10.30 | AX3: US label Sep 26, 2008 | AZ3: 0 | BA3: 0.94 | BB3: Completed | BC3: 1713 | BD3: 38169 | BE3: 39083 | BI3: 39321 | BJ3: 39717 | BK3: 13 | BU3: United States - Argentina - Australia - Austria - Belgium - Brazil - Canada - Denmark - Finland - France - Germany - Greece - Hungary - India - Israel - Italy - Mexico - Netherlands - Poland - Portugal - Puerto Rico - South Korea - Spain - Sweden - Taiwan - Turkey - United Kingdom | BV3: A Randomized Phase 3 Trial of ALIMTA and Cisplatin Versus GEMZAR and Cisplatin in Patients With Locally Advanced or Metastatic Non-Small Cell Lung Cancer | BW3: Inclusion Criteria:* Diagnosis of NSCLC Stage IIIB not amenable to curative treatment or Stage IV.* No prior chemotherapy for lung cancer.* Patients must have at least one uni-dimensionally measurable lesion.* Prior radiation therapy to less than 25% of bone marrow, whole pelvis not allowed. Radiation must be completed at least 4 weeks prior to study enrollment.Exclusion Criteria:* Treatment with any drug within the last 30 days that has not received regulatory approval.* Serious cardiac condition.* Serious medical disorder in addition to NSCLC that would make it difficult for the patient to complete the study.* Inability or unwillingness to take folic acid or Vitamin B12 supplementation.* Presence of fluid retention that cannot be controlled by drainage. | BX3: 39083 | BY3: 39508 | BZ3: Interventional | CA3: Allocation: Randomized | Intervention Model: Parallel Assignment | Masking: None (Open Label) () | Primary Purpose: Treatment
A4: Erlotinib | B4: Tarceva | C4: Tarceva | D4: Roche | E4: Genentech | F4: GECP - Spanish Lung Cancer Group | G4: Lung cancer - NSCLC | H4: Stage IIIB,Stage IV | J4: First line | K4: Approved | L4: Approved | M4: Approved | N4: Approved | O4: Approved | P4: Phase III | Q4: NCT00446225 | R4: 2006-003568-73 | S4: EGFR inhibitor | T4: EGFR, ERBB, HER1 | U4: No | V4: No | W4: Yes | Z4: No | AA4: D | AB4: Oncology | AC4: Stopped | AD4: Small molecule | AE4: EURTAC | AF4: Chemotherapy | AG4: PFS | AH4: 65.0% vs 16.0% | AI4: 65.0% | AJ4: 16.0% | AK4: US label May 14, 2013 | AL4: US label May 14, 2013 | AM4: 49 | AN4: 10.40 | AP4: 10.40 | AR4: US label May 14, 2013 | AS4: 5.2 | AT4: 0.34 | AU4: 22.90 vs 19.60 | AV4: 22.90 | AW4: 19.60 | AX4: ESMO Sep 26, 2014 | AY4: ESMO Sep 26, 2014 | AZ4: 3.5 | BA4: 0.92 | BB4: Completed | BC4: 174 | BD4: 39128 | BE4: 40148 | BF4: 40346 | BG4: 40787 | BH4: 14.5 | BI4: 41250 | BJ4: 41408 | BK4: 5.2 | BL4: 42349 | BM4: 42814 | BN4: 15.2 | BO4: 41439 | BP4: 41086 | BQ4: 11.6 | BR4: 40346 | BS4: 40787 | BT4: 14.5 | BU4: China - France - Italy - Spain | BV4: Phase III, Multicenter, Open-label, Randomized Trial of Tarceva® vs Chemotherapy in Patients With Advanced NSCLC With Mutations in the TK Domain of the EGFR | BW4: Inclusion criteria:* Informed consent* Histologically confirmed diagnosis of NSCLC, non epidermoid, stage IV or IIIB with pleural effusion, or N3 tumours not candidate for thoracic radiotherapy, harbouring deletions in the exon 19 or mutation in the exon 21 in the TK of the EGFR.* Either measurable or evaluable disease.* Age \> 18 years.* ECOG performance status \< 2.* Adequate bone marrow function* Adequate renal function* Adequate hepatic function* Patients must be accessible for treatment and follow-up.* Patients capable of following an adequate therapeutic compliance* Women of child bearing potential: negative pregnancy test.* Patients of both genders at a fertile age, including those women having their last menstruation within the two previous years, must follow effective contraceptive measures.* Ability to swallow.* Patients with asymptomatic brain metastasis and stable with medical treatment will be eligible for the study. Patients having received radiotherapy for their brain metastasis prior to the systemic treatment for the NSCLC will be also eligible.* Absence of gastrointestinal tract problemsExclusion criteria:* Pregnant or lactating women.* Women of child bearing potential having a positive pregnancy test in the basal visit or not accomplishing the test.* Patients of both genders sexually active (at a fertile age) not following contraceptive measures during the study.* Prior chemotherapy for metastatic disease. Both prior neoadjuvant and adjuvant chemotherapy allowed provided that completed â‰¥ 6 months before entering the study.* Prior treatment with EGFR targeted therapies.* Patients may have received radiotherapy, provided that the irradiated lesion is not the only evaluable lesion for response and completed before entering the study.* Prior experimental pharmacological agent within the 3 weeks prior to the inclusion of the study.* Any significant ophthalmologic impairment of the eye surface. Use of contact lenses is not recommended.* Pre-existing motor or sensorial neurotoxicity grade \> 2, according to the NCI-CTC criteria.* Evidence of spinal cord compression.* Inability to take oral medication and surgical procedures affecting the absorption or implying intravenous or parenteral feeding.* Any other severe disease or clinical conditions, as, but not only:* Unstable cardiopathy despite treatment, myocardial infarction within the 6 months before entering the study* History of significant neurological or psychiatric disorders, including dementia and epileptic seizures.* Uncontrolled active infection.* Uncontrolled peptic ulcer.* Unstable diabetes mellitus or any other contraindication for treatment with corticosteroids.* AST and/or ALT \> 1.5 x UNL associated to alkaline phosphatase \> 2.5 x UNL.* Any other underlying severe process affecting the ability to take part in the study.* Absolute contraindication for steroids.* Dementia or significant mental disorder interfering the understanding and giving the informed consent.* History of other malignancy except adequately treated basal cell or squamous cell skin cancer, carcinoma in situ of the cervix, radically treated prostatic carcinoma with good prognostic (Gleason = 6). History of other curatively treated malignancy and no evidence of disease within the past 5 years. | BX4: 41010 | BY4: 41244 | BZ4: Interventional | CA4: Allocation: Randomized | Intervention Model: Parallel Assignment | Masking: None (Open Label) () | Primary Purpose: Treatment | CB4: EGFR Exon 19-del, EGFR L858R | CD4: EGFR T790M | CE4: EGFR Exon 19-del, EGFR L858R
A5: Pemetrexed | B5: Alimta | C5: Alimta | D5: Eli Lilly | E5: Eli Lilly | F5: Eli Lilly | G5: Lung cancer - NSCLC | H5: Stage IIIB,Stage IV | I5: Non-squamous NSCLC | J5: First line | K5: Approved | L5: Approved | M5: Phase III | N5: Phase III | O5: Approved | P5: Phase III | Q5: NCT00789373 | S5: Multitargeted antifolate | T5: TS, TYMS | U5: No | V5: No | W5: Yes | Z5: No | AA5: C | AB5: Oncology | AC5: Stopped | AD5: Small molecule | AE5: PARAMOUNT | AF5: Placebo | AG5: PFS | AM5: 0 | AN5: 2.80 | AP5: 2.80 | AR5: Journal of Clinical Oncology Aug 10, 2013 | AS5: 1.3 | AT5: 0.6 | AU5: 13.90 | AV5: 13.90 | AX5: Journal of Clinical Oncology Aug 10, 2013 | AZ5: 2.9 | BA5: 0.78 | BB5: Completed | BC5: 939 | BD5: 39753 | BE5: 40330 | BF5: 40582 | BG5: 40817 | BH5: 7.7 | BI5: 40893 | BJ5: 41199 | BK5: 10 | BR5: 40582 | BS5: 40817 | BT5: 7.7 | BU5: Australia - Belgium - Finland - France - Germany - Greece - India - Italy - Netherlands - Poland - Portugal - Romania - Spain - Turkey - United Kingdom | BV5: A Phase 3, Double-Blind, Placebo-Controlled Study of Maintenance Pemetrexed Plus Best Supportive Care Versus Best Supportive Care Immediately Following Induction Treatment With Pemetrexed + Cisplatin for Advanced Non-squamous Non-Small Cell Lung Cancer. | BW5: Inclusion Criteria for the Induction Phase:* You must sign an informed consent document for clinical research.* You must have Stage IIIB or IV nonsquamous Non-Small Cell Lung Cancer.* You must at least be able to be physically mobile, take care of yourself, and must be up and about and able to perform light activities such as light housework or office work.* You are allowed to have had prior radiation therapy as long as it was not to more than 25% of the bone marrow and did not include the whole pelvis. Thoracic radiation must be completed more than 30 days before the study. You must be recovered from the toxic effects (except hair loss).* You must have at least 1 measurable tumor lesion according to the Response Evaluation Criteria in Solid Tumors (RECIST) guidelines or disease that can be evaluated by computed tomography (CT) Scan.* Your test results assessing the function of your blood forming tissue, kidneys, and liver must be satisfactory.* You must be 18 years of age or older.* Women must be sterile, postmenopausal or on contraception and men must be on contraception or sterile (e.g. post-vasectomy).Exclusion Criteria for the Induction Phase:* You cannot have squamous cell and/or mixed small cell, non-small cell lung cancer* You cannot have received other investigational drugs within the last 30 days of entering the trial.* You cannot have previously completed or withdrawn from this study or any other study investigating pemetrexed.* You cannot have other serious on-going illnesses including active infections.* You cannot have a serious cardiac condition, such as a heart attack, angina, or heart disease within 6 months of entering the trial.* You cannot have had another form of cancer other than superficial basal cell and superficial squamous (skin) cell cancer, or carcinoma in situ of the cervix within the last 5 years. Patients with a history of low-grade (Gleason score less than or equal to 6) localized prostate cancer will be eligible even if diagnosed less than 5 years ago.* You cannot have known central nervous system (CNS) metastases, other than treated, stable brain metastasis.* You cannot be receiving nor have received any prior systemic anticancer therapy for lung cancer (including chemotherapy given after surgery in early-stage treatment).* You cannot have clinically significant third-space fluid collections (e.g. ascites or pleural effusions that cannot be controlled by drainage or other procedures).* You cannot have received a recent (within 30 days) or are receiving a yellow fever vaccination.* You are unable to stop taking more than 1.3 grams of aspirin on a daily basis or other non-steroidal anti-inflammatory drugs (NSAIDs).* You are unable or unwilling to take folic acid, injections of vitamin B12, or corticosteroids.* You cannot be pregnant or breastfeeding.Inclusion criteria at Randomization for the Maintenance Phase:* You must at least be able to be physically mobile, take care of yourself, and must be up and about and able to perform light activities such as light housework or office work.* You must have documented radiographic evidence of a tumor response of complete response (CR), partial response (PR), or stable disease (SD) according to the Response Evaluation Criteria in Solid Tumors (RECIST) guidelines. Tumor assessment must occur between Cycle 4 (Day 1) of induction therapy and the date of randomization. This response does not have to be confirmed in order for the patient to be randomized to the maintenance phase. | BX5: 40330 | BY5: 43040 | BZ5: Interventional | CA5: Allocation: Randomized | Intervention Model: Parallel Assignment | Masking: Quadruple () | Primary Purpose: Treatment
A6: Nab-Paclitaxel | B6: Abraxane | C6: Abraxane | D6: BMS | E6: BMS | F6: BMS | G6: Lung cancer - NSCLC | H6: Stage IIIB,Stage IV | J6: First line | K6: Approved | L6: Approved | M6: Phase III | N6: Phase III | O6: Approved | P6: Phase III | Q6: NCT00540514 | S6: Microtubule inhibitor | U6: No | V6: No | W6: Yes | Z6: No | AA6: C | AB6: Oncology | AC6: Stopped | AD6: Other | AE6: CA031 | AF6: Carboplatino | AG6: ORR | AH6: 33% vs 25% | AI6: 33% | AJ6: 25% | AM6: 8 | AN6: 6.8 vs 6.5 | AO6: 6.8 | AP6: 6.5 | AS6: 0.3 | AT6: 0.95 | AU6: 12.1 vs 11.2 | AV6: 12.1 | AW6: 11.2 | AZ6: 0.9 | BA6: 0.92 | BB6: Completed | BC6: 1052 | BD6: 39387 | BE6: 40695 | BF6: 41796 | BG6: 42064 | BH6: 8.8 | BI6: 40886 | BJ6: 41193 | BK6: 10.1 | BR6: 41796 | BS6: 42064 | BT6: 8.8 | BU6: United States - Canada - Japan - Russian Federation - Ukraine | BV6: A Randomized, Phase III Trial of ABI-007 and Carboplatin Compared With Taxol and Carboplatin as First-Line Therapy in Patients With Advanced Non-Small Cell Lung Cancer (NSCLC) | BW6: Inclusion Criteria:* Histologically or cytologically confirmed stage IIIB or IV non-small cell lung cancer (NSCLC)* Male or non-pregnant and non-lactating female, and equal or greater than age 18* If a female patient is of child-bearing potential, as evidence by regular menstrual periods, she must have a negative serum pregnancy test (beta human chorionic gonadotropin \[βhCG\]) documented within 72 hours of the first administration of study drug* If sexually active, the patient must agree to utilize contraception considered adequate and appropriate by the investigator* No other current active malignancy* Radiographically-documented measurable disease (defined by the presence of at least 1 radiographically documented measurable lesion)* Patients must have received no prior chemotherapy for the treatment of metastatic disease. Adjuvant chemotherapy permitted providing cytotoxic chemotherapy was completed 12 months prior to starting the study* Patient has the following blood counts at baseline:* Absolute neutrophil count (ANC) greater than or equal to 1.5x10\^9/L* Platelets greater than or equal to 100x10\^9/L* Hemoglobin (Hgb) greater than or equal to 9 g/dL* Patient has the following blood chemistry levels at baseline:* Aspartate aminotransferase (SGOT), alanine aminotransferase (SGPT) less than or equal to 2.5 x upper limit of normal range (ULN) or less than or equal to 5.0 x ULN if liver metastases;* Total bilirubin less than or equal to ULN* Creatinine less than or equal to 1.5 mg/dL* Expected survival of greater than 12 weeks* Eastern Cooperative Oncology Group (ECOG) performance status 0 or 1* Patient or his/her legally authorized representative or guardian has been informed about the nature of the study, and has agreed to participate in the study, and signed the Informed Consent form prior to participation in any study-related activitiesExclusion Criteria:* Evidence of active brain metastases, including leptomeningeal involvement. Prior evidence of brain metastasis permitted only if treated and stable and off therapy for greater than or equal to 1 month* The only evidence of disease is non-measurable* Patient has pre-existing peripheral neuropathy of Grade 2, 3, or 4 (per Common Terminology Criteria for Adverse Events \[CTCAE\] Version 3).* Patient received radiotherapy in the last 4 weeks, except if to a non-target lesion only. Prior radiation to a target lesion is permitted only if there has been clear progression of the lesion since radiation was completed* Patient has a clinically significant concurrent illness* Patient has received treatment with any investigational drug within the previous 4 weeks* Patient has a history of allergy or hypersensitivity to any of the study drugs* Patient has serious medical risk factors involving any of the major organ systems such that the investigator considers it unsafe for the patient to receive an experimental research drug* Patient is enrolled in any other clinical protocol or investigational trial that involves administration of experimental therapy and/or therapeutic devices. | BX6: 40087 | BY6: 41306 | BZ6: Interventional | CA6: Allocation: Randomized | Intervention Model: Parallel Assignment | Masking: None (Open Label) () | Primary Purpose: Treatment | CD6: SPARC, Hb
A7: Afatinib | B7: Giotrif | C7: Gilotrif | D7: Boehringer Ingelheim | E7: Boehringer Ingelheim | F7: Boehringer Ingelheim | G7: Lung cancer - NSCLC | H7: Stage IIIB,Stage IV | J7: First line | K7: Approved | L7: Approved | M7: Approved | N7: Approved | O7: Approved | P7: Phase III | Q7: NCT00949650 | S7: EGFR inhibitor | T7: EGFR, EGFR Exon 19-del, EGFR L858R, HER2, HER4 | U7: No | V7: No | W7: Yes | Z7: No | AA7: C | AB7: Oncology | AC7: Ongoing | AD7: Small molecule | AE7: LUX-Lung 3 | AF7: Pemetrexed/Cisplatin | AG7: PFS | AH7: 57% vs 23% | AI7: 57% | AJ7: 23% | AM7: 34 | AN7: 11.2 vs 6.9 | AO7: 11.2 | AP7: 6.9 | AS7: 4.3 | AT7: 0.58 | AU7: 28.2 vs 28.2 | AV7: 28.2 | AW7: 28.2 | AZ7: 0 | BA7: 0.88 | BB7: Completed | BC7: 345 | BD7: 40039 | BE7: 40909 | BF7: 41149 | BG7: 41518 | BH7: 12.1 | BI7: 41228 | BJ7: 41467 | BK7: 7.8 | BL7: 42429 | BM7: 42794 | BN7: 12 | BO7: 41656 | BP7: 41243 | BQ7: 13.5 | BR7: 41149 | BS7: 41518 | BT7: 12.1 | BU7: United States - Argentina - Australia - Austria - Belgium - Brazil - Canada - Chile - China - France - Germany - Hong Kong - Hungary - Ireland - Italy - Japan - Malaysia - Peru - Philippines - Romania - Russian Federation - Singapore - South Korea - Taiwan - Thailand - Ukraine - United Kingdom | BV7: A Randomised, Open-label, Phase III Study of BIBW 2992 Versus Chemotherapy as First-line Treatment for Patients With Stage IIIB or IV Adenocarcinoma of the Lung Harbouring an EGFR Activating Mutation | BW7: Inclusion criteria:* Pathologically confirmed diagnosis of Stage IIIB (with cytologically proven pleural effusion or pericardial effusion) or Stage IV adenocarcinoma of the lung. Patients with mixed histology are eligible if adenocarcinoma is the predominant histology.* Epidermal Growth Factor Receptor mutation detected by central laboratory analysis of tumour biopsy material.* Measurable disease according to RECIST 1.1.* Eastern Cooperative Oncology Group score of 0 or 1.* Age \>/= 18 years.* Life expectancy of at least three months.* Written informed consent that is consistent with International Conference on Harmonisation-Good Clinical Practice guidelines.Exclusion criteria:* Prior chemotherapy for relapsed and/or metastatic NSCLC. Neoadjuvant/adjuvant chemotherapy is permitted if at least 12 months has elapsed between the end of chemotherapy and randomisation.* Prior treatment with Epidermal Growth Factor Receptor targeting small molecules or antibodies.* Radiotherapy or surgery (other than biopsy) within 4 weeks prior to randomisation.* Active brain metastases* Any other current malignancy or malignancy diagnosed within the past five years* Known pre-existing interstitial lung disease.* Significant or recent acute gastrointestinal disorders with diarrhoea as a major symptom.* History or presence of clinically relevant cardiovascular abnormalities.* Any other concomitant serious illness or organ system dysfunction.* Adequate absolute neutrophil count and platelet count* Adequate liver and kidney function* Active hepatitis B infection, active hepatitis C infection or known HIV carrier. | BX7: 40948 | BY7: 42810 | BZ7: Interventional | CA7: Allocation: Randomized | Intervention Model: Parallel Assignment | Masking: None (Open Label) () | Primary Purpose: Treatment | CB7: EGFR, EGFR Exon 19-del, EGFR L858R, EGFR Exon 20-ins, EGFR L861Q, EGFR G719S, EGFR G719A, EGFR G719C, EGFR T790M, EGFR S768I | CD7: EGFR Exon 19-del, EGFR L858R, EGFR Exon 20-ins, EGFR L861Q, EGFR G719S, EGFR G719A, EGFR G719C, EGFR T790M, EGFR S768I | CE7: EGFR
A8: Crizotinib | B8: Xalkori | C8: Xalkori | D8: Pfizer | E8: Pfizer | F8: Pfizer | G8: Lung cancer - NSCLC | H8: Stage III,Stage IV | I8: Non-squamous NSCLC | J8: First line | K8: Approved | L8: Approved | M8: Phase III | N8: Phase III | O8: Approved | P8: Phase III | Q8: NCT01154140 | R8: 2010-021336-33, PER-011-11, JapicCTI-111463, CTR20132985, jRCT2080221424 | S8: c-MET, ALK, ROS1 inhibitor | T8: ALK, c-MET/MET, ROS, ROS1 | U8: No | V8: No | W8: Yes | Z8: No | AA8: D | AB8: Oncology | AC8: Ongoing | AD8: Small molecule | AE8: PROFILE 1014 | AF8: Pemetrexed + Carboplatin/Cisplatin | AG8: PFS | AH8: 74% vs 45% | AI8: 74% | AJ8: 45% | AM8: 29 | AN8: 10.9 vs 7.0 | AO8: 10.9 | AP8: 7.0 | AS8: 3.9 | AT8: 0.45 | AU8: NR vs 47.5 (ns) | AV8: NR | AW8: 47.5 (ns) | AZ8: 0 | BA8: 0.76 | BB8: Completed | BC8: 343 | BD8: 40556 | BE8: 41699 | BF8: 41963 | BG8: 42333 | BH8: 12.1 | BI8: 41957 | BJ8: 42322 | BK8: 12 | BR8: 41963 | BS8: 42333 | BT8: 12.1 | BU8: United States - Australia - Austria - Belgium - Brazil - Canada - Chile - China - Finland - France - Germany - Hong Kong - India - Ireland - Italy - Japan - Luxembourg - Mexico - Netherlands - Norway - Peru - Portugal - Russian Federation - Singapore - South Africa - South Korea - Spain - Switzerland - Taiwan - Ukraine - United Kingdom | BV8: Phase 3, Randomized, Open-label Study Of The Efficacy And Safety Of Crizotinib Versus Pemetrexed/Cisplatin Or Pemetrexed/Carboplatin In Previously Untreated Patients With Non-squamous Carcinoma Of The Lung Harboring A Translocation Or Inversion Event Involving The Anaplastic Lymphoma Kinase (Alk) Gene Locus. | BW8: Inclusion Criteria:* Proven diagnosis of locally advanced not suitable for local treatment, recurrent and metastatic non-squamous cell carcinoma of the lung* Positive for translocation or inversion events involving the ALK gene locus* No prior systemic treatment for locally advanced or metastatic disease; Patients with brain metastases only if treated and neurologically stable with no ongoing requirement for corticosteroids* Evidence of a personally signed and dated informed consent document and willingness and ability to comply with scheduled visits, treatment plans, laboratory tests, and other study procedures including completion of patient reported outcome \[PRO\] measures.* 18 years of age or older with the exception of India which has an upper age limit of 65 years oldExclusion Criteria:* Current treatment on another therapeutic clinical trial.* Prior therapy directly targeting ALK.* Any of the following within the 3 months prior to starting study treatment: myocardial infarction, severe/unstable angina, coronary/peripheral artery bypass graft, congestive heart failure, or cerebrovascular accident including transient ischemic attack. - - Appropriate treatment with anticoagulants is permitted.* Ongoing cardiac dysrhythmias of NCI CTCAE Grade \>=2, uncontrolled atrial fibrillation of any grade, or QTc interval \>470 msec.* Pregnancy or breastfeeding.* Use of drugs or foods that are known potent CYP3A4 inducers/inhibitors Concurrent use of drugs that are CYP3A4 substrates with narrow therapeutic indices.* Known HIV infection* Known interstitial lung disease or interstitial fibrosis* Other severe acute or chronic medical conditions (including severe gastrointestinal conditions such as diarrhea or ulcer) or psychiatric conditions, or laboratory abnormalities that would impart, in the judgment of the investigator and/or sponsor, excess risk associated with study participation or study drug administration, and which would, therefore, make the patient inappropriate for entry into this study | BX8: 41608 | BY8: 42704 | BZ8: Interventional | CA8: Allocation: Randomized | Intervention Model: Parallel Assignment | Masking: None (Open Label) () | Primary Purpose: Treatment | CB8: ALK, EML4-ALK | CD8: ALK, EML4-ALK, c-MET/MET, EGFR, HER2 | CE8: ALK
A9: Necitumumab | B9: Portrazza | C9: Portrazza | D9: Eli Lilly | E9: Eli Lilly | F9: Eli Lilly | G9: Lung cancer - NSCLC | H9: Stage IV | I9: Squamous NSCLC | J9: First line | K9: Approved | L9: Approved | M9: Phase III | N9: Approved | O9: Approved | P9: Phase III | Q9: NCT00981058 | R9: 2009-013838-25 | S9: Anti-EGFR monoclonal antibody | T9: EGFR, ERBB, HER1 | U9: No | V9: No | W9: Yes | Z9: No | AA9: C | AB9: Oncology | AC9: Ongoing | AD9: Monoclonal antibody | AE9: SQUIRE | AF9: Gemcitabine + cisplatin | AG9: OS | AH9: 31% vs 29% | AI9: 31% | AJ9: 29% | AM9: 2 | AN9: 5.7 vs 5.5 | AO9: 5.7 | AP9: 5.5 | AS9: 0.2 | AT9: 0.85 | AU9: 11.5 vs 9.9 | AV9: 11.5 | AW9: 9.9 | AZ9: 1.6 | BA9: 0.84 | BB9: Completed | BC9: 1093 | BD9: 40185 | BE9: 41487 | BF9: 41974 | BG9: 42415 | BH9: 14.5 | BI9: 41975 | BJ9: 42332 | BK9: 11.7 | BO9: 43634 | BP9: 43344 | BQ9: 9.5 | BR9: 41974 | BS9: 42415 | BT9: 14.5 | BU9: United States - Australia - Austria - Belgium - Brazil - Canada - Croatia - France - Germany - Greece - Hungary - Italy - Japan - Philippines - Poland - Portugal - Romania - Russian Federation - Serbia - Singapore - Slovakia - South Africa - South Korea - Spain - Taiwan - Thailand - United Kingdom | BV9: A Randomized, Multicenter, Open-Label Phase 3 Study of Gemcitabine-Cisplatin Chemotherapy Plus Necitumumab (IMC-11F8) Versus Gemcitabine-Cisplatin Chemotherapy Alone in the First-Line Treatment of Patients With Stage IV Squamous Non-Small Cell Lung Cancer (NSCLC) | BW9: Inclusion Criteria:* Has histologically or cytologically confirmed squamous NSCLC* Has Stage IV disease at the time of study entry* Measurable or nonmeasurable disease at the time of study entry as defined by the Response Evaluation Criteria in Solid Tumors (RECIST 1.0) (participants with only truly nonmeasurable disease are not eligible)* Has resolution to Grade ≤ 1 of all clinically significant toxic effects of prior chemotherapy, surgery, radiotherapy, or hormonal therapy (with the exception of alopecia)* Has adequate hepatic function* Has adequate renal function* Has adequate hematologic function* If female, is surgically sterile, postmenopausal, or compliant with a highly effective contraceptive method (failure rate \< 1%) during and for 6 months after the treatment period (oral hormonal contraception alone is not considered highly effective and must be used in combination with a barrier method)* If male, the participant is surgically sterile or compliant with a highly effective contraceptive regimen during and for 6 months after the treatment period* Female participants of childbearing potential must have a negative serum pregnancy test within 7 days prior to randomization* Has archived tumor tissue available for analysis of EGFR and KRAS mutation status (by PCR) and EGFR gene copy number (by FISH); minimum of four slides, paraffin-embedded tissue, requiredExclusion Criteria:* Has nonsquamous NSCLC (adenocarcinoma/large cell or other)* Has received prior anticancer therapy with monoclonal antibodies, signal transduction inhibitors, or any therapies targeting the EGFR, vascular endothelial growth factor (VEGF), or VEGF receptor* Has received previous chemotherapy for advanced NSCLC (participants who have received adjuvant chemotherapy are eligible if the last administration of the prior adjuvant regimen occurred at least 1 year prior to randomization)* Has undergone major surgery or received any investigational therapy in the 4 weeks prior to randomization* Has undergone chest irradiation within 12 weeks prior to randomization (except palliative irradiation of bone lesions, which is allowed)* Has brain metastases that are symptomatic or require ongoing treatment with steroids or anticonvulsants. Participants who have undergone previous radiotherapy for brain metastases, who are now nonsymptomatic and no longer require treatment with steroids or anticonvulsants, are eligible* Has superior vena cava syndrome contraindicating hydration* Has current clinically-relevant coronary artery disease or uncontrolled congestive heart failure* Has experienced myocardial infarction within 6 months prior to randomization* Has an ongoing or active infection (requiring antibiotics), including active tuberculosis or known infection with the human immunodeficiency virus* Has a history of significant neurological or psychiatric disorders, including dementia, seizures, or bipolar disorder* Has any National Cancer Institute - Common Terminology Criteria for Adverse Events (NCI-CTCAE) Version 3.0 Grade ≥ 2 peripheral neuropathy* Has significant third space fluid retention, requiring repeated drainage* Has any other serious uncontrolled medical disorders or psychological conditions that would, in the opinion of the investigator, limit the participant's ability to complete the study or sign an informed consent document* Has a known allergy / history of hypersensitivity reaction to any of the treatment components, including any ingredient used in the formulation of necitumumab (IMC-11F8), or any other contraindication to one of the administered treatments* Is pregnant or breastfeeding* Has a known history of drug abuse* Has a concurrent active malignancy other than adequately-treated basal cell carcinoma of the skin or preinvasive carcinoma of the cervix. A participant with previous history of malignancy other than NSCLC is eligible, provided that he/she has been free of disease for ≥ 3 years | BX9: 41442 | BY9: 45442 | BZ9: Interventional | CA9: Allocation: Randomized | Intervention Model: Parallel Assignment | Masking: None (Open Label) () | Primary Purpose: Treatment | CD9: EGFR, KRAS
A10: Pembrolizumab | B10: Keytruda | C10: Keytruda | D10: MSD | E10: Merck | F10: Merck/MSD | G10: Lung cancer - NSCLC | H10: Stage IV | I10: Squamous NSCLC, Non-squamous NSCLC | J10: First line | K10: Approved | L10: Approved | M10: Phase III | N10: Approved | O10: Approved | P10: Phase III | Q10: NCT02142738 | R10: 2014-000323-25 | S10: Anti-PD-1 monoclonal antibody | T10: CD279, PD-1 | U10: Yes | V10: No | W10: Yes | Z10: No | AA10: A | AB10: Oncology | AC10: Ongoing | AD10: Monoclonal antibody | AE10: KEYNOTE-024 | AF10: Gemcitabine + pemetrexed | AG10: PFS | AH10: 46.0% | AI10: 46.0% | AK10: Journal of Clinical Oncology Apr 19, 2021 | AM10: 15 | AN10: 7.70 | AP10: 7.70 | AR10: Journal of Clinical Oncology Apr 19, 2021 | AS10: 2.2 | AT10: 0.5 | AU10: 26.30 vs 13.40 | AV10: 26.30 | AW10: 13.40 | AX10: Journal of Clinical Oncology Apr 19, 2021 | AY10: MSD Oct 20, 2025 | AZ10: 12.9 | BA10: 0.62 | BB10: Completed | BC10: 305 | BD10: 41876 | BE10: 42522 | BF10: 42620 | BG10: 42766 | BH10: 4.8 | BI10: 42545 | BJ10: 42667 | BK10: 4 | BO10: 42723 | BP10: 42649 | BQ10: 2.4 | BR10: 42620 | BS10: 42766 | BT10: 4.8 | BU10: United States - Australia - Austria - Belgium - Brazil - Canada - China - France - Germany - Hong Kong - Hungary - Ireland - Israel - Italy - Japan - Netherlands - New Zealand - Poland - Singapore - South Korea - Spain - United Kingdom | BV10: A Randomized Open-Label Phase III Trial of Pembrolizumab Versus Platinum Based Chemotherapy in 1L Subjects With PD-L1 Strong Metastatic Non-Small Cell Lung Cancer | BW10: Inclusion Criteria:* Histological or cytological diagnosis of Stage IV NSCLC lacking epidermal growth factor receptor (EGFR)-sensitizing mutation and/or anaplastic lymphoma kinase (ALK) translocation, and received no prior systemic chemotherapy treatment for their metastatic NSCLC* At least one radiographically measurable lesion per RECIST 1.1* Life expectancy of at least 3 months* Performance status of 0 or 1 on the Eastern Cooperative Oncology Group (ECOG) Performance Status* Adequate organ function* No history of prior malignancy, with the exception of basal cell carcinoma of the skin, superficial bladder cancer, squamous cell carcinoma of the skin, or in situ cervical cancer, or has undergone potentially curative therapy with no evidence of that disease recurrence for 5 years since initiation of that therapy* Provided newly obtained formalin fixed tumor tissue from a biopsy of a tumor at the time of or AFTER the diagnosis of metastatic disease has been made AND from a site not previously irradiated* PD-L1 strong expressing tumor as determined by immunohistochemistry (IHC) at a central laboratory* Female participants must have a negative pregnancy test at screening if of childbearing potential or be of non-childbearing potential* Female participants of childbearing potential and male partners with female partners of childbearing potential must agree to use 2 adequate barrier methods of contraception during the study and for 120 days after last dose of study drug and up to 180 days after last dose of chemotherapyExclusion Criteria:* EGFR sensitizing mutation and/or ALK translocation* Has received systemic therapy for the treatment of their stage IV NSCLC. Completion of treatment with chemotherapy and/or radiation as part of neoadjuvant/adjuvant therapy is allowed as long as therapy was completed at least 6 months prior to the diagnosis of metastatic disease.* Currently participating or has participated in a study of an investigational agent or using an investigational device within 4 weeks of first dose of study drug* Tumor specimen is not evaluable for PD-L1 expression by the central laboratory* Receiving systemic steroid therapy \< 3 days prior to first dose of study drug or receiving any other form of immunosuppressive medication* Expected to require any other form of systemic or localized antineoplastic therapy during the study* Received prior systemic cytotoxic chemotherapy, biological therapy, major surgery within 3 weeks of first dose of study drug; received thoracic radiation therapy of \> 30 gray (Gy) within 6 months of first dose of study drug* Received prior therapy with an anti-programmed cell death protein 1 (anti-PD-1), anti-PD-L1, anti-programmed cell death-ligand 2 (anti-PD-L2), anti-CD137 (4-1BB ligand, a member of the Tumor Necrosis Factor Receptor \[TNFR\] family), or anti-Cytotoxic T-lymphocyte-associated antigen-4 (anti-CTLA-4) antibody (including ipilimumab or any other antibody or drug specifically targeting T-cell co-stimulation or checkpoint pathways)* Has untreated central nervous system (CNS) metastases and/or carcinomatous meningitis* Active autoimmune disease that has required systemic treatment in past 2 years* Allogenic tissue/solid organ transplant* Interstitial lung disease or pneumonitis that has required oral or IV steroids* Received or will receive a live vaccine within 30 days prior to first dose of study drug* Active infection requiring IV systemic therapy* Known history of human immunodeficiency virus (HIV)* Known active tuberculosis, or hepatitis B or C* Known psychiatric or substance abuse disorders that would interfere with cooperation with the requirements of the study* Is, at the time of signing informed consent, a regular user (including "recreational use") of any illicit drugs or had a recent history (within the last year) of substance abuse (including alcohol)* Pregnant or breastfeeding, or expecting to conceive or father children during the study and through 120 days after last dose of pembrolizumab or 180 days after last dose of SOC chemotherapy* Immediate family member who is investigational site or sponsor staff directly involved with this study | BX10: 42499 | BY10: 44343 | BZ10: Interventional | CA10: Allocation: Randomized | Intervention Model: Parallel Assignment | Masking: None (Open Label) () | Primary Purpose: Treatment | CB10: PD-L1 TPS ≥ 50% | CC10: ALK, EGFR | CE10: PD-L1 TPS ≥ 50%
A11: Ceritinib | B11: Zykadia | C11: Zykadia | D11: Novartis | E11: Novartis | F11: Novartis | G11: Lung cancer - NSCLC | H11: Stage IIIB,Stage IV | I11: Non-squamous NSCLC | J11: First line | K11: Approved | L11: Approved | M11: Approved | N11: Phase III | O11: Approved | P11: Phase III | Q11: NCT01828099 | R11: 2013-000319-26, JapicCTI-132204, LBCTR2019121370, jRCT2080222158 | S11: ALK inhibitor | T11: ALK | U11: No | V11: No | W11: Yes | Z11: No | AA11: D | AB11: Oncology | AC11: Ongoing | AD11: Small molecule | AE11: ASCEND-4 | AF11: Pemetrexed + cisplatin | AG11: PFS | AH11: 73.0% vs 27.0% | AI11: 73.0% | AJ11: 27.0% | AK11: EU label Jun 29, 2017 | AL11: EU label Jun 29, 2017 | AM11: 46 | AN11: 16.60 | AP11: 16.60 | AR11: EU label Jun 29, 2017 | AS11: 8.5 | AT11: 0.55 | AZ11: 0 | BB11: Completed | BC11: 376 | BD11: 41464 | BE11: 42614 | BF11: 42709 | BG11: 42915 | BH11: 6.8 | BI11: 42702 | BJ11: 42881 | BK11: 5.9 | BL11: 43479 | BM11: 43985 | BN11: 16.6 | BR11: 42709 | BS11: 42915 | BT11: 6.8 | BU11: Argentina - Australia - Austria - Brazil - China - Colombia - Denmark - France - Germany - Greece - Hungary - India - Ireland - Italy - Japan - Lebanon - Mexico - Netherlands - New Zealand - Norway - Poland - Russian Federation - Singapore - South Korea - Spain - Sweden - Taiwan - Thailand - Turkey - United Kingdom | BV11: A Phase III Multicenter, Randomized Study of Oral LDK378 Versus Standard Chemotherapy in Previously Untreated Adult Patients With ALK Rearranged (ALK-positive), Stage IIIB or IV, Non-squamous Non-small Cell Lung Cancer | BW11: Key Inclusion Criteria:1. The patient had a histologically or cytologically confirmed diagnosis of non-squamous Non-small cell lung cancer (NSCLC) that was Anaplastic lymphoma kinase (ALK) positive as assessed by the Ventana Immunohistochemistry (IHC) test. The test was performed at Novartis designated central laboratories.2. The patient had a newly diagnosed stage IIIB (who was not a candidate for definitive multimodality therapy) or stage IV NSCLC or relapsed locally advanced or metastatic NSCLC not previously treated with any systemic anti-cancer therapy (e.g. cytotoxic drugs, monoclonal antibody therapy, crizotinib or other ALK inhibitors, or other targeted therapies, either experimental or not), with the exception of neo-adjuvant or adjuvant therapy.3. The patient had at least one measurable lesion as defined by RECIST 1.1.Key Exclusion Criteria:1. The patient had known hypersensitivity to any of the excipients of LDK378 (microcrystalline cellulose, mannitol, crospovidone, colloidal silicon dioxide, and magnesium stearate).2. The patient had a history of severe hypersensitivity reaction to platinum-containing drugs, pemetrexed, or any known excipients of these drugs.3. The patient had symptomatic central nervous system (CNS) metastases and was neurologically unstable or had required increasing doses of steroids within the 2 weeks prior to screening to manage CNS symptoms. | BX11: 42545 | BY11: 45298 | BZ11: Interventional | CA11: Allocation: Randomized | Intervention Model: Parallel Assignment | Masking: None (Open Label) () | Primary Purpose: Treatment | CB11: ALK | CE11: ALK
A12: Bevacizumab | B12: Mvasi | C12: Mvasi | D12: Amgen | E12: Amgen | F12: Amgen | G12: Lung cancer - NSCLC | H12: Stage IV | I12: Non-squamous NSCLC | J12: First line | K12: Approved | L12: Approved | M12: Phase III | N12: Approved | O12: Approved | P12: Phase III | Q12: NCT01966003 | R12: 2013-000738-36 | S12: Anti-VEGF monoclonal antibody | T12: VEGF | U12: No | V12: Yes | W12: Yes | Z12: No | AA12: E | AB12: Oncology | AC12: Ongoing | AD12: Monoclonal antibody | AE12: MAPLE | AF12: Bevacizumab | AG12: ORR | AH12: 39% vs 42% | AI12: 39% | AJ12: 42% | AM12: -3 | AS12: 0 | AT12: 1.03 | AZ12: 0 | BB12: Completed | BC12: 642 | BD12: 41589 | BE12: 42248 | BF12: 42705 | BG12: 43119 | BH12: 13.6 | BI12: 42688 | BJ12: 42992 | BK12: 10 | BO12: 43728 | BP12: 43378 | BQ12: 11.5 | BR12: 42705 | BS12: 43119 | BT12: 13.6 | BU12: United States - Australia - Bulgaria - Germany - Hungary - Japan - Romania - Russian Federation - Spain - United Kingdom | BV12: A Randomized, Double-blind, Phase 3 Study Evaluating the Efficacy and Safety of ABP 215 Compared With Bevacizumab in Subjects With Advanced Non-Small Cell Lung Cancer | BW12: Inclusion Criteria:* Histologically or cytologically confirmed non-squamous non-small cell lung cancer (NSCLC)* Subjects must be initiating first-line carboplatin/paclitaxel chemotherapy within 8 days after randomization and expected to receive at least 4 cycles of chemotherapy* Eastern Cooperative Oncology Group (ECOG) performance status score 0 or 1Exclusion Criteria:* Small cell lung cancer (SCLC) or mixed SCLC and NSCLC* Central nervous system (CNS) metastases* Malignancy other than NSCLC* Palliative radiotherapy for bone lesions inside the thorax* Prior radiotherapy of bone marrow* Known to be positive for hepatitis B surface antigen (HbsAg), hepatitis C virus (HCV), or human immunodeficiency virus (HIV)* Life expectancy \< 6 months* Woman of child-bearing potential who is pregnant or is breast feeding or who is not consenting to use highly effective methods of birth control during treatment and for an additional 6 months after the last administration of the protocol specified treatment* Man with a partner of childbearing potential who does not consent to use highly effective methods of birth control during treatment and for an additional 6 months after the last administration of the protocol specified treatment* Subject has known sensitivity to any of the products to be administered during the study, including mammalian cell derived drug products* Other inclusion/exclusion criteria may apply | BX12: 42208 | BY12: 42208 | BZ12: Interventional | CA12: Allocation: Randomized | Intervention Model: Parallel Assignment | Masking: Quadruple () | Primary Purpose: Treatment | CD12: EGFR, ALK
A13: Alectinib | B13: Alecensa | C13: Alecensa | D13: Roche | E13: Genentech | F13: Roche/Genentech | G13: Lung cancer - NSCLC | H13: Stage IIIB,Stage IV | J13: First line | K13: Approved | L13: Approved | M13: Approved | N13: Phase III | O13: Approved | P13: Phase III | Q13: NCT02075840 | R13: PER-064-14, SNCTP000001146, 2023-506859-13-00, CTR20150592 | S13: ALK inhibitor | T13: ALK, ALK L1196M | U13: No | V13: No | W13: Yes | Z13: No | AA13: C | AB13: Oncology | AC13: Ongoing | AD13: Small molecule | AE13: ALEX | AF13: Crizotinib | AG13: PFS | AM13: 0 | AN13: 10.90 | AP13: 10.90 | AR13: Annals of Oncology May 10, 2020 | AS13: 23.9 | AT13: 0.43 | AU13: 81.10 vs 54.20 | AV13: 81.10 | AW13: 54.20 | AX13: ESMO Oct 17, 2025 | AY13: ESMO Oct 17, 2025 | AZ13: 0 | BA13: 0.78 | BB13: Completed | BC13: 303 | BD13: 41870 | BE13: 42826 | BF13: 42840 | BG13: 43089 | BH13: 8.2 | BI13: 42889 | BJ13: 43045 | BK13: 5.1 | BL13: 43133 | BM13: 43332 | BN13: 6.5 | BR13: 42840 | BS13: 43089 | BT13: 8.2 | BU13: United States - Australia - Belgium - Bosnia and Herzegovina - Brazil - Canada - Chile - China - Costa Rica - Denmark - Dominican Republic - Egypt - France - Germany - Greece - Guatemala - Hong Kong - Israel - Italy - Mexico - Netherlands - New Zealand - Peru - Poland - Portugal - Russian Federation - Serbia - Singapore - South Korea - Spain - Switzerland - Taiwan - Thailand - Turkey - Ukraine - United Kingdom | BV13: Randomized, Multicenter, Phase III, Open-Label Study of Alectinib Versus Crizotinib in Treatment-Naive Anaplastic Lymphoma Kinase-Positive Advanced Non-Small Cell Lung Cancer | BW13: Inclusion Criteria:* Histologically or cytologically confirmed diagnosis of advanced or recurrent (Stage IIIB not amenable for multimodality treatment) or metastatic (Stage IV) NSCLC that is ALK-positive as assessed by the Ventana immunohistochemistry (IHC) test* Life expectancy of at least 12 weeks* Eastern cooperative oncology group performance status (ECOG PS) of 0-2* Participants with no prior systemic treatment for advanced or recurrent (Stage IIIB not amenable for multimodality treatment) or metastatic (Stage IV) NSCLC* Adequate renal, and hematologic function* Participants must have recovered from effects of any major surgery or significant traumatic injury at least 28 days before the first dose of study treatment* Measurable disease by response evaluation criteria in solid tumors (RECIST) version 1.1 (v1.1) prior to the administration of study treatment* Prior brain or leptomeningeal metastases allowed if asymptomatic (e.g., diagnosed incidentally at study baseline)* Negative pregnancy test for all females of child bearing potential* Use of highly effective contraception as defined by the study protocolExclusion Criteria:* Participants with a previous malignancy within the past 3 years* Any gastrointestinal (GI) disorder or liver disease* National cancer institute common terminology criteria for adverse events (NCI CTCAE) (version 4.0) Grade 3 or higher toxicities due to any prior therapy (e.g., radiotherapy) (excluding alopecia)* History of organ transplant* Co-administration of anti-cancer therapies other than those administered in this study* Participants with baseline QTc greater than (\>) 470 milliseconds or symptomatic bradycardia* Recipient of strong/potent cytochrome P4503A inhibitors or inducers within 14 days prior to the first dose until the end of study treatment* Recipient of any drug with potential QT interval prolonging effects within 14 days prior to the first dose for all participants and while on treatment through the end of the study for crizotinib-treated participants only* History of hypersensitivity to any of the additives in the alectinib and crizotinib drug formulation* Pregnancy or lactation* Any clinically significant disease or condition (or history of) that could interfere with, or for which the treatment might interfere with, the conduct of the study or the absorption of oral medications or that would, in the opinion of the principal investigator, pose an unacceptable risk to the participant in this study* Any psychological, familial, sociological, or geographical condition potentially hampering compliance with the study protocol requirements and/or follow-up procedures; those conditions should be discussed with the participant before trial entry | BX13: 42775 | BY13: 45775 | BZ13: Interventional | CA13: Allocation: Randomized | Intervention Model: Parallel Assignment | Masking: None (Open Label) () | Primary Purpose: Treatment | CB13: ALK | CD13: ALK, EML4-ALK, ctDNA/cfDNA, EGFR, KRAS, TP53 | CE13: ALK
A14: Durvalumab | B14: Imfinzi | C14: Imfinzi | D14: AstraZeneca | E14: AstraZeneca | F14: AstraZeneca | G14: Lung cancer - NSCLC | H14: Stage III | J14: First line | K14: Approved | L14: Approved | M14: Approved | N14: Approved | O14: Approved | P14: Phase III | Q14: NCT02125461 | R14: 2014-000336-42, PER-054-14, jRCT2080222682 | S14: Anti-PD-L1 monoclonal antibody | T14: B7-H1, CD274, PD-L1 | U14: Yes | V14: No | W14: Yes | Z14: No | AA14: B | AB14: Oncology | AC14: Ongoing | AD14: Monoclonal antibody | AE14: PACIFIC | AF14: Placebo | AG14: PFS + OS | AH14: 28.0% | AI14: 28.0% | AK14: ESMO Sep 9, 2017 | AM14: 12 | AN14: 16.90 | AP14: 16.90 | AR14: Journal of Clinical Oncology Feb 2, 2022 | AS14: 11.6 | AT14: 0.55 | AU14: 29.10 | AV14: 29.10 | AX14: Journal of Clinical Oncology Feb 2, 2022 | AZ14: 16.4 | BA14: 0.72 | BB14: Completed | BC14: 713 | BD14: 41766 | BE14: 42856 | BF14: 42979 | BG14: 43367 | BH14: 12.7 | BI14: 42963 | BJ14: 43147 | BK14: 6 | BL14: 43405 | BM14: 43811 | BN14: 13.3 | BO14: 43283 | BP14: 42977 | BQ14: 10 | BR14: 42979 | BS14: 43367 | BT14: 12.7 | BU14: United States - Australia - Austria - Belgium - Canada - Chile - China - France - Germany - Greece - Hungary - Israel - Italy - Japan - Mexico - Netherlands - Norway - Peru - Poland - Singapore - Slovakia - South Africa - South Korea - Spain - Taiwan - Thailand - Turkey - United Kingdom - Vietnam | BV14: A Phase III, Randomised, Double-blind, Placebo-controlled, Multi-centre, International Study of MEDI4736 as Sequential Therapy in Patients With Locally Advanced, Unresectable Non-Small Cell Lung Cancer (Stage III) Who Have Not Progressed Following Definitive, Platinum-based, Concurrent Chemoradiation Therapy (PACIFIC) | BW14: Inclusion Criteria:1. Age at least 18 years.2. Documented evidence of NSCLC (locally advanced, unresectable, Stage III)3. Patients must have received at least 2 cycles of platinum-based chemotherapy concurrent with radiation therapy.4. World Health Organisation (WHO) Performance Status of 0 to 1.5. Estimated life expectancy of more than 12 weeks.Exclusion Criteria:1. Prior exposure to any anti-PD-1 or anti-PD-L1 antibody.2. Active or prior autoimmune disease or history of immunodeficiency.3. Evidence of severe or uncontrolled systemic diseases, including active bleeding diatheses or active infections including hepatitis B, C and HIV.4. Evidence of uncontrolled illness such as symptomatic congestive heart failure, uncontrolled hypertension or unstable angina pectoris.5. Any unresolved toxicity CTCAE \>Grade 2 from the prior chemoradiation therapy.6. Active or prior documented inflammatory bowel disease (eg, Crohn's disease, ulcerative colitis). | BX14: 42779 | BY14: 45162 | BZ14: Interventional | CA14: Allocation: Randomized | Intervention Model: Parallel Assignment | Masking: Quadruple () | Primary Purpose: Treatment | CD14: PD-L1, GEP, IFN-γ, TNF-α, IL-2, IL-6, IL-10, IL-8, IL-12, CTLA-4, CD3, CD4, CD8, CD45RO, FOXP3, GZMB, OX40, PD-1, Caspase-3, Ki-67, EGFR, KRAS, NRAS, BRAF, ALK, c-MET/MET, miRNA, EGFR Exon 19-del, EGFR L858R, EGFR S768I, EGFR T790M, EGFR Exon 18
