Workbook

Sheet Cover
A1: Pharma Monthly Tracker
A4: Date Range: Jan 01, 1985 to Mar 31, 2026 | Generated: April 12, 2026
B7: Module Status
B8: Module | C8: Details | D8: Status
B9: Clinical Trials | C9: Not selected | D9: SKIPPED
B10: FDA Novel Approvals | C10: 1574 novel approvals | D10: OK
B11: FDA Biosimilars | C11: Not selected | D11: SKIPPED
B12: NIH Outlays | C12: Not selected | D12: SKIPPED
B15: Report Contents
B16: Charts
C17: FDA Charts
B18: Summary
C19: FDA Approval Summary
B20: Database
C21: Novel Approval Database
C22: Biosimilar Approval Database

Sheet ── Charts ──
A1: Charts

Sheet FDA Charts

Sheet ── Summary ──
A1: Summary

Sheet FDA Approval Summary
A1: Data pulled: 04/12/2026
A3: A) Annual Novel Approval Summary (CDER)
A4: Year | B4: Chemical (NDA) | C4: Biologics (BLA) | D4: Total
A5: 1985 | B5: =COUNTIFS('Novel Approval Database'!$G$3:$G$1576,1985,'Novel Approval Database'!$C$3:$C$1576,"NDA",'Novel Approval Database'!$A$3:$A$1576,"CDER") -> 31 | C5: =COUNTIFS('Novel Approval Database'!$G$3:$G$1576,1985,'Novel Approval Database'!$C$3:$C$1576,"BLA",'Novel Approval Database'!$A$3:$A$1576,"CDER") -> 0 | D5: =B5+C5 -> 31
A6: 1986 | B6: =COUNTIFS('Novel Approval Database'!$G$3:$G$1576,1986,'Novel Approval Database'!$C$3:$C$1576,"NDA",'Novel Approval Database'!$A$3:$A$1576,"CDER") -> 20 | C6: =COUNTIFS('Novel Approval Database'!$G$3:$G$1576,1986,'Novel Approval Database'!$C$3:$C$1576,"BLA",'Novel Approval Database'!$A$3:$A$1576,"CDER") -> 3 | D6: =B6+C6 -> 23
A7: 1987 | B7: =COUNTIFS('Novel Approval Database'!$G$3:$G$1576,1987,'Novel Approval Database'!$C$3:$C$1576,"NDA",'Novel Approval Database'!$A$3:$A$1576,"CDER") -> 21 | C7: =COUNTIFS('Novel Approval Database'!$G$3:$G$1576,1987,'Novel Approval Database'!$C$3:$C$1576,"BLA",'Novel Approval Database'!$A$3:$A$1576,"CDER") -> 1 | D7: =B7+C7 -> 22
A8: 1988 | B8: =COUNTIFS('Novel Approval Database'!$G$3:$G$1576,1988,'Novel Approval Database'!$C$3:$C$1576,"NDA",'Novel Approval Database'!$A$3:$A$1576,"CDER") -> 20 | C8: =COUNTIFS('Novel Approval Database'!$G$3:$G$1576,1988,'Novel Approval Database'!$C$3:$C$1576,"BLA",'Novel Approval Database'!$A$3:$A$1576,"CDER") -> 0 | D8: =B8+C8 -> 20
A9: 1989 | B9: =COUNTIFS('Novel Approval Database'!$G$3:$G$1576,1989,'Novel Approval Database'!$C$3:$C$1576,"NDA",'Novel Approval Database'!$A$3:$A$1576,"CDER") -> 23 | C9: =COUNTIFS('Novel Approval Database'!$G$3:$G$1576,1989,'Novel Approval Database'!$C$3:$C$1576,"BLA",'Novel Approval Database'!$A$3:$A$1576,"CDER") -> 4 | D9: =B9+C9 -> 27
A10: 1990 | B10: =COUNTIFS('Novel Approval Database'!$G$3:$G$1576,1990,'Novel Approval Database'!$C$3:$C$1576,"NDA",'Novel Approval Database'!$A$3:$A$1576,"CDER") -> 22 | C10: =COUNTIFS('Novel Approval Database'!$G$3:$G$1576,1990,'Novel Approval Database'!$C$3:$C$1576,"BLA",'Novel Approval Database'!$A$3:$A$1576,"CDER") -> 2 | D10: =B10+C10 -> 24
A11: 1991 | B11: =COUNTIFS('Novel Approval Database'!$G$3:$G$1576,1991,'Novel Approval Database'!$C$3:$C$1576,"NDA",'Novel Approval Database'!$A$3:$A$1576,"CDER") -> 29 | C11: =COUNTIFS('Novel Approval Database'!$G$3:$G$1576,1991,'Novel Approval Database'!$C$3:$C$1576,"BLA",'Novel Approval Database'!$A$3:$A$1576,"CDER") -> 3 | D11: =B11+C11 -> 32
A12: 1992 | B12: =COUNTIFS('Novel Approval Database'!$G$3:$G$1576,1992,'Novel Approval Database'!$C$3:$C$1576,"NDA",'Novel Approval Database'!$A$3:$A$1576,"CDER") -> 27 | C12: =COUNTIFS('Novel Approval Database'!$G$3:$G$1576,1992,'Novel Approval Database'!$C$3:$C$1576,"BLA",'Novel Approval Database'!$A$3:$A$1576,"CDER") -> 2 | D12: =B12+C12 -> 29
A13: 1993 | B13: =COUNTIFS('Novel Approval Database'!$G$3:$G$1576,1993,'Novel Approval Database'!$C$3:$C$1576,"NDA",'Novel Approval Database'!$A$3:$A$1576,"CDER") -> 24 | C13: =COUNTIFS('Novel Approval Database'!$G$3:$G$1576,1993,'Novel Approval Database'!$C$3:$C$1576,"BLA",'Novel Approval Database'!$A$3:$A$1576,"CDER") -> 3 | D13: =B13+C13 -> 27
A14: 1994 | B14: =COUNTIFS('Novel Approval Database'!$G$3:$G$1576,1994,'Novel Approval Database'!$C$3:$C$1576,"NDA",'Novel Approval Database'!$A$3:$A$1576,"CDER") -> 20 | C14: =COUNTIFS('Novel Approval Database'!$G$3:$G$1576,1994,'Novel Approval Database'!$C$3:$C$1576,"BLA",'Novel Approval Database'!$A$3:$A$1576,"CDER") -> 3 | D14: =B14+C14 -> 23
A15: 1995 | B15: =COUNTIFS('Novel Approval Database'!$G$3:$G$1576,1995,'Novel Approval Database'!$C$3:$C$1576,"NDA",'Novel Approval Database'!$A$3:$A$1576,"CDER") -> 29 | C15: =COUNTIFS('Novel Approval Database'!$G$3:$G$1576,1995,'Novel Approval Database'!$C$3:$C$1576,"BLA",'Novel Approval Database'!$A$3:$A$1576,"CDER") -> 1 | D15: =B15+C15 -> 30
A16: 1996 | B16: =COUNTIFS('Novel Approval Database'!$G$3:$G$1576,1996,'Novel Approval Database'!$C$3:$C$1576,"NDA",'Novel Approval Database'!$A$3:$A$1576,"CDER") -> 51 | C16: =COUNTIFS('Novel Approval Database'!$G$3:$G$1576,1996,'Novel Approval Database'!$C$3:$C$1576,"BLA",'Novel Approval Database'!$A$3:$A$1576,"CDER") -> 8 | D16: =B16+C16 -> 59
A17: 1997 | B17: =COUNTIFS('Novel Approval Database'!$G$3:$G$1576,1997,'Novel Approval Database'!$C$3:$C$1576,"NDA",'Novel Approval Database'!$A$3:$A$1576,"CDER") -> 37 | C17: =COUNTIFS('Novel Approval Database'!$G$3:$G$1576,1997,'Novel Approval Database'!$C$3:$C$1576,"BLA",'Novel Approval Database'!$A$3:$A$1576,"CDER") -> 5 | D17: =B17+C17 -> 42
A18: 1998 | B18: =COUNTIFS('Novel Approval Database'!$G$3:$G$1576,1998,'Novel Approval Database'!$C$3:$C$1576,"NDA",'Novel Approval Database'!$A$3:$A$1576,"CDER") -> 28 | C18: =COUNTIFS('Novel Approval Database'!$G$3:$G$1576,1998,'Novel Approval Database'!$C$3:$C$1576,"BLA",'Novel Approval Database'!$A$3:$A$1576,"CDER") -> 8 | D18: =B18+C18 -> 36
A19: 1999 | B19: =COUNTIFS('Novel Approval Database'!$G$3:$G$1576,1999,'Novel Approval Database'!$C$3:$C$1576,"NDA",'Novel Approval Database'!$A$3:$A$1576,"CDER") -> 34 | C19: =COUNTIFS('Novel Approval Database'!$G$3:$G$1576,1999,'Novel Approval Database'!$C$3:$C$1576,"BLA",'Novel Approval Database'!$A$3:$A$1576,"CDER") -> 3 | D19: =B19+C19 -> 37
A20: 2000 | B20: =COUNTIFS('Novel Approval Database'!$G$3:$G$1576,2000,'Novel Approval Database'!$C$3:$C$1576,"NDA",'Novel Approval Database'!$A$3:$A$1576,"CDER") -> 25 | C20: =COUNTIFS('Novel Approval Database'!$G$3:$G$1576,2000,'Novel Approval Database'!$C$3:$C$1576,"BLA",'Novel Approval Database'!$A$3:$A$1576,"CDER") -> 4 | D20: =B20+C20 -> 29
A21: 2001 | B21: =COUNTIFS('Novel Approval Database'!$G$3:$G$1576,2001,'Novel Approval Database'!$C$3:$C$1576,"NDA",'Novel Approval Database'!$A$3:$A$1576,"CDER") -> 24 | C21: =COUNTIFS('Novel Approval Database'!$G$3:$G$1576,2001,'Novel Approval Database'!$C$3:$C$1576,"BLA",'Novel Approval Database'!$A$3:$A$1576,"CDER") -> 5 | D21: =B21+C21 -> 29
A22: 2002 | B22: =COUNTIFS('Novel Approval Database'!$G$3:$G$1576,2002,'Novel Approval Database'!$C$3:$C$1576,"NDA",'Novel Approval Database'!$A$3:$A$1576,"CDER") -> 17 | C22: =COUNTIFS('Novel Approval Database'!$G$3:$G$1576,2002,'Novel Approval Database'!$C$3:$C$1576,"BLA",'Novel Approval Database'!$A$3:$A$1576,"CDER") -> 6 | D22: =B22+C22 -> 23
A23: 2003 | B23: =COUNTIFS('Novel Approval Database'!$G$3:$G$1576,2003,'Novel Approval Database'!$C$3:$C$1576,"NDA",'Novel Approval Database'!$A$3:$A$1576,"CDER") -> 20 | C23: =COUNTIFS('Novel Approval Database'!$G$3:$G$1576,2003,'Novel Approval Database'!$C$3:$C$1576,"BLA",'Novel Approval Database'!$A$3:$A$1576,"CDER") -> 7 | D23: =B23+C23 -> 27
A24: 2004 | B24: =COUNTIFS('Novel Approval Database'!$G$3:$G$1576,2004,'Novel Approval Database'!$C$3:$C$1576,"NDA",'Novel Approval Database'!$A$3:$A$1576,"CDER") -> 27 | C24: =COUNTIFS('Novel Approval Database'!$G$3:$G$1576,2004,'Novel Approval Database'!$C$3:$C$1576,"BLA",'Novel Approval Database'!$A$3:$A$1576,"CDER") -> 8 | D24: =B24+C24 -> 35
A25: 2005 | B25: =COUNTIFS('Novel Approval Database'!$G$3:$G$1576,2005,'Novel Approval Database'!$C$3:$C$1576,"NDA",'Novel Approval Database'!$A$3:$A$1576,"CDER") -> 13 | C25: =COUNTIFS('Novel Approval Database'!$G$3:$G$1576,2005,'Novel Approval Database'!$C$3:$C$1576,"BLA",'Novel Approval Database'!$A$3:$A$1576,"CDER") -> 7 | D25: =B25+C25 -> 20
A26: 2006 | B26: =COUNTIFS('Novel Approval Database'!$G$3:$G$1576,2006,'Novel Approval Database'!$C$3:$C$1576,"NDA",'Novel Approval Database'!$A$3:$A$1576,"CDER") -> 18 | C26: =COUNTIFS('Novel Approval Database'!$G$3:$G$1576,2006,'Novel Approval Database'!$C$3:$C$1576,"BLA",'Novel Approval Database'!$A$3:$A$1576,"CDER") -> 4 | D26: =B26+C26 -> 22
A27: 2007 | B27: =COUNTIFS('Novel Approval Database'!$G$3:$G$1576,2007,'Novel Approval Database'!$C$3:$C$1576,"NDA",'Novel Approval Database'!$A$3:$A$1576,"CDER") -> 16 | C27: =COUNTIFS('Novel Approval Database'!$G$3:$G$1576,2007,'Novel Approval Database'!$C$3:$C$1576,"BLA",'Novel Approval Database'!$A$3:$A$1576,"CDER") -> 2 | D27: =B27+C27 -> 18
A28: 2008 | B28: =COUNTIFS('Novel Approval Database'!$G$3:$G$1576,2008,'Novel Approval Database'!$C$3:$C$1576,"NDA",'Novel Approval Database'!$A$3:$A$1576,"CDER") -> 22 | C28: =COUNTIFS('Novel Approval Database'!$G$3:$G$1576,2008,'Novel Approval Database'!$C$3:$C$1576,"BLA",'Novel Approval Database'!$A$3:$A$1576,"CDER") -> 3 | D28: =B28+C28 -> 25
A29: 2009 | B29: =COUNTIFS('Novel Approval Database'!$G$3:$G$1576,2009,'Novel Approval Database'!$C$3:$C$1576,"NDA",'Novel Approval Database'!$A$3:$A$1576,"CDER") -> 20 | C29: =COUNTIFS('Novel Approval Database'!$G$3:$G$1576,2009,'Novel Approval Database'!$C$3:$C$1576,"BLA",'Novel Approval Database'!$A$3:$A$1576,"CDER") -> 6 | D29: =B29+C29 -> 26
A30: 2010 | B30: =COUNTIFS('Novel Approval Database'!$G$3:$G$1576,2010,'Novel Approval Database'!$C$3:$C$1576,"NDA",'Novel Approval Database'!$A$3:$A$1576,"CDER") -> 13 | C30: =COUNTIFS('Novel Approval Database'!$G$3:$G$1576,2010,'Novel Approval Database'!$C$3:$C$1576,"BLA",'Novel Approval Database'!$A$3:$A$1576,"CDER") -> 8 | D30: =B30+C30 -> 21
A31: 2011 | B31: =COUNTIFS('Novel Approval Database'!$G$3:$G$1576,2011,'Novel Approval Database'!$C$3:$C$1576,"NDA",'Novel Approval Database'!$A$3:$A$1576,"CDER") -> 24 | C31: =COUNTIFS('Novel Approval Database'!$G$3:$G$1576,2011,'Novel Approval Database'!$C$3:$C$1576,"BLA",'Novel Approval Database'!$A$3:$A$1576,"CDER") -> 6 | D31: =B31+C31 -> 30
A32: 2012 | B32: =COUNTIFS('Novel Approval Database'!$G$3:$G$1576,2012,'Novel Approval Database'!$C$3:$C$1576,"NDA",'Novel Approval Database'!$A$3:$A$1576,"CDER") -> 32 | C32: =COUNTIFS('Novel Approval Database'!$G$3:$G$1576,2012,'Novel Approval Database'!$C$3:$C$1576,"BLA",'Novel Approval Database'!$A$3:$A$1576,"CDER") -> 7 | D32: =B32+C32 -> 39
A33: 2013 | B33: =COUNTIFS('Novel Approval Database'!$G$3:$G$1576,2013,'Novel Approval Database'!$C$3:$C$1576,"NDA",'Novel Approval Database'!$A$3:$A$1576,"CDER") -> 25 | C33: =COUNTIFS('Novel Approval Database'!$G$3:$G$1576,2013,'Novel Approval Database'!$C$3:$C$1576,"BLA",'Novel Approval Database'!$A$3:$A$1576,"CDER") -> 2 | D33: =B33+C33 -> 27
A34: 2014 | B34: =COUNTIFS('Novel Approval Database'!$G$3:$G$1576,2014,'Novel Approval Database'!$C$3:$C$1576,"NDA",'Novel Approval Database'!$A$3:$A$1576,"CDER") -> 30 | C34: =COUNTIFS('Novel Approval Database'!$G$3:$G$1576,2014,'Novel Approval Database'!$C$3:$C$1576,"BLA",'Novel Approval Database'!$A$3:$A$1576,"CDER") -> 11 | D34: =B34+C34 -> 41
A35: 2015 | B35: =COUNTIFS('Novel Approval Database'!$G$3:$G$1576,2015,'Novel Approval Database'!$C$3:$C$1576,"NDA",'Novel Approval Database'!$A$3:$A$1576,"CDER") -> 32 | C35: =COUNTIFS('Novel Approval Database'!$G$3:$G$1576,2015,'Novel Approval Database'!$C$3:$C$1576,"BLA",'Novel Approval Database'!$A$3:$A$1576,"CDER") -> 13 | D35: =B35+C35 -> 45
A36: 2016 | B36: =COUNTIFS('Novel Approval Database'!$G$3:$G$1576,2016,'Novel Approval Database'!$C$3:$C$1576,"NDA",'Novel Approval Database'!$A$3:$A$1576,"CDER") -> 14 | C36: =COUNTIFS('Novel Approval Database'!$G$3:$G$1576,2016,'Novel Approval Database'!$C$3:$C$1576,"BLA",'Novel Approval Database'!$A$3:$A$1576,"CDER") -> 8 | D36: =B36+C36 -> 22
A37: 2017 | B37: =COUNTIFS('Novel Approval Database'!$G$3:$G$1576,2017,'Novel Approval Database'!$C$3:$C$1576,"NDA",'Novel Approval Database'!$A$3:$A$1576,"CDER") -> 34 | C37: =COUNTIFS('Novel Approval Database'!$G$3:$G$1576,2017,'Novel Approval Database'!$C$3:$C$1576,"BLA",'Novel Approval Database'!$A$3:$A$1576,"CDER") -> 12 | D37: =B37+C37 -> 46
A38: 2018 | B38: =COUNTIFS('Novel Approval Database'!$G$3:$G$1576,2018,'Novel Approval Database'!$C$3:$C$1576,"NDA",'Novel Approval Database'!$A$3:$A$1576,"CDER") -> 42 | C38: =COUNTIFS('Novel Approval Database'!$G$3:$G$1576,2018,'Novel Approval Database'!$C$3:$C$1576,"BLA",'Novel Approval Database'!$A$3:$A$1576,"CDER") -> 17 | D38: =B38+C38 -> 59
A39: 2019 | B39: =COUNTIFS('Novel Approval Database'!$G$3:$G$1576,2019,'Novel Approval Database'!$C$3:$C$1576,"NDA",'Novel Approval Database'!$A$3:$A$1576,"CDER") -> 38 | C39: =COUNTIFS('Novel Approval Database'!$G$3:$G$1576,2019,'Novel Approval Database'!$C$3:$C$1576,"BLA",'Novel Approval Database'!$A$3:$A$1576,"CDER") -> 10 | D39: =B39+C39 -> 48
A40: 2020 | B40: =COUNTIFS('Novel Approval Database'!$G$3:$G$1576,2020,'Novel Approval Database'!$C$3:$C$1576,"NDA",'Novel Approval Database'!$A$3:$A$1576,"CDER") -> 40 | C40: =COUNTIFS('Novel Approval Database'!$G$3:$G$1576,2020,'Novel Approval Database'!$C$3:$C$1576,"BLA",'Novel Approval Database'!$A$3:$A$1576,"CDER") -> 13 | D40: =B40+C40 -> 53
A41: 2021 | B41: =COUNTIFS('Novel Approval Database'!$G$3:$G$1576,2021,'Novel Approval Database'!$C$3:$C$1576,"NDA",'Novel Approval Database'!$A$3:$A$1576,"CDER") -> 36 | C41: =COUNTIFS('Novel Approval Database'!$G$3:$G$1576,2021,'Novel Approval Database'!$C$3:$C$1576,"BLA",'Novel Approval Database'!$A$3:$A$1576,"CDER") -> 14 | D41: =B41+C41 -> 50
...

Sheet ── Database ──
A1: Database

Sheet Novel Approval Database
A1: Data pulled: 04/12/2026 | CDER current as of: N/A | CBER current as of: N/A
A2: FDA Center | B2: Approval Date | C2: Approval Type | D2: Drug Name | E2: Active Ingredient | F2: Month | G2: Year | H2: Month & Year | I2: FDA-Approved Use | J2: Source
A3: CDER | B3: 46107 | C3: BLA | D3: Awiqli | E3: insulin icodec-abae | F3: 3 | G3: 2026 | H3: Mar 2026 | I3: To improve glycemic control in adults with type 2 diabetes mellitus | J3: https://www.fda.gov/drugs/novel-drug-approvals-fda/novel-drug-approvals-2026
A4: CDER | B4: 46106 | C4: NDA | D4: Lifyorli | E4: relacorilant | F4: 3 | G4: 2026 | H4: Mar 2026 | I4: To treat platinum-resistant epithelial ovarian, fallopian tube, or primary peritoneal cancer after one to three prior systemic treatment regimens, at least one of which included bevacizumab | J4: https://www.fda.gov/drugs/novel-drug-approvals-fda/novel-drug-approvals-2026
A5: CDER | B5: 46105 | C5: BLA | D5: Avlayah | E5: tividenofusp alfa-eknm | F5: 3 | G5: 2026 | H5: Mar 2026 | I5: To treat certain individuals with Hunter syndrome (Mucopolysaccharidosis type II or MPS II) | J5: https://www.fda.gov/drugs/novel-drug-approvals-fda/novel-drug-approvals-2026
A6: CDER | B6: 46098 | C6: NDA | D6: Lynavoy | E6: linerixibat | F6: 3 | G6: 2026 | H6: Mar 2026 | I6: To treat cholestatic pruritus associated with primary biliary cholangitis | J6: https://www.fda.gov/drugs/novel-drug-approvals-fda/novel-drug-approvals-2026
A7: CDER | B7: 46098 | C7: NDA | D7: Icotyde | E7: icotrokinra | F7: 3 | G7: 2026 | H7: Mar 2026 | I7: To treat moderate-to-severe plaque psoriasis in patients 12 years and older who weigh at least 40 kg and who are candidates for systemic therapy or phototherapy | J7: https://www.fda.gov/drugs/novel-drug-approvals-fda/novel-drug-approvals-2026
A8: CDER | B8: 46080 | C8: NDA | D8: Yuviwel | E8: navepegritide | F8: 2 | G8: 2026 | H8: Feb 2026 | I8: To increase linear growth in pediatric patients 2 years and older with achondroplasia with open epiphyses | J8: https://www.fda.gov/drugs/novel-drug-approvals-fda/novel-drug-approvals-2026
A9: CDER | B9: 46076 | C9: BLA | D9: Loargys | E9: pegzilarginase-nbln | F9: 2 | G9: 2026 | H9: Feb 2026 | I9: To treat hyperarginemia in adults and pediatric patients two years and older with Arginase 1 Deficiency, in conjunction with dietary protein restriction | J9: https://www.fda.gov/drugs/novel-drug-approvals-fda/novel-drug-approvals-2026
A10: CDER | B10: 46073 | C10: NDA | D10: Bysanti | E10: milsaperidone | F10: 2 | G10: 2026 | H10: Feb 2026 | I10: To treat schizophrenia and to treat manic or mixed episodes associated with bipolar I disorder | J10: https://www.fda.gov/drugs/novel-drug-approvals-fda/novel-drug-approvals-2026
A11: CDER | B11: 46065 | C11: NDA | D11: Adquey | E11: difamilast | F11: 2 | G11: 2026 | H11: Feb 2026 | I11: To treat mild to moderate atopic dermatitis | J11: https://www.fda.gov/drugs/novel-drug-approvals-fda/novel-drug-approvals-2026
A12: CDER | B12: 46034 | C12: NDA | D12: Zycubo | E12: copper histidinate | F12: 1 | G12: 2026 | H12: Jan 2026 | I12: To treat Menkes disease | J12: https://www.fda.gov/drugs/novel-drug-approvals-fda/novel-drug-approvals-2026
A13: CDER | B13: 46021 | C13: NDA | D13: Nereus | E13: tradipitant | F13: 12 | G13: 2025 | H13: Dec 2025 | I13: To treat vomiting associated with motion | J13: https://www.fda.gov/drugs/novel-drug-approvals-fda/novel-drug-approvals-2025
A14: CDER | B14: 46014 | C14: BLA | D14: Yartemlea | E14: narsoplimab-wuug | F14: 12 | G14: 2025 | H14: Dec 2025 | I14: To treat hematopoietic stem cell transplant-associated thrombotic microangiopathy | J14: https://www.fda.gov/drugs/novel-drug-approvals-fda/novel-drug-approvals-2025
... A79: CBER | B79: 45665 | C79: BLA | D79: Automated C3d PlateAnti-Human Globulin (Murine Monoclonal) | E79: Automated C3d PlateAnti-Human Globulin (Murine Monoclonal) | F79: 1 | G79: 2025 | H79: Jan 2025 | I79: Indicated for use on Echo Lumena and Galileo Echo in automated direct antiglobulin tests (DAT) where detection of C3d is required. | J79: https://www.fda.gov/vaccines-blood-biologics/development-approval-process-cber/2025-biological-license-application-approvals
A80: CDER | B80: 45646 | C80: BLA | D80: Alhemo | E80: concizumab-mtci | F80: 12 | G80: 2024 | H80: Dec 2024 | J80: FDA Compilation 1985-2024
A81: CDER | B81: 45646 | C81: NDA | D81: Alyftrek | E81: vanzacaftor, tezacaftor and deutivacaftor | F81: 12 | G81: 2024 | H81: Dec 2024 | J81: FDA Compilation 1985-2024
A82: CBER | B82: 45645 | C82: BLA | D82: SYMVESSacellular tissue engineered vessel-tyod | E82: SYMVESSacellular tissue engineered vessel-tyod | F82: 12 | G82: 2024 | H82: Dec 2024 | I82: Indicated for use in adults as a vascular conduit for extremity arterial injury when urgent revascularization is needed to avoid imminent limb loss, and autologous vein graft is not feasible. | J82: https://www.fda.gov/vaccines-blood-biologics/development-approval-process-cber/2024-biological-license-application-approvals
A83: CDER | B83: 45645 | C83: NDA | D83: Tryngolza | E83: olezarsen | F83: 12 | G83: 2024 | H83: Dec 2024 | J83: FDA Compilation 1985-2024
A84: CBER | B84: 45644 | C84: BLA | D84: RYONCILremestemcel-L-rknd | E84: RYONCILremestemcel-L-rknd | F84: 12 | G84: 2024 | H84: Dec 2024 | I84: Indicated for the treatment of steroid-refractory acute graft versus host disease (SR-aGvHD) in pediatric patients 2 months of age and older. | J84: https://www.fda.gov/vaccines-blood-biologics/development-approval-process-cber/2024-biological-license-application-approvals
A85: CDER | B85: 45644 | C85: NDA | D85: Ensacove | E85: ensartinib | F85: 12 | G85: 2024 | H85: Dec 2024 | J85: FDA Compilation 1985-2024
A86: CDER | B86: 45639 | C86: NDA | D86: Crenessity | E86: crinecerfont | F86: 12 | G86: 2024 | H86: Dec 2024 | J86: FDA Compilation 1985-2024
A87: CDER | B87: 45639 | C87: BLA | D87: Unloxcyt | E87: cosibelimab-ipdl | F87: 12 | G87: 2024 | H87: Dec 2024 | J87: FDA Compilation 1985-2024
A88: CDER | B88: 45630 | C88: BLA | D88: Bizengri | E88: zenocutuzumab-zbco | F88: 12 | G88: 2024 | H88: Dec 2024 | J88: FDA Compilation 1985-2024
A89: CDER | B89: 45623 | C89: NDA | D89: Iomervu | E89: iomeprol | F89: 11 | G89: 2024 | H89: Nov 2024 | J89: FDA Compilation 1985-2024
A90: CDER | B90: 45618 | C90: NDA | D90: Attruby | E90: acoramidis | F90: 11 | G90: 2024 | H90: Nov 2024 | J90: FDA Compilation 1985-2024
A91: CDER | B91: 45618 | C91: NDA | D91: Rapiblyk | E91: landiolol | F91: 11 | G91: 2024 | H91: Nov 2024 | J91: FDA Compilation 1985-2024
A92: CDER | B92: 45616 | C92: BLA | D92: Ziihera | E92: zanidatamab-hrii | F92: 11 | G92: 2024 | H92: Nov 2024 | J92: FDA Compilation 1985-2024
A93: CDER | B93: 45611 | C93: NDA | D93: Revuforj | E93: revumenib | F93: 11 | G93: 2024 | H93: Nov 2024 | J93: FDA Compilation 1985-2024
A94: CBER | B94: 45609 | C94: BLA | D94: Kebilidieladocagene exuparvovec-tneq | E94: Kebilidieladocagene exuparvovec-tneq | F94: 11 | G94: 2024 | H94: Nov 2024 | I94: For treatment of adult and pediatric patients with aromatic L-amino acid decarboxylase (AADC) deficiency. | J94: https://www.fda.gov/vaccines-blood-biologics/development-approval-process-cber/2024-biological-license-application-approvals
A95: CBER | B95: 45604 | C95: BLA | D95: Aucatzylobecabtagene autoleucel | E95: Aucatzylobecabtagene autoleucel | F95: 11 | G95: 2024 | H95: Nov 2024 | I95: Indicated for the treatment of adults with relapsed or refractory B-cell precursor acute lymphoblastic leukemia (ALL). | J95: https://www.fda.gov/vaccines-blood-biologics/development-approval-process-cber/2024-biological-license-application-approvals
A96: CDER | B96: 45590 | C96: NDA | D96: Orlynvah | E96: sulopenem etzadroxil and probenecid | F96: 10 | G96: 2024 | H96: Oct 2024 | J96: FDA Compilation 1985-2024
A97: CDER | B97: 45583 | C97: BLA | D97: Vyloy | E97: zolbetuximab-clzb | F97: 10 | G97: 2024 | H97: Oct 2024 | J97: FDA Compilation 1985-2024
A98: CDER | B98: 45576 | C98: BLA | D98: Hympavzi | E98: marstacimab-hncq | F98: 10 | G98: 2024 | H98: Oct 2024 | J98: FDA Compilation 1985-2024
A99: CDER | B99: 45575 | C99: NDA | D99: Itovebi | E99: inavolisib | F99: 10 | G99: 2024 | H99: Oct 2024 | J99: FDA Compilation 1985-2024
A100: CDER | B100: 45562 | C100: NDA | D100: Flyrcado | E100: flurpiridaz F 18 | F100: 9 | G100: 2024 | H100: Sep 2024 | J100: FDA Compilation 1985-2024
A101: CDER | B101: 45561 | C101: NDA | D101: Cobenfy | E101: xanomeline and trospium chloride | F101: 9 | G101: 2024 | H101: Sep 2024 | J101: FDA Compilation 1985-2024
A102: CDER | B102: 45559 | C102: NDA | D102: Aqneursa | E102: levacetylleucine | F102: 9 | G102: 2024 | H102: Sep 2024 | J102: FDA Compilation 1985-2024
A103: CDER | B103: 45555 | C103: NDA | D103: Miplyffa | E103: arimoclomol | F103: 9 | G103: 2024 | H103: Sep 2024 | J103: FDA Compilation 1985-2024
A104: CDER | B104: 45548 | C104: BLA | D104: Ebglyss | E104: lebrikizumab-lbkz | F104: 9 | G104: 2024 | H104: Sep 2024 | J104: FDA Compilation 1985-2024
...

Sheet Biosimilar Approval Database
A1: Data pulled: 04/12/2026 | Biosimilar page current as of: N/A
A2: Approval Date | B2: Approval Year | C2: Approval Month & Year | D2: Biosimilar Name | E2: Active Ingredient | F2: Reference Product | G2: Count | H2: Source
