Workbook

Sheet COVER
B2: Thermo Fisher Scientific (TMO) — Quarterly Bottom-Up Model
B4: Purpose
B5: Quarterly revenue and segment income build by subsegment, with organic / M&A / FX bridge and Clario acquisition + Microbiology divestiture defaults seeded.
B7: Tab guide
B8: COVER — this page.
B9: Summary — consolidated headline, per-segment table, Notable M&A schedule, long-range guide overlay.
B10: Model — revenue build (subseg + bridge) and segment income build (rev × margin), single combined tab.
B11: Upside — FY26/27/28 model output vs. management guidance.
B13: Color convention
B14: Black formulas | Blue hardcoded actuals | Red forward assumptions | Green cross-sheet links
B16: Period header band (rows 4–10) — GH-style
B17: Row 4: 1Q / 2Q / 3Q / 4Q / FY | Row 5: fiscal year (auto) | Row 7: REPORTED banner (boxed) | Row 8: "E" estimate marker | Row 9: combined label (e.g., 1Q24, FY26E) | Row 10: period end date
... B24: TMO 10-Q Q1/Q2/Q3 2025, Q1 2026 (Note 4, 6, 11); 2025 10-K; Q1-2026 Reconciliation of Financial Information PDF.

Sheet Summary
B2: TMO — Consolidated Summary
C4: Period | D4: 1Q | E4: 2Q | F4: 3Q | G4: 4Q | H4: FY | I4: 1Q | J4: 2Q | K4: 3Q | L4: 4Q | M4: FY | N4: 1Q | O4: 2Q | P4: 3Q | Q4: 4Q | R4: FY | S4: 1Q | T4: 2Q | U4: 3Q | V4: 4Q | W4: FY | X4: 1Q | Y4: 2Q | Z4: 3Q | AA4: 4Q | AB4: FY
C5: Company Fiscal Year | D5: 24 | E5: =D5 -> 24 | F5: =E5 -> 24 | G5: =F5 -> 24 | H5: =G5 -> 24 | I5: =H5+1 -> 25 | J5: =I5 -> 25 | K5: =J5 -> 25 | L5: =K5 -> 25 | M5: =L5 -> 25 | N5: =M5+1 -> 26 | O5: =N5 -> 26 | P5: =O5 -> 26 | Q5: =P5 -> 26 | R5: =Q5 -> 26 | S5: =R5+1 -> 27 | T5: =S5 -> 27 | U5: =T5 -> 27 | V5: =U5 -> 27 | W5: =V5 -> 27 | X5: =W5+1 -> 28 | Y5: =X5 -> 28 | Z5: =Y5 -> 28 | AA5: =Z5 -> 28 | AB5: =AA5 -> 28
C7: Status | D7: REPORTED | I7: REPORTED
C8: Reported (blank) or Estimate ("E") | O8: E | P8: E | Q8: E | R8: E | S8: E | T8: E | U8: E | V8: E | W8: E | X8: E | Y8: E | Z8: E | AA8: E | AB8: E
C9: Company Fiscal Period | D9: =D$4&D5&D8 -> 1Q24 | E9: =E$4&E5&E8 -> 2Q24 | F9: =F$4&F5&F8 -> 3Q24 | G9: =G$4&G5&G8 -> 4Q24 | H9: =H$4&H5&H8 -> FY24 | I9: =I$4&I5&I8 -> 1Q25 | J9: =J$4&J5&J8 -> 2Q25 | K9: =K$4&K5&K8 -> 3Q25 | ... AB9: =AB$4&AB5&AB8 -> FY28E
C10: Period end date | D10: 45381 | E10: 45472 | F10: 45563 | G10: 45657 | H10: 45657 | I10: 45745 | J10: 45836 | K10: 45927 | L10: 46022 | M10: 46022 | N10: 46109 | O10: 46200 | P10: 46291 | Q10: 46387 | R10: 46387 | S10: 46480 | T10: 46571 | U10: 46662 | V10: 46752 | W10: 46752 | X10: 46844 | Y10: 46935 | Z10: 47026 | AA10: 47117 | AB10: 47117
B11: REVENUE
C12: Consolidated revenue ($M) | D12: =Model!D144 -> 10345 | E12: =Model!E144 -> 10540 | F12: =Model!F144 -> 10597 | G12: =Model!G144 -> 11395 | H12: =Model!H144 -> 42877 | I12: =Model!I144 -> 10365 | J12: =Model!J144 -> 10856 | K12: =Model!K144 -> 11122 | ... AB12: =Model!AB144 -> 48369.684
C13: Reported Y/Y | D13: =Model!D145 -> 0 | E13: =Model!E145 -> 0 | F13: =Model!F145 -> 0 | G13: =Model!G145 -> 0 | H13: =Model!H145 -> 0 | I13: =Model!I145 -> 0.0019333011 | J13: =Model!J145 -> 0.029981025 | K13: =Model!K145 -> 0.049542323 | ... AB13: =Model!AB145 -> 0.019983655
C14: Organic | D14: =Model!D146 -> 0 | E14: =Model!E146 -> 0 | F14: =Model!F146 -> 0 | G14: =Model!G146 -> 0 | H14: =Model!H146 -> 0 | I14: =Model!I146 -> 0.0096557149 | J14: =Model!J146 -> 0.019377838 | K14: =Model!K146 -> 0.033214931 | ... AB14: =Model!AB146 -> 0.019983655
C15: M&A | D15: =Model!D147 -> 0 | E15: =Model!E147 -> 0 | F15: =Model!F147 -> 0 | G15: =Model!G147 -> 0 | H15: =Model!H147 -> 0 | I15: =Model!I147 -> 0.0042313744 | J15: =Model!J147 -> 0.0021389646 | K15: =Model!K147 -> 0.0064696312 | ... AB15: =Model!AB147 -> 0
C16: FX | D16: =Model!D148 -> 0 | E16: =Model!E148 -> 0 | F16: =Model!F148 -> 0 | G16: =Model!G148 -> 0 | H16: =Model!H148 -> 0 | I16: =Model!I148 -> -0.01 | J16: =Model!J148 -> 0.01 | K16: =Model!K148 -> 0.011020427 | ... AB16: =Model!AB148 -> 0
B18: SEGMENT INCOME
C19: Total segment income ($M) | D19: =Model!D176 -> 2278 | E19: =Model!E176 -> 2348 | F19: =Model!F176 -> 2362 | G19: =Model!G176 -> 2719 | H19: =Model!H176 -> 9707 | I19: =Model!I176 -> 2268 | J19: =Model!J176 -> 2375 | K19: =Model!K176 -> 2586 | ... AB19: =Model!AB176 -> 10816.826
C20: Total segment margin % | D20: =Model!D177 -> 0.220203 | E20: =Model!E177 -> 0.2227704 | F20: =Model!F177 -> 0.22289327 | G20: =Model!G177 -> 0.23861343 | H20: =Model!H177 -> 0.22639177 | I20: =Model!I177 -> 0.21881331 | J20: =Model!J177 -> 0.21877303 | K20: =Model!K177 -> 0.23251214 | ... AB20: =Model!AB177 -> 0.22362821
C21: Margin Y/Y (bps) | D21: =Model!D178 -> 0 | E21: =Model!E178 -> 0 | F21: =Model!F178 -> 0 | G21: =Model!G178 -> 0 | H21: =Model!H178 -> 0 | I21: =Model!I178 -> -13.896826 | J21: =Model!J178 -> -39.973697 | K21: =Model!K178 -> 96.188664 | ... AB21: =Model!AB178 -> -0.0099513181
B23: BY SEGMENT
C24: Life Sciences Solutions
C25: Revenue ($M) | D25: =Model!D45 -> 2286 | E25: =Model!E45 -> 2355 | F25: =Model!F45 -> 2386 | G25: =Model!G45 -> 2604 | H25: =Model!H45 -> 9631 | I25: =Model!I45 -> 2341 | J25: =Model!J45 -> 2499 | K25: =Model!K45 -> 2588 | ... AB25: =Model!AB45 -> 11268.239
C26: Segment income ($M) | D26: =Model!D155 -> 840 | E26: =Model!E155 -> 865 | F26: =Model!F155 -> 845 | G26: =Model!G155 -> 953 | H26: =Model!H155 -> 3503 | I26: =Model!I155 -> 834 | J26: =Model!J155 -> 919 | K26: =Model!K155 -> 968 | ... AB26: =Model!AB155 -> 4105.0647
C27: Margin % | D27: =Model!D154 -> 0.36745407 | E27: =Model!E154 -> 0.36730361 | F27: =Model!F154 -> 0.3541492 | G27: =Model!G154 -> 0.36597542 | H27: =Model!H154 -> 0.36372132 | I27: =Model!I154 -> 0.35625801 | J27: =Model!J154 -> 0.3677471 | K27: =Model!K154 -> 0.374034 | ... AB27: =Model!AB154 -> 0.364304
C29: Analytical Instruments
C30: Revenue ($M) | D30: =Model!D67 -> 1688 | E30: =Model!E67 -> 1781 | F30: =Model!F67 -> 1809 | G30: =Model!G67 -> 2185 | H30: =Model!H67 -> 7463 | I30: =Model!I67 -> 1718 | J30: =Model!J67 -> 1728 | K30: =Model!K67 -> 1893 | ... AB30: =Model!AB67 -> 7978.5363
C31: Segment income ($M) | D31: =Model!D161 -> 400 | E31: =Model!E161 -> 439 | F31: =Model!F161 -> 451 | G31: =Model!G161 -> 665 | H31: =Model!H161 -> 1955 | I31: =Model!I161 -> 399 | J31: =Model!J161 -> 325 | K31: =Model!K161 -> 429 | ... AB31: =Model!AB161 -> 1788.1771
C32: Margin % | D32: =Model!D160 -> 0.23696682 | E32: =Model!E160 -> 0.24649074 | F32: =Model!F160 -> 0.24930901 | G32: =Model!G160 -> 0.30434783 | H32: =Model!H160 -> 0.261959 | I32: =Model!I160 -> 0.2322468 | J32: =Model!J160 -> 0.1880787 | K32: =Model!K160 -> 0.22662441 | ... AB32: =Model!AB160 -> 0.22412345
C34: Specialty Diagnostics
C35: Revenue ($M) | D35: =Model!D104 -> 1109 | E35: =Model!E104 -> 1117 | F35: =Model!F104 -> 1129 | G35: =Model!G104 -> 1156 | H35: =Model!H104 -> 4511 | I35: =Model!I104 -> 1147 | J35: =Model!J104 -> 1135 | K35: =Model!K104 -> 1174 | ... AB35: =Model!AB104 -> 4284.0211
C36: Segment income ($M) | D36: =Model!D167 -> 294 | E36: =Model!E167 -> 299 | F36: =Model!F167 -> 293 | G36: =Model!G167 -> 273 | H36: =Model!H167 -> 1159 | I36: =Model!I167 -> 304 | J36: =Model!J167 -> 306 | K36: =Model!K167 -> 321 | ... AB36: =Model!AB167 -> 1159.3316
C37: Margin % | D37: =Model!D166 -> 0.2651037 | E37: =Model!E166 -> 0.26768129 | F37: =Model!F166 -> 0.2595217 | G37: =Model!G166 -> 0.23615917 | H37: =Model!H166 -> 0.25692751 | I37: =Model!I166 -> 0.26503923 | J37: =Model!J166 -> 0.26960352 | K37: =Model!K166 -> 0.27342419 | ... AB37: =Model!AB166 -> 0.27061762
C39: Laboratory Products & Biopharma Services
C40: Revenue ($M) | D40: =Model!D136 -> 5722 | E40: =Model!E136 -> 5757 | F40: =Model!F136 -> 5740 | G40: =Model!G136 -> 5938 | H40: =Model!H136 -> 23157 | I40: =Model!I136 -> 5641 | J40: =Model!J136 -> 5995 | K40: =Model!K136 -> 5970 | ... AB40: =Model!AB136 -> 27015.523
C41: Segment income ($M) | D41: =Model!D173 -> 744 | E41: =Model!E173 -> 745 | F41: =Model!F173 -> 773 | G41: =Model!G173 -> 828 | H41: =Model!H173 -> 3090 | I41: =Model!I173 -> 731 | J41: =Model!J173 -> 825 | K41: =Model!K173 -> 868 | ... AB41: =Model!AB173 -> 3764.2525
C42: Margin % | D42: =Model!D172 -> 0.13002447 | E42: =Model!E172 -> 0.12940768 | F42: =Model!F172 -> 0.13466899 | G42: =Model!G172 -> 0.13944089 | H42: =Model!H172 -> 0.13343697 | I42: =Model!I172 -> 0.12958695 | J42: =Model!J172 -> 0.13761468 | K42: =Model!K172 -> 0.14539363 | ... AB42: =Model!AB172 -> 0.13933665
B45: NOTABLE M&A / DIVESTITURE SCHEDULE
B46: Event | C46: Target subsegment | D46: Close date | E46: Annual rev ($M) | F46: Status | G46: Source
B47: Clario Holdings | C47: Clinical Research (LPBS) | D47: Mar 24, 2026 | E47: 1225 | F47: Closed | G47: Recon PDF p.15
B48: Microbiology divestiture | C48: Microbiology (SDS) | D48: 2H 2026 (assumed mid-3Q26) | E48: -645 | F48: Announced, pending close | G48: 26Q1 10Q Note 4 p.23
B50: Quarterly M&A $-impact embedded in model (computed):
C51: Clinical Research M&A $ vs PY | O51: =Model!O129*Model!J126 -> 304.98 | P51: =Model!P129*Model!K126 -> 306.888 | Q51: =Model!Q129*Model!L126 -> 306.306 | S51: =Model!S129*Model!N126 -> 306.432 | T51: =Model!T129*Model!O126 -> 0 | U51: =Model!U129*Model!P126 -> 0 | V51: =Model!V129*Model!Q126 -> 0 | X51: =Model!X129*Model!S126 -> 0 | Y51: =Model!Y129*Model!T126 -> 0 | Z51: =Model!Z129*Model!U126 -> 0 | AA51: =Model!AA129*Model!V126 -> 0
...

Sheet Model
B2: TMO Quarterly Model — Revenue & Segment Income ($M)
C4: Period | D4: 1Q | E4: 2Q | F4: 3Q | G4: 4Q | H4: FY | I4: 1Q | J4: 2Q | K4: 3Q | L4: 4Q | M4: FY | N4: 1Q | O4: 2Q | P4: 3Q | Q4: 4Q | R4: FY | S4: 1Q | T4: 2Q | U4: 3Q | V4: 4Q | W4: FY | X4: 1Q | Y4: 2Q | Z4: 3Q | AA4: 4Q | AB4: FY
C5: Company Fiscal Year | D5: 24 | E5: =D5 -> 24 | F5: =E5 -> 24 | G5: =F5 -> 24 | H5: =G5 -> 24 | I5: =H5+1 -> 25 | J5: =I5 -> 25 | K5: =J5 -> 25 | L5: =K5 -> 25 | M5: =L5 -> 25 | N5: =M5+1 -> 26 | O5: =N5 -> 26 | P5: =O5 -> 26 | Q5: =P5 -> 26 | R5: =Q5 -> 26 | S5: =R5+1 -> 27 | T5: =S5 -> 27 | U5: =T5 -> 27 | V5: =U5 -> 27 | W5: =V5 -> 27 | X5: =W5+1 -> 28 | Y5: =X5 -> 28 | Z5: =Y5 -> 28 | AA5: =Z5 -> 28 | AB5: =AA5 -> 28
C7: Status | D7: REPORTED | I7: REPORTED
C8: Reported (blank) or Estimate ("E") | O8: E | P8: E | Q8: E | R8: E | S8: E | T8: E | U8: E | V8: E | W8: E | X8: E | Y8: E | Z8: E | AA8: E | AB8: E
C9: Company Fiscal Period | D9: =D$4&D5&D8 -> 1Q24 | E9: =E$4&E5&E8 -> 2Q24 | F9: =F$4&F5&F8 -> 3Q24 | G9: =G$4&G5&G8 -> 4Q24 | H9: =H$4&H5&H8 -> FY24 | I9: =I$4&I5&I8 -> 1Q25 | J9: =J$4&J5&J8 -> 2Q25 | K9: =K$4&K5&K8 -> 3Q25 | ... AB9: =AB$4&AB5&AB8 -> FY28E
C10: Period end date | D10: 45381 | E10: 45472 | F10: 45563 | G10: 45657 | H10: 45657 | I10: 45745 | J10: 45836 | K10: 45927 | L10: 46022 | M10: 46022 | N10: 46109 | O10: 46200 | P10: 46291 | Q10: 46387 | R10: 46387 | S10: 46480 | T10: 46571 | U10: 46662 | V10: 46752 | W10: 46752 | X10: 46844 | Y10: 46935 | Z10: 47026 | AA10: 47117 | AB10: 47117
B11: TOP-LINE SUMMARY (from bottom of tab)
C12: Consolidated revenue ($M) | D12: =D144 -> 10345 | E12: =E144 -> 10540 | F12: =F144 -> 10597 | G12: =G144 -> 11395 | H12: =H144 -> 42877 | I12: =I144 -> 10365 | J12: =J144 -> 10856 | K12: =K144 -> 11122 | ... AB12: =AB144 -> 48369.684
C13: Reported Y/Y | D13: =D145 -> 0 | E13: =E145 -> 0 | F13: =F145 -> 0 | G13: =G145 -> 0 | H13: =H145 -> 0 | I13: =I145 -> 0.0019333011 | J13: =J145 -> 0.029981025 | K13: =K145 -> 0.049542323 | ... AB13: =AB145 -> 0.019983655
C14: Organic | D14: =D146 -> 0 | E14: =E146 -> 0 | F14: =F146 -> 0 | G14: =G146 -> 0 | H14: =H146 -> 0 | I14: =I146 -> 0.0096557149 | J14: =J146 -> 0.019377838 | K14: =K146 -> 0.033214931 | ... AB14: =AB146 -> 0.019983655
C15: M&A | D15: =D147 -> 0 | E15: =E147 -> 0 | F15: =F147 -> 0 | G15: =G147 -> 0 | H15: =H147 -> 0 | I15: =I147 -> 0.0042313744 | J15: =J147 -> 0.0021389646 | K15: =K147 -> 0.0064696312 | ... AB15: =AB147 -> 0
C16: FX | D16: =D148 -> 0 | E16: =E148 -> 0 | F16: =F148 -> 0 | G16: =G148 -> 0 | H16: =H148 -> 0 | I16: =I148 -> -0.01 | J16: =J148 -> 0.01 | K16: =K148 -> 0.011020427 | ... AB16: =AB148 -> 0
C18: Total segment income ($M) | D18: =D176 -> 2278 | E18: =E176 -> 2348 | F18: =F176 -> 2362 | G18: =G176 -> 2719 | H18: =H176 -> 9707 | I18: =I176 -> 2268 | J18: =J176 -> 2375 | K18: =K176 -> 2586 | ... AB18: =AB176 -> 10816.826
C19: Total segment margin % | D19: =D177 -> 0.220203 | E19: =E177 -> 0.2227704 | F19: =F177 -> 0.22289327 | G19: =G177 -> 0.23861343 | H19: =H177 -> 0.22639177 | I19: =I177 -> 0.21881331 | J19: =J177 -> 0.21877303 | K19: =K177 -> 0.23251214 | ... AB19: =AB177 -> 0.22362821
C20: Margin Y/Y (bps) | D20: =D178 -> 0 | E20: =E178 -> 0 | F20: =F178 -> 0 | G20: =G178 -> 0 | H20: =H178 -> 0 | I20: =I178 -> -13.896826 | J20: =J178 -> -39.973697 | K20: =K178 -> 96.188664 | ... AB20: =AB178 -> -0.0099513181
B22: REVENUE BUILD
C24: Life Sciences Solutions
A25: 10-Q / 10-K | C25: Biosciences | D25: 1059 | E25: 1059 | F25: 1006 | G25: 1068 | H25: =D25+E25+F25+G25 -> 4192 | I25: 993 | J25: 1075 | K25: 1023 | L25: 1078 | M25: =I25+J25+K25+L25 -> 4169 | N25: 981 | O25: =J25*(1+O27+O28+O29) -> 1096.5 | P25: =K25*(1+P27+P28+P29) -> 1043.46 | Q25: =L25*(1+Q27+Q28+Q29) -> 1099.56 | R25: =N25+O25+P25+Q25 -> 4220.52 | S25: =N25*(1+S27+S28+S29) -> 1000.62 | T25: =O25*(1+T27+T28+T29) -> 1118.43 | U25: =P25*(1+U27+U28+U29) -> 1064.3292 | V25: =Q25*(1+V27+V28+V29) -> 1121.5512 | W25: =S25+T25+U25+V25 -> 4304.9304 | X25: =S25*(1+X27+X28+X29) -> 1020.6324 | Y25: =T25*(1+Y27+Y28+Y29) -> 1140.7986 | Z25: =U25*(1+Z27+Z28+Z29) -> 1085.6158 | AA25: =V25*(1+AA27+AA28+AA29) -> 1143.9822 | AB25: =X25+Y25+Z25+AA25 -> 4391.029
C26: Reported Y/Y | I26: =IFERROR(I25/D25-1,0) -> -0.062322946 | J26: =IFERROR(J25/E25-1,0) -> 0.015108593 | K26: =IFERROR(K25/F25-1,0) -> 0.016898608 | L26: =IFERROR(L25/G25-1,0) -> 0.0093632959 | M26: =IFERROR(M25/H25-1,0) -> -0.0054866412 | N26: =IFERROR(N25/I25-1,0) -> -0.012084592 | O26: =O27+O28+O29 -> 0.02 | P26: =P27+P28+P29 -> 0.02 | Q26: =Q27+Q28+Q29 -> 0.02 | R26: =IFERROR(R25/M25-1,0) -> 0.01235788 | S26: =S27+S28+S29 -> 0.02 | T26: =T27+T28+T29 -> 0.02 | U26: =U27+U28+U29 -> 0.02 | V26: =V27+V28+V29 -> 0.02 | W26: =IFERROR(W25/R25-1,0) -> 0.02 | X26: =X27+X28+X29 -> 0.02 | Y26: =Y27+Y28+Y29 -> 0.02 | Z26: =Z27+Z28+Z29 -> 0.02 | AA26: =AA27+AA28+AA29 -> 0.02 | AB26: =IFERROR(AB25/W25-1,0) -> 0.02
C27: Organic | I27: =IFERROR(I26-I28-I29,0) -> -0.072322946 | J27: =IFERROR(J26-J28-J29,0) -> -0.004891407 | K27: =IFERROR(K26-K28-K29,0) -> -0.023101392 | L27: =IFERROR(L26-L28-L29,0) -> -0.090636704 | M27: =IFERROR(((I27*D25)+(J27*E25)+(K27*F25)+(L27*G25))/(D25+E25+F25+G25),0) -> -0.048141698 | N27: =IFERROR(N26-N28-N29,0) -> -0.13208459 | O27: 0.02 | P27: 0.02 | Q27: 0.02 | R27: =IFERROR(((N27*I25)+(O27*J25)+(P27*K25)+(Q27*L25))/(I25+J25+K25+L25),0) -> -0.016224514 | S27: 0.02 | T27: 0.02 | U27: 0.02 | V27: 0.02 | W27: =IFERROR(((S27*N25)+(T27*O25)+(U27*P25)+(V27*Q25))/(N25+O25+P25+Q25),0) -> 0.02 | X27: 0.02 | Y27: 0.02 | Z27: 0.02 | AA27: 0.02 | AB27: =IFERROR(((X27*S25)+(Y27*T25)+(Z27*U25)+(AA27*V25))/(S25+T25+U25+V25),0) -> 0.02
C28: M&A | I28: 0.02 | J28: 0.01 | K28: 0.03 | L28: 0.08 | M28: =IFERROR(((I28*D25)+(J28*E25)+(K28*F25)+(L28*G25))/(D25+E25+F25+G25),0) -> 0.035159828 | N28: 0.09 | O28: 0 | P28: 0 | Q28: 0 | R28: =IFERROR(((N28*I25)+(O28*J25)+(P28*K25)+(Q28*L25))/(I25+J25+K25+L25),0) -> 0.021436795 | S28: 0 | T28: 0 | U28: 0 | V28: 0 | W28: =IFERROR(((S28*N25)+(T28*O25)+(U28*P25)+(V28*Q25))/(N25+O25+P25+Q25),0) -> 0 | X28: 0 | Y28: 0 | Z28: 0 | AA28: 0 | AB28: =IFERROR(((X28*S25)+(Y28*T25)+(Z28*U25)+(AA28*V25))/(S25+T25+U25+V25),0) -> 0
C29: FX | I29: -0.01 | J29: 0.01 | K29: 0.01 | L29: 0.02 | M29: =IFERROR(((I29*D25)+(J29*E25)+(K29*F25)+(L29*G25))/(D25+E25+F25+G25),0) -> 0.007495229 | N29: 0.03 | O29: 0 | P29: 0 | Q29: 0 | R29: =IFERROR(((N29*I25)+(O29*J25)+(P29*K25)+(Q29*L25))/(I25+J25+K25+L25),0) -> 0.0071455985 | S29: 0 | T29: 0 | U29: 0 | V29: 0 | W29: =IFERROR(((S29*N25)+(T29*O25)+(U29*P25)+(V29*Q25))/(N25+O25+P25+Q25),0) -> 0 | X29: 0 | Y29: 0 | Z29: 0 | AA29: 0 | AB29: =IFERROR(((X29*S25)+(Y29*T25)+(Z29*U25)+(AA29*V25))/(S25+T25+U25+V25),0) -> 0
A30: 10-Q / 10-K | C30: Genetic Sciences | D30: 637 | E30: 663 | F30: 701 | G30: 786 | H30: =D30+E30+F30+G30 -> 2787 | I30: 677 | J30: 679 | K30: 720 | L30: 794 | M30: =I30+J30+K30+L30 -> 2870 | N30: 655 | O30: =J30*(1+O32+O33+O34) -> 692.58 | P30: =K30*(1+P32+P33+P34) -> 734.4 | Q30: =L30*(1+Q32+Q33+Q34) -> 809.88 | R30: =N30+O30+P30+Q30 -> 2891.86 | S30: =N30*(1+S32+S33+S34) -> 668.1 | T30: =O30*(1+T32+T33+T34) -> 706.4316 | U30: =P30*(1+U32+U33+U34) -> 749.088 | V30: =Q30*(1+V32+V33+V34) -> 826.0776 | W30: =S30+T30+U30+V30 -> 2949.6972 | X30: =S30*(1+X32+X33+X34) -> 681.462 | Y30: =T30*(1+Y32+Y33+Y34) -> 720.56023 | Z30: =U30*(1+Z32+Z33+Z34) -> 764.06976 | AA30: =V30*(1+AA32+AA33+AA34) -> 842.59915 | AB30: =X30+Y30+Z30+AA30 -> 3008.6911
C31: Reported Y/Y | I31: =IFERROR(I30/D30-1,0) -> 0.062794349 | J31: =IFERROR(J30/E30-1,0) -> 0.02413273 | K31: =IFERROR(K30/F30-1,0) -> 0.027104137 | L31: =IFERROR(L30/G30-1,0) -> 0.010178117 | M31: =IFERROR(M30/H30-1,0) -> 0.029781127 | N31: =IFERROR(N30/I30-1,0) -> -0.032496307 | O31: =O32+O33+O34 -> 0.02 | P31: =P32+P33+P34 -> 0.02 | Q31: =Q32+Q33+Q34 -> 0.02 | R31: =IFERROR(R30/M30-1,0) -> 0.0076167247 | S31: =S32+S33+S34 -> 0.02 | T31: =T32+T33+T34 -> 0.02 | U31: =U32+U33+U34 -> 0.02 | V31: =V32+V33+V34 -> 0.02 | W31: =IFERROR(W30/R30-1,0) -> 0.02 | X31: =X32+X33+X34 -> 0.02 | Y31: =Y32+Y33+Y34 -> 0.02 | Z31: =Z32+Z33+Z34 -> 0.02 | AA31: =AA32+AA33+AA34 -> 0.02 | AB31: =IFERROR(AB30/W30-1,0) -> 0.02
C32: Organic | I32: =IFERROR(I31-I33-I34,0) -> 0.052794349 | J32: =IFERROR(J31-J33-J34,0) -> 0.00413273 | K32: =IFERROR(K31-K33-K34,0) -> -0.012895863 | L32: =IFERROR(L31-L33-L34,0) -> -0.089821883 | M32: =IFERROR(((I32*D30)+(J32*E30)+(K32*F30)+(L32*G30))/(D30+E30+F30+G30),0) -> -0.015525655 | N32: =IFERROR(N31-N33-N34,0) -> -0.15249631 | O32: 0.02 | P32: 0.02 | Q32: 0.02 | R32: =IFERROR(((N32*I30)+(O32*J30)+(P32*K30)+(Q32*L30))/(I30+J30+K30+L30),0) -> -0.020689895 | S32: 0.02 | T32: 0.02 | U32: 0.02 | V32: 0.02 | W32: =IFERROR(((S32*N30)+(T32*O30)+(U32*P30)+(V32*Q30))/(N30+O30+P30+Q30),0) -> 0.02 | X32: 0.02 | Y32: 0.02 | Z32: 0.02 | AA32: 0.02 | AB32: =IFERROR(((X32*S30)+(Y32*T30)+(Z32*U30)+(AA32*V30))/(S30+T30+U30+V30),0) -> 0.02
C33: M&A | I33: 0.02 | J33: 0.01 | K33: 0.03 | L33: 0.08 | M33: =IFERROR(((I33*D30)+(J33*E30)+(K33*F30)+(L33*G30))/(D30+E30+F30+G30),0) -> 0.037057768 | N33: 0.09 | O33: 0 | P33: 0 | Q33: 0 | R33: =IFERROR(((N33*I30)+(O33*J30)+(P33*K30)+(Q33*L30))/(I30+J30+K30+L30),0) -> 0.021229965 | S33: 0 | T33: 0 | U33: 0 | V33: 0 | W33: =IFERROR(((S33*N30)+(T33*O30)+(U33*P30)+(V33*Q30))/(N30+O30+P30+Q30),0) -> 0 | X33: 0 | Y33: 0 | Z33: 0 | AA33: 0 | AB33: =IFERROR(((X33*S30)+(Y33*T30)+(Z33*U30)+(AA33*V30))/(S30+T30+U30+V30),0) -> 0
C34: FX | I34: -0.01 | J34: 0.01 | K34: 0.01 | L34: 0.02 | M34: =IFERROR(((I34*D30)+(J34*E30)+(K34*F30)+(L34*G30))/(D30+E30+F30+G30),0) -> 0.0082490133 | N34: 0.03 | O34: 0 | P34: 0 | Q34: 0 | R34: =IFERROR(((N34*I30)+(O34*J30)+(P34*K30)+(Q34*L30))/(I30+J30+K30+L30),0) -> 0.0070766551 | S34: 0 | T34: 0 | U34: 0 | V34: 0 | W34: =IFERROR(((S34*N30)+(T34*O30)+(U34*P30)+(V34*Q30))/(N30+O30+P30+Q30),0) -> 0 | X34: 0 | Y34: 0 | Z34: 0 | AA34: 0 | AB34: =IFERROR(((X34*S30)+(Y34*T30)+(Z34*U30)+(AA34*V30))/(S30+T30+U30+V30),0) -> 0
A35: 10-Q / 10-K | C35: BioProduction | D35: 590 | E35: 633 | F35: 680 | G35: 749 | H35: =D35+E35+F35+G35 -> 2652 | I35: 671 | J35: 745 | K35: 817 | L35: 967 | M35: =I35+J35+K35+L35 -> 3200 | N35: 893 | O35: =J35*(1+O37+O38+O39) -> 759.9 | P35: =K35*(1+P37+P38+P39) -> 833.34 | Q35: =L35*(1+Q37+Q38+Q39) -> 986.34 | R35: =N35+O35+P35+Q35 -> 3472.58 | S35: =N35*(1+S37+S38+S39) -> 910.86 | T35: =O35*(1+T37+T38+T39) -> 775.098 | U35: =P35*(1+U37+U38+U39) -> 850.0068 | V35: =Q35*(1+V37+V38+V39) -> 1006.0668 | W35: =S35+T35+U35+V35 -> 3542.0316 | X35: =S35*(1+X37+X38+X39) -> 929.0772 | Y35: =T35*(1+Y37+Y38+Y39) -> 790.59996 | Z35: =U35*(1+Z37+Z38+Z39) -> 867.00694 | AA35: =V35*(1+AA37+AA38+AA39) -> 1026.1881 | AB35: =X35+Y35+Z35+AA35 -> 3612.8722
C36: Reported Y/Y | I36: =IFERROR(I35/D35-1,0) -> 0.13728814 | J36: =IFERROR(J35/E35-1,0) -> 0.17693523 | K36: =IFERROR(K35/F35-1,0) -> 0.20147059 | L36: =IFERROR(L35/G35-1,0) -> 0.29105474 | M36: =IFERROR(M35/H35-1,0) -> 0.2066365 | N36: =IFERROR(N35/I35-1,0) -> 0.33084948 | O36: =O37+O38+O39 -> 0.02 | P36: =P37+P38+P39 -> 0.02 | Q36: =Q37+Q38+Q39 -> 0.02 | R36: =IFERROR(R35/M35-1,0) -> 0.08518125 | S36: =S37+S38+S39 -> 0.02 | T36: =T37+T38+T39 -> 0.02 | U36: =U37+U38+U39 -> 0.02 | V36: =V37+V38+V39 -> 0.02 | W36: =IFERROR(W35/R35-1,0) -> 0.02 | X36: =X37+X38+X39 -> 0.02 | Y36: =Y37+Y38+Y39 -> 0.02 | Z36: =Z37+Z38+Z39 -> 0.02 | AA36: =AA37+AA38+AA39 -> 0.02 | AB36: =IFERROR(AB35/W35-1,0) -> 0.02
C37: Organic | I37: =IFERROR(I36-I38-I39,0) -> 0.12728814 | J37: =IFERROR(J36-J38-J39,0) -> 0.15693523 | K37: =IFERROR(K36-K38-K39,0) -> 0.16147059 | L37: =IFERROR(L36-L38-L39,0) -> 0.19105474 | M37: =IFERROR(((I37*D35)+(J37*E35)+(K37*F35)+(L37*G35))/(D35+E35+F35+G35),0) -> 0.16113876 | N37: =IFERROR(N36-N38-N39,0) -> 0.21084948 | O37: 0.02 | P37: 0.02 | Q37: 0.02 | R37: =IFERROR(((N37*I35)+(O37*J35)+(P37*K35)+(Q37*L35))/(I35+J35+K35+L35),0) -> 0.06001875 | S37: 0.02 | T37: 0.02 | U37: 0.02 | V37: 0.02 | W37: =IFERROR(((S37*N35)+(T37*O35)+(U37*P35)+(V37*Q35))/(N35+O35+P35+Q35),0) -> 0.02 | X37: 0.02 | Y37: 0.02 | Z37: 0.02 | AA37: 0.02 | AB37: =IFERROR(((X37*S35)+(Y37*T35)+(Z37*U35)+(AA37*V35))/(S35+T35+U35+V35),0) -> 0.02
C38: M&A | I38: 0.02 | J38: 0.01 | K38: 0.03 | L38: 0.08 | M38: =IFERROR(((I38*D35)+(J38*E35)+(K38*F35)+(L38*G35))/(D35+E35+F35+G35),0) -> 0.037122926 | N38: 0.09 | O38: 0 | P38: 0 | Q38: 0 | R38: =IFERROR(((N38*I35)+(O38*J35)+(P38*K35)+(Q38*L35))/(I35+J35+K35+L35),0) -> 0.018871875 | S38: 0 | T38: 0 | U38: 0 | V38: 0 | W38: =IFERROR(((S38*N35)+(T38*O35)+(U38*P35)+(V38*Q35))/(N35+O35+P35+Q35),0) -> 0 | X38: 0 | Y38: 0 | Z38: 0 | AA38: 0 | AB38: =IFERROR(((X38*S35)+(Y38*T35)+(Z38*U35)+(AA38*V35))/(S35+T35+U35+V35),0) -> 0
C39: FX | I39: -0.01 | J39: 0.01 | K39: 0.01 | L39: 0.02 | M39: =IFERROR(((I39*D35)+(J39*E35)+(K39*F35)+(L39*G35))/(D35+E35+F35+G35),0) -> 0.0083748115 | N39: 0.03 | O39: 0 | P39: 0 | Q39: 0 | R39: =IFERROR(((N39*I35)+(O39*J35)+(P39*K35)+(Q39*L35))/(I35+J35+K35+L35),0) -> 0.006290625 | S39: 0 | T39: 0 | U39: 0 | V39: 0 | W39: =IFERROR(((S39*N35)+(T39*O35)+(U39*P35)+(V39*Q35))/(N35+O35+P35+Q35),0) -> 0 | X39: 0 | Y39: 0 | Z39: 0 | AA39: 0 | AB39: =IFERROR(((X39*S35)+(Y39*T35)+(Z39*U35)+(AA39*V35))/(S35+T35+U35+V35),0) -> 0
A40: 10-Q / 10-K | C40: Other (LSS) | D40: 0 | E40: 0 | F40: -1 | G40: 1 | H40: =D40+E40+F40+G40 -> 0 | I40: 0 | J40: 0 | K40: 28 | L40: 108 | M40: =I40+J40+K40+L40 -> 136 | N40: 107 | O40: =J40*(1+O42+O43+O44) -> 0 | P40: =K40*(1+P42+P43+P44) -> 28.56 | Q40: =L40*(1+Q42+Q43+Q44) -> 110.16 | R40: =N40+O40+P40+Q40 -> 245.72 | S40: =N40*(1+S42+S43+S44) -> 109.14 | T40: =O40*(1+T42+T43+T44) -> 0 | U40: =P40*(1+U42+U43+U44) -> 29.1312 | V40: =Q40*(1+V42+V43+V44) -> 112.3632 | W40: =S40+T40+U40+V40 -> 250.6344 | X40: =S40*(1+X42+X43+X44) -> 111.3228 | Y40: =T40*(1+Y42+Y43+Y44) -> 0 | Z40: =U40*(1+Z42+Z43+Z44) -> 29.713824 | AA40: =V40*(1+AA42+AA43+AA44) -> 114.61046 | AB40: =X40+Y40+Z40+AA40 -> 255.64709
C41: Reported Y/Y | I41: =IFERROR(I40/D40-1,0) -> 0 | J41: =IFERROR(J40/E40-1,0) -> 0 | K41: =IFERROR(K40/F40-1,0) -> -29 | L41: =IFERROR(L40/G40-1,0) -> 107 | M41: =IFERROR(M40/H40-1,0) -> 0 | N41: =IFERROR(N40/I40-1,0) -> 0 | O41: =O42+O43+O44 -> 0.02 | P41: =P42+P43+P44 -> 0.02 | Q41: =Q42+Q43+Q44 -> 0.02 | R41: =IFERROR(R40/M40-1,0) -> 0.80676471 | S41: =S42+S43+S44 -> 0.02 | T41: =T42+T43+T44 -> 0.02 | U41: =U42+U43+U44 -> 0.02 | V41: =V42+V43+V44 -> 0.02 | W41: =IFERROR(W40/R40-1,0) -> 0.02 | X41: =X42+X43+X44 -> 0.02 | Y41: =Y42+Y43+Y44 -> 0.02 | Z41: =Z42+Z43+Z44 -> 0.02 | AA41: =AA42+AA43+AA44 -> 0.02 | AB41: =IFERROR(AB40/W40-1,0) -> 0.02
C42: Organic | I42: =IFERROR(I41-I43-I44,0) -> -0.01 | J42: =IFERROR(J41-J43-J44,0) -> -0.02 | K42: =IFERROR(K41-K43-K44,0) -> -29.04 | L42: =IFERROR(L41-L43-L44,0) -> 106.9 | M42: =IFERROR(((I42*D40)+(J42*E40)+(K42*F40)+(L42*G40))/(D40+E40+F40+G40),0) -> 0 | N42: =IFERROR(N41-N43-N44,0) -> -0.12 | O42: 0.02 | P42: 0.02 | Q42: 0.02 | R42: =IFERROR(((N42*I40)+(O42*J40)+(P42*K40)+(Q42*L40))/(I40+J40+K40+L40),0) -> 0.02 | S42: 0.02 | T42: 0.02 | U42: 0.02 | V42: 0.02 | W42: =IFERROR(((S42*N40)+(T42*O40)+(U42*P40)+(V42*Q40))/(N40+O40+P40+Q40),0) -> 0.02 | X42: 0.02 | Y42: 0.02 | Z42: 0.02 | AA42: 0.02 | AB42: =IFERROR(((X42*S40)+(Y42*T40)+(Z42*U40)+(AA42*V40))/(S40+T40+U40+V40),0) -> 0.02
C43: M&A | I43: 0.02 | J43: 0.01 | K43: 0.03 | L43: 0.08 | M43: =IFERROR(((I43*D40)+(J43*E40)+(K43*F40)+(L43*G40))/(D40+E40+F40+G40),0) -> 0 | N43: 0.09 | O43: 0 | P43: 0 | Q43: 0 | R43: =IFERROR(((N43*I40)+(O43*J40)+(P43*K40)+(Q43*L40))/(I40+J40+K40+L40),0) -> 0 | S43: 0 | T43: 0 | U43: 0 | V43: 0 | W43: =IFERROR(((S43*N40)+(T43*O40)+(U43*P40)+(V43*Q40))/(N40+O40+P40+Q40),0) -> 0 | X43: 0 | Y43: 0 | Z43: 0 | AA43: 0 | AB43: =IFERROR(((X43*S40)+(Y43*T40)+(Z43*U40)+(AA43*V40))/(S40+T40+U40+V40),0) -> 0
C44: FX | I44: -0.01 | J44: 0.01 | K44: 0.01 | L44: 0.02 | M44: =IFERROR(((I44*D40)+(J44*E40)+(K44*F40)+(L44*G40))/(D40+E40+F40+G40),0) -> 0 | N44: 0.03 | O44: 0 | P44: 0 | Q44: 0 | R44: =IFERROR(((N44*I40)+(O44*J40)+(P44*K40)+(Q44*L40))/(I40+J40+K40+L40),0) -> 0 | S44: 0 | T44: 0 | U44: 0 | V44: 0 | W44: =IFERROR(((S44*N40)+(T44*O40)+(U44*P40)+(V44*Q40))/(N40+O40+P40+Q40),0) -> 0 | X44: 0 | Y44: 0 | Z44: 0 | AA44: 0 | AB44: =IFERROR(((X44*S40)+(Y44*T40)+(Z44*U40)+(AA44*V40))/(S40+T40+U40+V40),0) -> 0
C45: Life Sciences Solutions — Total | D45: =D25+D30+D35+D40 -> 2286 | E45: =E25+E30+E35+E40 -> 2355 | F45: =F25+F30+F35+F40 -> 2386 | G45: =G25+G30+G35+G40 -> 2604 | H45: =H25+H30+H35+H40 -> 9631 | I45: =I25+I30+I35+I40 -> 2341 | J45: =J25+J30+J35+J40 -> 2499 | K45: =K25+K30+K35+K40 -> 2588 | ... AB45: =AB25+AB30+AB35+AB40 -> 11268.239
C46: Reported Y/Y | I46: =IFERROR(I45/D45-1,0) -> 0.024059493 | J46: =IFERROR(J45/E45-1,0) -> 0.061146497 | K46: =IFERROR(K45/F45-1,0) -> 0.08466052 | L46: =IFERROR(L45/G45-1,0) -> 0.13172043 | M46: =IFERROR(M45/H45-1,0) -> 0.077250545 | N46: =IFERROR(N45/I45-1,0) -> 0.12601452 | O46: =IFERROR(O45/J45-1,0) -> 0.02 | P46: =IFERROR(P45/K45-1,0) -> 0.02 | ... AB46: =IFERROR(AB45/W45-1,0) -> 0.02
...

Sheet Upside
B2: Model vs Management Guidance
B4: Metric | C4: FY26 Guide | D4: FY26 Model | E4: FY26 Δ | F4: FY27 Model | G4: FY28 Model
B5: Revenue ($M) | C5: 45200 | D5: =Model!R144 -> 46521.975 | E5: =IFERROR((D5-C5)/C5,0) -> 0.029247237 | F5: =Model!W144 -> 47422.019 | G5: =Model!AB144 -> 48369.684
B6: Organic growth % | C6: 0.035 | D6: =Model!R146 -> 0.01865474 | E6: =D6-C6 -> -0.01634526 | F6: =Model!W146 -> 0.019835607 | G6: =Model!AB146 -> 0.019983655
B7: Total segment income ($M) | C7: 10500 | D7: =Model!R176 -> 10456.341 | E7: =IFERROR((D7-C7)/C7,0) -> -0.0041579885 | F7: =Model!W176 -> 10604.948 | G7: =Model!AB176 -> 10816.826
B8: Total segment margin % | C8: =C7/C5 -> 0.23230088 | D8: =D7/D5 -> 0.22476133 | E8: =D8-C8 -> -0.0075395524 | F8: =F7/F5 -> 0.2236292 | G8: =G7/G5 -> 0.22362821
B10: Long-range guide check (FY27E / FY28E)
B11: TMO LRP framework: ~7-9% organic revenue, ~22-23% adj op margin, mid-teens adj EPS growth. Update column C with current guide; D/F/G auto-pull.
