Workbook

Sheet COVER
B2: Waters Corporation (WAT) — Post-BD Quarterly Model
B4: Purpose
B5: Quarterly revenue model by Waters new 4-division / 10-subsegment structure with full organic/M&A/FX bridge (matching TMO and Agilent model framework). Post-BD Biosciences & Diagnostic Solutions acquisition (closed Feb 9, 2026).
B7: Division / Subsegment structure
B8: ASD — Analytical Sciences: Instruments, Service, Chemistry
B9: WBD — Biosciences (BD-acquired Feb 9, 2026): Flow Research, Flow Clinical
B10: ADX — Advanced Diagnostics: MSDx (legacy CBU), MDx & PoC (BD-acquired), Microbiology (BD-acquired)
B11: MSD — Materials Sciences (TA Instruments): Instruments, Service
B13: Bridge framework (5 rows per subsegment)
B14: Revenue | Reported Y/Y | Organic | M&A | FX. For Q1-26 BD-acquired subsegs (WBD + ADX-DS), M&A row captures the partial-year ownership impact (Feb 9 close means owned ~50% of Q1-26 — Reported Y/Y vs Q1-25 pro forma full quarter looks negative). Organic and FX use disclosed pro forma underlying growth from Q1-26 deck.
B16: Color convention
B17: Black formulas | Blue hardcoded actuals | Red forward assumptions | Green cross-sheet links
... B20: Waters Q1 2026 Earnings Presentation; Waters 1Q26 Financial Supplement; Waters Q1 2026 10-Q; Q1 2026 Non-GAAP Recs.

Sheet Summary
B2: Waters — Consolidated Summary
C4: Period | D4: 1Q | E4: 2Q | F4: 3Q | G4: 4Q | H4: FY | I4: 1Q | J4: 2Q | K4: 3Q | L4: 4Q | M4: FY | N4: 1Q | O4: 2Q | P4: 3Q | Q4: 4Q | R4: FY | S4: 1Q | T4: 2Q | U4: 3Q | V4: 4Q | W4: FY
C5: Fiscal Year (Dec YE) | D5: 25 | E5: =D5 -> 25 | F5: =E5 -> 25 | G5: =F5 -> 25 | H5: =G5 -> 25 | I5: =H5+1 -> 26 | J5: =I5 -> 26 | K5: =J5 -> 26 | L5: =K5 -> 26 | M5: =L5 -> 26 | N5: =M5+1 -> 27 | O5: =N5 -> 27 | P5: =O5 -> 27 | Q5: =P5 -> 27 | R5: =Q5 -> 27 | S5: =R5+1 -> 28 | T5: =S5 -> 28 | U5: =T5 -> 28 | V5: =U5 -> 28 | W5: =V5 -> 28
C7: Status | D7: REPORTED
C8: Reported (blank) or Estimate ("E") | J8: E | K8: E | L8: E | M8: E | N8: E | O8: E | P8: E | Q8: E | R8: E | S8: E | T8: E | U8: E | V8: E | W8: E
C9: Fiscal Period | D9: =D$4&D5&D8 -> 1Q25 | E9: =E$4&E5&E8 -> 2Q25 | F9: =F$4&F5&F8 -> 3Q25 | G9: =G$4&G5&G8 -> 4Q25 | H9: =H$4&H5&H8 -> FY25 | I9: =I$4&I5&I8 -> 1Q26 | J9: =J$4&J5&J8 -> 2Q26E | K9: =K$4&K5&K8 -> 3Q26E | ... W9: =W$4&W5&W8 -> FY28E
C10: Period end date | D10: 45745 | E10: 45836 | F10: 45927 | G10: 46022 | H10: 46022 | I10: 46116 | J10: 46207 | K10: 46298 | L10: 46387 | M10: 46387 | N10: 46480 | O10: 46571 | P10: 46662 | Q10: 46752 | R10: 46752 | S10: 46844 | T10: 46935 | U10: 47026 | V10: 47117 | W10: 47117
B11: TOTAL REVENUE
C12: Total Waters revenue ($M) | D12: =Model!D102 -> 1455 | E12: =Model!E102 -> 1553 | F12: =Model!F102 -> 1686 | G12: =Model!G102 -> 1699 | H12: =Model!H102 -> 6393 | I12: =Model!I102 -> 1267 | J12: =Model!J102 -> 1646.18 | K12: =Model!K102 -> 1787.16 | ... W12: =Model!W102 -> 7580.4382
C13: Reported Y/Y | D13: =Model!D103 -> 0 | E13: =Model!E103 -> 0 | F13: =Model!F103 -> 0 | G13: =Model!G103 -> 0 | H13: =Model!H103 -> 0 | I13: =Model!I103 -> -0.12920962 | J13: =Model!J103 -> 0.06 | K13: =Model!K103 -> 0.06 | ... W13: =Model!W103 -> 0.06
C14: Organic CC | D14: =Model!D104 -> 0 | E14: =Model!E104 -> 0 | F14: =Model!F104 -> 0 | G14: =Model!G104 -> 0 | H14: =Model!H104 -> 0 | I14: =Model!I104 -> 0.089353952 | J14: =Model!J104 -> 0.06 | K14: =Model!K104 -> 0.06 | ... W14: =Model!W104 -> 0.06
C15: M&A / Acquired | D15: =Model!D105 -> 0 | E15: =Model!E105 -> 0 | F15: =Model!F105 -> 0 | G15: =Model!G105 -> 0 | H15: =Model!H105 -> 0 | I15: =Model!I105 -> -0.23909966 | J15: =Model!J105 -> 0 | K15: =Model!K105 -> 0 | ... W15: =Model!W105 -> 0
C16: FX | D16: =Model!D106 -> 0 | E16: =Model!E106 -> 0 | F16: =Model!F106 -> 0 | G16: =Model!G106 -> 0 | H16: =Model!H106 -> 0 | I16: =Model!I106 -> 0.020536082 | J16: =Model!J106 -> 0 | K16: =Model!K106 -> 0 | ... W16: =Model!W106 -> 0
B18: BY DIVISION
C19: Analytical Sciences Division (ASD)
C20: Revenue ($M) | D20: =Model!D40 -> 534 | E20: =Model!E40 -> 625 | F20: =Model!F40 -> 650 | G20: =Model!G40 -> 732 | H20: =Model!H40 -> 2541 | I20: =Model!I40 -> 607 | J20: =Model!J40 -> 662.5 | K20: =Model!K40 -> 689 | ... W20: =Model!W40 -> 3072.3943
C21: Reported Y/Y | D21: =Model!D41 -> 0 | E21: =Model!E41 -> 0 | F21: =Model!F41 -> 0 | G21: =Model!G41 -> 0 | H21: =Model!H41 -> 0 | I21: =Model!I41 -> 0.13670412 | J21: =Model!J41 -> 0.06 | K21: =Model!K41 -> 0.06 | ... W21: =Model!W41 -> 0.06
C22: Organic | D22: =Model!D42 -> 0 | E22: =Model!E42 -> 0 | F22: =Model!F42 -> 0 | G22: =Model!G42 -> 0 | H22: =Model!H42 -> 0 | I22: =Model!I42 -> 0.11588015 | J22: =Model!J42 -> 0.06 | K22: =Model!K42 -> 0.06 | ... W22: =Model!W42 -> 0.06
C24: Biosciences Division (WBD)
C25: Revenue ($M) | D25: =Model!D57 -> 352 | E25: =Model!E57 -> 358 | F25: =Model!F57 -> 387 | G25: =Model!G57 -> 327 | H25: =Model!H57 -> 1424 | I25: =Model!I57 -> 233 | J25: =Model!J57 -> 379.48 | K25: =Model!K57 -> 410.22 | ... W25: =Model!W57 -> 1662.058
C26: Reported Y/Y | D26: =Model!D58 -> 0 | E26: =Model!E58 -> 0 | F26: =Model!F58 -> 0 | G26: =Model!G58 -> 0 | H26: =Model!H58 -> 0 | I26: =Model!I58 -> -0.33806818 | J26: =Model!J58 -> 0.06 | K26: =Model!K58 -> 0.06 | ... W26: =Model!W58 -> 0.06
C27: Organic | D27: =Model!D59 -> 0 | E27: =Model!E59 -> 0 | F27: =Model!F59 -> 0 | G27: =Model!G59 -> 0 | H27: =Model!H59 -> 0 | I27: =Model!I59 -> 0.07 | J27: =Model!J59 -> 0.06 | K27: =Model!K59 -> 0.06 | ... W27: =Model!W59 -> 0.06
C29: Advanced Diagnostics Division (ADX)
C30: Revenue ($M) | D30: =Model!D79 -> 494 | E30: =Model!E79 -> 488 | F30: =Model!F79 -> 562 | G30: =Model!G79 -> 532 | H30: =Model!H79 -> 2076 | I30: =Model!I79 -> 348 | J30: =Model!J79 -> 517.28 | K30: =Model!K79 -> 595.72 | ... W30: =Model!W79 -> 2427.3101
C31: Reported Y/Y | D31: =Model!D80 -> 0 | E31: =Model!E80 -> 0 | F31: =Model!F80 -> 0 | G31: =Model!G80 -> 0 | H31: =Model!H80 -> 0 | I31: =Model!I80 -> -0.29554656 | J31: =Model!J80 -> 0.06 | K31: =Model!K80 -> 0.06 | ... W31: =Model!W80 -> 0.06
C32: Organic | D32: =Model!D81 -> 0 | E32: =Model!E81 -> 0 | F32: =Model!F81 -> 0 | G32: =Model!G81 -> 0 | H32: =Model!H81 -> 0 | I32: =Model!I81 -> 0.085242915 | J32: =Model!J81 -> 0.06 | K32: =Model!K81 -> 0.06 | ... W32: =Model!W81 -> 0.06
C34: Materials Sciences Division (MSD)
C35: Revenue ($M) | D35: =Model!D96 -> 75 | E35: =Model!E96 -> 82 | F35: =Model!F96 -> 87 | G35: =Model!G96 -> 108 | H35: =Model!H96 -> 352 | I35: =Model!I96 -> 79 | J35: =Model!J96 -> 86.92 | K35: =Model!K96 -> 92.22 | ... W35: =Model!W96 -> 418.67583
C36: Reported Y/Y | D36: =Model!D97 -> 0 | E36: =Model!E97 -> 0 | F36: =Model!F97 -> 0 | G36: =Model!G97 -> 0 | H36: =Model!H97 -> 0 | I36: =Model!I97 -> 0.053333333 | J36: =Model!J97 -> 0.06 | K36: =Model!K97 -> 0.06 | ... W36: =Model!W97 -> 0.06
C37: Organic | D37: =Model!D98 -> 0 | E37: =Model!E98 -> 0 | F37: =Model!F98 -> 0 | G37: =Model!G98 -> 0 | H37: =Model!H98 -> 0 | I37: =Model!I98 -> 0.0184 | J37: =Model!J98 -> 0.06 | K37: =Model!K98 -> 0.06 | ... W37: =Model!W98 -> 0.06

Sheet Model
B2: Waters Quarterly Model — Revenue Bridge by Subsegment ($M)
C4: Period | D4: 1Q | E4: 2Q | F4: 3Q | G4: 4Q | H4: FY | I4: 1Q | J4: 2Q | K4: 3Q | L4: 4Q | M4: FY | N4: 1Q | O4: 2Q | P4: 3Q | Q4: 4Q | R4: FY | S4: 1Q | T4: 2Q | U4: 3Q | V4: 4Q | W4: FY
C5: Fiscal Year (Dec YE) | D5: 25 | E5: =D5 -> 25 | F5: =E5 -> 25 | G5: =F5 -> 25 | H5: =G5 -> 25 | I5: =H5+1 -> 26 | J5: =I5 -> 26 | K5: =J5 -> 26 | L5: =K5 -> 26 | M5: =L5 -> 26 | N5: =M5+1 -> 27 | O5: =N5 -> 27 | P5: =O5 -> 27 | Q5: =P5 -> 27 | R5: =Q5 -> 27 | S5: =R5+1 -> 28 | T5: =S5 -> 28 | U5: =T5 -> 28 | V5: =U5 -> 28 | W5: =V5 -> 28
C7: Status | D7: REPORTED
C8: Reported (blank) or Estimate ("E") | J8: E | K8: E | L8: E | M8: E | N8: E | O8: E | P8: E | Q8: E | R8: E | S8: E | T8: E | U8: E | V8: E | W8: E
C9: Fiscal Period | D9: =D$4&D5&D8 -> 1Q25 | E9: =E$4&E5&E8 -> 2Q25 | F9: =F$4&F5&F8 -> 3Q25 | G9: =G$4&G5&G8 -> 4Q25 | H9: =H$4&H5&H8 -> FY25 | I9: =I$4&I5&I8 -> 1Q26 | J9: =J$4&J5&J8 -> 2Q26E | K9: =K$4&K5&K8 -> 3Q26E | ... W9: =W$4&W5&W8 -> FY28E
C10: Period end date | D10: 45745 | E10: 45836 | F10: 45927 | G10: 46022 | H10: 46022 | I10: 46116 | J10: 46207 | K10: 46298 | L10: 46387 | M10: 46387 | N10: 46480 | O10: 46571 | P10: 46662 | Q10: 46752 | R10: 46752 | S10: 46844 | T10: 46935 | U10: 47026 | V10: 47117 | W10: 47117
B11: TOP-LINE SUMMARY (from bottom of tab)
C12: Total Waters revenue ($M) | D12: =D102 -> 1455 | E12: =E102 -> 1553 | F12: =F102 -> 1686 | G12: =G102 -> 1699 | H12: =H102 -> 6393 | I12: =I102 -> 1267 | J12: =J102 -> 1646.18 | K12: =K102 -> 1787.16 | ... W12: =W102 -> 7580.4382
C13: Reported Y/Y | D13: =D103 -> 0 | E13: =E103 -> 0 | F13: =F103 -> 0 | G13: =G103 -> 0 | H13: =H103 -> 0 | I13: =I103 -> -0.12920962 | J13: =J103 -> 0.06 | K13: =K103 -> 0.06 | ... W13: =W103 -> 0.06
C14: Organic CC | D14: =D104 -> 0 | E14: =E104 -> 0 | F14: =F104 -> 0 | G14: =G104 -> 0 | H14: =H104 -> 0 | I14: =I104 -> 0.089353952 | J14: =J104 -> 0.06 | K14: =K104 -> 0.06 | ... W14: =W104 -> 0.06
C15: M&A / Acquired | D15: =D105 -> 0 | E15: =E105 -> 0 | F15: =F105 -> 0 | G15: =G105 -> 0 | H15: =H105 -> 0 | I15: =I105 -> -0.23909966 | J15: =J105 -> 0 | K15: =K105 -> 0 | ... W15: =W105 -> 0
C16: FX | D16: =D106 -> 0 | E16: =E106 -> 0 | F16: =F106 -> 0 | G16: =G106 -> 0 | H16: =H106 -> 0 | I16: =I106 -> 0.020536082 | J16: =J106 -> 0 | K16: =K106 -> 0 | ... W16: =W106 -> 0
C18: Total adj op income ($M) | D18: =D125 -> 506.815 | E18: =E125 -> 426.86 | F18: =F125 -> 460.84 | G18: =G125 -> 467.14 | H18: =H125 -> 1861.655 | I18: =I125 -> 389.346 | J18: =J125 -> 452.4716 | K18: =K125 -> 488.4904 | ... W18: =W125 -> 2079.9467
C19: Adj op margin % | D19: =D126 -> 0.34832646 | E19: =E126 -> 0.27486156 | F19: =F126 -> 0.27333333 | G19: =G126 -> 0.27494997 | H19: =H126 -> 0.2912021 | I19: =I126 -> 0.30729755 | J19: =J126 -> 0.27486156 | K19: =K126 -> 0.27333333 | ... W19: =W126 -> 0.27438343
B22: REVENUE BUILD — BY DIVISION / SUBSEGMENT
C24: Analytical Sciences Division (ASD)
A25: 10-Q / Deck | C25: ASD - Instruments | D25: 194 | E25: 227 | F25: 236 | G25: 266 | H25: =D25+E25+F25+G25 -> 923 | I25: 210 | J25: =E25*(1+J27+J28+J29) -> 240.62 | K25: =F25*(1+K27+K28+K29) -> 250.16 | L25: =G25*(1+L27+L28+L29) -> 281.96 | M25: =I25+J25+K25+L25 -> 982.74 | N25: =I25*(1+N27+N28+N29) -> 222.6 | O25: =J25*(1+O27+O28+O29) -> 255.0572 | P25: =K25*(1+P27+P28+P29) -> 265.1696 | Q25: =L25*(1+Q27+Q28+Q29) -> 298.8776 | R25: =N25+O25+P25+Q25 -> 1041.7044 | S25: =N25*(1+S27+S28+S29) -> 235.956 | T25: =O25*(1+T27+T28+T29) -> 270.36063 | U25: =P25*(1+U27+U28+U29) -> 281.07978 | V25: =Q25*(1+V27+V28+V29) -> 316.81026 | W25: =S25+T25+U25+V25 -> 1104.2067
C26: Reported Y/Y | I26: =IFERROR(I25/D25-1,0) -> 0.082474227 | J26: =J27+J28+J29 -> 0.06 | K26: =K27+K28+K29 -> 0.06 | L26: =L27+L28+L29 -> 0.06 | M26: =IFERROR(M25/H25-1,0) -> 0.064723727 | N26: =N27+N28+N29 -> 0.06 | O26: =O27+O28+O29 -> 0.06 | P26: =P27+P28+P29 -> 0.06 | Q26: =Q27+Q28+Q29 -> 0.06 | R26: =IFERROR(R25/M25-1,0) -> 0.06 | S26: =S27+S28+S29 -> 0.06 | T26: =T27+T28+T29 -> 0.06 | U26: =U27+U28+U29 -> 0.06 | V26: =V27+V28+V29 -> 0.06 | W26: =IFERROR(W25/R25-1,0) -> 0.06
C27: Organic | I27: 0.08 | J27: 0.06 | K27: 0.06 | L27: 0.06 | M27: =IFERROR(((I27*D25)+(J27*E25)+(K27*F25)+(L27*G25))/(D25+E25+F25+G25),0) -> 0.064203684 | N27: 0.06 | O27: 0.06 | P27: 0.06 | Q27: 0.06 | R27: =IFERROR(((N27*I25)+(O27*J25)+(P27*K25)+(Q27*L25))/(I25+J25+K25+L25),0) -> 0.06 | S27: 0.06 | T27: 0.06 | U27: 0.06 | V27: 0.06 | W27: =IFERROR(((S27*N25)+(T27*O25)+(U27*P25)+(V27*Q25))/(N25+O25+P25+Q25),0) -> 0.06
C28: M&A / Acquired | I28: =I26-I27-I29 -> 0.0024742268 | J28: 0 | K28: 0 | L28: 0 | M28: =IFERROR(((I28*D25)+(J28*E25)+(K28*F25)+(L28*G25))/(D25+E25+F25+G25),0) -> 0.00052004334 | N28: 0 | O28: 0 | P28: 0 | Q28: 0 | R28: =IFERROR(((N28*I25)+(O28*J25)+(P28*K25)+(Q28*L25))/(I25+J25+K25+L25),0) -> 0 | S28: 0 | T28: 0 | U28: 0 | V28: 0 | W28: =IFERROR(((S28*N25)+(T28*O25)+(U28*P25)+(V28*Q25))/(N25+O25+P25+Q25),0) -> 0
C29: FX | I29: 0 | J29: 0 | K29: 0 | L29: 0 | M29: =IFERROR(((I29*D25)+(J29*E25)+(K29*F25)+(L29*G25))/(D25+E25+F25+G25),0) -> 0 | N29: 0 | O29: 0 | P29: 0 | Q29: 0 | R29: =IFERROR(((N29*I25)+(O29*J25)+(P29*K25)+(Q29*L25))/(I25+J25+K25+L25),0) -> 0 | S29: 0 | T29: 0 | U29: 0 | V29: 0 | W29: =IFERROR(((S29*N25)+(T29*O25)+(U29*P25)+(V29*Q25))/(N25+O25+P25+Q25),0) -> 0
A30: 10-Q / Deck | C30: ASD - Service | D30: 216 | E30: 253 | F30: 263 | G30: 296 | H30: =D30+E30+F30+G30 -> 1028 | I30: 253 | J30: =E30*(1+J32+J33+J34) -> 268.18 | K30: =F30*(1+K32+K33+K34) -> 278.78 | L30: =G30*(1+L32+L33+L34) -> 313.76 | M30: =I30+J30+K30+L30 -> 1113.72 | N30: =I30*(1+N32+N33+N34) -> 268.18 | O30: =J30*(1+O32+O33+O34) -> 284.2708 | P30: =K30*(1+P32+P33+P34) -> 295.5068 | Q30: =L30*(1+Q32+Q33+Q34) -> 332.5856 | R30: =N30+O30+P30+Q30 -> 1180.5432 | S30: =N30*(1+S32+S33+S34) -> 284.2708 | T30: =O30*(1+T32+T33+T34) -> 301.32705 | U30: =P30*(1+U32+U33+U34) -> 313.23721 | V30: =Q30*(1+V32+V33+V34) -> 352.54074 | W30: =S30+T30+U30+V30 -> 1251.3758
C31: Reported Y/Y | I31: =IFERROR(I30/D30-1,0) -> 0.1712963 | J31: =J32+J33+J34 -> 0.06 | K31: =K32+K33+K34 -> 0.06 | L31: =L32+L33+L34 -> 0.06 | M31: =IFERROR(M30/H30-1,0) -> 0.083385214 | N31: =N32+N33+N34 -> 0.06 | O31: =O32+O33+O34 -> 0.06 | P31: =P32+P33+P34 -> 0.06 | Q31: =Q32+Q33+Q34 -> 0.06 | R31: =IFERROR(R30/M30-1,0) -> 0.06 | S31: =S32+S33+S34 -> 0.06 | T31: =T32+T33+T34 -> 0.06 | U31: =U32+U33+U34 -> 0.06 | V31: =V32+V33+V34 -> 0.06 | W31: =IFERROR(W30/R30-1,0) -> 0.06
C32: Organic | I32: 0.14 | J32: 0.06 | K32: 0.06 | L32: 0.06 | M32: =IFERROR(((I32*D30)+(J32*E30)+(K32*F30)+(L32*G30))/(D30+E30+F30+G30),0) -> 0.076809339 | N32: 0.06 | O32: 0.06 | P32: 0.06 | Q32: 0.06 | R32: =IFERROR(((N32*I30)+(O32*J30)+(P32*K30)+(Q32*L30))/(I30+J30+K30+L30),0) -> 0.06 | S32: 0.06 | T32: 0.06 | U32: 0.06 | V32: 0.06 | W32: =IFERROR(((S32*N30)+(T32*O30)+(U32*P30)+(V32*Q30))/(N30+O30+P30+Q30),0) -> 0.06
C33: M&A / Acquired | I33: =I31-I32-I34 -> 0.0012962963 | J33: 0 | K33: 0 | L33: 0 | M33: =IFERROR(((I33*D30)+(J33*E30)+(K33*F30)+(L33*G30))/(D30+E30+F30+G30),0) -> 0.00027237354 | N33: 0 | O33: 0 | P33: 0 | Q33: 0 | R33: =IFERROR(((N33*I30)+(O33*J30)+(P33*K30)+(Q33*L30))/(I30+J30+K30+L30),0) -> 0 | S33: 0 | T33: 0 | U33: 0 | V33: 0 | W33: =IFERROR(((S33*N30)+(T33*O30)+(U33*P30)+(V33*Q30))/(N30+O30+P30+Q30),0) -> 0
C34: FX | I34: 0.03 | J34: 0 | K34: 0 | L34: 0 | M34: =IFERROR(((I34*D30)+(J34*E30)+(K34*F30)+(L34*G30))/(D30+E30+F30+G30),0) -> 0.0063035019 | N34: 0 | O34: 0 | P34: 0 | Q34: 0 | R34: =IFERROR(((N34*I30)+(O34*J30)+(P34*K30)+(Q34*L30))/(I30+J30+K30+L30),0) -> 0 | S34: 0 | T34: 0 | U34: 0 | V34: 0 | W34: =IFERROR(((S34*N30)+(T34*O30)+(U34*P30)+(V34*Q30))/(N30+O30+P30+Q30),0) -> 0
A35: 10-Q / Deck | C35: ASD - Chemistry | D35: 124 | E35: 145 | F35: 151 | G35: 170 | H35: =D35+E35+F35+G35 -> 590 | I35: 144 | J35: =E35*(1+J37+J38+J39) -> 153.7 | K35: =F35*(1+K37+K38+K39) -> 160.06 | L35: =G35*(1+L37+L38+L39) -> 180.2 | M35: =I35+J35+K35+L35 -> 637.96 | N35: =I35*(1+N37+N38+N39) -> 152.64 | O35: =J35*(1+O37+O38+O39) -> 162.922 | P35: =K35*(1+P37+P38+P39) -> 169.6636 | Q35: =L35*(1+Q37+Q38+Q39) -> 191.012 | R35: =N35+O35+P35+Q35 -> 676.2376 | S35: =N35*(1+S37+S38+S39) -> 161.7984 | T35: =O35*(1+T37+T38+T39) -> 172.69732 | U35: =P35*(1+U37+U38+U39) -> 179.84342 | V35: =Q35*(1+V37+V38+V39) -> 202.47272 | W35: =S35+T35+U35+V35 -> 716.81186
C36: Reported Y/Y | I36: =IFERROR(I35/D35-1,0) -> 0.16129032 | J36: =J37+J38+J39 -> 0.06 | K36: =K37+K38+K39 -> 0.06 | L36: =L37+L38+L39 -> 0.06 | M36: =IFERROR(M35/H35-1,0) -> 0.081288136 | N36: =N37+N38+N39 -> 0.06 | O36: =O37+O38+O39 -> 0.06 | P36: =P37+P38+P39 -> 0.06 | Q36: =Q37+Q38+Q39 -> 0.06 | R36: =IFERROR(R35/M35-1,0) -> 0.06 | S36: =S37+S38+S39 -> 0.06 | T36: =T37+T38+T39 -> 0.06 | U36: =U37+U38+U39 -> 0.06 | V36: =V37+V38+V39 -> 0.06 | W36: =IFERROR(W35/R35-1,0) -> 0.06
C37: Organic | I37: 0.13 | J37: 0.06 | K37: 0.06 | L37: 0.06 | M37: =IFERROR(((I37*D35)+(J37*E35)+(K37*F35)+(L37*G35))/(D35+E35+F35+G35),0) -> 0.074711864 | N37: 0.06 | O37: 0.06 | P37: 0.06 | Q37: 0.06 | R37: =IFERROR(((N37*I35)+(O37*J35)+(P37*K35)+(Q37*L35))/(I35+J35+K35+L35),0) -> 0.06 | S37: 0.06 | T37: 0.06 | U37: 0.06 | V37: 0.06 | W37: =IFERROR(((S37*N35)+(T37*O35)+(U37*P35)+(V37*Q35))/(N35+O35+P35+Q35),0) -> 0.06
C38: M&A / Acquired | I38: =I36-I37-I39 -> 0.0012903226 | J38: 0 | K38: 0 | L38: 0 | M38: =IFERROR(((I38*D35)+(J38*E35)+(K38*F35)+(L38*G35))/(D35+E35+F35+G35),0) -> 0.00027118644 | N38: 0 | O38: 0 | P38: 0 | Q38: 0 | R38: =IFERROR(((N38*I35)+(O38*J35)+(P38*K35)+(Q38*L35))/(I35+J35+K35+L35),0) -> 0 | S38: 0 | T38: 0 | U38: 0 | V38: 0 | W38: =IFERROR(((S38*N35)+(T38*O35)+(U38*P35)+(V38*Q35))/(N35+O35+P35+Q35),0) -> 0
C39: FX | I39: 0.03 | J39: 0 | K39: 0 | L39: 0 | M39: =IFERROR(((I39*D35)+(J39*E35)+(K39*F35)+(L39*G35))/(D35+E35+F35+G35),0) -> 0.0063050847 | N39: 0 | O39: 0 | P39: 0 | Q39: 0 | R39: =IFERROR(((N39*I35)+(O39*J35)+(P39*K35)+(Q39*L35))/(I35+J35+K35+L35),0) -> 0 | S39: 0 | T39: 0 | U39: 0 | V39: 0 | W39: =IFERROR(((S39*N35)+(T39*O35)+(U39*P35)+(V39*Q35))/(N35+O35+P35+Q35),0) -> 0
C40: Analytical Sciences Division (ASD) — Total | D40: =D25+D30+D35 -> 534 | E40: =E25+E30+E35 -> 625 | F40: =F25+F30+F35 -> 650 | G40: =G25+G30+G35 -> 732 | H40: =H25+H30+H35 -> 2541 | I40: =I25+I30+I35 -> 607 | J40: =J25+J30+J35 -> 662.5 | K40: =K25+K30+K35 -> 689 | ... W40: =W25+W30+W35 -> 3072.3943
C41: Reported Y/Y | I41: =IFERROR(I40/D40-1,0) -> 0.13670412 | J41: =IFERROR(J40/E40-1,0) -> 0.06 | K41: =IFERROR(K40/F40-1,0) -> 0.06 | L41: =IFERROR(L40/G40-1,0) -> 0.06 | M41: =IFERROR(M40/H40-1,0) -> 0.076119638 | N41: =IFERROR(N40/I40-1,0) -> 0.06 | O41: =IFERROR(O40/J40-1,0) -> 0.06 | P41: =IFERROR(P40/K40-1,0) -> 0.06 | ... W41: =IFERROR(W40/R40-1,0) -> 0.06
C42: Organic | I42: =IFERROR(((I27*D25)+(I32*D30)+(I37*D35))/(D25+D30+D35),0) -> 0.11588015 | J42: =IFERROR(((J27*E25)+(J32*E30)+(J37*E35))/(E25+E30+E35),0) -> 0.06 | K42: =IFERROR(((K27*F25)+(K32*F30)+(K37*F35))/(F25+F30+F35),0) -> 0.06 | L42: =IFERROR(((L27*G25)+(L32*G30)+(L37*G35))/(G25+G30+G35),0) -> 0.06 | M42: =IFERROR(((I42*D40)+(J42*E40)+(K42*F40)+(L42*G40))/(D40+E40+F40+G40),0) -> 0.071743408 | N42: =IFERROR(((N27*I25)+(N32*I30)+(N37*I35))/(I25+I30+I35),0) -> 0.06 | O42: =IFERROR(((O27*J25)+(O32*J30)+(O37*J35))/(J25+J30+J35),0) -> 0.06 | P42: =IFERROR(((P27*K25)+(P32*K30)+(P37*K35))/(K25+K30+K35),0) -> 0.06 | Q42: =IFERROR(((Q27*L25)+(Q32*L30)+(Q37*L35))/(L25+L30+L35),0) -> 0.06 | R42: =IFERROR(((N42*I40)+(O42*J40)+(P42*K40)+(Q42*L40))/(I40+J40+K40+L40),0) -> 0.06 | S42: =IFERROR(((S27*N25)+(S32*N30)+(S37*N35))/(N25+N30+N35),0) -> 0.06 | T42: =IFERROR(((T27*O25)+(T32*O30)+(T37*O35))/(O25+O30+O35),0) -> 0.06 | U42: =IFERROR(((U27*P25)+(U32*P30)+(U37*P35))/(P25+P30+P35),0) -> 0.06 | V42: =IFERROR(((V27*Q25)+(V32*Q30)+(V37*Q35))/(Q25+Q30+Q35),0) -> 0.06 | W42: =IFERROR(((S42*N40)+(T42*O40)+(U42*P40)+(V42*Q40))/(N40+O40+P40+Q40),0) -> 0.06
C43: M&A / Acquired | I43: =IFERROR(((I28*D25)+(I33*D30)+(I38*D35))/(D25+D30+D35),0) -> 0.0017228464 | J43: =IFERROR(((J28*E25)+(J33*E30)+(J38*E35))/(E25+E30+E35),0) -> 0 | K43: =IFERROR(((K28*F25)+(K33*F30)+(K38*F35))/(F25+F30+F35),0) -> 0 | L43: =IFERROR(((L28*G25)+(L33*G30)+(L38*G35))/(G25+G30+G35),0) -> 0 | M43: =IFERROR(((I43*D40)+(J43*E40)+(K43*F40)+(L43*G40))/(D40+E40+F40+G40),0) -> 0.00036206218 | N43: =IFERROR(((N28*I25)+(N33*I30)+(N38*I35))/(I25+I30+I35),0) -> 0 | O43: =IFERROR(((O28*J25)+(O33*J30)+(O38*J35))/(J25+J30+J35),0) -> 0 | P43: =IFERROR(((P28*K25)+(P33*K30)+(P38*K35))/(K25+K30+K35),0) -> 0 | Q43: =IFERROR(((Q28*L25)+(Q33*L30)+(Q38*L35))/(L25+L30+L35),0) -> 0 | R43: =IFERROR(((N43*I40)+(O43*J40)+(P43*K40)+(Q43*L40))/(I40+J40+K40+L40),0) -> 0 | S43: =IFERROR(((S28*N25)+(S33*N30)+(S38*N35))/(N25+N30+N35),0) -> 0 | T43: =IFERROR(((T28*O25)+(T33*O30)+(T38*O35))/(O25+O30+O35),0) -> 0 | U43: =IFERROR(((U28*P25)+(U33*P30)+(U38*P35))/(P25+P30+P35),0) -> 0 | V43: =IFERROR(((V28*Q25)+(V33*Q30)+(V38*Q35))/(Q25+Q30+Q35),0) -> 0 | W43: =IFERROR(((S43*N40)+(T43*O40)+(U43*P40)+(V43*Q40))/(N40+O40+P40+Q40),0) -> 0
C44: FX | I44: =IFERROR(((I29*D25)+(I34*D30)+(I39*D35))/(D25+D30+D35),0) -> 0.019101124 | J44: =IFERROR(((J29*E25)+(J34*E30)+(J39*E35))/(E25+E30+E35),0) -> 0 | K44: =IFERROR(((K29*F25)+(K34*F30)+(K39*F35))/(F25+F30+F35),0) -> 0 | L44: =IFERROR(((L29*G25)+(L34*G30)+(L39*G35))/(G25+G30+G35),0) -> 0 | M44: =IFERROR(((I44*D40)+(J44*E40)+(K44*F40)+(L44*G40))/(D40+E40+F40+G40),0) -> 0.0040141677 | N44: =IFERROR(((N29*I25)+(N34*I30)+(N39*I35))/(I25+I30+I35),0) -> 0 | O44: =IFERROR(((O29*J25)+(O34*J30)+(O39*J35))/(J25+J30+J35),0) -> 0 | P44: =IFERROR(((P29*K25)+(P34*K30)+(P39*K35))/(K25+K30+K35),0) -> 0 | Q44: =IFERROR(((Q29*L25)+(Q34*L30)+(Q39*L35))/(L25+L30+L35),0) -> 0 | R44: =IFERROR(((N44*I40)+(O44*J40)+(P44*K40)+(Q44*L40))/(I40+J40+K40+L40),0) -> 0 | S44: =IFERROR(((S29*N25)+(S34*N30)+(S39*N35))/(N25+N30+N35),0) -> 0 | T44: =IFERROR(((T29*O25)+(T34*O30)+(T39*O35))/(O25+O30+O35),0) -> 0 | U44: =IFERROR(((U29*P25)+(U34*P30)+(U39*P35))/(P25+P30+P35),0) -> 0 | V44: =IFERROR(((V29*Q25)+(V34*Q30)+(V39*Q35))/(Q25+Q30+Q35),0) -> 0 | W44: =IFERROR(((S44*N40)+(T44*O40)+(U44*P40)+(V44*Q40))/(N40+O40+P40+Q40),0) -> 0
C46: Biosciences Division (WBD)
A47: BD-acquired | C47: WBD - Flow Research | D47: 198 | E47: 201 | F47: 218 | G47: 184 | H47: =D47+E47+F47+G47 -> 801 | I47: 131 | J47: =E47*(1+J49+J50+J51) -> 213.06 | K47: =F47*(1+K49+K50+K51) -> 231.08 | L47: =G47*(1+L49+L50+L51) -> 195.04 | M47: =I47+J47+K47+L47 -> 770.18 | N47: =I47*(1+N49+N50+N51) -> 204.36 | O47: =J47*(1+O49+O50+O51) -> 225.8436 | P47: =K47*(1+P49+P50+P51) -> 244.9448 | Q47: =L47*(1+Q49+Q50+Q51) -> 206.7424 | R47: =N47+O47+P47+Q47 -> 881.8908 | S47: =N47*(1+S49+S50+S51) -> 216.6216 | T47: =O47*(1+T49+T50+T51) -> 239.39422 | U47: =P47*(1+U49+U50+U51) -> 259.64149 | V47: =Q47*(1+V49+V50+V51) -> 219.14694 | W47: =S47+T47+U47+V47 -> 934.80425
C48: Reported Y/Y | I48: =IFERROR(I47/D47-1,0) -> -0.33838384 | J48: =J49+J50+J51 -> 0.06 | K48: =K49+K50+K51 -> 0.06 | L48: =L49+L50+L51 -> 0.06 | M48: =IFERROR(M47/H47-1,0) -> -0.038476904 | N48: =N49+N50+N51 -> 0.56 | O48: =O49+O50+O51 -> 0.06 | P48: =P49+P50+P51 -> 0.06 | Q48: =Q49+Q50+Q51 -> 0.06 | R48: =IFERROR(R47/M47-1,0) -> 0.14504505 | S48: =S49+S50+S51 -> 0.06 | T48: =T49+T50+T51 -> 0.06 | U48: =U49+U50+U51 -> 0.06 | V48: =V49+V50+V51 -> 0.06 | W48: =IFERROR(W47/R47-1,0) -> 0.06
...

Sheet Upside
B2: Waters Model vs Guidance
B4: Metric | C4: FY26 Guide | D4: FY26 Model | E4: FY26 Δ | F4: FY27 Model | G4: FY28 Model
B5: Total revenue ($M) | C5: 6430 | D5: =Model!M102 -> 6501.28 | E5: =IFERROR((D5-C5)/C5,0) -> 0.011085537 | F5: =Model!R102 -> 7151.3568 | G5: =Model!W102 -> 7580.4382
B6: Organic CC growth % | C6: 0.0725 | D6: =Model!M104 -> 0.066680745 | E6: =D6-C6 -> -0.0058192554 | F6: =Model!R104 -> 0.06 | G6: =Model!W104 -> 0.06
B7: Adj op income ($M) | C7: 1813 | D7: =Model!M125 -> 1825.4764 | E7: =IFERROR((D7-C7)/C7,0) -> 0.0068816327 | F7: =Model!R125 -> 1962.2138 | G7: =Model!W125 -> 2079.9467
B8: Adj op margin % | C8: =C7/C5 -> 0.28195956 | D8: =D7/D5 -> 0.28078723 | E8: =D8-C8 -> -0.0011723349 | F8: =F7/F5 -> 0.27438343 | G8: =G7/G5 -> 0.27438343
